Workbook

Sheet READ ME
B1: Ashok Leyland model — clean-up READ ME
B2: Structure, formatting and audit conventions. No number in this workbook was changed.
B4: COLOUR CODE
B5: 1,234 | C5: Blue — Hardcoded input. Typed number. Change these freely.
B6: 1,234 | C6: Blue on amber — Formula built only from hardcoded numbers, e.g. =8835+8903+12146. An input in disguise.
B7: 1,234 | C7: Black — Formula referencing cells on the same sheet. Do not overtype.
B8: 1,234 | C8: Black on amber — Formula with a hardcoded plug inside it, e.g. =+C41-1722.094 or =+AH20*0.21. Undocumented assumption — audit these first.
B9: 1,234 | C9: Green — Link to another sheet in this workbook.
B10: 1,234 | C10: Red on amber — Broken formula returning #REF!. Source has been deleted.
B12: CELL COUNTS BY TYPE
B13: Sheet | C13: Main Model | D13: New Qrtrly - Ind AS | E13: New Qrtrly | F13: DCF | G13: Comments
B14: Hardcoded inputs | C14: 2833 | D14: 870 | E14: 564 | F14: 19 | G14: 401
B15: Formulas made only of hardcodes | C15: 592 | D15: 137 | E15: 136 | F15: 8 | G15: 8
B16: Clean formulas | C16: 15502 | D16: 2806 | E16: 1576 | F16: 91 | G16: 108
B17: Formulas with a hardcoded plug | C17: 535 | D17: 173 | E17: 37 | F17: 0 | G17: 10
B18: Cross-sheet links | C18: 0 | D18: 91 | E18: 3 | F18: 23 | G18: 0
B19: Broken (#REF!) | C19: 0 | D19: 0 | E19: 0 | F19: 0 | G19: 3
B20: Text | C20: 986 | D20: 416 | E20: 165 | F20: 55 | G20: 692
B22: WHAT CHANGED
B23: Quarters vs years | C23: On "New Qrtrly - Ind AS" the annual columns (FY16, FY17, FY26E) no longer sit inside the run of quarters. They are in their own ANNUAL block to the right.
B24: Estimates vs actuals | C24: The interleaved E / A pairs are split into two blocks: QUARTERLY — ACTUALS (49 columns) and QUARTERLY — BSe ESTIMATES (30 columns), each in date order. The side-by-side comparison you lose is rebuilt live on the "Est vs Act" tab.
B25: Workings | C25: Unheaded scratch columns (old CE, CF, CH, CI, CJ, CK) are parked in a WORKINGS / CHECKS block at the far right instead of trailing the estimates.
B26: Blank rows | C26: All blank rows removed. Content is now grouped under 15 titled section bands.
B27: Duplicate labels | C27: 8 empty legacy label rows deleted (pre-Ind-AS margin and cost-ratio lines that were superseded by the rows below them). Listed on the Issues tab.
B28: Orphan rows | C28: Four unlabelled rows that carried live formulas are grouped under ORPHAN CALC ROWS. Nothing references them.
B29: Headers | C29: Two-row header: fiscal year over period, frozen. A small grey row records each column's original letter, so anything can be traced back to the source file.
B30: Number formats | C30: One consistent format per row, derived from the values in that row. Rows formatted as % but holding non-percentage values were reformatted — flagged on the Issues tab.
B31: Formulas | C31: All 3,207 formulas on the restructured sheet were re-pointed to the new addresses. Every one of the 9,416 data cells was checked against the original: zero differences.
B32: Not changed | C32: No value, no formula logic, no estimate on this sheet.
B34: MAIN MODEL — WHAT CHANGED
B35: Rows | C35: 1,048 rows cut to 780. 256 fully-blank rows removed, plus 12 rows that were 100% #REF! errors and referenced by nothing (an old chart-data block and an orphaned duplicate of it — see Issues). Two blank-looking rows that a live formula still pointed at were deliberately kept.
B36: Columns | C36: Columns AZ:IJ (193 of them) held no data anywhere in the sheet and nothing referenced them. Deleted. Data now runs A:AY.
B37: Section headers | C37: 64 section-title rows (SOURCES OF FUNDS, Costing, Balance Sheet, Cash Flow statement, and similar) now get a shaded banner across the row, so the sheet reads in blocks on screen instead of as one continuous grid.
B38: Borders on key lines | C38: ~78 subtotal/total rows — Net Revenue, EBITDA, PBT, PAT, Total Sources/Application of Funds, the three Cash Flow subtotals, and similar — get a border above and below. These were identified from the bold formatting the original analyst had already applied to those exact lines, not re-guessed.
B39: Number formats | C39: One consistent format per row, derived from that row's own values — whole numbers for INR m lines, one decimal for smaller figures, "x" for multiples, percent for ratio lines.
B40: Colour code | C40: Same key as the rest of the workbook — blue inputs, black formulas, green cross-sheet links, amber-filled cells where a formula has a hardcoded plug buried in it, red for broken formulas.
B41: Formulas | C41: All 22,157 formulas were re-pointed to the new row numbers, including the 46 cross-sheet formulas in DCF and the quarterly sheets that read from Main Model. Every one of the 39,780 surviving cells was checked against the original: zero differences. Total Sources of Funds still ties to Total Application of Funds at every forecast year, exactly as before.
B42: Errors | C42: Total workbook formula errors fell from 738 to 420 — the 318 dead #REF! cells were in the rows that got removed. The remaining 420 (414 #DIV/0!, 5 #REF!, 1 #VALUE!) are pre-existing and untouched; see Issues.
B43: Not changed | C43: No value, no formula logic, no forecast. Column order is exactly as before — this pass only removed rows/columns that were empty or dead, it did not reorganise the model.
B45: TABS
...

Sheet Issues
B1: Issues found — for your call, not mine
B2: Nothing below was changed in the workbook. Each is preserved exactly as it was in the source file.
B4: Sheet | C4: Where | D4: What
B5: New Qrtrly - Ind AS (restructured) | C5: row 4: "H / MCVs" | D5: Row mixes magnitudes — it holds both sub-1 ratios and figures in the thousands, so it is carrying two different quantities on one line. Shown to 2dp so both are readable; values unchanged.
B6: New Qrtrly - Ind AS (restructured) | C6: row 5: "LCVs" | D6: Row mixes magnitudes — it holds both sub-1 ratios and figures in the thousands, so it is carrying two different quantities on one line. Shown to 2dp so both are readable; values unchanged.
B7: New Qrtrly - Ind AS (restructured) | C7: row 6: "Total CVs" | D7: Row mixes magnitudes — it holds both sub-1 ratios and figures in the thousands, so it is carrying two different quantities on one line. Shown to 2dp so both are readable; values unchanged.
B8: New Qrtrly - Ind AS (restructured) | C8: row 7: "Product mix (%)" | D8: Row mixes magnitudes — it holds both sub-1 ratios and figures in the thousands, so it is carrying two different quantities on one line. Shown to 2dp so both are readable; values unchanged.
B9: New Qrtrly - Ind AS (restructured) | C9: row 11: "H / MCVs" | D9: Row mixes magnitudes — it holds both sub-1 ratios and figures in the thousands, so it is carrying two different quantities on one line. Shown to 2dp so both are readable; values unchanged.
B10: New Qrtrly - Ind AS (restructured) | C10: row 17: "Discounts" | D10: Row mixes magnitudes — it holds both sub-1 ratios and figures in the thousands, so it is carrying two different quantities on one line. Shown to 2dp so both are readable; values unchanged.
B11: New Qrtrly - Ind AS (restructured) | C11: row 22: "Net sales" | D11: Row mixes magnitudes — it holds both sub-1 ratios and figures in the thousands, so it is carrying two different quantities on one line. Shown to 2dp so both are readable; values unchanged.
B12: New Qrtrly - Ind AS (restructured) | C12: row 31: "EBITDA" | D12: Row mixes magnitudes — it holds both sub-1 ratios and figures in the thousands, so it is carrying two different quantities on one line. Shown to 2dp so both are readable; values unchanged.
B13: New Qrtrly - Ind AS (restructured) | C13: row 38: "Exceptional income" | D13: Row mixes magnitudes — it holds both sub-1 ratios and figures in the thousands, so it is carrying two different quantities on one line. Shown to 2dp so both are readable; values unchanged.
B14: New Qrtrly - Ind AS (restructured) | C14: row 42: "PAT (pre exceptionals)" | D14: Row mixes magnitudes — it holds both sub-1 ratios and figures in the thousands, so it is carrying two different quantities on one line. Shown to 2dp so both are readable; values unchanged.
B15: New Qrtrly - Ind AS (restructured) | C15: row 46: "" | D15: Row mixes magnitudes — it holds both sub-1 ratios and figures in the thousands, so it is carrying two different quantities on one line. Shown to 2dp so both are readable; values unchanged.
... B34: Main Model | C34: Borders and section shading — what was used | D34: Borders were added to ~78 rows that are genuine subtotals/totals (Net Revenue, EBITDA, PBT, PAT, Total Sources/Application of Funds, the three Cash Flow subtotals, etc.), identified from the labels the original analyst had already bolded — not guessed from scratch. 64 section-header rows (SOURCES OF FUNDS, Costing, Balance Sheet, Cash Flow statement, and similar) got banner shading the same way. A handful of bold-but-clearly-fragment rows (a mid-sentence continuation, an analyst's personal note "Re do FY93") were left alone rather than mis-treated as headers.

Sheet Industry launches and cap
A2: 41401
A3: Daimler Trucks -
A4: Still a niche player – BUT – has strong market shares in certain segments – eg – 30% market share in the Kerala construction market (small). Has 8-9% market share in Mumbai – which accounts for around 8-9% of overall CV sales.
A5: 40% of all trucks bought are through Bharat Benz Financial services
A6: Daimler trucks – launched 3 new models – 914 Rigid, 1214 construction and 1217 tipper. Will launch 6 more models end of 2013 – taking its overall tally to 12. Will launch overall 17 trucks – will have 110 dealers by that time

Sheet Est vs Act
A1: Ashok Leyland — reported vs BSe estimate
A2: Rebuilt from the restructured quarterly sheet. Every figure is a live link — nothing is typed. This replaces the side-by-side E/A columns that used to be interleaved.
A4: Quarter | B4: Total CVs (nos.) | E4: Net sales (INR m) | H4: EBITDA (INR m) | K4: EBITDA margin (%) | N4: PAT pre-except. (INR m)
B5: BSe | C5: Act | D5: Var | E5: BSe | F5: Act | G5: Var | H5: BSe | I5: Act | J5: Var | K5: BSe | L5: Act | M5: Var | N5: BSe | O5: Act | P5: Var
A6: 4QFY19 | B6: ='New Qrtrly - Ind AS'!AZ11 -> 59521 | C6: ='New Qrtrly - Ind AS'!U11 -> 59521 | D6: =IFERROR('New Qrtrly - Ind AS'!U11/'New Qrtrly - Ind AS'!AZ11-1,"") -> 0 | E6: ='New Qrtrly - Ind AS'!AZ33 -> 85167.782 | F6: ='New Qrtrly - Ind AS'!U33 -> 88459.3 | G6: =IFERROR('New Qrtrly - Ind AS'!U33/'New Qrtrly - Ind AS'!AZ33-1,"") -> 0.038647456 | H6: ='New Qrtrly - Ind AS'!AZ40 -> 9096.9789 | I6: ='New Qrtrly - Ind AS'!U40 -> 9854.4 | J6: =IFERROR('New Qrtrly - Ind AS'!U40/'New Qrtrly - Ind AS'!AZ40-1,"") -> 0.083260726 | K6: ='New Qrtrly - Ind AS'!AZ61 -> 10.681244 | L6: ='New Qrtrly - Ind AS'!U61 -> 11.140038 | M6: =IFERROR(('New Qrtrly - Ind AS'!U61-'New Qrtrly - Ind AS'!AZ61)*100,"") -> 45.879402 | N6: ='New Qrtrly - Ind AS'!AZ51 -> 5618.9842 | O6: ='New Qrtrly - Ind AS'!U51 -> 6611.66 | P6: =IFERROR('New Qrtrly - Ind AS'!U51/'New Qrtrly - Ind AS'!AZ51-1,"") -> 0.17666464
A7: 1QFY20 | B7: ='New Qrtrly - Ind AS'!BA11 -> 39608 | C7: ='New Qrtrly - Ind AS'!V11 -> 39608 | D7: =IFERROR('New Qrtrly - Ind AS'!V11/'New Qrtrly - Ind AS'!BA11-1,"") -> 0 | E7: ='New Qrtrly - Ind AS'!BA33 -> 58864.87 | F7: ='New Qrtrly - Ind AS'!V33 -> 56838.6 | G7: =IFERROR('New Qrtrly - Ind AS'!V33/'New Qrtrly - Ind AS'!BA33-1,"") -> -0.034422406 | H7: ='New Qrtrly - Ind AS'!BA40 -> 4482.1637 | I7: ='New Qrtrly - Ind AS'!V40 -> 5369.7 | J7: =IFERROR('New Qrtrly - Ind AS'!V40/'New Qrtrly - Ind AS'!BA40-1,"") -> 0.19801514 | K7: ='New Qrtrly - Ind AS'!BA61 -> 7.614327 | L7: ='New Qrtrly - Ind AS'!V61 -> 9.447277 | M7: =IFERROR(('New Qrtrly - Ind AS'!V61-'New Qrtrly - Ind AS'!BA61)*100,"") -> 183.295 | N7: ='New Qrtrly - Ind AS'!BA51 -> 2529.1228 | O7: ='New Qrtrly - Ind AS'!V51 -> 2442.97 | P7: =IFERROR('New Qrtrly - Ind AS'!V51/'New Qrtrly - Ind AS'!BA51-1,"") -> -0.034064299
A8: 2QFY20 | B8: ='New Qrtrly - Ind AS'!BB11 -> 28938 | C8: ='New Qrtrly - Ind AS'!W11 -> 28938 | D8: =IFERROR('New Qrtrly - Ind AS'!W11/'New Qrtrly - Ind AS'!BB11-1,"") -> 0 | E8: ='New Qrtrly - Ind AS'!BB33 -> 40696.311 | F8: ='New Qrtrly - Ind AS'!W33 -> 39295 | G8: =IFERROR('New Qrtrly - Ind AS'!W33/'New Qrtrly - Ind AS'!BB33-1,"") -> -0.034433374 | H8: ='New Qrtrly - Ind AS'!BB40 -> 1812.375 | I8: ='New Qrtrly - Ind AS'!W40 -> 2285.8 | J8: =IFERROR('New Qrtrly - Ind AS'!W40/'New Qrtrly - Ind AS'!BB40-1,"") -> 0.26121805 | K8: ='New Qrtrly - Ind AS'!BB61 -> 4.4534133 | L8: ='New Qrtrly - Ind AS'!W61 -> 5.8170251 | M8: =IFERROR(('New Qrtrly - Ind AS'!W61-'New Qrtrly - Ind AS'!BB61)*100,"") -> 136.36117 | N8: ='New Qrtrly - Ind AS'!BB51 -> 203.20496 | O8: ='New Qrtrly - Ind AS'!W51 -> 874.775 | P8: =IFERROR('New Qrtrly - Ind AS'!W51/'New Qrtrly - Ind AS'!BB51-1,"") -> 3.3048899
A9: 3QFY20 | B9: ='New Qrtrly - Ind AS'!BC11 -> 31200 | C9: ='New Qrtrly - Ind AS'!X11 -> 31200 | D9: =IFERROR('New Qrtrly - Ind AS'!X11/'New Qrtrly - Ind AS'!BC11-1,"") -> 0 | E9: ='New Qrtrly - Ind AS'!BC33 -> 41307.412 | F9: ='New Qrtrly - Ind AS'!X33 -> 40156.5 | G9: =IFERROR('New Qrtrly - Ind AS'!X33/'New Qrtrly - Ind AS'!BC33-1,"") -> -0.027862128 | H9: ='New Qrtrly - Ind AS'!BC40 -> 2490.0682 | I9: ='New Qrtrly - Ind AS'!X40 -> 2251.5 | J9: =IFERROR('New Qrtrly - Ind AS'!X40/'New Qrtrly - Ind AS'!BC40-1,"") -> -0.095807896 | K9: ='New Qrtrly - Ind AS'!BC61 -> 6.0281389 | L9: ='New Qrtrly - Ind AS'!X61 -> 5.6068133 | M9: =IFERROR(('New Qrtrly - Ind AS'!X61-'New Qrtrly - Ind AS'!BC61)*100,"") -> -42.132555 | N9: ='New Qrtrly - Ind AS'!BC51 -> 832.05456 | O9: ='New Qrtrly - Ind AS'!X51 -> 292.69 | P9: =IFERROR('New Qrtrly - Ind AS'!X51/'New Qrtrly - Ind AS'!BC51-1,"") -> -0.6482322
A10: 4QFY20 | B10: ='New Qrtrly - Ind AS'!BD11 -> 25507 | C10: ='New Qrtrly - Ind AS'!Y11 -> 25507 | D10: =IFERROR('New Qrtrly - Ind AS'!Y11/'New Qrtrly - Ind AS'!BD11-1,"") -> 0 | E10: ='New Qrtrly - Ind AS'!BD33 -> 32829.226 | F10: ='New Qrtrly - Ind AS'!Y33 -> 38384.6 | G10: =IFERROR('New Qrtrly - Ind AS'!Y33/'New Qrtrly - Ind AS'!BD33-1,"") -> 0.16922038 | H10: ='New Qrtrly - Ind AS'!BD40 -> 634.08639 | I10: ='New Qrtrly - Ind AS'!Y40 -> 1829.5 | J10: =IFERROR('New Qrtrly - Ind AS'!Y40/'New Qrtrly - Ind AS'!BD40-1,"") -> 1.8852535 | K10: ='New Qrtrly - Ind AS'!BD61 -> 1.9314692 | L10: ='New Qrtrly - Ind AS'!Y61 -> 4.7662344 | M10: =IFERROR(('New Qrtrly - Ind AS'!Y61-'New Qrtrly - Ind AS'!BD61)*100,"") -> 283.47652 | N10: ='New Qrtrly - Ind AS'!BD51 -> -704.13953 | O10: ='New Qrtrly - Ind AS'!Y51 -> -57.725 | P10: =IFERROR('New Qrtrly - Ind AS'!Y51/'New Qrtrly - Ind AS'!BD51-1,"") -> -0.91802051
A11: 1QFY21 | B11: ='New Qrtrly - Ind AS'!BE11 -> 3814 | C11: ='New Qrtrly - Ind AS'!Z11 -> 3814 | D11: =IFERROR('New Qrtrly - Ind AS'!Z11/'New Qrtrly - Ind AS'!BE11-1,"") -> 0 | E11: ='New Qrtrly - Ind AS'!BE33 -> 6313.512 | F11: ='New Qrtrly - Ind AS'!Z33 -> 6508.7 | G11: =IFERROR('New Qrtrly - Ind AS'!Z33/'New Qrtrly - Ind AS'!BE33-1,"") -> 0.030915913 | H11: ='New Qrtrly - Ind AS'!BE40 -> -3069.0815 | I11: ='New Qrtrly - Ind AS'!Z40 -> -3332.4 | J11: =IFERROR('New Qrtrly - Ind AS'!Z40/'New Qrtrly - Ind AS'!BE40-1,"") -> 0.085797162 | K11: ='New Qrtrly - Ind AS'!BE61 -> -48.61132 | L11: ='New Qrtrly - Ind AS'!Z61 -> -51.199164 | M11: =IFERROR(('New Qrtrly - Ind AS'!Z61-'New Qrtrly - Ind AS'!BE61)*100,"") -> -258.78443 | N11: ='New Qrtrly - Ind AS'!BE51 -> -3527.3571 | O11: ='New Qrtrly - Ind AS'!Z51 -> -3875.475 | P11: =IFERROR('New Qrtrly - Ind AS'!Z51/'New Qrtrly - Ind AS'!BE51-1,"") -> 0.09869087
A12: 2QFY21 | B12: ='New Qrtrly - Ind AS'!BF11 -> 19444 | C12: ='New Qrtrly - Ind AS'!AA11 -> 19444 | D12: =IFERROR('New Qrtrly - Ind AS'!AA11/'New Qrtrly - Ind AS'!BF11-1,"") -> 0 | E12: ='New Qrtrly - Ind AS'!BF33 -> 31522.655 | F12: ='New Qrtrly - Ind AS'!AA33 -> 28365.8 | G12: =IFERROR('New Qrtrly - Ind AS'!AA33/'New Qrtrly - Ind AS'!BF33-1,"") -> -0.10014558 | H12: ='New Qrtrly - Ind AS'!BF40 -> 1087.2495 | I12: ='New Qrtrly - Ind AS'!AA40 -> 804.3 | J12: =IFERROR('New Qrtrly - Ind AS'!AA40/'New Qrtrly - Ind AS'!BF40-1,"") -> -0.26024338 | K12: ='New Qrtrly - Ind AS'!BF61 -> 3.4491051 | L12: ='New Qrtrly - Ind AS'!AA61 -> 2.8354568 | M12: =IFERROR(('New Qrtrly - Ind AS'!AA61-'New Qrtrly - Ind AS'!BF61)*100,"") -> -61.364827 | N12: ='New Qrtrly - Ind AS'!BF51 -> -561.92537 | O12: ='New Qrtrly - Ind AS'!AA51 -> -1453.95 | P12: =IFERROR('New Qrtrly - Ind AS'!AA51/'New Qrtrly - Ind AS'!BF51-1,"") -> 1.5874432
A13: 3QFY21 | B13: ='New Qrtrly - Ind AS'!BG11 -> 33410 | C13: ='New Qrtrly - Ind AS'!AB11 -> 33410 | D13: =IFERROR('New Qrtrly - Ind AS'!AB11/'New Qrtrly - Ind AS'!BG11-1,"") -> 0 | E13: ='New Qrtrly - Ind AS'!BG33 -> 50689.644 | F13: ='New Qrtrly - Ind AS'!AB33 -> 48135.1 | G13: =IFERROR('New Qrtrly - Ind AS'!AB33/'New Qrtrly - Ind AS'!BG33-1,"") -> -0.050395772 | H13: ='New Qrtrly - Ind AS'!BG40 -> 4246.5485 | I13: ='New Qrtrly - Ind AS'!AB40 -> 2537.9 | J13: =IFERROR('New Qrtrly - Ind AS'!AB40/'New Qrtrly - Ind AS'!BG40-1,"") -> -0.4023617 | K13: ='New Qrtrly - Ind AS'!BG61 -> 8.3775465 | L13: ='New Qrtrly - Ind AS'!AB61 -> 5.2724519 | M13: =IFERROR(('New Qrtrly - Ind AS'!AB61-'New Qrtrly - Ind AS'!BG61)*100,"") -> -310.50946 | N13: ='New Qrtrly - Ind AS'!BG51 -> 1467.5839 | O13: ='New Qrtrly - Ind AS'!AB51 -> 151.425 | P13: =IFERROR('New Qrtrly - Ind AS'!AB51/'New Qrtrly - Ind AS'!BG51-1,"") -> -0.89682021
A14: 4QFY21 | B14: ='New Qrtrly - Ind AS'!BH11 -> 44060 | C14: ='New Qrtrly - Ind AS'!AC11 -> 44060 | D14: =IFERROR('New Qrtrly - Ind AS'!AC11/'New Qrtrly - Ind AS'!BH11-1,"") -> 0 | E14: ='New Qrtrly - Ind AS'!BH33 -> 65065.948 | F14: ='New Qrtrly - Ind AS'!AC33 -> 70004.9 | G14: =IFERROR('New Qrtrly - Ind AS'!AC33/'New Qrtrly - Ind AS'!BH33-1,"") -> 0.075906865 | H14: ='New Qrtrly - Ind AS'!BH40 -> 4845.9594 | I14: ='New Qrtrly - Ind AS'!AC40 -> 5341.6 | J14: =IFERROR('New Qrtrly - Ind AS'!AC40/'New Qrtrly - Ind AS'!BH40-1,"") -> 0.10227915 | K14: ='New Qrtrly - Ind AS'!BH61 -> 7.4477658 | L14: ='New Qrtrly - Ind AS'!AC61 -> 7.630323 | M14: =IFERROR(('New Qrtrly - Ind AS'!AC61-'New Qrtrly - Ind AS'!BH61)*100,"") -> 18.255726 | N14: ='New Qrtrly - Ind AS'!BH51 -> 1747.1716 | O14: ='New Qrtrly - Ind AS'!AC51 -> 2131.575 | P14: =IFERROR('New Qrtrly - Ind AS'!AC51/'New Qrtrly - Ind AS'!BH51-1,"") -> 0.2200147
A15: 1QFY22 | B15: ='New Qrtrly - Ind AS'!BI11 -> 17987 | C15: ='New Qrtrly - Ind AS'!AD11 -> 17987 | D15: =IFERROR('New Qrtrly - Ind AS'!AD11/'New Qrtrly - Ind AS'!BI11-1,"") -> 0 | E15: ='New Qrtrly - Ind AS'!BI33 -> 27149.778 | F15: ='New Qrtrly - Ind AS'!AD33 -> 29509.9 | G15: =IFERROR('New Qrtrly - Ind AS'!AD33/'New Qrtrly - Ind AS'!BI33-1,"") -> 0.086929688 | H15: ='New Qrtrly - Ind AS'!BI40 -> -1019.8021 | I15: ='New Qrtrly - Ind AS'!AD40 -> -1401 | J15: =IFERROR('New Qrtrly - Ind AS'!AD40/'New Qrtrly - Ind AS'!BI40-1,"") -> 0.37379594 | K15: ='New Qrtrly - Ind AS'!BI61 -> -3.7562079 | L15: ='New Qrtrly - Ind AS'!AD61 -> -4.7475593 | M15: =IFERROR(('New Qrtrly - Ind AS'!AD61-'New Qrtrly - Ind AS'!BI61)*100,"") -> -99.13514 | N15: ='New Qrtrly - Ind AS'!BI51 -> -2463.8615 | O15: ='New Qrtrly - Ind AS'!AD51 -> -2810.3 | P15: =IFERROR('New Qrtrly - Ind AS'!AD51/'New Qrtrly - Ind AS'!BI51-1,"") -> 0.14060795
A16: 2QFY22 | B16: ='New Qrtrly - Ind AS'!BJ11 -> 27543 | C16: ='New Qrtrly - Ind AS'!AE11 -> 27543 | D16: =IFERROR('New Qrtrly - Ind AS'!AE11/'New Qrtrly - Ind AS'!BJ11-1,"") -> 0 | E16: ='New Qrtrly - Ind AS'!BJ33 -> 46091.455 | F16: ='New Qrtrly - Ind AS'!AE33 -> 44578.5 | G16: =IFERROR('New Qrtrly - Ind AS'!AE33/'New Qrtrly - Ind AS'!BJ33-1,"") -> -0.032825063 | H16: ='New Qrtrly - Ind AS'!BJ40 -> 1799.4125 | I16: ='New Qrtrly - Ind AS'!AE40 -> 1346.9 | J16: =IFERROR('New Qrtrly - Ind AS'!AE40/'New Qrtrly - Ind AS'!BJ40-1,"") -> -0.25147789 | K16: ='New Qrtrly - Ind AS'!BJ61 -> 3.9040045 | L16: ='New Qrtrly - Ind AS'!AE61 -> 3.0214117 | M16: =IFERROR(('New Qrtrly - Ind AS'!AE61-'New Qrtrly - Ind AS'!BJ61)*100,"") -> -88.259279 | N16: ='New Qrtrly - Ind AS'!BJ51 -> -420.41128 | O16: ='New Qrtrly - Ind AS'!AE51 -> -831.825 | P16: =IFERROR('New Qrtrly - Ind AS'!AE51/'New Qrtrly - Ind AS'!BJ51-1,"") -> 0.97859818
A17: 3QFY22 | B17: ='New Qrtrly - Ind AS'!BK11 -> 34077 | C17: ='New Qrtrly - Ind AS'!AF11 -> 34077 | D17: =IFERROR('New Qrtrly - Ind AS'!AF11/'New Qrtrly - Ind AS'!BK11-1,"") -> 0 | E17: ='New Qrtrly - Ind AS'!BK33 -> 56808.43 | F17: ='New Qrtrly - Ind AS'!AF33 -> 55351.6 | G17: =IFERROR('New Qrtrly - Ind AS'!AF33/'New Qrtrly - Ind AS'!BK33-1,"") -> -0.025644612 | H17: ='New Qrtrly - Ind AS'!BK40 -> 2952.3221 | I17: ='New Qrtrly - Ind AS'!AF40 -> 2238.9 | J17: =IFERROR('New Qrtrly - Ind AS'!AF40/'New Qrtrly - Ind AS'!BK40-1,"") -> -0.24164778 | K17: ='New Qrtrly - Ind AS'!BK61 -> 5.1969788 | L17: ='New Qrtrly - Ind AS'!AF61 -> 4.0448695 | M17: =IFERROR(('New Qrtrly - Ind AS'!AF61-'New Qrtrly - Ind AS'!BK61)*100,"") -> -115.21093 | N17: ='New Qrtrly - Ind AS'!BK51 -> 337.62545 | O17: ='New Qrtrly - Ind AS'!AF51 -> -257.55 | P17: =IFERROR('New Qrtrly - Ind AS'!AF51/'New Qrtrly - Ind AS'!BK51-1,"") -> -1.7628276
A18: 4QFY22 | B18: ='New Qrtrly - Ind AS'!BL11 -> 48719 | C18: ='New Qrtrly - Ind AS'!AG11 -> 48719 | D18: =IFERROR('New Qrtrly - Ind AS'!AG11/'New Qrtrly - Ind AS'!BL11-1,"") -> 0 | E18: ='New Qrtrly - Ind AS'!BL33 -> 81508.784 | F18: ='New Qrtrly - Ind AS'!AG33 -> 87442.9 | G18: =IFERROR('New Qrtrly - Ind AS'!AG33/'New Qrtrly - Ind AS'!BL33-1,"") -> 0.07280339 | H18: ='New Qrtrly - Ind AS'!BL40 -> 5809.3008 | I18: ='New Qrtrly - Ind AS'!AG40 -> 7760.4 | J18: =IFERROR('New Qrtrly - Ind AS'!AG40/'New Qrtrly - Ind AS'!BL40-1,"") -> 0.33585785 | K18: ='New Qrtrly - Ind AS'!BL61 -> 7.1272082 | L18: ='New Qrtrly - Ind AS'!AG61 -> 8.87482 | M18: =IFERROR(('New Qrtrly - Ind AS'!AG61-'New Qrtrly - Ind AS'!BL61)*100,"") -> 174.76118 | N18: ='New Qrtrly - Ind AS'!BL51 -> 2372.5105 | O18: ='New Qrtrly - Ind AS'!AG51 -> 5486.75 | P18: =IFERROR('New Qrtrly - Ind AS'!AG51/'New Qrtrly - Ind AS'!BL51-1,"") -> 1.3126346
A19: 1QFY23 | B19: ='New Qrtrly - Ind AS'!BM11 -> 39651 | C19: ='New Qrtrly - Ind AS'!AH11 -> 39651 | D19: =IFERROR('New Qrtrly - Ind AS'!AH11/'New Qrtrly - Ind AS'!BM11-1,"") -> 0 | E19: ='New Qrtrly - Ind AS'!BM33 -> 71167.274 | F19: ='New Qrtrly - Ind AS'!AH33 -> 72228.5 | G19: =IFERROR('New Qrtrly - Ind AS'!AH33/'New Qrtrly - Ind AS'!BM33-1,"") -> 0.014911712 | H19: ='New Qrtrly - Ind AS'!BM40 -> 4545.1276 | I19: ='New Qrtrly - Ind AS'!AH40 -> 3202.8 | J19: =IFERROR('New Qrtrly - Ind AS'!AH40/'New Qrtrly - Ind AS'!BM40-1,"") -> -0.29533331 | K19: ='New Qrtrly - Ind AS'!BM61 -> 6.3865416 | L19: ='New Qrtrly - Ind AS'!AH61 -> 4.4342607 | M19: =IFERROR(('New Qrtrly - Ind AS'!AH61-'New Qrtrly - Ind AS'!BM61)*100,"") -> -195.22809 | N19: ='New Qrtrly - Ind AS'!BM51 -> 1424.5893 | O19: ='New Qrtrly - Ind AS'!AH51 -> 582.925 | P19: =IFERROR('New Qrtrly - Ind AS'!AH51/'New Qrtrly - Ind AS'!BM51-1,"") -> -0.59081189
A20: 2QFY23 | B20: ='New Qrtrly - Ind AS'!BN11 -> 45295 | C20: ='New Qrtrly - Ind AS'!AI11 -> 45295 | D20: =IFERROR('New Qrtrly - Ind AS'!AI11/'New Qrtrly - Ind AS'!BN11-1,"") -> 0 | E20: ='New Qrtrly - Ind AS'!BN33 -> 82922.193 | F20: ='New Qrtrly - Ind AS'!AI33 -> 82659.5 | G20: =IFERROR('New Qrtrly - Ind AS'!AI33/'New Qrtrly - Ind AS'!BN33-1,"") -> -0.0031679403 | H20: ='New Qrtrly - Ind AS'!BN40 -> 4956.3502 | I20: ='New Qrtrly - Ind AS'!AI40 -> 5373.4 | J20: =IFERROR('New Qrtrly - Ind AS'!AI40/'New Qrtrly - Ind AS'!BN40-1,"") -> 0.084144529 | K20: ='New Qrtrly - Ind AS'!BN61 -> 5.9771095 | L20: ='New Qrtrly - Ind AS'!AI61 -> 6.5006442 | M20: =IFERROR(('New Qrtrly - Ind AS'!AI61-'New Qrtrly - Ind AS'!BN61)*100,"") -> 52.353471 | N20: ='New Qrtrly - Ind AS'!BN51 -> 1866.4452 | O20: ='New Qrtrly - Ind AS'!AI51 -> 1931.375 | P20: =IFERROR('New Qrtrly - Ind AS'!AI51/'New Qrtrly - Ind AS'!BN51-1,"") -> 0.034787965
A21: 3QFY23 | B21: ='New Qrtrly - Ind AS'!BO11 -> 47562 | C21: ='New Qrtrly - Ind AS'!AJ11 -> 47562 | D21: =IFERROR('New Qrtrly - Ind AS'!AJ11/'New Qrtrly - Ind AS'!BO11-1,"") -> 0 | E21: ='New Qrtrly - Ind AS'!BO33 -> 87924.937 | F21: ='New Qrtrly - Ind AS'!AJ33 -> 90296.7 | G21: =IFERROR('New Qrtrly - Ind AS'!AJ33/'New Qrtrly - Ind AS'!BO33-1,"") -> 0.026974866 | H21: ='New Qrtrly - Ind AS'!BO40 -> 6631.3187 | I21: ='New Qrtrly - Ind AS'!AJ40 -> 7973.4 | J21: =IFERROR('New Qrtrly - Ind AS'!AJ40/'New Qrtrly - Ind AS'!BO40-1,"") -> 0.20238527 | K21: ='New Qrtrly - Ind AS'!BO61 -> 7.5420228 | L21: ='New Qrtrly - Ind AS'!AJ61 -> 8.830223 | M21: =IFERROR(('New Qrtrly - Ind AS'!AJ61-'New Qrtrly - Ind AS'!BO61)*100,"") -> 128.82003 | N21: ='New Qrtrly - Ind AS'!BO51 -> 2989.9231 | O21: ='New Qrtrly - Ind AS'!AJ51 -> 3561.35 | P21: =IFERROR('New Qrtrly - Ind AS'!AJ51/'New Qrtrly - Ind AS'!BO51-1,"") -> 0.19111758
A22: 4QFY23 | B22: ='New Qrtrly - Ind AS'!BP11 -> 59697 | C22: ='New Qrtrly - Ind AS'!AK11 -> 59697 | D22: =IFERROR('New Qrtrly - Ind AS'!AK11/'New Qrtrly - Ind AS'!BP11-1,"") -> 0 | E22: ='New Qrtrly - Ind AS'!BP33 -> 114695.08 | F22: ='New Qrtrly - Ind AS'!AK33 -> 116256.7 | G22: =IFERROR('New Qrtrly - Ind AS'!AK33/'New Qrtrly - Ind AS'!BP33-1,"") -> 0.013615403 | H22: ='New Qrtrly - Ind AS'!BP40 -> 12264.194 | I22: ='New Qrtrly - Ind AS'!AK40 -> 12757.4 | J22: =IFERROR('New Qrtrly - Ind AS'!AK40/'New Qrtrly - Ind AS'!BP40-1,"") -> 0.040215096 | K22: ='New Qrtrly - Ind AS'!BP61 -> 10.692869 | L22: ='New Qrtrly - Ind AS'!AK61 -> 10.973475 | M22: =IFERROR(('New Qrtrly - Ind AS'!AK61-'New Qrtrly - Ind AS'!BP61)*100,"") -> 28.060645 | N22: ='New Qrtrly - Ind AS'!BP51 -> 6904.936 | O22: ='New Qrtrly - Ind AS'!AK51 -> 7090.875 | P22: =IFERROR('New Qrtrly - Ind AS'!AK51/'New Qrtrly - Ind AS'!BP51-1,"") -> 0.026928421
A23: 1QFY24 | B23: ='New Qrtrly - Ind AS'!BQ11 -> 41329 | C23: ='New Qrtrly - Ind AS'!AL11 -> 41329 | D23: =IFERROR('New Qrtrly - Ind AS'!AL11/'New Qrtrly - Ind AS'!BQ11-1,"") -> 0 | E23: ='New Qrtrly - Ind AS'!BQ33 -> 80486.007 | F23: ='New Qrtrly - Ind AS'!AL33 -> 81892.9 | G23: =IFERROR('New Qrtrly - Ind AS'!AL33/'New Qrtrly - Ind AS'!BQ33-1,"") -> 0.017479971 | H23: ='New Qrtrly - Ind AS'!BQ40 -> 6140.5297 | I23: ='New Qrtrly - Ind AS'!AL40 -> 8207.5 | J23: =IFERROR('New Qrtrly - Ind AS'!AL40/'New Qrtrly - Ind AS'!BQ40-1,"") -> 0.33661107 | K23: ='New Qrtrly - Ind AS'!BQ61 -> 7.6293134 | L23: ='New Qrtrly - Ind AS'!AL61 -> 10.022236 | M23: =IFERROR(('New Qrtrly - Ind AS'!AL61-'New Qrtrly - Ind AS'!BQ61)*100,"") -> 239.2923 | N23: ='New Qrtrly - Ind AS'!BQ51 -> 2618.3708 | O23: ='New Qrtrly - Ind AS'!AL51 -> 5768.625 | P23: =IFERROR('New Qrtrly - Ind AS'!AL51/'New Qrtrly - Ind AS'!BQ51-1,"") -> 1.2031352
A24: 2QFY24 | B24: ='New Qrtrly - Ind AS'!BR11 -> 49846 | C24: ='New Qrtrly - Ind AS'!AM11 -> 49846 | D24: =IFERROR('New Qrtrly - Ind AS'!AM11/'New Qrtrly - Ind AS'!BR11-1,"") -> 0 | E24: ='New Qrtrly - Ind AS'!BR33 -> 96793.845 | F24: ='New Qrtrly - Ind AS'!AM33 -> 96380.4 | G24: =IFERROR('New Qrtrly - Ind AS'!AM33/'New Qrtrly - Ind AS'!BR33-1,"") -> -0.0042713985 | H24: ='New Qrtrly - Ind AS'!BR40 -> 10466.4 | I24: ='New Qrtrly - Ind AS'!AM40 -> 10797.9 | J24: =IFERROR('New Qrtrly - Ind AS'!AM40/'New Qrtrly - Ind AS'!BR40-1,"") -> 0.031672809 | K24: ='New Qrtrly - Ind AS'!BR61 -> 10.813084 | L24: ='New Qrtrly - Ind AS'!AM61 -> 11.203419 | M24: =IFERROR(('New Qrtrly - Ind AS'!AM61-'New Qrtrly - Ind AS'!BR61)*100,"") -> 39.033501 | N24: ='New Qrtrly - Ind AS'!BR51 -> 5821.4798 | O24: ='New Qrtrly - Ind AS'!AM51 -> 5781.7 | P24: =IFERROR('New Qrtrly - Ind AS'!AM51/'New Qrtrly - Ind AS'!BR51-1,"") -> -0.0068332807
A25: 3QFY24 | B25: ='New Qrtrly - Ind AS'!BS11 -> 47241 | C25: ='New Qrtrly - Ind AS'!AN11 -> 47241 | D25: =IFERROR('New Qrtrly - Ind AS'!AN11/'New Qrtrly - Ind AS'!BS11-1,"") -> 0 | E25: ='New Qrtrly - Ind AS'!BS33 -> 89516.598 | F25: ='New Qrtrly - Ind AS'!AN33 -> 92730.1 | G25: =IFERROR('New Qrtrly - Ind AS'!AN33/'New Qrtrly - Ind AS'!BS33-1,"") -> 0.035898392 | H25: ='New Qrtrly - Ind AS'!BS40 -> 9211.4151 | I25: ='New Qrtrly - Ind AS'!AN40 -> 11139.3 | J25: =IFERROR('New Qrtrly - Ind AS'!AN40/'New Qrtrly - Ind AS'!BS40-1,"") -> 0.20929302 | K25: ='New Qrtrly - Ind AS'!BS61 -> 10.290176 | L25: ='New Qrtrly - Ind AS'!AN61 -> 12.012604 | M25: =IFERROR(('New Qrtrly - Ind AS'!AN61-'New Qrtrly - Ind AS'!BS61)*100,"") -> 172.24288 | N25: ='New Qrtrly - Ind AS'!BS51 -> 5082.9906 | O25: ='New Qrtrly - Ind AS'!AN51 -> 5804.725 | P25: =IFERROR('New Qrtrly - Ind AS'!AN51/'New Qrtrly - Ind AS'!BS51-1,"") -> 0.14199012
A26: 4QFY24 | B26: ='New Qrtrly - Ind AS'!BT11 -> 56269 | C26: ='New Qrtrly - Ind AS'!AO11 -> 56269 | D26: =IFERROR('New Qrtrly - Ind AS'!AO11/'New Qrtrly - Ind AS'!BT11-1,"") -> 0 | E26: ='New Qrtrly - Ind AS'!BT33 -> 111003.56 | F26: ='New Qrtrly - Ind AS'!AO33 -> 112666.9 | G26: =IFERROR('New Qrtrly - Ind AS'!AO33/'New Qrtrly - Ind AS'!BT33-1,"") -> 0.01498457 | H26: ='New Qrtrly - Ind AS'!BT40 -> 13735.965 | I26: ='New Qrtrly - Ind AS'!AO40 -> 15921.1 | J26: =IFERROR('New Qrtrly - Ind AS'!AO40/'New Qrtrly - Ind AS'!BT40-1,"") -> 0.15908129 | K26: ='New Qrtrly - Ind AS'!BT61 -> 12.374346 | L26: ='New Qrtrly - Ind AS'!AO61 -> 14.131125 | M26: =IFERROR(('New Qrtrly - Ind AS'!AO61-'New Qrtrly - Ind AS'!BT61)*100,"") -> 175.67781 | N26: ='New Qrtrly - Ind AS'!BT51 -> 8131.1755 | O26: ='New Qrtrly - Ind AS'!AO51 -> 9526.55 | P26: =IFERROR('New Qrtrly - Ind AS'!AO51/'New Qrtrly - Ind AS'!BT51-1,"") -> 0.17160797
A27: 1QFY25 | B27: ='New Qrtrly - Ind AS'!BU11 -> 43893 | C27: ='New Qrtrly - Ind AS'!AP11 -> 43893 | D27: =IFERROR('New Qrtrly - Ind AS'!AP11/'New Qrtrly - Ind AS'!BU11-1,"") -> 0 | E27: ='New Qrtrly - Ind AS'!BU33 -> 86128.818 | F27: ='New Qrtrly - Ind AS'!AP33 -> 85985.3 | G27: =IFERROR('New Qrtrly - Ind AS'!AP33/'New Qrtrly - Ind AS'!BU33-1,"") -> -0.0016663215 | H27: ='New Qrtrly - Ind AS'!BU40 -> 8971.5539 | I27: ='New Qrtrly - Ind AS'!AP40 -> 9108.7 | J27: =IFERROR('New Qrtrly - Ind AS'!AP40/'New Qrtrly - Ind AS'!BU40-1,"") -> 0.015286778 | K27: ='New Qrtrly - Ind AS'!BU61 -> 10.416437 | L27: ='New Qrtrly - Ind AS'!AP61 -> 10.593322 | M27: =IFERROR(('New Qrtrly - Ind AS'!AP61-'New Qrtrly - Ind AS'!BU61)*100,"") -> 17.688563 | N27: ='New Qrtrly - Ind AS'!BU51 -> 5286.0877 | O27: ='New Qrtrly - Ind AS'!AP51 -> 5255.8 | P27: =IFERROR('New Qrtrly - Ind AS'!AP51/'New Qrtrly - Ind AS'!BU51-1,"") -> -0.0057296998
A28: 2QFY25 | B28: ='New Qrtrly - Ind AS'!BV11 -> 45624 | C28: ='New Qrtrly - Ind AS'!AQ11 -> 45624 | D28: =IFERROR('New Qrtrly - Ind AS'!AQ11/'New Qrtrly - Ind AS'!BV11-1,"") -> 0 | E28: ='New Qrtrly - Ind AS'!BV33 -> 87588.76 | F28: ='New Qrtrly - Ind AS'!AQ33 -> 87688.3 | G28: =IFERROR('New Qrtrly - Ind AS'!AQ33/'New Qrtrly - Ind AS'!BV33-1,"") -> 0.0011364425 | H28: ='New Qrtrly - Ind AS'!BV40 -> 9349.6754 | I28: ='New Qrtrly - Ind AS'!AQ40 -> 10173 | J28: =IFERROR('New Qrtrly - Ind AS'!AQ40/'New Qrtrly - Ind AS'!BV40-1,"") -> 0.088059165 | K28: ='New Qrtrly - Ind AS'!BV61 -> 10.674515 | L28: ='New Qrtrly - Ind AS'!AQ61 -> 11.60132 | M28: =IFERROR(('New Qrtrly - Ind AS'!AQ61-'New Qrtrly - Ind AS'!BV61)*100,"") -> 92.680465 | N28: ='New Qrtrly - Ind AS'!BV51 -> 5074.7728 | O28: ='New Qrtrly - Ind AS'!AQ51 -> 6820.65 | P28: =IFERROR('New Qrtrly - Ind AS'!AQ51/'New Qrtrly - Ind AS'!BV51-1,"") -> 0.34403062
A29: 3QFY25 | B29: ='New Qrtrly - Ind AS'!BW11 -> 46404 | C29: ='New Qrtrly - Ind AS'!AR11 -> 46404 | D29: =IFERROR('New Qrtrly - Ind AS'!AR11/'New Qrtrly - Ind AS'!BW11-1,"") -> 0 | E29: ='New Qrtrly - Ind AS'!BW33 -> 90525.254 | F29: ='New Qrtrly - Ind AS'!AR33 -> 94786.7 | G29: =IFERROR('New Qrtrly - Ind AS'!AR33/'New Qrtrly - Ind AS'!BW33-1,"") -> 0.047074664 | H29: ='New Qrtrly - Ind AS'!BW40 -> 10680.942 | I29: ='New Qrtrly - Ind AS'!AR40 -> 12114.3 | J29: =IFERROR('New Qrtrly - Ind AS'!AR40/'New Qrtrly - Ind AS'!BW40-1,"") -> 0.13419775 | K29: ='New Qrtrly - Ind AS'!BW61 -> 11.798853 | L29: ='New Qrtrly - Ind AS'!AR61 -> 12.780591 | M29: =IFERROR(('New Qrtrly - Ind AS'!AR61-'New Qrtrly - Ind AS'!BW61)*100,"") -> 98.173752 | N29: ='New Qrtrly - Ind AS'!BW51 -> 6069.6592 | O29: ='New Qrtrly - Ind AS'!AR51 -> 7617.4 | P29: =IFERROR('New Qrtrly - Ind AS'!AR51/'New Qrtrly - Ind AS'!BW51-1,"") -> 0.25499633
A30: 4QFY25 | B30: ='New Qrtrly - Ind AS'!BX11 -> 59176 | C30: ='New Qrtrly - Ind AS'!AS11 -> 59176 | D30: =IFERROR('New Qrtrly - Ind AS'!AS11/'New Qrtrly - Ind AS'!BX11-1,"") -> 0 | E30: ='New Qrtrly - Ind AS'!BX33 -> 122688.44 | F30: ='New Qrtrly - Ind AS'!AS33 -> 119067.1 | G30: =IFERROR('New Qrtrly - Ind AS'!AS33/'New Qrtrly - Ind AS'!BX33-1,"") -> -0.02951653 | H30: ='New Qrtrly - Ind AS'!BX40 -> 17366.205 | I30: ='New Qrtrly - Ind AS'!AS40 -> 17909.6 | J30: =IFERROR('New Qrtrly - Ind AS'!AS40/'New Qrtrly - Ind AS'!BX40-1,"") -> 0.0312904 | K30: ='New Qrtrly - Ind AS'!BX61 -> 14.15472 | L30: ='New Qrtrly - Ind AS'!AS61 -> 15.041603 | M30: =IFERROR(('New Qrtrly - Ind AS'!AS61-'New Qrtrly - Ind AS'!BX61)*100,"") -> 88.688276 | N30: ='New Qrtrly - Ind AS'!BX51 -> 11322.153 | O30: ='New Qrtrly - Ind AS'!AS51 -> 12561.075 | P30: =IFERROR('New Qrtrly - Ind AS'!AS51/'New Qrtrly - Ind AS'!BX51-1,"") -> 0.10942456
A31: 1QFY26 | B31: ='New Qrtrly - Ind AS'!BY11 -> 44238 | C31: ='New Qrtrly - Ind AS'!AT11 -> 44238 | D31: =IFERROR('New Qrtrly - Ind AS'!AT11/'New Qrtrly - Ind AS'!BY11-1,"") -> 0 | E31: ='New Qrtrly - Ind AS'!BY33 -> 87230.373 | F31: ='New Qrtrly - Ind AS'!AT33 -> 87245.1 | G31: =IFERROR('New Qrtrly - Ind AS'!AT33/'New Qrtrly - Ind AS'!BY33-1,"") -> 0.00016882692 | H31: ='New Qrtrly - Ind AS'!BY40 -> 9685.1171 | I31: ='New Qrtrly - Ind AS'!AT40 -> 9695.5 | J31: =IFERROR('New Qrtrly - Ind AS'!AT40/'New Qrtrly - Ind AS'!BY40-1,"") -> 0.0010720471 | K31: ='New Qrtrly - Ind AS'!BY61 -> 11.102918 | L31: ='New Qrtrly - Ind AS'!AT61 -> 11.112945 | M31: =IFERROR(('New Qrtrly - Ind AS'!AT61-'New Qrtrly - Ind AS'!BY61)*100,"") -> 1.0026687 | N31: ='New Qrtrly - Ind AS'!BY51 -> 5883.582 | O31: ='New Qrtrly - Ind AS'!AT51 -> 5937.3 | P31: =IFERROR('New Qrtrly - Ind AS'!AT51/'New Qrtrly - Ind AS'!BY51-1,"") -> 0.0091301577
A32: 2QFY26 | B32: ='New Qrtrly - Ind AS'!BZ11 -> 49116 | C32: ='New Qrtrly - Ind AS'!AU11 -> 49116 | D32: =IFERROR('New Qrtrly - Ind AS'!AU11/'New Qrtrly - Ind AS'!BZ11-1,"") -> 0 | E32: ='New Qrtrly - Ind AS'!BZ33 -> 96381.045 | F32: ='New Qrtrly - Ind AS'!AU33 -> 95881.8 | G32: =IFERROR('New Qrtrly - Ind AS'!AU33/'New Qrtrly - Ind AS'!BZ33-1,"") -> -0.0051799112 | H32: ='New Qrtrly - Ind AS'!BZ40 -> 11004.122 | I32: ='New Qrtrly - Ind AS'!AU40 -> 11621.6 | J32: =IFERROR('New Qrtrly - Ind AS'!AU40/'New Qrtrly - Ind AS'!BZ40-1,"") -> 0.056113329 | K32: ='New Qrtrly - Ind AS'!BZ61 -> 11.417309 | L32: ='New Qrtrly - Ind AS'!AU61 -> 12.120757 | M32: =IFERROR(('New Qrtrly - Ind AS'!AU61-'New Qrtrly - Ind AS'!BZ61)*100,"") -> 70.344768 | N32: ='New Qrtrly - Ind AS'!BZ51 -> 6449.8855 | O32: ='New Qrtrly - Ind AS'!AU51 -> 8010.6 | P32: =IFERROR('New Qrtrly - Ind AS'!AU51/'New Qrtrly - Ind AS'!BZ51-1,"") -> 0.24197554
A33: 3QFY26 | B33: ='New Qrtrly - Ind AS'!CA11 -> 57625 | C33: ='New Qrtrly - Ind AS'!AV11 -> 57625 | D33: =IFERROR('New Qrtrly - Ind AS'!AV11/'New Qrtrly - Ind AS'!CA11-1,"") -> 0 | E33: ='New Qrtrly - Ind AS'!CA33 -> 114180.03 | F33: ='New Qrtrly - Ind AS'!AV33 -> 115338.5 | G33: =IFERROR('New Qrtrly - Ind AS'!AV33/'New Qrtrly - Ind AS'!CA33-1,"") -> 0.010145958 | H33: ='New Qrtrly - Ind AS'!CA40 -> 14798.77 | I33: ='New Qrtrly - Ind AS'!AV40 -> 15350.2 | J33: =IFERROR('New Qrtrly - Ind AS'!AV40/'New Qrtrly - Ind AS'!CA40-1,"") -> 0.037261907 | K33: ='New Qrtrly - Ind AS'!CA61 -> 12.960908 | L33: ='New Qrtrly - Ind AS'!AV61 -> 13.308826 | M33: =IFERROR(('New Qrtrly - Ind AS'!AV61-'New Qrtrly - Ind AS'!CA61)*100,"") -> 34.791737 | N33: ='New Qrtrly - Ind AS'!CA51 -> 9996.5772 | O33: ='New Qrtrly - Ind AS'!AV51 -> 10273.8 | P33: =IFERROR('New Qrtrly - Ind AS'!AV51/'New Qrtrly - Ind AS'!CA51-1,"") -> 0.02773177
A34: 4QFY26 | B34: ='New Qrtrly - Ind AS'!CB11 -> 69458 | C34: ='New Qrtrly - Ind AS'!AW11 -> 69458 | D34: =IFERROR('New Qrtrly - Ind AS'!AW11/'New Qrtrly - Ind AS'!CB11-1,"") -> 0 | E34: ='New Qrtrly - Ind AS'!CB33 -> 140899.48 | F34: ='New Qrtrly - Ind AS'!AW33 -> 141604.9 | G34: =IFERROR('New Qrtrly - Ind AS'!AW33/'New Qrtrly - Ind AS'!CB33-1,"") -> 0.0050065543 | H34: ='New Qrtrly - Ind AS'!CB40 -> 19806.457 | I34: ='New Qrtrly - Ind AS'!AW40 -> 20655.2 | J34: =IFERROR('New Qrtrly - Ind AS'!AW40/'New Qrtrly - Ind AS'!CB40-1,"") -> 0.042851819 | K34: ='New Qrtrly - Ind AS'!CB61 -> 14.057154 | L34: ='New Qrtrly - Ind AS'!AW61 -> 14.586501 | M34: =IFERROR(('New Qrtrly - Ind AS'!AW61-'New Qrtrly - Ind AS'!CB61)*100,"") -> 52.934653 | N34: ='New Qrtrly - Ind AS'!CB51 -> 13774.843 | O34: ='New Qrtrly - Ind AS'!AW51 -> 14047.2 | P34: =IFERROR('New Qrtrly - Ind AS'!AW51/'New Qrtrly - Ind AS'!CB51-1,"") -> 0.019772062
A35: 1QFY27 | B35: ='New Qrtrly - Ind AS'!CC11 -> 48763 | C35: ='New Qrtrly - Ind AS'!AX11 -> 48763 | D35: =IFERROR('New Qrtrly - Ind AS'!AX11/'New Qrtrly - Ind AS'!CC11-1,"") -> 0 | E35: ='New Qrtrly - Ind AS'!CC33 -> 98419.605 | F35: ='New Qrtrly - Ind AS'!AX33 -> 96343.5 | G35: =IFERROR('New Qrtrly - Ind AS'!AX33/'New Qrtrly - Ind AS'!CC33-1,"") -> -0.021094428 | H35: ='New Qrtrly - Ind AS'!CC40 -> 9576.4542 | I35: ='New Qrtrly - Ind AS'!AX40 -> 9695.3 | J35: =IFERROR('New Qrtrly - Ind AS'!AX40/'New Qrtrly - Ind AS'!CC40-1,"") -> 0.012410209 | K35: ='New Qrtrly - Ind AS'!CC61 -> 9.7302303 | L35: ='New Qrtrly - Ind AS'!AX61 -> 10.063263 | M35: =IFERROR(('New Qrtrly - Ind AS'!AX61-'New Qrtrly - Ind AS'!CC61)*100,"") -> 33.303296 | N35: ='New Qrtrly - Ind AS'!CC51 -> 6004.8407 | O35: ='New Qrtrly - Ind AS'!AX51 -> 6091.1 | P35: =IFERROR('New Qrtrly - Ind AS'!AX51/'New Qrtrly - Ind AS'!CC51-1,"") -> 0.014364968

Sheet Main Model
Y1: =+Y57 -> 1.6825652e-11 | Z1: =+Z31+Z34-Z37-(23279.2) -> 0 | AA1: =+AA31+AA34-AA37-30757.301 -> 0 | AC1: =+AC31+AC34-AC37-23096.1 -> 0 | AD1: =+AD31+AD34-AD37 -> 17791.1 | AE1: =+AE31+AE34-AE37-22381 -> 0 | AF1: =+AF31+AF34-AF37-32504.3 -> 0 | AH1: =+AH18 -> 1986372.7 | AI1: =+AI18 -> 1996354.1 | AJ1: =+AJ18 -> 2021180.7 | AK1: =+AK18 -> 2039068.7 | AL1: =+AL18 -> 2061411.2 | AM1: Multiple | AN1: EBITDA | AO1: Debt | AP1: TP
Z2: =+Z207 -> 113296 | AD2: =+AD34+AD31-AD37 -> 17791.1 | AE2: =+AE34+AE31-AE37 -> 22381 | AF2: =+AF34+AF31-AF37 -> 32504.3 | AG2: =+AG31+AG34-AG37-36150.6 -> 0 | AH2: =+AH31+AH34-AH37-37931.3 -> 0 | AM2: 18 | AN2: =+AVERAGE(AJ43:AK43) -> 60694.811 | AO2: =AVERAGE(AJ101:AK101) -> -81674.808 | AP2: =+ROUND(((AM2*AN2-AO2)/AH78)/5,0)*5 -> 200 | AQ2: =+AP2/AP3-1+AJ119/AP3 -> 0.121498 | AR2: =+ROUND(((AM2*AN2-AO2)/AH78)/1,0)*1 -> 200
B3: FY 1993 | C3: FY 1994 | D3: FY 1995 | E3: FY 1996 | F3: FY 1997 | G3: FY 1998 | H3: FY 1999 | I3: FY2000 | J3: FY2001 | K3: FY2002 | L3: FY2003 | M3: FY2004 | N3: FY2005 | O3: FY2006 | P3: FY2007 | Q3: FY2008 | R3: FY2009 | S3: FY2010 | T3: FY2011 | U3: FY2012 | V3: FY2013 | W3: FY2014 | X3: FY2015 | Y3: FY2016 | Z3: FY2017 | AA3: FY2018 | AB3: FY2019 | AC3: FY2020 | AD3: FY2021 | AE3: FY2022 | AF3: FY2023 | AG3: FY2024 | AH3: FY2025 | AI3: FY2026 | AJ3: FY2027E | AK3: FY2028E | AL3: FY2029E | AO3: CMP | AP3: 181.3
A4: Summary | AO4: Old TP | AP4: 165 | AQ4: =+AP2/AP4-1 -> 0.21212121
AP5: =145/130-1 -> 0.11538462
A6: Income Statement | AE6: =+AE8/12 -> 10693.833 | AF6: =+AF8/12 -> 16017.083 | AG6: =+AG8/12 -> 16223.583 | AH6: =+AH8/12 -> 16257.75 | AI6: =+AI8/12 -> 18369.75 | AJ6: =+AJ8/12 -> 19782.97 | AK6: =+AK8/12 -> 21182.658 | AL6: =+AL8/12 -> 22525.657
A7: (Rs m) | B7: FY 1993 | C7: FY 1994 | D7: FY 1995 | E7: FY 1996 | F7: FY 1997 | G7: FY 1998 | H7: FY 1999 | I7: FY2000 | J7: FY2001 | K7: FY2002 | L7: FY 2003 | M7: FY2004 | N7: FY 2005 | O7: FY 2006 | P7: FY 2007 | Q7: FY2008 | R7: FY2009 | S7: FY2010 | T7: FY2011 | U7: FY2012 | V7: =+V3 -> FY2013 | W7: =+W3 -> FY2014 | X7: =+X3 -> FY2015 | Y7: =+Y3 -> FY2016 | Z7: =+Z3 -> FY2017 | AA7: =+AA3 -> FY2018 | AB7: =+AB3 -> FY2019 | AC7: =+AC3 -> FY2020 | ... AL7: =+AL3 -> FY2029E
A8: Volumes (Nos) | B8: =+B281 -> 20571 | C8: =+C281 -> 24226 | D8: =+D281 -> 30410 | E8: =+E281 -> 37399 | F8: =+F281 -> 43352 | G8: =+G281 -> 31547 | H8: =+H281 -> 29741 | I8: =+I281 -> 37859 | ... T8: =+T281 -> 94106 | U8: =+U281+U288 -> 101990 | V8: =+V281+V288 -> 114611 | W8: =+W281+W288 -> 89337 | X8: =+X281+X288 -> 104902 | Y8: =+Y281+Y288 -> 140457 | Z8: =+Z281+Z288 -> 145066 | AA8: =+AA281+AA288 -> 174873 | AB8: =+AB281+AB288 -> 197366 | ... AL8: =+AL281+AL288 -> 270307.88
A9: % change YoY | C9: =C8/B8*100-100 -> 17.767731 | D9: =D8/C8*100-100 -> 25.526294 | E9: =E8/D8*100-100 -> 22.982572 | F9: =F8/E8*100-100 -> 15.917538 | G9: =G8/F8*100-100 -> -27.230578 | H9: =H8/G8*100-100 -> -5.7247916 | I9: =I8/H8*100-100 -> 27.295652 | J9: =J8/I8*100-100 -> -14.221189 | ... AL9: =AL8/AK8*100-100 -> 6.3400895
A10: Sales & operational income | B10: =+B327 -> 9544.37 | C10: =+C327 -> 11812.94 | D10: =+D327 -> 15132.92 | E10: =+E327 -> 20097.02 | F10: =+F327 -> 24824.51 | G10: =+G327 -> 20142.802 | H10: =+H327 -> 20450.478 | I10: =+I327 -> 25987.18 | ... AL10: =+AL327 -> 557215.7 | AO10: 33236
A11: % change YoY | C11: =C10/B10*100-100 -> 23.768672 | D11: =D10/C10*100-100 -> 28.104604 | E11: =E10/D10*100-100 -> 32.803319 | F11: =F10/E10*100-100 -> 23.523338 | G11: =G10/F10*100-100 -> -18.859218 | H11: =H10/G10*100-100 -> 1.5274777 | I11: =I10/H10*100-100 -> 27.073702 | J11: =J10/I10*100-100 -> 0.30572767 | ... AL11: =AL10/AK10*100-100 -> 7.5052785 | AO11: =+AO10-AD8 -> -67479
AC12: =174674.7-AC10 -> 0 | AE12: =+AE8/AC8-1 -> 0.024534342 | AO12: =+AO11/5 -> -13495.8
A13: Excise | B13: =+B440 -> 1330.6 | C13: =+C440 -> 1223.45 | D13: =+D440 -> 1791.33 | E13: =+E440 -> 2199.23 | F13: =+F440 -> 3011.55 | G13: =+G440 -> 2454.9 | H13: =+H440 -> 2263.75 | I13: =+I440 -> 3454.64 | ... AL13: =+AL440 -> 0
A14: % of sales | B14: =+B442 -> 13.941203 | C14: =+C442 -> 10.356863 | D14: =+D442 -> 11.837306 | E14: =+E442 -> 10.943065 | F14: =+F442 -> 12.131357 | G14: =+G442 -> 12.18748 | H14: =+H442 -> 11.069423 | I14: =+I442 -> 13.293632 | ... AA14: =+AA442 -> 1.0428241
AN15: Base | AO15: FY19 | AP15: FY20 | AQ15: FY21 | AR15: FY22 | AS15: FY23 | AT15: FY24 | AU15: FY25 | AV15: FY26 | AW15: FY27 | AX15: FY28
A16: Net revenue | B16: =B10-B13 -> 8213.77 | C16: =C10-C13 -> 10589.49 | D16: =D10-D13 -> 13341.59 | E16: =E10-E13 -> 17897.79 | F16: =F10-F13 -> 21812.96 | G16: =G10-G13 -> 17687.902 | H16: =H10-H13 -> 18186.728 | I16: =I10-I13 -> 22532.54 | ... AL16: =AL10-AL13 -> 557215.7 | AN16: Volumes | AO16: =+AB8 -> 197366 | AP16: =+AC8 -> 125253 | AQ16: =+AD8 -> 100715 | AR16: =+AE8 -> 128326 | AS16: =+AF8 -> 192205 | AT16: =+AG8 -> 194683 | AU16: =+AH8 -> 195093 | AV16: =+AI8 -> 220437 | ... AX16: =+AK8 -> 254191.89 | AY16: =+SQRT(AX16/AV16)-1 -> 0.073837584
A17: % change YoY | C17: =C16/B16*100-100 -> 28.923625 | D17: =D16/C16*100-100 -> 25.988976 | E17: =E16/D16*100-100 -> 34.150352 | F17: =F16/E16*100-100 -> 21.875159 | G17: =G16/F16*100-100 -> -18.911044 | H17: =H16/G16*100-100 -> 2.8201582 | I17: =I16/H16*100-100 -> 23.895511 | J17: =J16/I16*100-100 -> -0.055120284 | ... AL17: =AL16/AK16*100-100 -> 7.5052785 | AN17: % Chg YoY | AO17: =+AO16/AA8-1 -> 0.12862477 | AP17: =+AP16/AO16-1 -> -0.36537702 | AQ17: =+AQ16/AP16-1 -> -0.19590748 | AR17: =+AR16/AQ16-1 -> 0.27414983 | AS17: =+AS16/AR16-1 -> 0.49778689 | AT17: =+AT16/AS16-1 -> 0.012892485 | AU17: =+AU16/AT16-1 -> 0.0021059877 | AV17: =+AV16/AU16-1 -> 0.12990727 | AW17: =+AW16/AV16-1 -> 0.076931913 | AX17: =+AX16/AW16-1 -> 0.070752147
A18: ASP | X18: =+X16-135621.836 -> 0 | AC18: =+AC16*1000000/AC8 -> 1394575 | AD18: =+AD16*1000000/AD8 -> 1519282.1 | AE18: =+AE16*1000000/AE8 -> 1690093.2 | AF18: =+AF16*1000000/AF8 -> 1880499.5 | AG18: =+AG16*1000000/AG8 -> 1970743.7 | AH18: =+AH16*1000000/AH8 -> 1986372.7 | AI18: =+AI16*1000000/AI8 -> 1996354.1 | AJ18: =+AJ16*1000000/AJ8 -> 2021180.7 | ... AL18: =+AL16*1000000/AL8 -> 2061411.2 | AN18: ASP | AO18: =+AB19 -> 1472135.5 | AP18: =+AC19 -> 1394575 | AQ18: =+AD19 -> 1519282.1 | AR18: =+AE19 -> 1690093.2 | AS18: =+AF19 -> 1880499.5 | AT18: =+AG19 -> 1970743.7 | AU18: =+AH19 -> 1986372.7 | AV18: =+AI19 -> 1996354.1 | ... AX18: =+AK19 -> 2039068.7 | AY18: =+SQRT(AX18/AV18)-1 -> 0.01064155
A19: Revenue / vehicle | B19: =+B16/B8*1000000 -> 399288.8 | C19: =+C16/C8*1000000 -> 437112.61 | D19: =+D16/D8*1000000 -> 438723.78 | E19: =+E16/E8*1000000 -> 478563.33 | F19: =+F16/F8*1000000 -> 503159.25 | G19: =+G16/G8*1000000 -> 560684.11 | H19: =+H16/H8*1000000 -> 611503.59 | I19: =+I16/I8*1000000 -> 595169.97 | ... R19: =+R16/R8*1000000 -> 1098835.9 | S19: =S16/S8*1000000 -> 1133296.4 | T19: =T16/T8*1000000 -> 1181402.8 | U19: =U16/U8*1000000 -> 1258008.9 | V19: =V16/V8*1000000 -> 1089005.4 | W19: =W16/W8*1000000 -> 1113024.5 | X19: =X16/X8*1000000 -> 1292843.2 | Y19: =Y16/Y8*1000000 -> 1348263.5 | Z19: =Z16/Z8*1000000 -> 1379968.9 | ... AL19: =AL16/AL8*1000000 -> 2061411.2 | AN19: % Chg YoY | AO19: =+AO18/AA19-1 -> -0.019210382 | AP19: =+AP18/AO18-1 -> -0.052685737 | AQ19: =+AQ18/AP18-1 -> 0.089423053 | AR19: =+AR18/AQ18-1 -> 0.1124288 | AS19: =+AS18/AR18-1 -> 0.11266022 | AT19: =+AT18/AS18-1 -> 0.047989514 | AU19: =+AU18/AT18-1 -> 0.0079304737 | AV19: =+AV18/AU18-1 -> 0.005024942 | AW19: =+AW18/AV18-1 -> 0.012435992 | AX19: =+AX18/AW18-1 -> 0.0088502883
X20: =86266.352+13911.872-526.126-X22 -> 0 | Y20: =122521.706+15312.255-5214.366-Y22 -> 670.991 | AA20: =+AA19/Z19-1 -> 0.087683737 | AB20: =+AB19/AA19-1 -> -0.019210382 | AC20: =+AC19/AB19-1 -> -0.052685737 | AD20: =+AD19/AC19-1 -> 0.089423053 | AE20: =+AE19/AD19-1 -> 0.1124288 | AF20: =+AF19/AE19-1 -> 0.11266022 | AG20: =+AG19/AF19-1 -> 0.047989514 | AH20: =+AH19/AG19-1 -> 0.0079304737 | ... AL20: =+AL19/AK19-1 -> 0.010957194 | AN20: Revenue | AO20: =+AO18*AO16/1000000 -> 290549.5 | AP20: =+AP18*AP16/1000000 -> 174674.7 | AQ20: =+AQ18*AQ16/1000000 -> 153014.5 | AR20: =+AR18*AR16/1000000 -> 216882.9 | AS20: =+AS18*AS16/1000000 -> 361441.4 | AT20: =+AT18*AT16/1000000 -> 383670.3 | AU20: =+AU18*AU16/1000000 -> 387527.4 | AV20: =+AV18*AV16/1000000 -> 440070.3 | ... AX20: =+AX18*AX16/1000000 -> 518314.74
AG21: =+AG18/AF18-1 -> 0.047989514 | AH21: =+AH18/AG18-1 -> 0.0079304737 | AI21: =+AI18/AH18-1 -> 0.005024942 | AJ21: =+AJ18/AI18-1 -> 0.012435992 | AQ21: =+AQ18/AP18-1 -> 0.089423053 | AR21: =+AR18/AQ18-1 -> 0.1124288 | AS21: =+AS18/AR18-1 -> 0.11266022 | AT21: =+AT18/AS18-1 -> 0.047989514 | AU21: =+AU18/AT18-1 -> 0.0079304737 | AV21: =+AV18/AU18-1 -> 0.005024942 | AW21: =+AW18/AV18-1 -> 0.012435992 | AX21: =+AX18/AW18-1 -> 0.0088502883
A22: Raw material expenses | B22: =+B434 -> 5960.34 | C22: =+C434 -> 7619.16 | D22: =+D434 -> 9785.26 | E22: =+E434 -> 13034.08 | F22: =+F434 -> 15709.15 | G22: =+G434 -> 12432.96 | H22: =+H434 -> 12799.48 | I22: =+I434 -> 15614.33 | ... AL22: =+AL434 -> 401195.31 | AN22: EBITDA | AO22: =+AO20*AO23 -> 31357.4 | AP22: =+AP20*AP23 -> 11736.5 | AQ22: =+AQ20*AQ23 -> 5351.4 | AR22: =+AR20*AR23 -> 9945.2 | AS22: =+AS20*AS23 -> 29307 | AT22: =+AT20*AT23 -> 46065.8 | AU22: =+AU20*AU23 -> 49305.6 | AV22: =+AV20*AV23 -> 57322.5 | ... AX22: =+AX20*AX23 -> 63844.138 | AY22: =+SQRT(AX22/AV22)-1 -> 0.055353491
A23: % of sales | B23: =B22/B16*100 -> 72.565217 | C23: =C22/C16*100 -> 71.950207 | D23: =D22/D16*100 -> 73.344032 | E23: =E22/E16*100 -> 72.825081 | F23: =F22/F16*100 -> 72.017507 | G23: =G22/G16*100 -> 70.290757 | H23: =H22/H16*100 -> 70.378134 | I23: =I22/I16*100 -> 69.296804 | ... AL23: =AL22/AL16*100 -> 72 | AN23: EBITDA Margin | AO23: =+AB44 -> 0.10792447 | AP23: =+AC44 -> 0.067190612 | AQ23: =+AD44 -> 0.034973156 | AR23: =+AE44 -> 0.04585516 | AS23: =+AF44 -> 0.081083683 | AT23: =+AG44 -> 0.12006611 | AU23: =+AH44 -> 0.12723126 | AV23: =+AI44 -> 0.1302576 | ... AX23: =+AK44 -> 0.12317639
AN24: Non operating items | AO24: =+AB46-AB45-AB49 -> -5814.5 | AP24: =+AC46-AC45-AC49 -> -6559.1 | AQ24: =+AD46-AD45-AD49 -> -9350 | AR24: =+AE46-AE45-AE49 -> -9777.4 | AS24: =+AF46-AF45-AF49+AF50 -> -8203 | AT24: =+AG46-AG45-AG49 -> -7206.8 | AU24: =+AH46-AH45-AH49 -> -6860 | AV24: =+AI46-AI45-AI49 -> -5697.5 | AW24: =+AJ46-AJ45-AJ49 -> -5423.0348 | AX24: =+AK46-AK45-AK49 -> -5383.3649
A25: Mat cost / vehicle | B25: =B22/B8*1000000 -> 289744.79 | C25: =C22/C8*1000000 -> 314503.43 | D25: =D22/D8*1000000 -> 321777.7 | E25: =E22/E8*1000000 -> 348514.13 | F25: =F22/F8*1000000 -> 362362.75 | G25: =G22/G8*1000000 -> 394109.11 | H25: =H22/H8*1000000 -> 430364.82 | I25: =I22/I8*1000000 -> 412433.77 | ... AL25: =AL22/AL8*1000000 -> 1484216.1 | AN25: PBT | AO25: =+AO22+AO24 -> 25542.9 | AP25: =+AP22+AP24 -> 5177.4 | AQ25: =+AQ22+AQ24 -> -3998.6 | AR25: =+AR22+AR24 -> 167.8 | AS25: =+AS22+AS24 -> 21104 | AT25: =+AT22+AT24 -> 38859 | AU25: =+AU22+AU24 -> 42445.6 | AV25: =+AV22+AV24 -> 51625 | ... AX25: =+AX22+AX24 -> 58460.773
AN26: Tax | AO26: =+AB52 -> 5136 | AP26: =+AC52 -> 1224 | AQ26: =+AD52 -> -982.3 | AR26: =+AE52 -> -142.2 | AS26: =+AF52 -> 7302.9 | AT26: =+AG52 -> 11743.1 | AU26: =+AH52 -> 10450 | AV26: =+AI52 -> 12484.9 | ... AX26: =+AK52 -> 14615.193
A27: Gross profit / unit | B27: =(B16-B22)/B8*1000000 -> 109544.02 | C27: =(C16-C22)/C8*1000000 -> 122609.18 | D27: =(D16-D22)/D8*1000000 -> 116946.07 | E27: =(E16-E22)/E8*1000000 -> 130049.2 | F27: =(F16-F22)/F8*1000000 -> 140796.5 | G27: =(G16-G22)/G8*1000000 -> 166575 | H27: =(H16-H22)/H8*1000000 -> 181138.78 | I27: =(I16-I22)/I8*1000000 -> 182736.21 | ... AL27: =(AL16-AL22)/AL8*1000000 -> 577195.14 | AN27: PAT | AO27: =+AO25-AO26 -> 20406.9 | AP27: =+AP25-AP26 -> 3953.4 | AQ27: =+AQ25-AQ26 -> -3016.3 | AR27: =+AR25-AR26 -> 310 | AS27: =+AS25-AS26 -> 13801.1 | AT27: =+AT25-AT26 -> 27115.9 | AU27: =+AU25-AU26+AH55-AH53+AH50 -> 32254.925 | AV27: =+AV25-AV26 -> 39140.1 | AW27: =+AW25-AW26 -> 39091.838 | AX27: =+AX25-AX26 -> 43845.58
AN28: Net debt | AO28: =+AB101 -> -7412.3 | AP28: =+AC101 -> 19588.9 | AQ28: =+AD101 -> 30183 | AR28: =+AE101 -> 12088.7 | AS28: =+AF101 -> -478.8 | AT28: =+AG101 -> -13878.4 | AU28: =+AH101 -> -42429.3 | AV28: =+AI101 -> -59017.2 | ... AX28: =+AK101 -> -93625.428
A29: Manpower costs | B29: =+B467 -> 718.28 | C29: =+C467 -> 934.41 | D29: =+D467 -> 1138.95 | E29: =+E467 -> 1571.62 | F29: =+F467 -> 1864.34 | G29: =+G467 -> 1846.74 | H29: =+H467 -> 2083.88 | I29: =+I467 -> 2286.04 | ... AL29: =+AL467 -> 33444.875 | AN29: Multiple | AP29: =+AM2 -> 18
A30: % of sales | B30: =B29/B16*100 -> 8.7448273 | C30: =C29/C16*100 -> 8.8239377 | D30: =D29/D16*100 -> 8.5368386 | E30: =E29/E16*100 -> 8.7810841 | F30: =F29/F16*100 -> 8.5469372 | G30: =G29/G16*100 -> 10.440696 | H30: =H29/H16*100 -> 11.458246 | I30: =I29/I16*100 -> 10.145505 | ... AL30: =AL29/AL16*100 -> 6.0021416 | AN30: TP | AP30: =+ROUND((AP29*AVERAGE(AW22:AX22)-AVERAGE(AW28:AX28))/$AH$78/5,0)*5 -> 200 | AQ30: =+AP30-AP2 -> 0 | AR30: =+AQ30-AQ2 -> -0.121498 | AS30: =+AR30-AR2 -> -200.1215 | AT30: =+AS30-AS2 -> -200.1215 | AU30: =+AT30-AT2 -> -200.1215 | AV30: =+AU30-AU2 -> -200.1215 | AW30: =+AV30-AV2 -> -200.1215 | AX30: =+AW30-AW2 -> -200.1215
A31: Other variable expenses | B31: =+B448 -> 82.84 | C31: =+C448 -> 132.1 | D31: =+D448 -> 123.6 | E31: =+E448 -> 237.2 | F31: =+F448 -> 295.4 | G31: =+G448 -> 217.18 | H31: =+H448 -> 163.68 | I31: =+I448 -> 230.14 | ... AL31: =+AL448 -> 3900.5099 | AN31: Bull | AO31: =+AO15 -> FY19 | AP31: =+AP15 -> FY20 | AQ31: =+AQ15 -> FY21 | AR31: =+AR15 -> FY22 | AS31: =+AS15 -> FY23 | AT31: =+AT15 -> FY24 | AU31: =+AU15 -> FY25 | AV31: =+AV15 -> FY26 | ... AX31: =+AX15 -> FY28
A32: % of sales | B32: =B31/B16*100 -> 1.0085503 | C32: =C31/C16*100 -> 1.2474633 | D32: =D31/D16*100 -> 0.92642631 | E32: =E31/E16*100 -> 1.3253033 | F32: =F31/F16*100 -> 1.3542408 | G32: =G31/G16*100 -> 1.2278449 | H32: =H31/H16*100 -> 0.89999695 | I32: =I31/I16*100 -> 1.0213673 | ... AL32: =AL31/AL16*100 -> 0.7 | AN32: Volumes | AO32: =+AO16 -> 197366 | AP32: =+AP16 -> 125253 | AQ32: =+AQ16 -> 100715 | AR32: =+AR16 -> 128326 | AS32: =+AS16 -> 192205 | AT32: =+AT16 -> 194683 | AU32: =+AU16 -> 195093 | AV32: =+AV16 -> 220437 | AW32: =+AV32*(1+AW33) -> 242480.7 | AX32: =+AW32*(1+AX33) -> 266728.77 | AY32: =+SQRT(AX32/AV32)-1 -> 0.1
AN33: % Chg YoY | AW33: 0.1 | AX33: 0.1
A34: Other fixed expenses | B34: =B486-B29 -> 827.29 | C34: =C486-C29 -> 1027.32 | D34: =D486-D29 -> 1212.78 | E34: =E486-E29 -> 1643 | F34: =F486-F29 -> 1731.23 | G34: =G486-G29 -> 1647.68 | H34: =H486-H29 -> 1483.97 | I34: =I486-I29 -> 1796.29 | ... AL34: =AL486-AL29 -> 51306.698 | AN34: ASP | AO34: =+AO18 -> 1472135.5 | AP34: =+AP18 -> 1394575 | AQ34: =+AQ18 -> 1519282.1 | AR34: =+AR18 -> 1690093.2 | AS34: =+AS18 -> 1880499.5 | AT34: =+AT18 -> 1970743.7 | AU34: =+AU18 -> 1986372.7 | AV34: =+AV18 -> 1996354.1 | AW34: =+AV34*(1+AW35) -> 2116135.3 | AX34: =+AW34*(1+AX35) -> 2158458 | AY34: =+SQRT(AX34/AV34)-1 -> 0.039807675
A35: % of sales | B35: =B34/B16*100 -> 10.071989 | C35: =C34/C16*100 -> 9.7013171 | D35: =D34/D16*100 -> 9.0902209 | E35: =E34/E16*100 -> 9.1799043 | F35: =F34/F16*100 -> 7.9367037 | G35: =G34/G16*100 -> 9.3152938 | H35: =H34/H16*100 -> 8.1596314 | I35: =I34/I16*100 -> 7.9719819 | ... AL35: =AL34/AL16*100 -> 9.2076906 | AN35: % Chg YoY | AW35: 0.06 | AX35: 0.02
AN36: Revenue | AO36: =+AO34*AO32/1000000 -> 290549.5 | AP36: =+AP34*AP32/1000000 -> 174674.7 | AQ36: =+AQ34*AQ32/1000000 -> 153014.5 | AR36: =+AR34*AR32/1000000 -> 216882.9 | AS36: =+AS34*AS32/1000000 -> 361441.4 | AT36: =+AT34*AT32/1000000 -> 383670.3 | AU36: =+AU34*AU32/1000000 -> 387527.4 | AV36: =+AV34*AV32/1000000 -> 440070.3 | ... AX36: =+AX34*AX32/1000000 -> 575722.85
A37: Expenses capitalised | B37: =+B494 -> 1.3 | C37: =+C494 -> 0.83 | D37: =+D494 -> -0.4 | E37: =+E494 -> 42.29 | F37: =+F494 -> 77.21 | G37: =+G494 -> 4.28 | H37: =+H494 -> 0 | I37: =+I494 -> 2.47 | ... AL37: =+AL494 -> 900 | AN37: EBITDA | AO37: =+AO22 -> 31357.4 | AP37: =+AP22 -> 11736.5 | AQ37: =+AQ22 -> 5351.4 | AR37: =+AR22 -> 9945.2 | AS37: =+AS22 -> 29307 | AT37: =+AT22 -> 46065.8 | AU37: =+AU22 -> 49305.6 | AV37: =+AV22 -> 57322.5 | AW37: =+AW36*AW38 -> 66705.856 | AX37: =+AX36*AX38 -> 77722.585 | AY37: =+SQRT(AX37/AV37)-1 -> 0.16442375
A38: % of sales | B38: =B37/B16*100 -> 0.015827081 | C38: =C37/C16*100 -> 0.0078379601 | D38: =D37/D16*100 -> -0.0029981434 | E38: =E37/E16*100 -> 0.23628616 | F38: =F37/F16*100 -> 0.35396388 | G38: =G37/G16*100 -> 0.02419733 | H38: =H37/H16*100 -> 0 | I38: =I37/I16*100 -> 0.010961924 | ... AL38: =AL37/AL16*100 -> 0.16151734 | AN38: EBITDA Margin | AO38: =+AO37/AO36 -> 0.10792447 | AP38: =+AP37/AP36 -> 0.067190612 | AQ38: =+AQ37/AQ36 -> 0.034973156 | AR38: =+AR37/AR36 -> 0.04585516 | AS38: =+AS37/AS36 -> 0.081083683 | AT38: =+AT37/AT36 -> 0.12006611 | AU38: =+AU37/AU36 -> 0.12723126 | AV38: =+AV37/AV36 -> 0.1302576 | AW38: 0.13 | AX38: 0.135
AN39: Non operating items | AO39: =+AO24 -> -5814.5 | AP39: =+AP24 -> -6559.1 | AQ39: =+AQ24 -> -9350 | AR39: =+AR24 -> -9777.4 | AS39: =+AS24 -> -8203 | AT39: =+AT24 -> -7206.8 | AU39: =+AU24 -> -6860 | AV39: =+AV24 -> -5697.5 | ... AX39: =+AX24 -> -5383.3649
A40: Cost of sales | B40: =+B22+B29+B31+B34-B37 -> 7587.45 | C40: =+C22+C29+C31+C34-C37 -> 9712.16 | D40: =+D22+D29+D31+D34-D37 -> 12260.99 | E40: =+E22+E29+E31+E34-E37 -> 16443.61 | F40: =+F22+F29+F31+F34-F37 -> 19522.91 | G40: =+G22+G29+G31+G34-G37 -> 16140.28 | H40: =+H22+H29+H31+H34-H37 -> 16531.01 | I40: =+I22+I29+I31+I34-I37 -> 19924.33 | ... AL40: =+AL22+AL29+AL31+AL34-AL37 -> 488947.39 | AN40: PBT | AO40: =+AO37+AO39 -> 25542.9 | AP40: =+AP37+AP39 -> 5177.4 | AQ40: =+AQ37+AQ39 -> -3998.6 | AR40: =+AR37+AR39 -> 167.8 | AS40: =+AS37+AS39 -> 21104 | AT40: =+AT37+AT39 -> 38859 | AU40: =+AU37+AU39 -> 42445.6 | AV40: =+AV37+AV39 -> 51625 | ... AX40: =+AX37+AX39 -> 72339.22
...

Sheet New Qrtrly - Ind AS
A1: Ashok Leyland (AL IN) — Quarterly model, Ind AS
A2: Note: Have used our Q database for volumes | Restructured: actuals, estimates and annual columns separated; blank rows removed; colour coding applied. No values changed — see README.
B3: QUARTERLY — ACTUALS (reported) | AZ3: QUARTERLY — BSe ESTIMATES | CE3: ANNUAL | CI3: WORKINGS / CHECKS
A4: Fiscal year | B4: FY16 | C4: FY16 | D4: FY16 | E4: FY16 | F4: FY17 | G4: FY17 | H4: FY17 | I4: FY17 | J4: FY18 | K4: FY18 | L4: FY18 | M4: FY18 | N4: FY18 | O4: FY18 | P4: FY19 | Q4: FY19 | R4: FY19 | S4: FY19 | T4: FY19 | U4: FY19 | V4: FY20 | W4: FY20 | X4: FY20 | Y4: FY20 | Z4: FY21 | AA4: FY21 | AB4: FY21 | AC4: FY21 | AD4: FY22 | AE4: FY22 | AF4: FY22 | AG4: FY22 | AH4: FY23 | AI4: FY23 | AJ4: FY23 | AK4: FY23 | AL4: FY24 | AM4: FY24 | AN4: FY24 | AO4: FY24 | AP4: FY25 | AQ4: FY25 | AR4: FY25 | AS4: FY25 | AT4: FY26 | AU4: FY26 | AV4: FY26 | AW4: FY26 | AX4: FY27 | AZ4: FY19 | BA4: FY20 | BB4: FY20 | BC4: FY20 | BD4: FY20 | BE4: FY21 | BF4: FY21 | BG4: FY21 | BH4: FY21 | BI4: FY22 | BJ4: FY22 | BK4: FY22 | BL4: FY22 | BM4: FY23 | BN4: FY23 | BO4: FY23 | BP4: FY23 | BQ4: FY24 | BR4: FY24 | BS4: FY24 | BT4: FY24 | BU4: FY25 | BV4: FY25 | BW4: FY25 | BX4: FY25 | BY4: FY26 | BZ4: FY26 | CA4: FY26 | CB4: FY26 | CC4: FY27 | CE4: FY16 | CF4: FY17 | CG4: FY26E | CJ4: FY26
A5: Period | B5: 1Q | C5: 2Q | D5: 3Q | E5: 4Q | F5: 1Q | G5: 2Q | H5: 3Q | I5: 4Q | J5: 1Q | K5: 2Q | L5: 3Q | M5: 3Q rest. | N5: 4Q | O5: 4Q rest. | P5: 1Q | Q5: 1Q rest. | R5: 2Q | S5: 2Q rest. | T5: 3Q | U5: 4Q | V5: 1Q | W5: 2Q | X5: 3Q | Y5: 4Q | Z5: 1Q | AA5: 2Q | AB5: 3Q | AC5: 4Q | AD5: 1Q | AE5: 2Q | AF5: 3Q | AG5: 4Q | AH5: 1Q | AI5: 2Q | AJ5: 3Q | AK5: 4Q | AL5: 1Q | AM5: 2Q | AN5: 3Q | AO5: 4Q | AP5: 1Q | AQ5: 2Q | AR5: 3Q | AS5: 4Q | AT5: 1Q | AU5: 2Q | AV5: 3Q | AW5: 4Q | AX5: 1Q | AZ5: 4Q | BA5: 1Q | BB5: 2Q | BC5: 3Q | BD5: 4Q | BE5: 1Q | BF5: 2Q | BG5: 3Q | BH5: 4Q | BI5: 1Q | BJ5: 2Q | BK5: 3Q | BL5: 4Q | BM5: 1Q | BN5: 2Q | BO5: 3Q | BP5: 4Q | BQ5: 1Q | BR5: 2Q | BS5: 3Q | BT5: 4Q | BU5: 1Q | BV5: 2Q | BW5: 3Q | BX5: 4Q | BY5: 1Q | BZ5: 2Q | CA5: 3Q | CB5: 4Q | CC5: 1Q | CE5: FY16 | CF5: FY17 | CG5: FY26E | CI5: (CE) | CJ5: 4Q | CK5: (CH) | CL5: (CI) | CM5: (CJ) | CN5: (CK)
A6: Source column | B6: src B | C6: src C | D6: src D | E6: src E | F6: src G | G6: src H | H6: src I | I6: src J | J6: src L | K6: src M | L6: src N | M6: src O | N6: src P | O6: src Q | P6: src R | Q6: src S | R6: src T | S6: src U | T6: src V | U6: src X | V6: src Z | W6: src AB | X6: src AD | Y6: src AF | Z6: src AH | AA6: src AJ | AB6: src AL | AC6: src AN | AD6: src AP | AE6: src AR | AF6: src AT | AG6: src AV | AH6: src AX | AI6: src AZ | AJ6: src BB | AK6: src BD | AL6: src BF | AM6: src BH | AN6: src BJ | AO6: src BL | AP6: src BN | AQ6: src BP | AR6: src BR | AS6: src BT | AT6: src BV | AU6: src BX | AV6: src BZ | AW6: src CB | AX6: src CD | AZ6: src W | BA6: src Y | BB6: src AA | BC6: src AC | BD6: src AE | BE6: src AG | BF6: src AI | BG6: src AK | BH6: src AM | BI6: src AO | BJ6: src AQ | BK6: src AS | BL6: src AU | BM6: src AW | BN6: src AY | BO6: src BA | BP6: src BC | BQ6: src BE | BR6: src BG | BS6: src BI | BT6: src BK | BU6: src BM | BV6: src BO | BW6: src BQ | BX6: src BS | BY6: src BU | BZ6: src BW | CA6: src BY | CB6: src CA | CC6: src CC | CE6: src F | CF6: src K | CG6: src CG | CI6: src CE | CJ6: src CF | CK6: src CH | CL6: src CI | CM6: src CJ | CN6: src CK
A8: VOLUMES (Nos.)
