Workbook

Sheet READ ME
B1: Ashok Leyland model — clean-up READ ME
B2: Structure, formatting and audit conventions. No number in this workbook was changed.
B4: COLOUR CODE
B5: 1,234 | C5: Blue — Hardcoded input. Typed number. Change these freely.
B6: 1,234 | C6: Blue on amber — Formula built only from hardcoded numbers, e.g. =8835+8903+12146. An input in disguise.
B7: 1,234 | C7: Black — Formula referencing cells on the same sheet. Do not overtype.
B8: 1,234 | C8: Black on amber — Formula with a hardcoded plug inside it, e.g. =+C41-1722.094 or =+AH20*0.21. Undocumented assumption — audit these first.
B9: 1,234 | C9: Green — Link to another sheet in this workbook.
B10: 1,234 | C10: Red on amber — Broken formula returning #REF!. Source has been deleted.
B12: CELL COUNTS BY TYPE
B13: Sheet | C13: Main Model | D13: New Qrtrly - Ind AS | E13: New Qrtrly | F13: DCF | G13: Comments
B14: Hardcoded inputs | C14: 2833 | D14: 870 | E14: 564 | F14: 19 | G14: 401
B15: Formulas made only of hardcodes | C15: 592 | D15: 137 | E15: 136 | F15: 8 | G15: 8
B16: Clean formulas | C16: 15502 | D16: 2806 | E16: 1576 | F16: 91 | G16: 108
B17: Formulas with a hardcoded plug | C17: 535 | D17: 173 | E17: 37 | F17: 0 | G17: 10
B18: Cross-sheet links | C18: 0 | D18: 91 | E18: 3 | F18: 23 | G18: 0
B19: Broken (#REF!) | C19: 318 | D19: 0 | E19: 0 | F19: 0 | G19: 3
B20: Text | C20: 995 | D20: 416 | E20: 165 | F20: 55 | G20: 692
B22: WHAT CHANGED
B23: Quarters vs years | C23: On "New Qrtrly - Ind AS" the annual columns (FY16, FY17, FY26E) no longer sit inside the run of quarters. They are in their own ANNUAL block to the right.
B24: Estimates vs actuals | C24: The interleaved E / A pairs are split into two blocks: QUARTERLY — ACTUALS (49 columns) and QUARTERLY — BSe ESTIMATES (30 columns), each in date order. The side-by-side comparison you lose is rebuilt live on the "Est vs Act" tab.
B25: Workings | C25: Unheaded scratch columns (old CE, CF, CH, CI, CJ, CK) are parked in a WORKINGS / CHECKS block at the far right instead of trailing the estimates.
B26: Blank rows | C26: All blank rows removed. Content is now grouped under 15 titled section bands.
B27: Duplicate labels | C27: 8 empty legacy label rows deleted (pre-Ind-AS margin and cost-ratio lines that were superseded by the rows below them). Listed on the Issues tab.
B28: Orphan rows | C28: Four unlabelled rows that carried live formulas are grouped under ORPHAN CALC ROWS. Nothing references them.
B29: Headers | C29: Two-row header: fiscal year over period, frozen. A small grey row records each column's original letter, so anything can be traced back to the source file.
B30: Number formats | C30: One consistent format per row, derived from the values in that row. Rows formatted as % but holding non-percentage values were reformatted — flagged on the Issues tab.
B31: Formulas | C31: All 3,207 formulas on the restructured sheet were re-pointed to the new addresses. Every one of the 9,416 data cells was checked against the original: zero differences. The other sheets were not moved at all — 277,641 cells checked, zero differences.
B32: Not changed | C32: No value, no formula logic, no estimate. The 738 pre-existing formula errors were left exactly as they were rather than silently patched — they are itemised on the Issues tab.
B34: TABS
B35: READ ME | C35: This page.
B36: Issues | C36: Everything found that needs your judgement, not mine.
B37: New Qrtrly - Ind AS | C37: Restructured quarterly model. The live sheet.
B38: Est vs Act | C38: Reported vs BSe by quarter. All links, no typed numbers.
B39: Main Model | C39: Annual model FY1993-FY2029E. Colour-coded only; nothing moved.
B40: New Qrtrly | C40: Legacy pre-Ind-AS quarterly sheet, FY07 onward. Colour-coded only.
B41: DCF, Comments, Industry launches and cap | C41: Untouched apart from colour coding.

Sheet Issues
B1: Issues found — for your call, not mine
B2: Nothing below was changed in the workbook. Each is preserved exactly as it was in the source file.
B4: Sheet | C4: Where | D4: What
B5: New Qrtrly - Ind AS (restructured) | C5: row 4: "H / MCVs" | D5: Row mixes magnitudes — it holds both sub-1 ratios and figures in the thousands, so it is carrying two different quantities on one line. Shown to 2dp so both are readable; values unchanged.
B6: New Qrtrly - Ind AS (restructured) | C6: row 5: "LCVs" | D6: Row mixes magnitudes — it holds both sub-1 ratios and figures in the thousands, so it is carrying two different quantities on one line. Shown to 2dp so both are readable; values unchanged.
B7: New Qrtrly - Ind AS (restructured) | C7: row 6: "Total CVs" | D7: Row mixes magnitudes — it holds both sub-1 ratios and figures in the thousands, so it is carrying two different quantities on one line. Shown to 2dp so both are readable; values unchanged.
B8: New Qrtrly - Ind AS (restructured) | C8: row 7: "Product mix (%)" | D8: Row mixes magnitudes — it holds both sub-1 ratios and figures in the thousands, so it is carrying two different quantities on one line. Shown to 2dp so both are readable; values unchanged.
B9: New Qrtrly - Ind AS (restructured) | C9: row 11: "H / MCVs" | D9: Row mixes magnitudes — it holds both sub-1 ratios and figures in the thousands, so it is carrying two different quantities on one line. Shown to 2dp so both are readable; values unchanged.
B10: New Qrtrly - Ind AS (restructured) | C10: row 17: "Discounts" | D10: Row mixes magnitudes — it holds both sub-1 ratios and figures in the thousands, so it is carrying two different quantities on one line. Shown to 2dp so both are readable; values unchanged.
B11: New Qrtrly - Ind AS (restructured) | C11: row 22: "Net sales" | D11: Row mixes magnitudes — it holds both sub-1 ratios and figures in the thousands, so it is carrying two different quantities on one line. Shown to 2dp so both are readable; values unchanged.
B12: New Qrtrly - Ind AS (restructured) | C12: row 31: "EBITDA" | D12: Row mixes magnitudes — it holds both sub-1 ratios and figures in the thousands, so it is carrying two different quantities on one line. Shown to 2dp so both are readable; values unchanged.
B13: New Qrtrly - Ind AS (restructured) | C13: row 38: "Exceptional income" | D13: Row mixes magnitudes — it holds both sub-1 ratios and figures in the thousands, so it is carrying two different quantities on one line. Shown to 2dp so both are readable; values unchanged.
B14: New Qrtrly - Ind AS (restructured) | C14: row 42: "PAT (pre exceptionals)" | D14: Row mixes magnitudes — it holds both sub-1 ratios and figures in the thousands, so it is carrying two different quantities on one line. Shown to 2dp so both are readable; values unchanged.
B15: New Qrtrly - Ind AS (restructured) | C15: row 46: "" | D15: Row mixes magnitudes — it holds both sub-1 ratios and figures in the thousands, so it is carrying two different quantities on one line. Shown to 2dp so both are readable; values unchanged.
... B41: All sheets | C41: Amber-shaded cells | D41: Formula contains a hardcoded number that is not a unit conversion — e.g. =+C41-1722.094, =+AH20*0.21, =H22*91%*88%/H6*1000000. Each is an undocumented assumption or plug. Count in this workbook: see the READ ME tab.

Sheet Industry launches and cap
A2: 41401
A3: Daimler Trucks -
A4: Still a niche player – BUT – has strong market shares in certain segments – eg – 30% market share in the Kerala construction market (small). Has 8-9% market share in Mumbai – which accounts for around 8-9% of overall CV sales.
A5: 40% of all trucks bought are through Bharat Benz Financial services
A6: Daimler trucks – launched 3 new models – 914 Rigid, 1214 construction and 1217 tipper. Will launch 6 more models end of 2013 – taking its overall tally to 12. Will launch overall 17 trucks – will have 110 dealers by that time

Sheet Est vs Act
A1: Ashok Leyland — reported vs BSe estimate
A2: Rebuilt from the restructured quarterly sheet. Every figure is a live link — nothing is typed. This replaces the side-by-side E/A columns that used to be interleaved.
A4: Quarter | B4: Total CVs (nos.) | E4: Net sales (INR m) | H4: EBITDA (INR m) | K4: EBITDA margin (%) | N4: PAT pre-except. (INR m)
B5: BSe | C5: Act | D5: Var | E5: BSe | F5: Act | G5: Var | H5: BSe | I5: Act | J5: Var | K5: BSe | L5: Act | M5: Var | N5: BSe | O5: Act | P5: Var
A6: 4QFY19 | B6: ='New Qrtrly - Ind AS'!AZ11 -> 59521 | C6: ='New Qrtrly - Ind AS'!U11 -> 59521 | D6: =IFERROR('New Qrtrly - Ind AS'!U11/'New Qrtrly - Ind AS'!AZ11-1,"") -> 0 | E6: ='New Qrtrly - Ind AS'!AZ33 -> 85167.782 | F6: ='New Qrtrly - Ind AS'!U33 -> 88459.3 | G6: =IFERROR('New Qrtrly - Ind AS'!U33/'New Qrtrly - Ind AS'!AZ33-1,"") -> 0.038647456 | H6: ='New Qrtrly - Ind AS'!AZ40 -> 9096.9789 | I6: ='New Qrtrly - Ind AS'!U40 -> 9854.4 | J6: =IFERROR('New Qrtrly - Ind AS'!U40/'New Qrtrly - Ind AS'!AZ40-1,"") -> 0.083260726 | K6: ='New Qrtrly - Ind AS'!AZ61 -> 10.681244 | L6: ='New Qrtrly - Ind AS'!U61 -> 11.140038 | M6: =IFERROR(('New Qrtrly - Ind AS'!U61-'New Qrtrly - Ind AS'!AZ61)*100,"") -> 45.879402 | N6: ='New Qrtrly - Ind AS'!AZ51 -> 5618.9842 | O6: ='New Qrtrly - Ind AS'!U51 -> 6611.66 | P6: =IFERROR('New Qrtrly - Ind AS'!U51/'New Qrtrly - Ind AS'!AZ51-1,"") -> 0.17666464
A7: 1QFY20 | B7: ='New Qrtrly - Ind AS'!BA11 -> 39608 | C7: ='New Qrtrly - Ind AS'!V11 -> 39608 | D7: =IFERROR('New Qrtrly - Ind AS'!V11/'New Qrtrly - Ind AS'!BA11-1,"") -> 0 | E7: ='New Qrtrly - Ind AS'!BA33 -> 58864.87 | F7: ='New Qrtrly - Ind AS'!V33 -> 56838.6 | G7: =IFERROR('New Qrtrly - Ind AS'!V33/'New Qrtrly - Ind AS'!BA33-1,"") -> -0.034422406 | H7: ='New Qrtrly - Ind AS'!BA40 -> 4482.1637 | I7: ='New Qrtrly - Ind AS'!V40 -> 5369.7 | J7: =IFERROR('New Qrtrly - Ind AS'!V40/'New Qrtrly - Ind AS'!BA40-1,"") -> 0.19801514 | K7: ='New Qrtrly - Ind AS'!BA61 -> 7.614327 | L7: ='New Qrtrly - Ind AS'!V61 -> 9.447277 | M7: =IFERROR(('New Qrtrly - Ind AS'!V61-'New Qrtrly - Ind AS'!BA61)*100,"") -> 183.295 | N7: ='New Qrtrly - Ind AS'!BA51 -> 2529.1228 | O7: ='New Qrtrly - Ind AS'!V51 -> 2442.97 | P7: =IFERROR('New Qrtrly - Ind AS'!V51/'New Qrtrly - Ind AS'!BA51-1,"") -> -0.034064299
A8: 2QFY20 | B8: ='New Qrtrly - Ind AS'!BB11 -> 28938 | C8: ='New Qrtrly - Ind AS'!W11 -> 28938 | D8: =IFERROR('New Qrtrly - Ind AS'!W11/'New Qrtrly - Ind AS'!BB11-1,"") -> 0 | E8: ='New Qrtrly - Ind AS'!BB33 -> 40696.311 | F8: ='New Qrtrly - Ind AS'!W33 -> 39295 | G8: =IFERROR('New Qrtrly - Ind AS'!W33/'New Qrtrly - Ind AS'!BB33-1,"") -> -0.034433374 | H8: ='New Qrtrly - Ind AS'!BB40 -> 1812.375 | I8: ='New Qrtrly - Ind AS'!W40 -> 2285.8 | J8: =IFERROR('New Qrtrly - Ind AS'!W40/'New Qrtrly - Ind AS'!BB40-1,"") -> 0.26121805 | K8: ='New Qrtrly - Ind AS'!BB61 -> 4.4534133 | L8: ='New Qrtrly - Ind AS'!W61 -> 5.8170251 | M8: =IFERROR(('New Qrtrly - Ind AS'!W61-'New Qrtrly - Ind AS'!BB61)*100,"") -> 136.36117 | N8: ='New Qrtrly - Ind AS'!BB51 -> 203.20496 | O8: ='New Qrtrly - Ind AS'!W51 -> 874.775 | P8: =IFERROR('New Qrtrly - Ind AS'!W51/'New Qrtrly - Ind AS'!BB51-1,"") -> 3.3048899
A9: 3QFY20 | B9: ='New Qrtrly - Ind AS'!BC11 -> 31200 | C9: ='New Qrtrly - Ind AS'!X11 -> 31200 | D9: =IFERROR('New Qrtrly - Ind AS'!X11/'New Qrtrly - Ind AS'!BC11-1,"") -> 0 | E9: ='New Qrtrly - Ind AS'!BC33 -> 41307.412 | F9: ='New Qrtrly - Ind AS'!X33 -> 40156.5 | G9: =IFERROR('New Qrtrly - Ind AS'!X33/'New Qrtrly - Ind AS'!BC33-1,"") -> -0.027862128 | H9: ='New Qrtrly - Ind AS'!BC40 -> 2490.0682 | I9: ='New Qrtrly - Ind AS'!X40 -> 2251.5 | J9: =IFERROR('New Qrtrly - Ind AS'!X40/'New Qrtrly - Ind AS'!BC40-1,"") -> -0.095807896 | K9: ='New Qrtrly - Ind AS'!BC61 -> 6.0281389 | L9: ='New Qrtrly - Ind AS'!X61 -> 5.6068133 | M9: =IFERROR(('New Qrtrly - Ind AS'!X61-'New Qrtrly - Ind AS'!BC61)*100,"") -> -42.132555 | N9: ='New Qrtrly - Ind AS'!BC51 -> 832.05456 | O9: ='New Qrtrly - Ind AS'!X51 -> 292.69 | P9: =IFERROR('New Qrtrly - Ind AS'!X51/'New Qrtrly - Ind AS'!BC51-1,"") -> -0.6482322
A10: 4QFY20 | B10: ='New Qrtrly - Ind AS'!BD11 -> 25507 | C10: ='New Qrtrly - Ind AS'!Y11 -> 25507 | D10: =IFERROR('New Qrtrly - Ind AS'!Y11/'New Qrtrly - Ind AS'!BD11-1,"") -> 0 | E10: ='New Qrtrly - Ind AS'!BD33 -> 32829.226 | F10: ='New Qrtrly - Ind AS'!Y33 -> 38384.6 | G10: =IFERROR('New Qrtrly - Ind AS'!Y33/'New Qrtrly - Ind AS'!BD33-1,"") -> 0.16922038 | H10: ='New Qrtrly - Ind AS'!BD40 -> 634.08639 | I10: ='New Qrtrly - Ind AS'!Y40 -> 1829.5 | J10: =IFERROR('New Qrtrly - Ind AS'!Y40/'New Qrtrly - Ind AS'!BD40-1,"") -> 1.8852535 | K10: ='New Qrtrly - Ind AS'!BD61 -> 1.9314692 | L10: ='New Qrtrly - Ind AS'!Y61 -> 4.7662344 | M10: =IFERROR(('New Qrtrly - Ind AS'!Y61-'New Qrtrly - Ind AS'!BD61)*100,"") -> 283.47652 | N10: ='New Qrtrly - Ind AS'!BD51 -> -704.13953 | O10: ='New Qrtrly - Ind AS'!Y51 -> -57.725 | P10: =IFERROR('New Qrtrly - Ind AS'!Y51/'New Qrtrly - Ind AS'!BD51-1,"") -> -0.91802051
A11: 1QFY21 | B11: ='New Qrtrly - Ind AS'!BE11 -> 3814 | C11: ='New Qrtrly - Ind AS'!Z11 -> 3814 | D11: =IFERROR('New Qrtrly - Ind AS'!Z11/'New Qrtrly - Ind AS'!BE11-1,"") -> 0 | E11: ='New Qrtrly - Ind AS'!BE33 -> 6313.512 | F11: ='New Qrtrly - Ind AS'!Z33 -> 6508.7 | G11: =IFERROR('New Qrtrly - Ind AS'!Z33/'New Qrtrly - Ind AS'!BE33-1,"") -> 0.030915913 | H11: ='New Qrtrly - Ind AS'!BE40 -> -3069.0815 | I11: ='New Qrtrly - Ind AS'!Z40 -> -3332.4 | J11: =IFERROR('New Qrtrly - Ind AS'!Z40/'New Qrtrly - Ind AS'!BE40-1,"") -> 0.085797162 | K11: ='New Qrtrly - Ind AS'!BE61 -> -48.61132 | L11: ='New Qrtrly - Ind AS'!Z61 -> -51.199164 | M11: =IFERROR(('New Qrtrly - Ind AS'!Z61-'New Qrtrly - Ind AS'!BE61)*100,"") -> -258.78443 | N11: ='New Qrtrly - Ind AS'!BE51 -> -3527.3571 | O11: ='New Qrtrly - Ind AS'!Z51 -> -3875.475 | P11: =IFERROR('New Qrtrly - Ind AS'!Z51/'New Qrtrly - Ind AS'!BE51-1,"") -> 0.09869087
A12: 2QFY21 | B12: ='New Qrtrly - Ind AS'!BF11 -> 19444 | C12: ='New Qrtrly - Ind AS'!AA11 -> 19444 | D12: =IFERROR('New Qrtrly - Ind AS'!AA11/'New Qrtrly - Ind AS'!BF11-1,"") -> 0 | E12: ='New Qrtrly - Ind AS'!BF33 -> 31522.655 | F12: ='New Qrtrly - Ind AS'!AA33 -> 28365.8 | G12: =IFERROR('New Qrtrly - Ind AS'!AA33/'New Qrtrly - Ind AS'!BF33-1,"") -> -0.10014558 | H12: ='New Qrtrly - Ind AS'!BF40 -> 1087.2495 | I12: ='New Qrtrly - Ind AS'!AA40 -> 804.3 | J12: =IFERROR('New Qrtrly - Ind AS'!AA40/'New Qrtrly - Ind AS'!BF40-1,"") -> -0.26024338 | K12: ='New Qrtrly - Ind AS'!BF61 -> 3.4491051 | L12: ='New Qrtrly - Ind AS'!AA61 -> 2.8354568 | M12: =IFERROR(('New Qrtrly - Ind AS'!AA61-'New Qrtrly - Ind AS'!BF61)*100,"") -> -61.364827 | N12: ='New Qrtrly - Ind AS'!BF51 -> -561.92537 | O12: ='New Qrtrly - Ind AS'!AA51 -> -1453.95 | P12: =IFERROR('New Qrtrly - Ind AS'!AA51/'New Qrtrly - Ind AS'!BF51-1,"") -> 1.5874432
A13: 3QFY21 | B13: ='New Qrtrly - Ind AS'!BG11 -> 33410 | C13: ='New Qrtrly - Ind AS'!AB11 -> 33410 | D13: =IFERROR('New Qrtrly - Ind AS'!AB11/'New Qrtrly - Ind AS'!BG11-1,"") -> 0 | E13: ='New Qrtrly - Ind AS'!BG33 -> 50689.644 | F13: ='New Qrtrly - Ind AS'!AB33 -> 48135.1 | G13: =IFERROR('New Qrtrly - Ind AS'!AB33/'New Qrtrly - Ind AS'!BG33-1,"") -> -0.050395772 | H13: ='New Qrtrly - Ind AS'!BG40 -> 4246.5485 | I13: ='New Qrtrly - Ind AS'!AB40 -> 2537.9 | J13: =IFERROR('New Qrtrly - Ind AS'!AB40/'New Qrtrly - Ind AS'!BG40-1,"") -> -0.4023617 | K13: ='New Qrtrly - Ind AS'!BG61 -> 8.3775465 | L13: ='New Qrtrly - Ind AS'!AB61 -> 5.2724519 | M13: =IFERROR(('New Qrtrly - Ind AS'!AB61-'New Qrtrly - Ind AS'!BG61)*100,"") -> -310.50946 | N13: ='New Qrtrly - Ind AS'!BG51 -> 1467.5839 | O13: ='New Qrtrly - Ind AS'!AB51 -> 151.425 | P13: =IFERROR('New Qrtrly - Ind AS'!AB51/'New Qrtrly - Ind AS'!BG51-1,"") -> -0.89682021
A14: 4QFY21 | B14: ='New Qrtrly - Ind AS'!BH11 -> 44060 | C14: ='New Qrtrly - Ind AS'!AC11 -> 44060 | D14: =IFERROR('New Qrtrly - Ind AS'!AC11/'New Qrtrly - Ind AS'!BH11-1,"") -> 0 | E14: ='New Qrtrly - Ind AS'!BH33 -> 65065.948 | F14: ='New Qrtrly - Ind AS'!AC33 -> 70004.9 | G14: =IFERROR('New Qrtrly - Ind AS'!AC33/'New Qrtrly - Ind AS'!BH33-1,"") -> 0.075906865 | H14: ='New Qrtrly - Ind AS'!BH40 -> 4845.9594 | I14: ='New Qrtrly - Ind AS'!AC40 -> 5341.6 | J14: =IFERROR('New Qrtrly - Ind AS'!AC40/'New Qrtrly - Ind AS'!BH40-1,"") -> 0.10227915 | K14: ='New Qrtrly - Ind AS'!BH61 -> 7.4477658 | L14: ='New Qrtrly - Ind AS'!AC61 -> 7.630323 | M14: =IFERROR(('New Qrtrly - Ind AS'!AC61-'New Qrtrly - Ind AS'!BH61)*100,"") -> 18.255726 | N14: ='New Qrtrly - Ind AS'!BH51 -> 1747.1716 | O14: ='New Qrtrly - Ind AS'!AC51 -> 2131.575 | P14: =IFERROR('New Qrtrly - Ind AS'!AC51/'New Qrtrly - Ind AS'!BH51-1,"") -> 0.2200147
A15: 1QFY22 | B15: ='New Qrtrly - Ind AS'!BI11 -> 17987 | C15: ='New Qrtrly - Ind AS'!AD11 -> 17987 | D15: =IFERROR('New Qrtrly - Ind AS'!AD11/'New Qrtrly - Ind AS'!BI11-1,"") -> 0 | E15: ='New Qrtrly - Ind AS'!BI33 -> 27149.778 | F15: ='New Qrtrly - Ind AS'!AD33 -> 29509.9 | G15: =IFERROR('New Qrtrly - Ind AS'!AD33/'New Qrtrly - Ind AS'!BI33-1,"") -> 0.086929688 | H15: ='New Qrtrly - Ind AS'!BI40 -> -1019.8021 | I15: ='New Qrtrly - Ind AS'!AD40 -> -1401 | J15: =IFERROR('New Qrtrly - Ind AS'!AD40/'New Qrtrly - Ind AS'!BI40-1,"") -> 0.37379594 | K15: ='New Qrtrly - Ind AS'!BI61 -> -3.7562079 | L15: ='New Qrtrly - Ind AS'!AD61 -> -4.7475593 | M15: =IFERROR(('New Qrtrly - Ind AS'!AD61-'New Qrtrly - Ind AS'!BI61)*100,"") -> -99.13514 | N15: ='New Qrtrly - Ind AS'!BI51 -> -2463.8615 | O15: ='New Qrtrly - Ind AS'!AD51 -> -2810.3 | P15: =IFERROR('New Qrtrly - Ind AS'!AD51/'New Qrtrly - Ind AS'!BI51-1,"") -> 0.14060795
A16: 2QFY22 | B16: ='New Qrtrly - Ind AS'!BJ11 -> 27543 | C16: ='New Qrtrly - Ind AS'!AE11 -> 27543 | D16: =IFERROR('New Qrtrly - Ind AS'!AE11/'New Qrtrly - Ind AS'!BJ11-1,"") -> 0 | E16: ='New Qrtrly - Ind AS'!BJ33 -> 46091.455 | F16: ='New Qrtrly - Ind AS'!AE33 -> 44578.5 | G16: =IFERROR('New Qrtrly - Ind AS'!AE33/'New Qrtrly - Ind AS'!BJ33-1,"") -> -0.032825063 | H16: ='New Qrtrly - Ind AS'!BJ40 -> 1799.4125 | I16: ='New Qrtrly - Ind AS'!AE40 -> 1346.9 | J16: =IFERROR('New Qrtrly - Ind AS'!AE40/'New Qrtrly - Ind AS'!BJ40-1,"") -> -0.25147789 | K16: ='New Qrtrly - Ind AS'!BJ61 -> 3.9040045 | L16: ='New Qrtrly - Ind AS'!AE61 -> 3.0214117 | M16: =IFERROR(('New Qrtrly - Ind AS'!AE61-'New Qrtrly - Ind AS'!BJ61)*100,"") -> -88.259279 | N16: ='New Qrtrly - Ind AS'!BJ51 -> -420.41128 | O16: ='New Qrtrly - Ind AS'!AE51 -> -831.825 | P16: =IFERROR('New Qrtrly - Ind AS'!AE51/'New Qrtrly - Ind AS'!BJ51-1,"") -> 0.97859818
A17: 3QFY22 | B17: ='New Qrtrly - Ind AS'!BK11 -> 34077 | C17: ='New Qrtrly - Ind AS'!AF11 -> 34077 | D17: =IFERROR('New Qrtrly - Ind AS'!AF11/'New Qrtrly - Ind AS'!BK11-1,"") -> 0 | E17: ='New Qrtrly - Ind AS'!BK33 -> 56808.43 | F17: ='New Qrtrly - Ind AS'!AF33 -> 55351.6 | G17: =IFERROR('New Qrtrly - Ind AS'!AF33/'New Qrtrly - Ind AS'!BK33-1,"") -> -0.025644612 | H17: ='New Qrtrly - Ind AS'!BK40 -> 2952.3221 | I17: ='New Qrtrly - Ind AS'!AF40 -> 2238.9 | J17: =IFERROR('New Qrtrly - Ind AS'!AF40/'New Qrtrly - Ind AS'!BK40-1,"") -> -0.24164778 | K17: ='New Qrtrly - Ind AS'!BK61 -> 5.1969788 | L17: ='New Qrtrly - Ind AS'!AF61 -> 4.0448695 | M17: =IFERROR(('New Qrtrly - Ind AS'!AF61-'New Qrtrly - Ind AS'!BK61)*100,"") -> -115.21093 | N17: ='New Qrtrly - Ind AS'!BK51 -> 337.62545 | O17: ='New Qrtrly - Ind AS'!AF51 -> -257.55 | P17: =IFERROR('New Qrtrly - Ind AS'!AF51/'New Qrtrly - Ind AS'!BK51-1,"") -> -1.7628276
A18: 4QFY22 | B18: ='New Qrtrly - Ind AS'!BL11 -> 48719 | C18: ='New Qrtrly - Ind AS'!AG11 -> 48719 | D18: =IFERROR('New Qrtrly - Ind AS'!AG11/'New Qrtrly - Ind AS'!BL11-1,"") -> 0 | E18: ='New Qrtrly - Ind AS'!BL33 -> 81508.784 | F18: ='New Qrtrly - Ind AS'!AG33 -> 87442.9 | G18: =IFERROR('New Qrtrly - Ind AS'!AG33/'New Qrtrly - Ind AS'!BL33-1,"") -> 0.07280339 | H18: ='New Qrtrly - Ind AS'!BL40 -> 5809.3008 | I18: ='New Qrtrly - Ind AS'!AG40 -> 7760.4 | J18: =IFERROR('New Qrtrly - Ind AS'!AG40/'New Qrtrly - Ind AS'!BL40-1,"") -> 0.33585785 | K18: ='New Qrtrly - Ind AS'!BL61 -> 7.1272082 | L18: ='New Qrtrly - Ind AS'!AG61 -> 8.87482 | M18: =IFERROR(('New Qrtrly - Ind AS'!AG61-'New Qrtrly - Ind AS'!BL61)*100,"") -> 174.76118 | N18: ='New Qrtrly - Ind AS'!BL51 -> 2372.5105 | O18: ='New Qrtrly - Ind AS'!AG51 -> 5486.75 | P18: =IFERROR('New Qrtrly - Ind AS'!AG51/'New Qrtrly - Ind AS'!BL51-1,"") -> 1.3126346
A19: 1QFY23 | B19: ='New Qrtrly - Ind AS'!BM11 -> 39651 | C19: ='New Qrtrly - Ind AS'!AH11 -> 39651 | D19: =IFERROR('New Qrtrly - Ind AS'!AH11/'New Qrtrly - Ind AS'!BM11-1,"") -> 0 | E19: ='New Qrtrly - Ind AS'!BM33 -> 71167.274 | F19: ='New Qrtrly - Ind AS'!AH33 -> 72228.5 | G19: =IFERROR('New Qrtrly - Ind AS'!AH33/'New Qrtrly - Ind AS'!BM33-1,"") -> 0.014911712 | H19: ='New Qrtrly - Ind AS'!BM40 -> 4545.1276 | I19: ='New Qrtrly - Ind AS'!AH40 -> 3202.8 | J19: =IFERROR('New Qrtrly - Ind AS'!AH40/'New Qrtrly - Ind AS'!BM40-1,"") -> -0.29533331 | K19: ='New Qrtrly - Ind AS'!BM61 -> 6.3865416 | L19: ='New Qrtrly - Ind AS'!AH61 -> 4.4342607 | M19: =IFERROR(('New Qrtrly - Ind AS'!AH61-'New Qrtrly - Ind AS'!BM61)*100,"") -> -195.22809 | N19: ='New Qrtrly - Ind AS'!BM51 -> 1424.5893 | O19: ='New Qrtrly - Ind AS'!AH51 -> 582.925 | P19: =IFERROR('New Qrtrly - Ind AS'!AH51/'New Qrtrly - Ind AS'!BM51-1,"") -> -0.59081189
A20: 2QFY23 | B20: ='New Qrtrly - Ind AS'!BN11 -> 45295 | C20: ='New Qrtrly - Ind AS'!AI11 -> 45295 | D20: =IFERROR('New Qrtrly - Ind AS'!AI11/'New Qrtrly - Ind AS'!BN11-1,"") -> 0 | E20: ='New Qrtrly - Ind AS'!BN33 -> 82922.193 | F20: ='New Qrtrly - Ind AS'!AI33 -> 82659.5 | G20: =IFERROR('New Qrtrly - Ind AS'!AI33/'New Qrtrly - Ind AS'!BN33-1,"") -> -0.0031679403 | H20: ='New Qrtrly - Ind AS'!BN40 -> 4956.3502 | I20: ='New Qrtrly - Ind AS'!AI40 -> 5373.4 | J20: =IFERROR('New Qrtrly - Ind AS'!AI40/'New Qrtrly - Ind AS'!BN40-1,"") -> 0.084144529 | K20: ='New Qrtrly - Ind AS'!BN61 -> 5.9771095 | L20: ='New Qrtrly - Ind AS'!AI61 -> 6.5006442 | M20: =IFERROR(('New Qrtrly - Ind AS'!AI61-'New Qrtrly - Ind AS'!BN61)*100,"") -> 52.353471 | N20: ='New Qrtrly - Ind AS'!BN51 -> 1866.4452 | O20: ='New Qrtrly - Ind AS'!AI51 -> 1931.375 | P20: =IFERROR('New Qrtrly - Ind AS'!AI51/'New Qrtrly - Ind AS'!BN51-1,"") -> 0.034787965
A21: 3QFY23 | B21: ='New Qrtrly - Ind AS'!BO11 -> 47562 | C21: ='New Qrtrly - Ind AS'!AJ11 -> 47562 | D21: =IFERROR('New Qrtrly - Ind AS'!AJ11/'New Qrtrly - Ind AS'!BO11-1,"") -> 0 | E21: ='New Qrtrly - Ind AS'!BO33 -> 87924.937 | F21: ='New Qrtrly - Ind AS'!AJ33 -> 90296.7 | G21: =IFERROR('New Qrtrly - Ind AS'!AJ33/'New Qrtrly - Ind AS'!BO33-1,"") -> 0.026974866 | H21: ='New Qrtrly - Ind AS'!BO40 -> 6631.3187 | I21: ='New Qrtrly - Ind AS'!AJ40 -> 7973.4 | J21: =IFERROR('New Qrtrly - Ind AS'!AJ40/'New Qrtrly - Ind AS'!BO40-1,"") -> 0.20238527 | K21: ='New Qrtrly - Ind AS'!BO61 -> 7.5420228 | L21: ='New Qrtrly - Ind AS'!AJ61 -> 8.830223 | M21: =IFERROR(('New Qrtrly - Ind AS'!AJ61-'New Qrtrly - Ind AS'!BO61)*100,"") -> 128.82003 | N21: ='New Qrtrly - Ind AS'!BO51 -> 2989.9231 | O21: ='New Qrtrly - Ind AS'!AJ51 -> 3561.35 | P21: =IFERROR('New Qrtrly - Ind AS'!AJ51/'New Qrtrly - Ind AS'!BO51-1,"") -> 0.19111758
A22: 4QFY23 | B22: ='New Qrtrly - Ind AS'!BP11 -> 59697 | C22: ='New Qrtrly - Ind AS'!AK11 -> 59697 | D22: =IFERROR('New Qrtrly - Ind AS'!AK11/'New Qrtrly - Ind AS'!BP11-1,"") -> 0 | E22: ='New Qrtrly - Ind AS'!BP33 -> 114695.08 | F22: ='New Qrtrly - Ind AS'!AK33 -> 116256.7 | G22: =IFERROR('New Qrtrly - Ind AS'!AK33/'New Qrtrly - Ind AS'!BP33-1,"") -> 0.013615403 | H22: ='New Qrtrly - Ind AS'!BP40 -> 12264.194 | I22: ='New Qrtrly - Ind AS'!AK40 -> 12757.4 | J22: =IFERROR('New Qrtrly - Ind AS'!AK40/'New Qrtrly - Ind AS'!BP40-1,"") -> 0.040215096 | K22: ='New Qrtrly - Ind AS'!BP61 -> 10.692869 | L22: ='New Qrtrly - Ind AS'!AK61 -> 10.973475 | M22: =IFERROR(('New Qrtrly - Ind AS'!AK61-'New Qrtrly - Ind AS'!BP61)*100,"") -> 28.060645 | N22: ='New Qrtrly - Ind AS'!BP51 -> 6904.936 | O22: ='New Qrtrly - Ind AS'!AK51 -> 7090.875 | P22: =IFERROR('New Qrtrly - Ind AS'!AK51/'New Qrtrly - Ind AS'!BP51-1,"") -> 0.026928421
A23: 1QFY24 | B23: ='New Qrtrly - Ind AS'!BQ11 -> 41329 | C23: ='New Qrtrly - Ind AS'!AL11 -> 41329 | D23: =IFERROR('New Qrtrly - Ind AS'!AL11/'New Qrtrly - Ind AS'!BQ11-1,"") -> 0 | E23: ='New Qrtrly - Ind AS'!BQ33 -> 80486.007 | F23: ='New Qrtrly - Ind AS'!AL33 -> 81892.9 | G23: =IFERROR('New Qrtrly - Ind AS'!AL33/'New Qrtrly - Ind AS'!BQ33-1,"") -> 0.017479971 | H23: ='New Qrtrly - Ind AS'!BQ40 -> 6140.5297 | I23: ='New Qrtrly - Ind AS'!AL40 -> 8207.5 | J23: =IFERROR('New Qrtrly - Ind AS'!AL40/'New Qrtrly - Ind AS'!BQ40-1,"") -> 0.33661107 | K23: ='New Qrtrly - Ind AS'!BQ61 -> 7.6293134 | L23: ='New Qrtrly - Ind AS'!AL61 -> 10.022236 | M23: =IFERROR(('New Qrtrly - Ind AS'!AL61-'New Qrtrly - Ind AS'!BQ61)*100,"") -> 239.2923 | N23: ='New Qrtrly - Ind AS'!BQ51 -> 2618.3708 | O23: ='New Qrtrly - Ind AS'!AL51 -> 5768.625 | P23: =IFERROR('New Qrtrly - Ind AS'!AL51/'New Qrtrly - Ind AS'!BQ51-1,"") -> 1.2031352
A24: 2QFY24 | B24: ='New Qrtrly - Ind AS'!BR11 -> 49846 | C24: ='New Qrtrly - Ind AS'!AM11 -> 49846 | D24: =IFERROR('New Qrtrly - Ind AS'!AM11/'New Qrtrly - Ind AS'!BR11-1,"") -> 0 | E24: ='New Qrtrly - Ind AS'!BR33 -> 96793.845 | F24: ='New Qrtrly - Ind AS'!AM33 -> 96380.4 | G24: =IFERROR('New Qrtrly - Ind AS'!AM33/'New Qrtrly - Ind AS'!BR33-1,"") -> -0.0042713985 | H24: ='New Qrtrly - Ind AS'!BR40 -> 10466.4 | I24: ='New Qrtrly - Ind AS'!AM40 -> 10797.9 | J24: =IFERROR('New Qrtrly - Ind AS'!AM40/'New Qrtrly - Ind AS'!BR40-1,"") -> 0.031672809 | K24: ='New Qrtrly - Ind AS'!BR61 -> 10.813084 | L24: ='New Qrtrly - Ind AS'!AM61 -> 11.203419 | M24: =IFERROR(('New Qrtrly - Ind AS'!AM61-'New Qrtrly - Ind AS'!BR61)*100,"") -> 39.033501 | N24: ='New Qrtrly - Ind AS'!BR51 -> 5821.4798 | O24: ='New Qrtrly - Ind AS'!AM51 -> 5781.7 | P24: =IFERROR('New Qrtrly - Ind AS'!AM51/'New Qrtrly - Ind AS'!BR51-1,"") -> -0.0068332807
A25: 3QFY24 | B25: ='New Qrtrly - Ind AS'!BS11 -> 47241 | C25: ='New Qrtrly - Ind AS'!AN11 -> 47241 | D25: =IFERROR('New Qrtrly - Ind AS'!AN11/'New Qrtrly - Ind AS'!BS11-1,"") -> 0 | E25: ='New Qrtrly - Ind AS'!BS33 -> 89516.598 | F25: ='New Qrtrly - Ind AS'!AN33 -> 92730.1 | G25: =IFERROR('New Qrtrly - Ind AS'!AN33/'New Qrtrly - Ind AS'!BS33-1,"") -> 0.035898392 | H25: ='New Qrtrly - Ind AS'!BS40 -> 9211.4151 | I25: ='New Qrtrly - Ind AS'!AN40 -> 11139.3 | J25: =IFERROR('New Qrtrly - Ind AS'!AN40/'New Qrtrly - Ind AS'!BS40-1,"") -> 0.20929302 | K25: ='New Qrtrly - Ind AS'!BS61 -> 10.290176 | L25: ='New Qrtrly - Ind AS'!AN61 -> 12.012604 | M25: =IFERROR(('New Qrtrly - Ind AS'!AN61-'New Qrtrly - Ind AS'!BS61)*100,"") -> 172.24288 | N25: ='New Qrtrly - Ind AS'!BS51 -> 5082.9906 | O25: ='New Qrtrly - Ind AS'!AN51 -> 5804.725 | P25: =IFERROR('New Qrtrly - Ind AS'!AN51/'New Qrtrly - Ind AS'!BS51-1,"") -> 0.14199012
A26: 4QFY24 | B26: ='New Qrtrly - Ind AS'!BT11 -> 56269 | C26: ='New Qrtrly - Ind AS'!AO11 -> 56269 | D26: =IFERROR('New Qrtrly - Ind AS'!AO11/'New Qrtrly - Ind AS'!BT11-1,"") -> 0 | E26: ='New Qrtrly - Ind AS'!BT33 -> 111003.56 | F26: ='New Qrtrly - Ind AS'!AO33 -> 112666.9 | G26: =IFERROR('New Qrtrly - Ind AS'!AO33/'New Qrtrly - Ind AS'!BT33-1,"") -> 0.01498457 | H26: ='New Qrtrly - Ind AS'!BT40 -> 13735.965 | I26: ='New Qrtrly - Ind AS'!AO40 -> 15921.1 | J26: =IFERROR('New Qrtrly - Ind AS'!AO40/'New Qrtrly - Ind AS'!BT40-1,"") -> 0.15908129 | K26: ='New Qrtrly - Ind AS'!BT61 -> 12.374346 | L26: ='New Qrtrly - Ind AS'!AO61 -> 14.131125 | M26: =IFERROR(('New Qrtrly - Ind AS'!AO61-'New Qrtrly - Ind AS'!BT61)*100,"") -> 175.67781 | N26: ='New Qrtrly - Ind AS'!BT51 -> 8131.1755 | O26: ='New Qrtrly - Ind AS'!AO51 -> 9526.55 | P26: =IFERROR('New Qrtrly - Ind AS'!AO51/'New Qrtrly - Ind AS'!BT51-1,"") -> 0.17160797
A27: 1QFY25 | B27: ='New Qrtrly - Ind AS'!BU11 -> 43893 | C27: ='New Qrtrly - Ind AS'!AP11 -> 43893 | D27: =IFERROR('New Qrtrly - Ind AS'!AP11/'New Qrtrly - Ind AS'!BU11-1,"") -> 0 | E27: ='New Qrtrly - Ind AS'!BU33 -> 86128.818 | F27: ='New Qrtrly - Ind AS'!AP33 -> 85985.3 | G27: =IFERROR('New Qrtrly - Ind AS'!AP33/'New Qrtrly - Ind AS'!BU33-1,"") -> -0.0016663215 | H27: ='New Qrtrly - Ind AS'!BU40 -> 8971.5539 | I27: ='New Qrtrly - Ind AS'!AP40 -> 9108.7 | J27: =IFERROR('New Qrtrly - Ind AS'!AP40/'New Qrtrly - Ind AS'!BU40-1,"") -> 0.015286778 | K27: ='New Qrtrly - Ind AS'!BU61 -> 10.416437 | L27: ='New Qrtrly - Ind AS'!AP61 -> 10.593322 | M27: =IFERROR(('New Qrtrly - Ind AS'!AP61-'New Qrtrly - Ind AS'!BU61)*100,"") -> 17.688563 | N27: ='New Qrtrly - Ind AS'!BU51 -> 5286.0877 | O27: ='New Qrtrly - Ind AS'!AP51 -> 5255.8 | P27: =IFERROR('New Qrtrly - Ind AS'!AP51/'New Qrtrly - Ind AS'!BU51-1,"") -> -0.0057296998
A28: 2QFY25 | B28: ='New Qrtrly - Ind AS'!BV11 -> 45624 | C28: ='New Qrtrly - Ind AS'!AQ11 -> 45624 | D28: =IFERROR('New Qrtrly - Ind AS'!AQ11/'New Qrtrly - Ind AS'!BV11-1,"") -> 0 | E28: ='New Qrtrly - Ind AS'!BV33 -> 87588.76 | F28: ='New Qrtrly - Ind AS'!AQ33 -> 87688.3 | G28: =IFERROR('New Qrtrly - Ind AS'!AQ33/'New Qrtrly - Ind AS'!BV33-1,"") -> 0.0011364425 | H28: ='New Qrtrly - Ind AS'!BV40 -> 9349.6754 | I28: ='New Qrtrly - Ind AS'!AQ40 -> 10173 | J28: =IFERROR('New Qrtrly - Ind AS'!AQ40/'New Qrtrly - Ind AS'!BV40-1,"") -> 0.088059165 | K28: ='New Qrtrly - Ind AS'!BV61 -> 10.674515 | L28: ='New Qrtrly - Ind AS'!AQ61 -> 11.60132 | M28: =IFERROR(('New Qrtrly - Ind AS'!AQ61-'New Qrtrly - Ind AS'!BV61)*100,"") -> 92.680465 | N28: ='New Qrtrly - Ind AS'!BV51 -> 5074.7728 | O28: ='New Qrtrly - Ind AS'!AQ51 -> 6820.65 | P28: =IFERROR('New Qrtrly - Ind AS'!AQ51/'New Qrtrly - Ind AS'!BV51-1,"") -> 0.34403062
A29: 3QFY25 | B29: ='New Qrtrly - Ind AS'!BW11 -> 46404 | C29: ='New Qrtrly - Ind AS'!AR11 -> 46404 | D29: =IFERROR('New Qrtrly - Ind AS'!AR11/'New Qrtrly - Ind AS'!BW11-1,"") -> 0 | E29: ='New Qrtrly - Ind AS'!BW33 -> 90525.254 | F29: ='New Qrtrly - Ind AS'!AR33 -> 94786.7 | G29: =IFERROR('New Qrtrly - Ind AS'!AR33/'New Qrtrly - Ind AS'!BW33-1,"") -> 0.047074664 | H29: ='New Qrtrly - Ind AS'!BW40 -> 10680.942 | I29: ='New Qrtrly - Ind AS'!AR40 -> 12114.3 | J29: =IFERROR('New Qrtrly - Ind AS'!AR40/'New Qrtrly - Ind AS'!BW40-1,"") -> 0.13419775 | K29: ='New Qrtrly - Ind AS'!BW61 -> 11.798853 | L29: ='New Qrtrly - Ind AS'!AR61 -> 12.780591 | M29: =IFERROR(('New Qrtrly - Ind AS'!AR61-'New Qrtrly - Ind AS'!BW61)*100,"") -> 98.173752 | N29: ='New Qrtrly - Ind AS'!BW51 -> 6069.6592 | O29: ='New Qrtrly - Ind AS'!AR51 -> 7617.4 | P29: =IFERROR('New Qrtrly - Ind AS'!AR51/'New Qrtrly - Ind AS'!BW51-1,"") -> 0.25499633
A30: 4QFY25 | B30: ='New Qrtrly - Ind AS'!BX11 -> 59176 | C30: ='New Qrtrly - Ind AS'!AS11 -> 59176 | D30: =IFERROR('New Qrtrly - Ind AS'!AS11/'New Qrtrly - Ind AS'!BX11-1,"") -> 0 | E30: ='New Qrtrly - Ind AS'!BX33 -> 122688.44 | F30: ='New Qrtrly - Ind AS'!AS33 -> 119067.1 | G30: =IFERROR('New Qrtrly - Ind AS'!AS33/'New Qrtrly - Ind AS'!BX33-1,"") -> -0.02951653 | H30: ='New Qrtrly - Ind AS'!BX40 -> 17366.205 | I30: ='New Qrtrly - Ind AS'!AS40 -> 17909.6 | J30: =IFERROR('New Qrtrly - Ind AS'!AS40/'New Qrtrly - Ind AS'!BX40-1,"") -> 0.0312904 | K30: ='New Qrtrly - Ind AS'!BX61 -> 14.15472 | L30: ='New Qrtrly - Ind AS'!AS61 -> 15.041603 | M30: =IFERROR(('New Qrtrly - Ind AS'!AS61-'New Qrtrly - Ind AS'!BX61)*100,"") -> 88.688276 | N30: ='New Qrtrly - Ind AS'!BX51 -> 11322.153 | O30: ='New Qrtrly - Ind AS'!AS51 -> 12561.075 | P30: =IFERROR('New Qrtrly - Ind AS'!AS51/'New Qrtrly - Ind AS'!BX51-1,"") -> 0.10942456
A31: 1QFY26 | B31: ='New Qrtrly - Ind AS'!BY11 -> 44238 | C31: ='New Qrtrly - Ind AS'!AT11 -> 44238 | D31: =IFERROR('New Qrtrly - Ind AS'!AT11/'New Qrtrly - Ind AS'!BY11-1,"") -> 0 | E31: ='New Qrtrly - Ind AS'!BY33 -> 87230.373 | F31: ='New Qrtrly - Ind AS'!AT33 -> 87245.1 | G31: =IFERROR('New Qrtrly - Ind AS'!AT33/'New Qrtrly - Ind AS'!BY33-1,"") -> 0.00016882692 | H31: ='New Qrtrly - Ind AS'!BY40 -> 9685.1171 | I31: ='New Qrtrly - Ind AS'!AT40 -> 9695.5 | J31: =IFERROR('New Qrtrly - Ind AS'!AT40/'New Qrtrly - Ind AS'!BY40-1,"") -> 0.0010720471 | K31: ='New Qrtrly - Ind AS'!BY61 -> 11.102918 | L31: ='New Qrtrly - Ind AS'!AT61 -> 11.112945 | M31: =IFERROR(('New Qrtrly - Ind AS'!AT61-'New Qrtrly - Ind AS'!BY61)*100,"") -> 1.0026687 | N31: ='New Qrtrly - Ind AS'!BY51 -> 5883.582 | O31: ='New Qrtrly - Ind AS'!AT51 -> 5937.3 | P31: =IFERROR('New Qrtrly - Ind AS'!AT51/'New Qrtrly - Ind AS'!BY51-1,"") -> 0.0091301577
A32: 2QFY26 | B32: ='New Qrtrly - Ind AS'!BZ11 -> 49116 | C32: ='New Qrtrly - Ind AS'!AU11 -> 49116 | D32: =IFERROR('New Qrtrly - Ind AS'!AU11/'New Qrtrly - Ind AS'!BZ11-1,"") -> 0 | E32: ='New Qrtrly - Ind AS'!BZ33 -> 96381.045 | F32: ='New Qrtrly - Ind AS'!AU33 -> 95881.8 | G32: =IFERROR('New Qrtrly - Ind AS'!AU33/'New Qrtrly - Ind AS'!BZ33-1,"") -> -0.0051799112 | H32: ='New Qrtrly - Ind AS'!BZ40 -> 11004.122 | I32: ='New Qrtrly - Ind AS'!AU40 -> 11621.6 | J32: =IFERROR('New Qrtrly - Ind AS'!AU40/'New Qrtrly - Ind AS'!BZ40-1,"") -> 0.056113329 | K32: ='New Qrtrly - Ind AS'!BZ61 -> 11.417309 | L32: ='New Qrtrly - Ind AS'!AU61 -> 12.120757 | M32: =IFERROR(('New Qrtrly - Ind AS'!AU61-'New Qrtrly - Ind AS'!BZ61)*100,"") -> 70.344768 | N32: ='New Qrtrly - Ind AS'!BZ51 -> 6449.8855 | O32: ='New Qrtrly - Ind AS'!AU51 -> 8010.6 | P32: =IFERROR('New Qrtrly - Ind AS'!AU51/'New Qrtrly - Ind AS'!BZ51-1,"") -> 0.24197554
A33: 3QFY26 | B33: ='New Qrtrly - Ind AS'!CA11 -> 57625 | C33: ='New Qrtrly - Ind AS'!AV11 -> 57625 | D33: =IFERROR('New Qrtrly - Ind AS'!AV11/'New Qrtrly - Ind AS'!CA11-1,"") -> 0 | E33: ='New Qrtrly - Ind AS'!CA33 -> 114180.03 | F33: ='New Qrtrly - Ind AS'!AV33 -> 115338.5 | G33: =IFERROR('New Qrtrly - Ind AS'!AV33/'New Qrtrly - Ind AS'!CA33-1,"") -> 0.010145958 | H33: ='New Qrtrly - Ind AS'!CA40 -> 14798.77 | I33: ='New Qrtrly - Ind AS'!AV40 -> 15350.2 | J33: =IFERROR('New Qrtrly - Ind AS'!AV40/'New Qrtrly - Ind AS'!CA40-1,"") -> 0.037261907 | K33: ='New Qrtrly - Ind AS'!CA61 -> 12.960908 | L33: ='New Qrtrly - Ind AS'!AV61 -> 13.308826 | M33: =IFERROR(('New Qrtrly - Ind AS'!AV61-'New Qrtrly - Ind AS'!CA61)*100,"") -> 34.791737 | N33: ='New Qrtrly - Ind AS'!CA51 -> 9996.5772 | O33: ='New Qrtrly - Ind AS'!AV51 -> 10273.8 | P33: =IFERROR('New Qrtrly - Ind AS'!AV51/'New Qrtrly - Ind AS'!CA51-1,"") -> 0.02773177
A34: 4QFY26 | B34: ='New Qrtrly - Ind AS'!CB11 -> 69458 | C34: ='New Qrtrly - Ind AS'!AW11 -> 69458 | D34: =IFERROR('New Qrtrly - Ind AS'!AW11/'New Qrtrly - Ind AS'!CB11-1,"") -> 0 | E34: ='New Qrtrly - Ind AS'!CB33 -> 140899.48 | F34: ='New Qrtrly - Ind AS'!AW33 -> 141604.9 | G34: =IFERROR('New Qrtrly - Ind AS'!AW33/'New Qrtrly - Ind AS'!CB33-1,"") -> 0.0050065543 | H34: ='New Qrtrly - Ind AS'!CB40 -> 19806.457 | I34: ='New Qrtrly - Ind AS'!AW40 -> 20655.2 | J34: =IFERROR('New Qrtrly - Ind AS'!AW40/'New Qrtrly - Ind AS'!CB40-1,"") -> 0.042851819 | K34: ='New Qrtrly - Ind AS'!CB61 -> 14.057154 | L34: ='New Qrtrly - Ind AS'!AW61 -> 14.586501 | M34: =IFERROR(('New Qrtrly - Ind AS'!AW61-'New Qrtrly - Ind AS'!CB61)*100,"") -> 52.934653 | N34: ='New Qrtrly - Ind AS'!CB51 -> 13774.843 | O34: ='New Qrtrly - Ind AS'!AW51 -> 14047.2 | P34: =IFERROR('New Qrtrly - Ind AS'!AW51/'New Qrtrly - Ind AS'!CB51-1,"") -> 0.019772062
A35: 1QFY27 | B35: ='New Qrtrly - Ind AS'!CC11 -> 48763 | C35: ='New Qrtrly - Ind AS'!AX11 -> 48763 | D35: =IFERROR('New Qrtrly - Ind AS'!AX11/'New Qrtrly - Ind AS'!CC11-1,"") -> 0 | E35: ='New Qrtrly - Ind AS'!CC33 -> 98419.605 | F35: ='New Qrtrly - Ind AS'!AX33 -> 96343.5 | G35: =IFERROR('New Qrtrly - Ind AS'!AX33/'New Qrtrly - Ind AS'!CC33-1,"") -> -0.021094428 | H35: ='New Qrtrly - Ind AS'!CC40 -> 9576.4542 | I35: ='New Qrtrly - Ind AS'!AX40 -> 9695.3 | J35: =IFERROR('New Qrtrly - Ind AS'!AX40/'New Qrtrly - Ind AS'!CC40-1,"") -> 0.012410209 | K35: ='New Qrtrly - Ind AS'!CC61 -> 9.7302303 | L35: ='New Qrtrly - Ind AS'!AX61 -> 10.063263 | M35: =IFERROR(('New Qrtrly - Ind AS'!AX61-'New Qrtrly - Ind AS'!CC61)*100,"") -> 33.303296 | N35: ='New Qrtrly - Ind AS'!CC51 -> 6004.8407 | O35: ='New Qrtrly - Ind AS'!AX51 -> 6091.1 | P35: =IFERROR('New Qrtrly - Ind AS'!AX51/'New Qrtrly - Ind AS'!CC51-1,"") -> 0.014364968

Sheet Main Model
Y1: =+Y61 -> 1.6825652e-11 | Z1: =+Z35+Z38-Z41-(23279.2) -> 0 | AA1: =+AA35+AA38-AA41-30757.301 -> 0 | AC1: =+AC35+AC38-AC41-23096.1 -> 0 | AD1: =+AD35+AD38-AD41 -> 17791.1 | AE1: =+AE35+AE38-AE41-22381 -> 0 | AF1: =+AF35+AF38-AF41-32504.3 -> 0 | AH1: =+AH21 -> 1986372.7 | AI1: =+AI21 -> 1996354.1 | AJ1: =+AJ21 -> 2021180.7 | AK1: =+AK21 -> 2039068.7 | AL1: =+AL21 -> 2061411.2 | AM1: Multiple | AN1: EBITDA | AO1: Debt | AP1: TP
Z2: =+Z294 -> 113296 | AD2: =+AD38+AD35-AD41 -> 17791.1 | AE2: =+AE38+AE35-AE41 -> 22381 | AF2: =+AF38+AF35-AF41 -> 32504.3 | AG2: =+AG35+AG38-AG41-36150.6 -> 0 | AH2: =+AH35+AH38-AH41-37931.3 -> 0 | AM2: 18 | AN2: =+AVERAGE(AJ47:AK47) -> 60694.811 | AO2: =AVERAGE(AJ115:AK115) -> -81674.808 | AP2: =+ROUND(((AM2*AN2-AO2)/AH84)/5,0)*5 -> 200 | AQ2: =+AP2/AP3-1+AJ137/AP3 -> 0.121498 | AR2: =+ROUND(((AM2*AN2-AO2)/AH84)/1,0)*1 -> 200
B3: FY 1993 | C3: FY 1994 | D3: FY 1995 | E3: FY 1996 | F3: FY 1997 | G3: FY 1998 | H3: FY 1999 | I3: FY2000 | J3: FY2001 | K3: FY2002 | L3: FY2003 | M3: FY2004 | N3: FY2005 | O3: FY2006 | P3: FY2007 | Q3: FY2008 | R3: FY2009 | S3: FY2010 | T3: FY2011 | U3: FY2012 | V3: FY2013 | W3: FY2014 | X3: FY2015 | Y3: FY2016 | Z3: FY2017 | AA3: FY2018 | AB3: FY2019 | AC3: FY2020 | AD3: FY2021 | AE3: FY2022 | AF3: FY2023 | AG3: FY2024 | AH3: FY2025 | AI3: FY2026 | AJ3: FY2027E | AK3: FY2028E | AL3: FY2029E | AO3: CMP | AP3: 181.3
A4: Summary | AO4: Old TP | AP4: 165 | AQ4: =+AP2/AP4-1 -> 0.21212121
AP5: =145/130-1 -> 0.11538462
A6: Income Statement | AE6: =+AE10/12 -> 10693.833 | AF6: =+AF10/12 -> 16017.083 | AG6: =+AG10/12 -> 16223.583 | AH6: =+AH10/12 -> 16257.75 | AI6: =+AI10/12 -> 18369.75 | AJ6: =+AJ10/12 -> 19782.97 | AK6: =+AK10/12 -> 21182.658 | AL6: =+AL10/12 -> 22525.657
A8: (Rs m) | B8: FY 1993 | C8: FY 1994 | D8: FY 1995 | E8: FY 1996 | F8: FY 1997 | G8: FY 1998 | H8: FY 1999 | I8: FY2000 | J8: FY2001 | K8: FY2002 | L8: FY 2003 | M8: FY2004 | N8: FY 2005 | O8: FY 2006 | P8: FY 2007 | Q8: FY2008 | R8: FY2009 | S8: FY2010 | T8: FY2011 | U8: FY2012 | V8: =+V3 -> FY2013 | W8: =+W3 -> FY2014 | X8: =+X3 -> FY2015 | Y8: =+Y3 -> FY2016 | Z8: =+Z3 -> FY2017 | AA8: =+AA3 -> FY2018 | AB8: =+AB3 -> FY2019 | AC8: =+AC3 -> FY2020 | ... AL8: =+AL3 -> FY2029E
A10: Volumes (Nos) | B10: =+B378 -> 20571 | C10: =+C378 -> 24226 | D10: =+D378 -> 30410 | E10: =+E378 -> 37399 | F10: =+F378 -> 43352 | G10: =+G378 -> 31547 | H10: =+H378 -> 29741 | I10: =+I378 -> 37859 | ... T10: =+T378 -> 94106 | U10: =+U378+U386 -> 101990 | V10: =+V378+V386 -> 114611 | W10: =+W378+W386 -> 89337 | X10: =+X378+X386 -> 104902 | Y10: =+Y378+Y386 -> 140457 | Z10: =+Z378+Z386 -> 145066 | AA10: =+AA378+AA386 -> 174873 | AB10: =+AB378+AB386 -> 197366 | ... AL10: =+AL378+AL386 -> 270307.88
A11: % change YoY | C11: =C10/B10*100-100 -> 17.767731 | D11: =D10/C10*100-100 -> 25.526294 | E11: =E10/D10*100-100 -> 22.982572 | F11: =F10/E10*100-100 -> 15.917538 | G11: =G10/F10*100-100 -> -27.230578 | H11: =H10/G10*100-100 -> -5.7247916 | I11: =I10/H10*100-100 -> 27.295652 | J11: =J10/I10*100-100 -> -14.221189 | ... AL11: =AL10/AK10*100-100 -> 6.3400895
A13: Sales & operational income | B13: =+B436 -> 9544.37 | C13: =+C436 -> 11812.94 | D13: =+D436 -> 15132.92 | E13: =+E436 -> 20097.02 | F13: =+F436 -> 24824.51 | G13: =+G436 -> 20142.802 | H13: =+H436 -> 20450.478 | I13: =+I436 -> 25987.18 | ... AL13: =+AL436 -> 557215.7 | AO13: 33236
A14: % change YoY | C14: =C13/B13*100-100 -> 23.768672 | D14: =D13/C13*100-100 -> 28.104604 | E14: =E13/D13*100-100 -> 32.803319 | F14: =F13/E13*100-100 -> 23.523338 | G14: =G13/F13*100-100 -> -18.859218 | H14: =H13/G13*100-100 -> 1.5274777 | I14: =I13/H13*100-100 -> 27.073702 | J14: =J13/I13*100-100 -> 0.30572767 | ... AL14: =AL13/AK13*100-100 -> 7.5052785 | AO14: =+AO13-AD10 -> -67479
AC15: =174674.7-AC13 -> 0 | AE15: =+AE10/AC10-1 -> 0.024534342 | AO15: =+AO14/5 -> -13495.8
A16: Excise | B16: =+B572 -> 1330.6 | C16: =+C572 -> 1223.45 | D16: =+D572 -> 1791.33 | E16: =+E572 -> 2199.23 | F16: =+F572 -> 3011.55 | G16: =+G572 -> 2454.9 | H16: =+H572 -> 2263.75 | I16: =+I572 -> 3454.64 | ... AL16: =+AL572 -> 0
A17: % of sales | B17: =+B574 -> 13.941203 | C17: =+C574 -> 10.356863 | D17: =+D574 -> 11.837306 | E17: =+E574 -> 10.943065 | F17: =+F574 -> 12.131357 | G17: =+G574 -> 12.18748 | H17: =+H574 -> 11.069423 | I17: =+I574 -> 13.293632 | ... AA17: =+AA574 -> 1.0428241
AN18: Base | AO18: FY19 | AP18: FY20 | AQ18: FY21 | AR18: FY22 | AS18: FY23 | AT18: FY24 | AU18: FY25 | AV18: FY26 | AW18: FY27 | AX18: FY28
A19: Net revenue | B19: =B13-B16 -> 8213.77 | C19: =C13-C16 -> 10589.49 | D19: =D13-D16 -> 13341.59 | E19: =E13-E16 -> 17897.79 | F19: =F13-F16 -> 21812.96 | G19: =G13-G16 -> 17687.902 | H19: =H13-H16 -> 18186.728 | I19: =I13-I16 -> 22532.54 | ... AL19: =AL13-AL16 -> 557215.7 | AN19: Volumes | AO19: =+AB10 -> 197366 | AP19: =+AC10 -> 125253 | AQ19: =+AD10 -> 100715 | AR19: =+AE10 -> 128326 | AS19: =+AF10 -> 192205 | AT19: =+AG10 -> 194683 | AU19: =+AH10 -> 195093 | AV19: =+AI10 -> 220437 | ... AX19: =+AK10 -> 254191.89 | AY19: =+SQRT(AX19/AV19)-1 -> 0.073837584
A20: % change YoY | C20: =C19/B19*100-100 -> 28.923625 | D20: =D19/C19*100-100 -> 25.988976 | E20: =E19/D19*100-100 -> 34.150352 | F20: =F19/E19*100-100 -> 21.875159 | G20: =G19/F19*100-100 -> -18.911044 | H20: =H19/G19*100-100 -> 2.8201582 | I20: =I19/H19*100-100 -> 23.895511 | J20: =J19/I19*100-100 -> -0.055120284 | ... AL20: =AL19/AK19*100-100 -> 7.5052785 | AN20: % Chg YoY | AO20: =+AO19/AA10-1 -> 0.12862477 | AP20: =+AP19/AO19-1 -> -0.36537702 | AQ20: =+AQ19/AP19-1 -> -0.19590748 | AR20: =+AR19/AQ19-1 -> 0.27414983 | AS20: =+AS19/AR19-1 -> 0.49778689 | AT20: =+AT19/AS19-1 -> 0.012892485 | AU20: =+AU19/AT19-1 -> 0.0021059877 | AV20: =+AV19/AU19-1 -> 0.12990727 | AW20: =+AW19/AV19-1 -> 0.076931913 | AX20: =+AX19/AW19-1 -> 0.070752147
A21: ASP | X21: =+X19-135621.836 -> 0 | AC21: =+AC19*1000000/AC10 -> 1394575 | AD21: =+AD19*1000000/AD10 -> 1519282.1 | AE21: =+AE19*1000000/AE10 -> 1690093.2 | AF21: =+AF19*1000000/AF10 -> 1880499.5 | AG21: =+AG19*1000000/AG10 -> 1970743.7 | AH21: =+AH19*1000000/AH10 -> 1986372.7 | AI21: =+AI19*1000000/AI10 -> 1996354.1 | AJ21: =+AJ19*1000000/AJ10 -> 2021180.7 | ... AL21: =+AL19*1000000/AL10 -> 2061411.2 | AN21: ASP | AO21: =+AB22 -> 1472135.5 | AP21: =+AC22 -> 1394575 | AQ21: =+AD22 -> 1519282.1 | AR21: =+AE22 -> 1690093.2 | AS21: =+AF22 -> 1880499.5 | AT21: =+AG22 -> 1970743.7 | AU21: =+AH22 -> 1986372.7 | AV21: =+AI22 -> 1996354.1 | ... AX21: =+AK22 -> 2039068.7 | AY21: =+SQRT(AX21/AV21)-1 -> 0.01064155
A22: Revenue / vehicle | B22: =+B19/B10*1000000 -> 399288.8 | C22: =+C19/C10*1000000 -> 437112.61 | D22: =+D19/D10*1000000 -> 438723.78 | E22: =+E19/E10*1000000 -> 478563.33 | F22: =+F19/F10*1000000 -> 503159.25 | G22: =+G19/G10*1000000 -> 560684.11 | H22: =+H19/H10*1000000 -> 611503.59 | I22: =+I19/I10*1000000 -> 595169.97 | ... R22: =+R19/R10*1000000 -> 1098835.9 | S22: =S19/S10*1000000 -> 1133296.4 | T22: =T19/T10*1000000 -> 1181402.8 | U22: =U19/U10*1000000 -> 1258008.9 | V22: =V19/V10*1000000 -> 1089005.4 | W22: =W19/W10*1000000 -> 1113024.5 | X22: =X19/X10*1000000 -> 1292843.2 | Y22: =Y19/Y10*1000000 -> 1348263.5 | Z22: =Z19/Z10*1000000 -> 1379968.9 | ... AL22: =AL19/AL10*1000000 -> 2061411.2 | AN22: % Chg YoY | AO22: =+AO21/AA22-1 -> -0.019210382 | AP22: =+AP21/AO21-1 -> -0.052685737 | AQ22: =+AQ21/AP21-1 -> 0.089423053 | AR22: =+AR21/AQ21-1 -> 0.1124288 | AS22: =+AS21/AR21-1 -> 0.11266022 | AT22: =+AT21/AS21-1 -> 0.047989514 | AU22: =+AU21/AT21-1 -> 0.0079304737 | AV22: =+AV21/AU21-1 -> 0.005024942 | AW22: =+AW21/AV21-1 -> 0.012435992 | AX22: =+AX21/AW21-1 -> 0.0088502883
X23: =86266.352+13911.872-526.126-X25 -> 0 | Y23: =122521.706+15312.255-5214.366-Y25 -> 670.991 | AA23: =+AA22/Z22-1 -> 0.087683737 | AB23: =+AB22/AA22-1 -> -0.019210382 | AC23: =+AC22/AB22-1 -> -0.052685737 | AD23: =+AD22/AC22-1 -> 0.089423053 | AE23: =+AE22/AD22-1 -> 0.1124288 | AF23: =+AF22/AE22-1 -> 0.11266022 | AG23: =+AG22/AF22-1 -> 0.047989514 | AH23: =+AH22/AG22-1 -> 0.0079304737 | ... AL23: =+AL22/AK22-1 -> 0.010957194 | AN23: Revenue | AO23: =+AO21*AO19/1000000 -> 290549.5 | AP23: =+AP21*AP19/1000000 -> 174674.7 | AQ23: =+AQ21*AQ19/1000000 -> 153014.5 | AR23: =+AR21*AR19/1000000 -> 216882.9 | AS23: =+AS21*AS19/1000000 -> 361441.4 | AT23: =+AT21*AT19/1000000 -> 383670.3 | AU23: =+AU21*AU19/1000000 -> 387527.4 | AV23: =+AV21*AV19/1000000 -> 440070.3 | ... AX23: =+AX21*AX19/1000000 -> 518314.74
AG24: =+AG21/AF21-1 -> 0.047989514 | AH24: =+AH21/AG21-1 -> 0.0079304737 | AI24: =+AI21/AH21-1 -> 0.005024942 | AJ24: =+AJ21/AI21-1 -> 0.012435992 | AQ24: =+AQ21/AP21-1 -> 0.089423053 | AR24: =+AR21/AQ21-1 -> 0.1124288 | AS24: =+AS21/AR21-1 -> 0.11266022 | AT24: =+AT21/AS21-1 -> 0.047989514 | AU24: =+AU21/AT21-1 -> 0.0079304737 | AV24: =+AV21/AU21-1 -> 0.005024942 | AW24: =+AW21/AV21-1 -> 0.012435992 | AX24: =+AX21/AW21-1 -> 0.0088502883
A25: Raw material expenses | B25: =+B565 -> 5960.34 | C25: =+C565 -> 7619.16 | D25: =+D565 -> 9785.26 | E25: =+E565 -> 13034.08 | F25: =+F565 -> 15709.15 | G25: =+G565 -> 12432.96 | H25: =+H565 -> 12799.48 | I25: =+I565 -> 15614.33 | ... AL25: =+AL565 -> 401195.31 | AN25: EBITDA | AO25: =+AO23*AO26 -> 31357.4 | AP25: =+AP23*AP26 -> 11736.5 | AQ25: =+AQ23*AQ26 -> 5351.4 | AR25: =+AR23*AR26 -> 9945.2 | AS25: =+AS23*AS26 -> 29307 | AT25: =+AT23*AT26 -> 46065.8 | AU25: =+AU23*AU26 -> 49305.6 | AV25: =+AV23*AV26 -> 57322.5 | ... AX25: =+AX23*AX26 -> 63844.138 | AY25: =+SQRT(AX25/AV25)-1 -> 0.055353491
A26: % of sales | B26: =B25/B19*100 -> 72.565217 | C26: =C25/C19*100 -> 71.950207 | D26: =D25/D19*100 -> 73.344032 | E26: =E25/E19*100 -> 72.825081 | F26: =F25/F19*100 -> 72.017507 | G26: =G25/G19*100 -> 70.290757 | H26: =H25/H19*100 -> 70.378134 | I26: =I25/I19*100 -> 69.296804 | ... AL26: =AL25/AL19*100 -> 72 | AN26: EBITDA Margin | AO26: =+AB48 -> 0.10792447 | AP26: =+AC48 -> 0.067190612 | AQ26: =+AD48 -> 0.034973156 | AR26: =+AE48 -> 0.04585516 | AS26: =+AF48 -> 0.081083683 | AT26: =+AG48 -> 0.12006611 | AU26: =+AH48 -> 0.12723126 | AV26: =+AI48 -> 0.1302576 | ... AX26: =+AK48 -> 0.12317639
AN27: Non operating items | AO27: =+AB50-AB49-AB53 -> -5814.5 | AP27: =+AC50-AC49-AC53 -> -6559.1 | AQ27: =+AD50-AD49-AD53 -> -9350 | AR27: =+AE50-AE49-AE53 -> -9777.4 | AS27: =+AF50-AF49-AF53+AF54 -> -8203 | AT27: =+AG50-AG49-AG53 -> -7206.8 | AU27: =+AH50-AH49-AH53 -> -6860 | AV27: =+AI50-AI49-AI53 -> -5697.5 | AW27: =+AJ50-AJ49-AJ53 -> -5423.0348 | AX27: =+AK50-AK49-AK53 -> -5383.3649
A28: Mat cost / vehicle | B28: =B25/B10*1000000 -> 289744.79 | C28: =C25/C10*1000000 -> 314503.43 | D28: =D25/D10*1000000 -> 321777.7 | E28: =E25/E10*1000000 -> 348514.13 | F28: =F25/F10*1000000 -> 362362.75 | G28: =G25/G10*1000000 -> 394109.11 | H28: =H25/H10*1000000 -> 430364.82 | I28: =I25/I10*1000000 -> 412433.77 | ... AL28: =AL25/AL10*1000000 -> 1484216.1 | AN28: PBT | AO28: =+AO25+AO27 -> 25542.9 | AP28: =+AP25+AP27 -> 5177.4 | AQ28: =+AQ25+AQ27 -> -3998.6 | AR28: =+AR25+AR27 -> 167.8 | AS28: =+AS25+AS27 -> 21104 | AT28: =+AT25+AT27 -> 38859 | AU28: =+AU25+AU27 -> 42445.6 | AV28: =+AV25+AV27 -> 51625 | ... AX28: =+AX25+AX27 -> 58460.773
AN29: Tax | AO29: =+AB56 -> 5136 | AP29: =+AC56 -> 1224 | AQ29: =+AD56 -> -982.3 | AR29: =+AE56 -> -142.2 | AS29: =+AF56 -> 7302.9 | AT29: =+AG56 -> 11743.1 | AU29: =+AH56 -> 10450 | AV29: =+AI56 -> 12484.9 | ... AX29: =+AK56 -> 14615.193
A30: Gross profit / unit | B30: =(B19-B25)/B10*1000000 -> 109544.02 | C30: =(C19-C25)/C10*1000000 -> 122609.18 | D30: =(D19-D25)/D10*1000000 -> 116946.07 | E30: =(E19-E25)/E10*1000000 -> 130049.2 | F30: =(F19-F25)/F10*1000000 -> 140796.5 | G30: =(G19-G25)/G10*1000000 -> 166575 | H30: =(H19-H25)/H10*1000000 -> 181138.78 | I30: =(I19-I25)/I10*1000000 -> 182736.21 | ... AL30: =(AL19-AL25)/AL10*1000000 -> 577195.14 | AN30: PAT | AO30: =+AO28-AO29 -> 20406.9 | AP30: =+AP28-AP29 -> 3953.4 | AQ30: =+AQ28-AQ29 -> -3016.3 | AR30: =+AR28-AR29 -> 310 | AS30: =+AS28-AS29 -> 13801.1 | AT30: =+AT28-AT29 -> 27115.9 | AU30: =+AU28-AU29+AH59-AH57+AH54 -> 32254.925 | AV30: =+AV28-AV29 -> 39140.1 | AW30: =+AW28-AW29 -> 39091.838 | AX30: =+AX28-AX29 -> 43845.58
AN31: Net debt | AO31: =+AB115 -> -7412.3 | AP31: =+AC115 -> 19588.9 | AQ31: =+AD115 -> 30183 | AR31: =+AE115 -> 12088.7 | AS31: =+AF115 -> -478.8 | AT31: =+AG115 -> -13878.4 | AU31: =+AH115 -> -42429.3 | AV31: =+AI115 -> -59017.2 | ... AX31: =+AK115 -> -93625.428
A32: Manpower costs | B32: =+B607 -> 718.28 | C32: =+C607 -> 934.41 | D32: =+D607 -> 1138.95 | E32: =+E607 -> 1571.62 | F32: =+F607 -> 1864.34 | G32: =+G607 -> 1846.74 | H32: =+H607 -> 2083.88 | I32: =+I607 -> 2286.04 | ... AL32: =+AL607 -> 33444.875 | AN32: Multiple | AP32: =+AM2 -> 18
A33: % of sales | B33: =B32/B19*100 -> 8.7448273 | C33: =C32/C19*100 -> 8.8239377 | D33: =D32/D19*100 -> 8.5368386 | E33: =E32/E19*100 -> 8.7810841 | F33: =F32/F19*100 -> 8.5469372 | G33: =G32/G19*100 -> 10.440696 | H33: =H32/H19*100 -> 11.458246 | I33: =I32/I19*100 -> 10.145505 | ... AL33: =AL32/AL19*100 -> 6.0021416 | AN33: TP | AP33: =+ROUND((AP32*AVERAGE(AW25:AX25)-AVERAGE(AW31:AX31))/$AH$84/5,0)*5 -> 200 | AQ33: =+AP33-AP2 -> 0 | AR33: =+AQ33-AQ2 -> -0.121498 | AS33: =+AR33-AR2 -> -200.1215 | AT33: =+AS33-AS2 -> -200.1215 | AU33: =+AT33-AT2 -> -200.1215 | AV33: =+AU33-AU2 -> -200.1215 | AW33: =+AV33-AV2 -> -200.1215 | AX33: =+AW33-AW2 -> -200.1215
A35: Other variable expenses | B35: =+B584 -> 82.84 | C35: =+C584 -> 132.1 | D35: =+D584 -> 123.6 | E35: =+E584 -> 237.2 | F35: =+F584 -> 295.4 | G35: =+G584 -> 217.18 | H35: =+H584 -> 163.68 | I35: =+I584 -> 230.14 | ... AL35: =+AL584 -> 3900.5099 | AN35: Bull | AO35: =+AO18 -> FY19 | AP35: =+AP18 -> FY20 | AQ35: =+AQ18 -> FY21 | AR35: =+AR18 -> FY22 | AS35: =+AS18 -> FY23 | AT35: =+AT18 -> FY24 | AU35: =+AU18 -> FY25 | AV35: =+AV18 -> FY26 | ... AX35: =+AX18 -> FY28
A36: % of sales | B36: =B35/B19*100 -> 1.0085503 | C36: =C35/C19*100 -> 1.2474633 | D36: =D35/D19*100 -> 0.92642631 | E36: =E35/E19*100 -> 1.3253033 | F36: =F35/F19*100 -> 1.3542408 | G36: =G35/G19*100 -> 1.2278449 | H36: =H35/H19*100 -> 0.89999695 | I36: =I35/I19*100 -> 1.0213673 | ... AL36: =AL35/AL19*100 -> 0.7 | AN36: Volumes | AO36: =+AO19 -> 197366 | AP36: =+AP19 -> 125253 | AQ36: =+AQ19 -> 100715 | AR36: =+AR19 -> 128326 | AS36: =+AS19 -> 192205 | AT36: =+AT19 -> 194683 | AU36: =+AU19 -> 195093 | AV36: =+AV19 -> 220437 | AW36: =+AV36*(1+AW37) -> 242480.7 | AX36: =+AW36*(1+AX37) -> 266728.77 | AY36: =+SQRT(AX36/AV36)-1 -> 0.1
AN37: % Chg YoY | AW37: 0.1 | AX37: 0.1
A38: Other fixed expenses | B38: =B632-B32 -> 827.29 | C38: =C632-C32 -> 1027.32 | D38: =D632-D32 -> 1212.78 | E38: =E632-E32 -> 1643 | F38: =F632-F32 -> 1731.23 | G38: =G632-G32 -> 1647.68 | H38: =H632-H32 -> 1483.97 | I38: =I632-I32 -> 1796.29 | ... AL38: =AL632-AL32 -> 51306.698 | AN38: ASP | AO38: =+AO21 -> 1472135.5 | AP38: =+AP21 -> 1394575 | AQ38: =+AQ21 -> 1519282.1 | AR38: =+AR21 -> 1690093.2 | AS38: =+AS21 -> 1880499.5 | AT38: =+AT21 -> 1970743.7 | AU38: =+AU21 -> 1986372.7 | AV38: =+AV21 -> 1996354.1 | AW38: =+AV38*(1+AW39) -> 2116135.3 | AX38: =+AW38*(1+AX39) -> 2158458 | AY38: =+SQRT(AX38/AV38)-1 -> 0.039807675
A39: % of sales | B39: =B38/B19*100 -> 10.071989 | C39: =C38/C19*100 -> 9.7013171 | D39: =D38/D19*100 -> 9.0902209 | E39: =E38/E19*100 -> 9.1799043 | F39: =F38/F19*100 -> 7.9367037 | G39: =G38/G19*100 -> 9.3152938 | H39: =H38/H19*100 -> 8.1596314 | I39: =I38/I19*100 -> 7.9719819 | ... AL39: =AL38/AL19*100 -> 9.2076906 | AN39: % Chg YoY | AW39: 0.06 | AX39: 0.02
AN40: Revenue | AO40: =+AO38*AO36/1000000 -> 290549.5 | AP40: =+AP38*AP36/1000000 -> 174674.7 | AQ40: =+AQ38*AQ36/1000000 -> 153014.5 | AR40: =+AR38*AR36/1000000 -> 216882.9 | AS40: =+AS38*AS36/1000000 -> 361441.4 | AT40: =+AT38*AT36/1000000 -> 383670.3 | AU40: =+AU38*AU36/1000000 -> 387527.4 | AV40: =+AV38*AV36/1000000 -> 440070.3 | ... AX40: =+AX38*AX36/1000000 -> 575722.85
A41: Expenses capitalised | B41: =+B643 -> 1.3 | C41: =+C643 -> 0.83 | D41: =+D643 -> -0.4 | E41: =+E643 -> 42.29 | F41: =+F643 -> 77.21 | G41: =+G643 -> 4.28 | H41: =+H643 -> 0 | I41: =+I643 -> 2.47 | ... AL41: =+AL643 -> 900 | AN41: EBITDA | AO41: =+AO25 -> 31357.4 | AP41: =+AP25 -> 11736.5 | AQ41: =+AQ25 -> 5351.4 | AR41: =+AR25 -> 9945.2 | AS41: =+AS25 -> 29307 | AT41: =+AT25 -> 46065.8 | AU41: =+AU25 -> 49305.6 | AV41: =+AV25 -> 57322.5 | AW41: =+AW40*AW42 -> 66705.856 | AX41: =+AX40*AX42 -> 77722.585 | AY41: =+SQRT(AX41/AV41)-1 -> 0.16442375
A42: % of sales | B42: =B41/B19*100 -> 0.015827081 | C42: =C41/C19*100 -> 0.0078379601 | D42: =D41/D19*100 -> -0.0029981434 | E42: =E41/E19*100 -> 0.23628616 | F42: =F41/F19*100 -> 0.35396388 | G42: =G41/G19*100 -> 0.02419733 | H42: =H41/H19*100 -> 0 | I42: =I41/I19*100 -> 0.010961924 | ... AL42: =AL41/AL19*100 -> 0.16151734 | AN42: EBITDA Margin | AO42: =+AO41/AO40 -> 0.10792447 | AP42: =+AP41/AP40 -> 0.067190612 | AQ42: =+AQ41/AQ40 -> 0.034973156 | AR42: =+AR41/AR40 -> 0.04585516 | AS42: =+AS41/AS40 -> 0.081083683 | AT42: =+AT41/AT40 -> 0.12006611 | AU42: =+AU41/AU40 -> 0.12723126 | AV42: =+AV41/AV40 -> 0.1302576 | AW42: 0.13 | AX42: 0.135
AN43: Non operating items | AO43: =+AO27 -> -5814.5 | AP43: =+AP27 -> -6559.1 | AQ43: =+AQ27 -> -9350 | AR43: =+AR27 -> -9777.4 | AS43: =+AS27 -> -8203 | AT43: =+AT27 -> -7206.8 | AU43: =+AU27 -> -6860 | AV43: =+AV27 -> -5697.5 | ... AX43: =+AX27 -> -5383.3649
A44: Cost of sales | B44: =+B25+B32+B35+B38-B41 -> 7587.45 | C44: =+C25+C32+C35+C38-C41 -> 9712.16 | D44: =+D25+D32+D35+D38-D41 -> 12260.99 | E44: =+E25+E32+E35+E38-E41 -> 16443.61 | F44: =+F25+F32+F35+F38-F41 -> 19522.91 | G44: =+G25+G32+G35+G38-G41 -> 16140.28 | H44: =+H25+H32+H35+H38-H41 -> 16531.01 | I44: =+I25+I32+I35+I38-I41 -> 19924.33 | ... AL44: =+AL25+AL32+AL35+AL38-AL41 -> 488947.39 | AN44: PBT | AO44: =+AO41+AO43 -> 25542.9 | AP44: =+AP41+AP43 -> 5177.4 | AQ44: =+AQ41+AQ43 -> -3998.6 | AR44: =+AR41+AR43 -> 167.8 | AS44: =+AS41+AS43 -> 21104 | AT44: =+AT41+AT43 -> 38859 | AU44: =+AU41+AU43 -> 42445.6 | AV44: =+AV41+AV43 -> 51625 | ... AX44: =+AX41+AX43 -> 72339.22
...

Sheet New Qrtrly - Ind AS
A1: Ashok Leyland (AL IN) — Quarterly model, Ind AS
A2: Note: Have used our Q database for volumes | Restructured: actuals, estimates and annual columns separated; blank rows removed; colour coding applied. No values changed — see README.
B3: QUARTERLY — ACTUALS (reported) | AZ3: QUARTERLY — BSe ESTIMATES | CE3: ANNUAL | CI3: WORKINGS / CHECKS
A4: Fiscal year | B4: FY16 | C4: FY16 | D4: FY16 | E4: FY16 | F4: FY17 | G4: FY17 | H4: FY17 | I4: FY17 | J4: FY18 | K4: FY18 | L4: FY18 | M4: FY18 | N4: FY18 | O4: FY18 | P4: FY19 | Q4: FY19 | R4: FY19 | S4: FY19 | T4: FY19 | U4: FY19 | V4: FY20 | W4: FY20 | X4: FY20 | Y4: FY20 | Z4: FY21 | AA4: FY21 | AB4: FY21 | AC4: FY21 | AD4: FY22 | AE4: FY22 | AF4: FY22 | AG4: FY22 | AH4: FY23 | AI4: FY23 | AJ4: FY23 | AK4: FY23 | AL4: FY24 | AM4: FY24 | AN4: FY24 | AO4: FY24 | AP4: FY25 | AQ4: FY25 | AR4: FY25 | AS4: FY25 | AT4: FY26 | AU4: FY26 | AV4: FY26 | AW4: FY26 | AX4: FY27 | AZ4: FY19 | BA4: FY20 | BB4: FY20 | BC4: FY20 | BD4: FY20 | BE4: FY21 | BF4: FY21 | BG4: FY21 | BH4: FY21 | BI4: FY22 | BJ4: FY22 | BK4: FY22 | BL4: FY22 | BM4: FY23 | BN4: FY23 | BO4: FY23 | BP4: FY23 | BQ4: FY24 | BR4: FY24 | BS4: FY24 | BT4: FY24 | BU4: FY25 | BV4: FY25 | BW4: FY25 | BX4: FY25 | BY4: FY26 | BZ4: FY26 | CA4: FY26 | CB4: FY26 | CC4: FY27 | CE4: FY16 | CF4: FY17 | CG4: FY26E | CJ4: FY26
A5: Period | B5: 1Q | C5: 2Q | D5: 3Q | E5: 4Q | F5: 1Q | G5: 2Q | H5: 3Q | I5: 4Q | J5: 1Q | K5: 2Q | L5: 3Q | M5: 3Q rest. | N5: 4Q | O5: 4Q rest. | P5: 1Q | Q5: 1Q rest. | R5: 2Q | S5: 2Q rest. | T5: 3Q | U5: 4Q | V5: 1Q | W5: 2Q | X5: 3Q | Y5: 4Q | Z5: 1Q | AA5: 2Q | AB5: 3Q | AC5: 4Q | AD5: 1Q | AE5: 2Q | AF5: 3Q | AG5: 4Q | AH5: 1Q | AI5: 2Q | AJ5: 3Q | AK5: 4Q | AL5: 1Q | AM5: 2Q | AN5: 3Q | AO5: 4Q | AP5: 1Q | AQ5: 2Q | AR5: 3Q | AS5: 4Q | AT5: 1Q | AU5: 2Q | AV5: 3Q | AW5: 4Q | AX5: 1Q | AZ5: 4Q | BA5: 1Q | BB5: 2Q | BC5: 3Q | BD5: 4Q | BE5: 1Q | BF5: 2Q | BG5: 3Q | BH5: 4Q | BI5: 1Q | BJ5: 2Q | BK5: 3Q | BL5: 4Q | BM5: 1Q | BN5: 2Q | BO5: 3Q | BP5: 4Q | BQ5: 1Q | BR5: 2Q | BS5: 3Q | BT5: 4Q | BU5: 1Q | BV5: 2Q | BW5: 3Q | BX5: 4Q | BY5: 1Q | BZ5: 2Q | CA5: 3Q | CB5: 4Q | CC5: 1Q | CE5: FY16 | CF5: FY17 | CG5: FY26E | CI5: (CE) | CJ5: 4Q | CK5: (CH) | CL5: (CI) | CM5: (CJ) | CN5: (CK)
A6: Source column | B6: src B | C6: src C | D6: src D | E6: src E | F6: src G | G6: src H | H6: src I | I6: src J | J6: src L | K6: src M | L6: src N | M6: src O | N6: src P | O6: src Q | P6: src R | Q6: src S | R6: src T | S6: src U | T6: src V | U6: src X | V6: src Z | W6: src AB | X6: src AD | Y6: src AF | Z6: src AH | AA6: src AJ | AB6: src AL | AC6: src AN | AD6: src AP | AE6: src AR | AF6: src AT | AG6: src AV | AH6: src AX | AI6: src AZ | AJ6: src BB | AK6: src BD | AL6: src BF | AM6: src BH | AN6: src BJ | AO6: src BL | AP6: src BN | AQ6: src BP | AR6: src BR | AS6: src BT | AT6: src BV | AU6: src BX | AV6: src BZ | AW6: src CB | AX6: src CD | AZ6: src W | BA6: src Y | BB6: src AA | BC6: src AC | BD6: src AE | BE6: src AG | BF6: src AI | BG6: src AK | BH6: src AM | BI6: src AO | BJ6: src AQ | BK6: src AS | BL6: src AU | BM6: src AW | BN6: src AY | BO6: src BA | BP6: src BC | BQ6: src BE | BR6: src BG | BS6: src BI | BT6: src BK | BU6: src BM | BV6: src BO | BW6: src BQ | BX6: src BS | BY6: src BU | BZ6: src BW | CA6: src BY | CB6: src CA | CC6: src CC | CE6: src F | CF6: src K | CG6: src CG | CI6: src CE | CJ6: src CF | CK6: src CH | CL6: src CI | CM6: src CJ | CN6: src CK
A8: VOLUMES (Nos.)
A9: H / MCVs | B9: 21485 | C9: =8835+8903+12146 -> 29884 | D9: =7177+6296+9703 -> 23176 | E9: =11208+10801+13240 -> 35249 | F9: =7873+7469+8685 -> 24027 | G9: =8182+8201+8958 -> 25341 | H9: =9575+6928+8782 -> 25285 | I9: 38643 | J9: 19877 | K9: 31397 | L9: =9140+10638+15950 -> 35728 | M9: =9140+10638+15950 -> 35728 | N9: =13726+13643+17057 -> 44426 | O9: =13726+13643+17057 -> 44426 | P9: 30646 | Q9: 30646 | R9: 38387 | S9: 38387 | T9: =9797+8718+11295 -> 29810 | U9: =14694+13291+16034 -> 44019 | V9: 26719 | W9: 16815 | X9: =5126+5966+7025 -> 18117 | Y9: 16956 | Z9: 1021 | AA9: =1705+2589+3642 -> 7936 | AB9: =4588+5114+6884 -> 16586 | AC9: 26277 | AD9: 9050 | AE9: 13514 | AF9: 19305 | AG9: 32016 | AH9: 24987 | AI9: =8148+8379+11314 -> 27841 | AJ9: 30790 | AK9: 40491 | AL9: 26165 | AM9: 32086 | AN9: 29485 | AO9: 37149 | AP9: 27885 | AQ9: 28180 | AR9: 30058 | AS9: 39908 | AT9: 28071 | AU9: 30718 | AV9: 37376 | AW9: 46493 | AX9: 29424 | AZ9: =14694+13291+16034 -> 44019 | BA9: 26719 | BB9: 16815 | BC9: =5126+5966+7025 -> 18117 | BD9: =78607-X9-W9-V9 -> 16956 | BE9: 1021 | BF9: =1705+2589+3642 -> 7936 | BG9: =4588+5114+6884 -> 16586 | BH9: 26277 | BI9: 9050 | BJ9: 13514 | BK9: 19305 | BL9: 32016 | BM9: 24987 | BN9: =8148+8379+11314 -> 27841 | BO9: 30790 | BP9: 40491 | BQ9: 26165 | BR9: 32086 | BS9: =87736-AM9-AL9 -> 29485 | BT9: 37149 | BU9: 27885 | BV9: 28180 | BW9: 30058 | BX9: 39908 | BY9: 28071 | BZ9: 30718 | CA9: 37376 | CB9: 46493 | CC9: 29424 | CG9: ='Main Model'!AI294 -> 142658 | CI9: =+CC9/AW9-1 -> -0.36713054 | CJ9: =CG9-AV9-AU9-AT9 -> 46493 | CL9: =+CA9/AU9-1 -> 0.21674588
