Workbook

Sheet Cover & Guide
A1: INDIA AUTO — COMMODITY COST MONITOR
A2: Proprietary commodity price database and blended cost-index framework for Indian and global auto OEM coverage.
A4: PURPOSE
A5: Turns the monthly SIAM Commodity Price Monitor into (i) a clean rolling raw database, (ii) FX-adjusted INR indices,
A6: (iii) segment-level bill-of-material baskets, and (iv) a quarterly QoQ / YoY cost read with a gross-margin translation.
A8: WHAT THIS ANSWERS
A9: 1. How much higher are commodity costs this quarter vs last quarter and vs last year — by segment, not just headline steel.
A10: 2. Which sub-complex (ferrous / non-ferrous / PGM / polymer / rubber / battery / energy) is driving the move.
A11: 3. What that means for OEM gross margin in bps, after inventory lag and assumed price pass-through.
A13: SHEET MAP
A14: Assumptions | B14: All levers live here — currency basis, base month, forecast drift, segment weights, RM % of ASP, pass-through, lag.
A15: Raw Data | B15: SIAM-reported prices, as published, in native units. THE ONLY SHEET YOU TYPE INTO EACH MONTH.
A16: INR Normalised | B16: Everything restated in INR per kg (or INR per bbl / litre) at the month's USD-INR. Captures currency drag.
A17: Commodity Indices | B17: Each commodity rebased to 100 at the chosen base month, on the chosen currency basis.
A18: Basket Weights | B18: The proprietary weight matrix: 6 segment BOM baskets + 7 sub-complex monitors. Edit weights here.
A19: Basket Monitors | B19: Monthly basket indices = weighted sum of commodity indices. Includes the blended India Auto Composite.
A20: Quarterly Dashboard | B20: The output page. Quarterly basket levels, QoQ, YoY, plus the current-quarter build-up and a commodity-level table.
A21: Margin & Scenarios | B21: Lagged realised cost move to gross-margin bps, and bear / base / bull scenarios for the current quarter.
A22: Methodology | B22: Full write-up of index construction, weighting logic, lag and pass-through treatment, and known limitations.
A23: Update Log | B23: Monthly update checklist and the version history.
A25: COLOUR CONVENTION
A26: Blue text | B26: Hardcoded input or scenario lever — safe to change.
A27: Black text | B27: Formula — do not overwrite.
A28: Green text | B28: Link to another sheet.
A29: Yellow fill | B29: Key assumption you should review before publishing anything off this.
A31: IMPORTANT DATA CAVEATS
A32: The SIAM deck's data tables start at July 2025 (through the latest edition). April-June 2025 appear only as plotted points on
A33: the FY26 chart lines and are not published as numbers, so they are NOT in this database. The series therefore begins Jul-25,
A34: which conveniently equals the start of Q2FY26. Q1FY26 comparisons are not possible from this source alone.
A35: The Baltic Dry Index was not published in the Aug-26 edition (marked '*' by SIAM); it is carried flat from Jul-26 and flagged
A36: in the Raw Data notes column. This affects only the Energy & Freight sub-complex monitor, not any segment BOM basket.
A38: Source: Society of Indian Automobile Manufacturers (SIAM), Commodity Price Monthly Monitor, August 2026 edition. Framework and weights are proprietary.

Sheet Assumptions
A1: ASSUMPTIONS & LEVERS
A2: Every blue cell is an input. Nothing else on this sheet should be overwritten.
A4: INDEX CONSTRUCTION
A5: Currency basis for indices | C5: INR | D5: INR basis captures rupee depreciation on dollar-priced inputs — that is what OEMs actually pay.
A6: Base month (= 100) | C6: Jul-25 | D6: Must exactly match a column header on Raw Data row 5.
A7: Base column position (calculated) | C7: =MATCH($C$6,'Raw Data'!$F$5:$S$5,0) -> 1 | D7: Do not edit.
A9: CURRENT-QUARTER FORECAST
A10: Latest actual month | C10: Aug-26
A11: Months of actual data in current quarter | C11: 2 | D11: Q2FY27 = Jul-Sep 26. Two months of actuals as at the Aug-26 SIAM deck.
A12: Assumed avg MoM drift for un-reported months (base) | C12: 0 | D12: 0.0% = spot-flat carry. This is the single most important forecast lever.
A13: Bear case MoM drift (cost inflation) | C13: 0.02
A14: Bull case MoM drift (cost deflation) | C14: -0.02
A16: BLENDED COMPOSITE — SEGMENT WEIGHTS | D16: Share of industry raw-material spend, not units. Set to sum to 100%.
A17: PV (ICE) | C17: 0.38
A18: 2W (ICE) | C18: 0.2
A19: CV | C19: 0.2
A20: Tractor | C20: 0.07
A21: BEV - PV | C21: 0.07
A22: E-2W | C22: 0.08
A23: Total | C23: =SUM(C17:C22) -> 1 | D23: Must equal 100.0%
A25: MARGIN TRANSLATION
A26: Raw material basket as % of ASP | D26: BofA works with metals at 20-25% of ASP for 4W and 2W; these are total-RM baskets so sit at the upper end.
A27: PV (ICE) | C27: 0.22
A28: 2W (ICE) | C28: 0.23
A29: CV | C29: 0.25
A30: Tractor | C30: 0.22
A31: BEV - PV | C31: 0.3
A32: E-2W | C32: 0.32
A34: Inventory / contract lag — weight on current quarter | C34: 0.35 | D34: Steel and aluminium contracts reprice with a lag; most of a quarter's spot move lands next quarter.
A35: Inventory / contract lag — weight on prior quarter | C35: 0.65 | D35: Two lag weights should sum to 100%.
A36: Lag weights total | C36: =C34+C35 -> 1
A37: Assumed pass-through to customer (price hikes) | C37: 0.5 | D37: 0% = OEM eats the entire move. 100% = fully recovered in the same quarter.
A40: Sources: SIAM Commodity Price Monthly Monitor (August 2026). BOM weights, segment weights, RM/ASP ratios, lag and pass-through are analyst estimates.

Sheet Raw Data
A1: RAW DATABASE — SIAM MONTHLY COMMODITY PRICES
A2: As published by SIAM, in native units. This is the only sheet to type into when the next monthly deck arrives.
A5: Commodity | B5: Category | C5: Unit | D5: Ccy | E5: SIAM pg | F5: Jul-25 | G5: Aug-25 | H5: Sept-25 | I5: Oct-25 | J5: Nov-25 | K5: Dec-25 | L5: Jan-26 | M5: Feb-26 | N5: Mar-26 | O5: Apr-26 | P5: May-26 | Q5: June-26 | R5: July-26 | S5: Aug-26 | T5: MoM % | U5: YoY % | V5: Notes
A6: FERROUS - FLAT, LONG & SPECIAL STEEL
A7: HR Steel (HRC 1.8mm, IS2062) | B7: Ferrous - Flat, Long & Special Steel | C7: INR/Tonne | D7: INR | E7: 5 | F7: 50950 | G7: 51437.5 | H7: 50812.5 | I7: 49812.5 | J7: 48187.5 | K7: 49080 | L7: 53612.5 | M7: 55212.5 | N7: 57625 | O7: 60550 | P7: 59750 | Q7: 61375 | R7: 60890 | S7: 61544 | T7: =IFERROR(S7/R7-1,"") -> 0.01074068 | U7: =IFERROR(S7/F7-1,"") -> 0.20792934 | V7: Mid-point of SIAM published low-high band
A8: CR Steel (CRC 0.90mm, IS513 GrO) | B8: Ferrous - Flat, Long & Special Steel | C8: INR/Tonne | D8: INR | E8: 6 | F8: 56450 | G8: 57000 | H8: 56500 | I8: 55500 | J8: 54937.5 | K8: 54870 | L8: 57850 | M8: 59637.5 | N8: 62625 | O8: 66450 | P8: 65750 | Q8: 65750 | R8: 65150 | S8: 65625 | T8: =IFERROR(S8/R8-1,"") -> 0.0072908672 | U8: =IFERROR(S8/F8-1,"") -> 0.16253322 | V8: Mid-point of SIAM published low-high band
A9: Alloy Steel - Forging (20MnCr5) | B9: Ferrous - Flat, Long & Special Steel | C9: INR/Tonne | D9: INR | E9: 7 | F9: 62000 | G9: 62000 | H9: 61250 | I9: 61000 | J9: 60250 | K9: 60000 | L9: 60800 | M9: 62000 | N9: 62000 | O9: 67380 | P9: 67330 | Q9: 65630 | R9: 62330 | S9: 62130 | T9: =IFERROR(S9/R9-1,"") -> -0.0032087277 | U9: =IFERROR(S9/F9-1,"") -> 0.0020967742
A10: Alloy Steel - Forging (EN-8) | B10: Ferrous - Flat, Long & Special Steel | C10: INR/Tonne | D10: INR | E10: 8 | F10: 61000 | G10: 61000 | H10: 60250 | I10: 60000 | J10: 59250 | K10: 59000 | L10: 59800 | M10: 61000 | N10: 61000 | O10: 64250 | P10: 64200 | Q10: 62500 | R10: 59200 | S10: 59000 | T10: =IFERROR(S10/R10-1,"") -> -0.0033783784 | U10: =IFERROR(S10/F10-1,"") -> -0.032786885
A11: Pig Iron (Foundry Grade B) | B11: Ferrous - Flat, Long & Special Steel | C11: INR/Tonne | D11: INR | E11: 9 | F11: 37625 | G11: 37600 | H11: 39250 | I11: 39200 | J11: 39000 | K11: 38250 | L11: 41600 | M11: 42667 | N11: 43500 | O11: 45250 | P11: 45500 | Q11: 44250 | R11: 46300 | S11: 48750 | T11: =IFERROR(S11/R11-1,"") -> 0.052915767 | U11: =IFERROR(S11/F11-1,"") -> 0.29568106
A12: Stainless Steel (G304 CR Coil) | B12: Ferrous - Flat, Long & Special Steel | C12: INR/Tonne | D12: INR | E12: 10 | F12: 193800 | G12: 197500 | H12: 200500 | I12: 200000 | J12: 192500 | K12: 190000 | L12: 198750 | M12: 203500 | N12: 215000 | O12: 226000 | P12: 231375 | Q12: 224500 | R12: 221000 | S12: 225000 | T12: =IFERROR(S12/R12-1,"") -> 0.018099548 | U12: =IFERROR(S12/F12-1,"") -> 0.16099071 | V12: Mid-point of SIAM published low-high band
A13: Stainless Steel (G304 HR Coil) | B13: Ferrous - Flat, Long & Special Steel | C13: INR/Tonne | D13: INR | E13: 11 | F13: 184000 | G13: 187125 | H13: 190500 | I13: 190000 | J13: 182500 | K13: 181600 | L13: 190500 | M13: 194250 | N13: 208000 | O13: 216400 | P13: 224250 | Q13: 218250 | R13: 214000 | S13: 218750 | T13: =IFERROR(S13/R13-1,"") -> 0.022196262 | U13: =IFERROR(S13/F13-1,"") -> 0.1888587 | V13: Mid-point of SIAM published low-high band
A14: Steel Scrap (RM end scrap) | B14: Ferrous - Flat, Long & Special Steel | C14: INR/Tonne | D14: INR | E14: 12 | F14: 36325 | G14: 36520 | H14: 35425 | I14: 34720 | J14: 33550 | K14: 33575 | L14: 35300 | M14: 37167 | N14: 38900 | O14: 40950 | P14: 40060 | Q14: 38700 | R14: 36780 | S14: 37275 | T14: =IFERROR(S14/R14-1,"") -> 0.013458401 | U14: =IFERROR(S14/F14-1,"") -> 0.026152787
A15: UPSTREAM STEEL INPUTS
A16: Coking Coal (Premium HCC, Australia) | B16: Upstream Steel Inputs | C16: USD/Tonne | D16: USD | E16: 13 | F16: 193 | G16: 203 | H16: 203 | I16: 208 | J16: 214 | K16: 227 | L16: 248 | M16: 263 | N16: 249 | O16: 255 | P16: 264 | Q16: 266 | R16: 252 | S16: 253 | T16: =IFERROR(S16/R16-1,"") -> 0.003968254 | U16: =IFERROR(S16/F16-1,"") -> 0.31088083
A17: Iron Ore (Fe 62%, Australia) | B17: Upstream Steel Inputs | C17: USD/Tonne | D17: USD | E17: 14 | F17: 99 | G17: 102 | H17: 105 | I17: 106 | J17: 104 | K17: 107 | L17: 106 | M17: 99 | N17: 106 | O17: 107 | P17: 109 | Q17: 101 | R17: 98 | S17: 96 | T17: =IFERROR(S17/R17-1,"") -> -0.020408163 | U17: =IFERROR(S17/F17-1,"") -> -0.03030303
A18: NON-FERROUS METALS
A19: Virgin Aluminium | B19: Non-Ferrous Metals | C19: USD/Tonne | D19: USD | E19: 16 | F19: 2604.2 | G19: 2594 | H19: 2653.3 | I19: 2786.3 | J19: 2822.9 | K19: 2875.5 | L19: 3148.4 | M19: 3065.4 | N19: 3370.2 | O19: 3600.6 | P19: 3670.2 | Q19: 3458.6 | R19: 3156 | S19: 3252 | T19: =IFERROR(S19/R19-1,"") -> 0.030418251 | U19: =IFERROR(S19/F19-1,"") -> 0.24875202
A20: Copper | B20: Non-Ferrous Metals | C20: USD/Tonne | D20: USD | E20: 17 | F20: 9778.2 | G20: 9645.9 | H20: 9952.7 | I20: 10696 | J20: 10800.8 | K20: 11803.8 | L20: 13088.9 | M20: 12967.8 | N20: 12499 | O20: 12891.4 | P20: 13507.1 | Q20: 13574.3 | R20: 13525.2 | S20: 14353.4 | T20: =IFERROR(S20/R20-1,"") -> 0.061233845 | U20: =IFERROR(S20/F20-1,"") -> 0.46789798
A21: Lead | B21: Non-Ferrous Metals | C21: USD/Tonne | D21: USD | E21: 18 | F21: 1994.9 | G21: 1945.2 | H21: 1954.5 | I21: 1968.2 | J21: 2001.8 | K21: 1942.3 | L21: 1998.3 | M21: 1916.1 | N21: 1879.8 | O21: 1922.7 | P21: 1991 | Q21: 1951.3 | R21: 1844.1 | S21: 1855.1 | T21: =IFERROR(S21/R21-1,"") -> 0.0059649694 | U21: =IFERROR(S21/F21-1,"") -> -0.070078701
A22: Nickel | B22: Non-Ferrous Metals | C22: USD/Tonne | D22: USD | E22: 19 | F22: 15023.3 | G22: 14909 | H22: 15102 | I22: 15079.8 | J22: 14689.3 | K22: 14878.8 | L22: 17844 | M22: 17132.8 | N22: 17093.2 | O22: 18005.8 | P22: 18805 | Q22: 17663.9 | R22: 16657.4 | S22: 16765.8 | T22: =IFERROR(S22/R22-1,"") -> 0.0065076182 | U22: =IFERROR(S22/F22-1,"") -> 0.1159865
A23: Zinc | B23: Non-Ferrous Metals | C23: USD/Tonne | D23: USD | E23: 20 | F23: 2758.8 | G23: 2784.4 | H23: 2930 | I23: 3149.1 | J23: 3187.4 | K23: 3159.7 | L23: 3220.2 | M23: 3320.8 | N23: 3187.9 | O23: 3361.6 | P23: 3488.2 | Q23: 3540.5 | R23: 3596.1 | S23: 3875.1 | T23: =IFERROR(S23/R23-1,"") -> 0.077584049 | U23: =IFERROR(S23/F23-1,"") -> 0.40463245
A24: PRECIOUS / PGM
A25: Platinum | B25: Precious / Pgm | C25: INR/gm | D25: INR | E25: 21 | F25: 3884.42 | G25: 3785.29 | H25: 4099.4 | I25: 4629.46 | J25: 4526.03 | K25: 5419.39 | L25: 7140.6 | M25: 6300.94 | N25: 6196 | O25: 6149.69 | P25: 6188.93 | Q25: 5372.09 | R25: 5041.2 | S25: 5502.57 | T25: =IFERROR(S25/R25-1,"") -> 0.091519876 | U25: =IFERROR(S25/F25-1,"") -> 0.41657442
A26: Palladium | B26: Precious / Pgm | C26: INR/gm | D26: INR | E26: 22 | F26: 3351.79 | G26: 3234.55 | H26: 3383.84 | I26: 4056.91 | J26: 4088.69 | K26: 4613.22 | L26: 5439.55 | M26: 5114.88 | N26: 4712.15 | O26: 4632.31 | P26: 4479.22 | Q26: 3961.58 | R26: 3956.24 | S26: 4168.59 | T26: =IFERROR(S26/R26-1,"") -> 0.053674701 | U26: =IFERROR(S26/F26-1,"") -> 0.24369068
A27: Rhodium | B27: Precious / Pgm | C27: INR/gm | D27: INR | E27: 23 | F27: 16427.41 | G27: 20359.26 | H27: 20273.75 | I27: 21590.22 | J27: 22894.99 | K27: 23523.36 | L27: 29578.83 | M27: 31919.66 | N27: 33686.43 | O27: 30287.54 | P27: 29887.72 | Q27: 24583.84 | R27: 25151.09 | S27: 26661.83 | T27: =IFERROR(S27/R27-1,"") -> 0.060066582 | U27: =IFERROR(S27/F27-1,"") -> 0.62300874
A28: POLYMERS
A29: Polypropylene (PP) | B29: Polymers | C29: INR/kg | D29: INR | E29: 25 | F29: 100 | G29: 100.5 | H29: 99.3 | I29: 99.4 | J29: 95.2 | K29: 94.3 | L29: 96.5 | M29: 98.2 | N29: 136.2 | O29: 137.5 | P29: 129.9 | Q29: 133 | R29: 131.5 | S29: 134.4 | T29: =IFERROR(S29/R29-1,"") -> 0.022053232 | U29: =IFERROR(S29/F29-1,"") -> 0.344
A30: ABS | B30: Polymers | C30: INR/kg | D30: INR | E30: 26 | F30: 147.3 | G30: 146.8 | H30: 143.1 | I30: 137.6 | J30: 130.7 | K30: 124.1 | L30: 126.4 | M30: 130.6 | N30: 170.4 | O30: 197 | P30: 188.6 | Q30: 190.2 | R30: 185.8 | S30: 171.8 | T30: =IFERROR(S30/R30-1,"") -> -0.075349839 | U30: =IFERROR(S30/F30-1,"") -> 0.16632722
A31: Polycarbonate (PC) | B31: Polymers | C31: INR/kg | D31: INR | E31: 27 | F31: 214.6 | G31: 218.3 | H31: 222.7 | I31: 221.6 | J31: 221.5 | K31: 209.6 | L31: 208.9 | M31: 194.4 | N31: 227.5 | O31: 264 | P31: 265.2 | Q31: 261.9 | R31: 255.5 | S31: 253 | T31: =IFERROR(S31/R31-1,"") -> -0.0097847358 | U31: =IFERROR(S31/F31-1,"") -> 0.17893756
A32: CHEMICALS
A33: Urea (Prilled), CFR | B33: Chemicals | C33: USD/Ton | D33: USD | E33: 29 | F33: 475.4 | G33: 531 | H33: 463.5 | I33: 445.44 | J33: 403.42 | K33: 419 | L33: 423.53 | M33: 425.8 | N33: 510 | O33: 678.07 | P33: 947 | Q33: 677.82 | R33: 447.1 | S33: 419.55 | T33: =IFERROR(S33/R33-1,"") -> -0.061619325 | U33: =IFERROR(S33/F33-1,"") -> -0.11748002 | V33: Not in auto BOM baskets; tracked for agri / tractor demand read-across
A34: RUBBER & CARBON BLACK
A35: Natural Rubber (RSS 4) | B35: Rubber & Carbon Black | C35: INR/kg | D35: INR | E35: 31 | F35: 207.26 | G35: 196.34 | H35: 188.41 | I35: 187.33 | J35: 186.05 | K35: 183.74 | L35: 191.68 | M35: 212.48 | N35: 217.35 | O35: 234.54 | P35: 255.96 | Q35: 268.98 | R35: 276.14 | S35: 278.76 | T35: =IFERROR(S35/R35-1,"") -> 0.0094879409 | U35: =IFERROR(S35/F35-1,"") -> 0.34497732
A36: Synthetic Rubber - SBR 1502 | B36: Rubber & Carbon Black | C36: INR/kg | D36: INR | E36: 32 | F36: 184.18 | G36: 174.33 | H36: 177.57 | I36: 177.44 | J36: 176.52 | K36: 161.7 | L36: 155.59 | M36: 150.2 | N36: 164.88 | O36: 264.11 | P36: 281.34 | Q36: 235.88 | R36: 246.62 | S36: 251.5 | T36: =IFERROR(S36/R36-1,"") -> 0.019787527 | U36: =IFERROR(S36/F36-1,"") -> 0.365512
A37: EPDM | B37: Rubber & Carbon Black | C37: INR/kg | D37: INR | E37: 33 | F37: 220.45 | G37: 219.12 | H37: 216.76 | I37: 215.11 | J37: 212.16 | K37: 211.48 | L37: 207.7 | M37: 205.19 | N37: 248.35 | O37: 276.67 | P37: 299.11 | Q37: 299.55 | R37: 288.02 | S37: 292.85 | T37: =IFERROR(S37/R37-1,"") -> 0.016769669 | U37: =IFERROR(S37/F37-1,"") -> 0.32841914
A38: Carbon Black (N330) | B38: Rubber & Carbon Black | C38: INR/kg | D38: INR | E38: 34 | F38: 113.05 | G38: 105.68 | H38: 102.9 | I38: 99.55 | J38: 96.16 | K38: 96.3 | L38: 93.5 | M38: 92.64 | N38: 92.64 | O38: 124.92 | P38: 134.57 | Q38: 150.77 | R38: 156.79 | S38: 155.42 | T38: =IFERROR(S38/R38-1,"") -> -0.0087378022 | U38: =IFERROR(S38/F38-1,"") -> 0.37478992
A39: Polybutadiene Rubber (1220) | B39: Rubber & Carbon Black | C39: INR/kg | D39: INR | E39: 35 | F39: 172.29 | G39: 169.86 | H39: 175.69 | I39: 171.66 | J39: 169.56 | K39: 168.85 | L39: 153.55 | M39: 150.95 | N39: 163.92 | O39: 272.11 | P39: 304.5 | Q39: 282.07 | R39: 272.59 | S39: 270.61 | T39: =IFERROR(S39/R39-1,"") -> -0.007263656 | U39: =IFERROR(S39/F39-1,"") -> 0.57066574
A40: ADVANCED CHEMISTRIES (BATTERY)
A41: Lithium Carbonate (99.5% batt grade) | B41: Advanced Chemistries (Battery) | C41: USD/kg | D41: USD | E41: 37 | F41: 8.41 | G41: 9.38 | H41: 9.38 | I41: 9.45 | J41: 10.27 | K41: 11.51 | L41: 17.52 | M41: 18.41 | N41: 19.89 | O41: 20.21 | P41: 21.91 | Q41: 20.81 | R41: 19.54 | S41: 19.3 | T41: =IFERROR(S41/R41-1,"") -> -0.012282497 | U41: =IFERROR(S41/F41-1,"") -> 1.294887
A42: Lithium Hydroxide (56.5% batt grade) | B42: Advanced Chemistries (Battery) | C42: USD/kg | D42: USD | E42: 38 | F42: 8.11 | G42: 8.57 | H42: 9.3 | I42: 9.53 | J42: 10.22 | K42: 10.79 | L42: 16.74 | M42: 17.61 | N42: 18.37 | O42: 18.6 | P42: 20.41 | Q42: 19.26 | R42: 18 | S42: 17.88 | T42: =IFERROR(S42/R42-1,"") -> -0.0066666667 | U42: =IFERROR(S42/F42-1,"") -> 1.2046856
...

Sheet INR Normalised
A1: INR-NORMALISED PRICES
A2: All material inputs restated in INR per kg at that month's USD-INR selling rate. Isolates the currency drag on dollar-priced commodities.
A5: Commodity | B5: Category | C5: Normalised unit | D5: Conversion | E5: SIAM pg | F5: Jul-25 | G5: Aug-25 | H5: Sept-25 | I5: Oct-25 | J5: Nov-25 | K5: Dec-25 | L5: Jan-26 | M5: Feb-26 | N5: Mar-26 | O5: Apr-26 | P5: May-26 | Q5: June-26 | R5: July-26 | S5: Aug-26 | T5: MoM % | U5: YoY % | V5: Notes
A6: FERROUS - FLAT, LONG & SPECIAL STEEL
A7: ='Raw Data'!A7 -> HR Steel (HRC 1.8mm, IS2062) | B7: Ferrous - Flat, Long & Special Steel | C7: INR/kg | D7: / 1,000 | E7: 5 | F7: ='Raw Data'!F7/1000 -> 50.95 | G7: ='Raw Data'!G7/1000 -> 51.4375 | H7: ='Raw Data'!H7/1000 -> 50.8125 | I7: ='Raw Data'!I7/1000 -> 49.8125 | J7: ='Raw Data'!J7/1000 -> 48.1875 | K7: ='Raw Data'!K7/1000 -> 49.08 | L7: ='Raw Data'!L7/1000 -> 53.6125 | M7: ='Raw Data'!M7/1000 -> 55.2125 | ... S7: ='Raw Data'!S7/1000 -> 61.544 | T7: =IFERROR(S7/R7-1,"") -> 0.01074068 | U7: =IFERROR(S7/F7-1,"") -> 0.20792934
A8: ='Raw Data'!A8 -> CR Steel (CRC 0.90mm, IS513 GrO) | B8: Ferrous - Flat, Long & Special Steel | C8: INR/kg | D8: / 1,000 | E8: 6 | F8: ='Raw Data'!F8/1000 -> 56.45 | G8: ='Raw Data'!G8/1000 -> 57 | H8: ='Raw Data'!H8/1000 -> 56.5 | I8: ='Raw Data'!I8/1000 -> 55.5 | J8: ='Raw Data'!J8/1000 -> 54.9375 | K8: ='Raw Data'!K8/1000 -> 54.87 | L8: ='Raw Data'!L8/1000 -> 57.85 | M8: ='Raw Data'!M8/1000 -> 59.6375 | ... S8: ='Raw Data'!S8/1000 -> 65.625 | T8: =IFERROR(S8/R8-1,"") -> 0.0072908672 | U8: =IFERROR(S8/F8-1,"") -> 0.16253322
A9: ='Raw Data'!A9 -> Alloy Steel - Forging (20MnCr5) | B9: Ferrous - Flat, Long & Special Steel | C9: INR/kg | D9: / 1,000 | E9: 7 | F9: ='Raw Data'!F9/1000 -> 62 | G9: ='Raw Data'!G9/1000 -> 62 | H9: ='Raw Data'!H9/1000 -> 61.25 | I9: ='Raw Data'!I9/1000 -> 61 | J9: ='Raw Data'!J9/1000 -> 60.25 | K9: ='Raw Data'!K9/1000 -> 60 | L9: ='Raw Data'!L9/1000 -> 60.8 | M9: ='Raw Data'!M9/1000 -> 62 | ... S9: ='Raw Data'!S9/1000 -> 62.13 | T9: =IFERROR(S9/R9-1,"") -> -0.0032087277 | U9: =IFERROR(S9/F9-1,"") -> 0.0020967742
A10: ='Raw Data'!A10 -> Alloy Steel - Forging (EN-8) | B10: Ferrous - Flat, Long & Special Steel | C10: INR/kg | D10: / 1,000 | E10: 8 | F10: ='Raw Data'!F10/1000 -> 61 | G10: ='Raw Data'!G10/1000 -> 61 | H10: ='Raw Data'!H10/1000 -> 60.25 | I10: ='Raw Data'!I10/1000 -> 60 | J10: ='Raw Data'!J10/1000 -> 59.25 | K10: ='Raw Data'!K10/1000 -> 59 | L10: ='Raw Data'!L10/1000 -> 59.8 | M10: ='Raw Data'!M10/1000 -> 61 | ... S10: ='Raw Data'!S10/1000 -> 59 | T10: =IFERROR(S10/R10-1,"") -> -0.0033783784 | U10: =IFERROR(S10/F10-1,"") -> -0.032786885
A11: ='Raw Data'!A11 -> Pig Iron (Foundry Grade B) | B11: Ferrous - Flat, Long & Special Steel | C11: INR/kg | D11: / 1,000 | E11: 9 | F11: ='Raw Data'!F11/1000 -> 37.625 | G11: ='Raw Data'!G11/1000 -> 37.6 | H11: ='Raw Data'!H11/1000 -> 39.25 | I11: ='Raw Data'!I11/1000 -> 39.2 | J11: ='Raw Data'!J11/1000 -> 39 | K11: ='Raw Data'!K11/1000 -> 38.25 | L11: ='Raw Data'!L11/1000 -> 41.6 | M11: ='Raw Data'!M11/1000 -> 42.667 | ... S11: ='Raw Data'!S11/1000 -> 48.75 | T11: =IFERROR(S11/R11-1,"") -> 0.052915767 | U11: =IFERROR(S11/F11-1,"") -> 0.29568106
A12: ='Raw Data'!A12 -> Stainless Steel (G304 CR Coil) | B12: Ferrous - Flat, Long & Special Steel | C12: INR/kg | D12: / 1,000 | E12: 10 | F12: ='Raw Data'!F12/1000 -> 193.8 | G12: ='Raw Data'!G12/1000 -> 197.5 | H12: ='Raw Data'!H12/1000 -> 200.5 | I12: ='Raw Data'!I12/1000 -> 200 | J12: ='Raw Data'!J12/1000 -> 192.5 | K12: ='Raw Data'!K12/1000 -> 190 | L12: ='Raw Data'!L12/1000 -> 198.75 | M12: ='Raw Data'!M12/1000 -> 203.5 | ... S12: ='Raw Data'!S12/1000 -> 225 | T12: =IFERROR(S12/R12-1,"") -> 0.018099548 | U12: =IFERROR(S12/F12-1,"") -> 0.16099071
A13: ='Raw Data'!A13 -> Stainless Steel (G304 HR Coil) | B13: Ferrous - Flat, Long & Special Steel | C13: INR/kg | D13: / 1,000 | E13: 11 | F13: ='Raw Data'!F13/1000 -> 184 | G13: ='Raw Data'!G13/1000 -> 187.125 | H13: ='Raw Data'!H13/1000 -> 190.5 | I13: ='Raw Data'!I13/1000 -> 190 | J13: ='Raw Data'!J13/1000 -> 182.5 | K13: ='Raw Data'!K13/1000 -> 181.6 | L13: ='Raw Data'!L13/1000 -> 190.5 | M13: ='Raw Data'!M13/1000 -> 194.25 | ... S13: ='Raw Data'!S13/1000 -> 218.75 | T13: =IFERROR(S13/R13-1,"") -> 0.022196262 | U13: =IFERROR(S13/F13-1,"") -> 0.1888587
A14: ='Raw Data'!A14 -> Steel Scrap (RM end scrap) | B14: Ferrous - Flat, Long & Special Steel | C14: INR/kg | D14: / 1,000 | E14: 12 | F14: ='Raw Data'!F14/1000 -> 36.325 | G14: ='Raw Data'!G14/1000 -> 36.52 | H14: ='Raw Data'!H14/1000 -> 35.425 | I14: ='Raw Data'!I14/1000 -> 34.72 | J14: ='Raw Data'!J14/1000 -> 33.55 | K14: ='Raw Data'!K14/1000 -> 33.575 | L14: ='Raw Data'!L14/1000 -> 35.3 | M14: ='Raw Data'!M14/1000 -> 37.167 | ... S14: ='Raw Data'!S14/1000 -> 37.275 | T14: =IFERROR(S14/R14-1,"") -> 0.013458401 | U14: =IFERROR(S14/F14-1,"") -> 0.026152787
A15: UPSTREAM STEEL INPUTS
A16: ='Raw Data'!A16 -> Coking Coal (Premium HCC, Australia) | B16: Upstream Steel Inputs | C16: INR/kg | D16: x USD-INR / 1,000 | E16: 13 | F16: ='Raw Data'!F16*'Raw Data'!F$61/1000 -> 16.73503 | G16: ='Raw Data'!G16*'Raw Data'!G$61/1000 -> 17.89242 | H16: ='Raw Data'!H16*'Raw Data'!H$61/1000 -> 18.04467 | I16: ='Raw Data'!I16*'Raw Data'!I$61/1000 -> 18.50992 | J16: ='Raw Data'!J16*'Raw Data'!J$61/1000 -> 19.13588 | K16: ='Raw Data'!K16*'Raw Data'!K$61/1000 -> 20.57074 | L16: ='Raw Data'!L16*'Raw Data'!L$61/1000 -> 22.65232 | M16: ='Raw Data'!M16*'Raw Data'!M$61/1000 -> 24.01716 | ... S16: ='Raw Data'!S16*'Raw Data'!S$61/1000 -> 24.30065 | T16: =IFERROR(S16/R16-1,"") -> 0.00073838516 | U16: =IFERROR(S16/F16-1,"") -> 0.45208285 | V16: Dollar-priced: INR move = commodity move + rupee move
A17: ='Raw Data'!A17 -> Iron Ore (Fe 62%, Australia) | B17: Upstream Steel Inputs | C17: INR/kg | D17: x USD-INR / 1,000 | E17: 14 | F17: ='Raw Data'!F17*'Raw Data'!F$61/1000 -> 8.58429 | G17: ='Raw Data'!G17*'Raw Data'!G$61/1000 -> 8.99028 | H17: ='Raw Data'!H17*'Raw Data'!H$61/1000 -> 9.33345 | I17: ='Raw Data'!I17*'Raw Data'!I$61/1000 -> 9.43294 | J17: ='Raw Data'!J17*'Raw Data'!J$61/1000 -> 9.29968 | K17: ='Raw Data'!K17*'Raw Data'!K$61/1000 -> 9.69634 | L17: ='Raw Data'!L17*'Raw Data'!L$61/1000 -> 9.68204 | M17: ='Raw Data'!M17*'Raw Data'!M$61/1000 -> 9.04068 | ... S17: ='Raw Data'!S17*'Raw Data'!S$61/1000 -> 9.2208 | T17: =IFERROR(S17/R17-1,"") -> -0.023559611 | U17: =IFERROR(S17/F17-1,"") -> 0.074148241 | V17: Dollar-priced: INR move = commodity move + rupee move
A18: NON-FERROUS METALS
A19: ='Raw Data'!A19 -> Virgin Aluminium | B19: Non-Ferrous Metals | C19: INR/kg | D19: x USD-INR / 1,000 | E19: 16 | F19: ='Raw Data'!F19*'Raw Data'!F$61/1000 -> 225.81018 | G19: ='Raw Data'!G19*'Raw Data'!G$61/1000 -> 228.63516 | H19: ='Raw Data'!H19*'Raw Data'!H$61/1000 -> 235.85184 | I19: ='Raw Data'!I19*'Raw Data'!I$61/1000 -> 247.95284 | J19: ='Raw Data'!J19*'Raw Data'!J$61/1000 -> 252.42372 | K19: ='Raw Data'!K19*'Raw Data'!K$61/1000 -> 260.57781 | L19: ='Raw Data'!L19*'Raw Data'!L$61/1000 -> 287.57486 | M19: ='Raw Data'!M19*'Raw Data'!M$61/1000 -> 279.93233 | ... S19: ='Raw Data'!S19*'Raw Data'!S$61/1000 -> 312.3546 | T19: =IFERROR(S19/R19-1,"") -> 0.02710329 | U19: =IFERROR(S19/F19-1,"") -> 0.38326181 | V19: Dollar-priced: INR move = commodity move + rupee move
A20: ='Raw Data'!A20 -> Copper | B20: Non-Ferrous Metals | C20: INR/kg | D20: x USD-INR / 1,000 | E20: 17 | F20: ='Raw Data'!F20*'Raw Data'!F$61/1000 -> 847.86772 | G20: ='Raw Data'!G20*'Raw Data'!G$61/1000 -> 850.18963 | H20: ='Raw Data'!H20*'Raw Data'!H$61/1000 -> 884.6955 | I20: ='Raw Data'!I20*'Raw Data'!I$61/1000 -> 951.83704 | J20: ='Raw Data'!J20*'Raw Data'!J$61/1000 -> 965.80754 | K20: ='Raw Data'!K20*'Raw Data'!K$61/1000 -> 1069.6604 | L20: ='Raw Data'!L20*'Raw Data'!L$61/1000 -> 1195.5401 | M20: ='Raw Data'!M20*'Raw Data'!M$61/1000 -> 1184.2195 | ... S20: ='Raw Data'!S20*'Raw Data'!S$61/1000 -> 1378.6441 | T20: =IFERROR(S20/R20-1,"") -> 0.057819747 | U20: =IFERROR(S20/F20-1,"") -> 0.62601316 | V20: Dollar-priced: INR move = commodity move + rupee move
A21: ='Raw Data'!A21 -> Lead | B21: Non-Ferrous Metals | C21: INR/kg | D21: x USD-INR / 1,000 | E21: 18 | F21: ='Raw Data'!F21*'Raw Data'!F$61/1000 -> 172.97778 | G21: ='Raw Data'!G21*'Raw Data'!G$61/1000 -> 171.44993 | H21: ='Raw Data'!H21*'Raw Data'!H$61/1000 -> 173.7355 | I21: ='Raw Data'!I21*'Raw Data'!I$61/1000 -> 175.15012 | J21: ='Raw Data'!J21*'Raw Data'!J$61/1000 -> 179.00096 | K21: ='Raw Data'!K21*'Raw Data'!K$61/1000 -> 176.01123 | L21: ='Raw Data'!L21*'Raw Data'!L$61/1000 -> 182.52472 | M21: ='Raw Data'!M21*'Raw Data'!M$61/1000 -> 174.97825 | ... S21: ='Raw Data'!S21*'Raw Data'!S$61/1000 -> 178.18236 | T21: =IFERROR(S21/R21-1,"") -> 0.0027286769 | U21: =IFERROR(S21/F21-1,"") -> 0.030088119 | V21: Dollar-priced: INR move = commodity move + rupee move
A22: ='Raw Data'!A22 -> Nickel | B22: Non-Ferrous Metals | C22: INR/kg | D22: x USD-INR / 1,000 | E22: 19 | F22: ='Raw Data'!F22*'Raw Data'!F$61/1000 -> 1302.6703 | G22: ='Raw Data'!G22*'Raw Data'!G$61/1000 -> 1314.0793 | H22: ='Raw Data'!H22*'Raw Data'!H$61/1000 -> 1342.4168 | I22: ='Raw Data'!I22*'Raw Data'!I$61/1000 -> 1341.9514 | J22: ='Raw Data'!J22*'Raw Data'!J$61/1000 -> 1313.5172 | K22: ='Raw Data'!K22*'Raw Data'!K$61/1000 -> 1348.3169 | L22: ='Raw Data'!L22*'Raw Data'!L$61/1000 -> 1629.871 | M22: ='Raw Data'!M22*'Raw Data'!M$61/1000 -> 1564.5673 | ... S22: ='Raw Data'!S22*'Raw Data'!S$61/1000 -> 1610.3551 | T22: =IFERROR(S22/R22-1,"") -> 0.00326958 | U22: =IFERROR(S22/F22-1,"") -> 0.2361954 | V22: Dollar-priced: INR move = commodity move + rupee move
A23: ='Raw Data'!A23 -> Zinc | B23: Non-Ferrous Metals | C23: INR/kg | D23: x USD-INR / 1,000 | E23: 20 | F23: ='Raw Data'!F23*'Raw Data'!F$61/1000 -> 239.21555 | G23: ='Raw Data'!G23*'Raw Data'!G$61/1000 -> 245.41702 | H23: ='Raw Data'!H23*'Raw Data'!H$61/1000 -> 260.4477 | I23: ='Raw Data'!I23*'Raw Data'!I$61/1000 -> 280.23841 | J23: ='Raw Data'!J23*'Raw Data'!J$61/1000 -> 285.01731 | K23: ='Raw Data'!K23*'Raw Data'!K$61/1000 -> 286.33201 | L23: ='Raw Data'!L23*'Raw Data'!L$61/1000 -> 294.13307 | M23: ='Raw Data'!M23*'Raw Data'!M$61/1000 -> 303.25546 | ... S23: ='Raw Data'!S23*'Raw Data'!S$61/1000 -> 372.20335 | T23: =IFERROR(S23/R23-1,"") -> 0.074117351 | U23: =IFERROR(S23/F23-1,"") -> 0.55593296 | V23: Dollar-priced: INR move = commodity move + rupee move
A24: PRECIOUS / PGM
A25: ='Raw Data'!A25 -> Platinum | B25: Precious / Pgm | C25: INR/kg | D25: x 1,000 | E25: 21 | F25: ='Raw Data'!F25*1000 -> 3884420 | G25: ='Raw Data'!G25*1000 -> 3785290 | H25: ='Raw Data'!H25*1000 -> 4099400 | I25: ='Raw Data'!I25*1000 -> 4629460 | J25: ='Raw Data'!J25*1000 -> 4526030 | K25: ='Raw Data'!K25*1000 -> 5419390 | L25: ='Raw Data'!L25*1000 -> 7140600 | M25: ='Raw Data'!M25*1000 -> 6300940 | ... S25: ='Raw Data'!S25*1000 -> 5502570 | T25: =IFERROR(S25/R25-1,"") -> 0.091519876 | U25: =IFERROR(S25/F25-1,"") -> 0.41657442
A26: ='Raw Data'!A26 -> Palladium | B26: Precious / Pgm | C26: INR/kg | D26: x 1,000 | E26: 22 | F26: ='Raw Data'!F26*1000 -> 3351790 | G26: ='Raw Data'!G26*1000 -> 3234550 | H26: ='Raw Data'!H26*1000 -> 3383840 | I26: ='Raw Data'!I26*1000 -> 4056910 | J26: ='Raw Data'!J26*1000 -> 4088690 | K26: ='Raw Data'!K26*1000 -> 4613220 | L26: ='Raw Data'!L26*1000 -> 5439550 | M26: ='Raw Data'!M26*1000 -> 5114880 | ... S26: ='Raw Data'!S26*1000 -> 4168590 | T26: =IFERROR(S26/R26-1,"") -> 0.053674701 | U26: =IFERROR(S26/F26-1,"") -> 0.24369068
A27: ='Raw Data'!A27 -> Rhodium | B27: Precious / Pgm | C27: INR/kg | D27: x 1,000 | E27: 23 | F27: ='Raw Data'!F27*1000 -> 16427410 | G27: ='Raw Data'!G27*1000 -> 20359260 | H27: ='Raw Data'!H27*1000 -> 20273750 | I27: ='Raw Data'!I27*1000 -> 21590220 | J27: ='Raw Data'!J27*1000 -> 22894990 | K27: ='Raw Data'!K27*1000 -> 23523360 | L27: ='Raw Data'!L27*1000 -> 29578830 | M27: ='Raw Data'!M27*1000 -> 31919660 | ... S27: ='Raw Data'!S27*1000 -> 26661830 | T27: =IFERROR(S27/R27-1,"") -> 0.060066582 | U27: =IFERROR(S27/F27-1,"") -> 0.62300874
A28: POLYMERS
A29: ='Raw Data'!A29 -> Polypropylene (PP) | B29: Polymers | C29: INR/kg | D29: as reported | E29: 25 | F29: ='Raw Data'!F29 -> 100 | G29: ='Raw Data'!G29 -> 100.5 | H29: ='Raw Data'!H29 -> 99.3 | I29: ='Raw Data'!I29 -> 99.4 | J29: ='Raw Data'!J29 -> 95.2 | K29: ='Raw Data'!K29 -> 94.3 | L29: ='Raw Data'!L29 -> 96.5 | M29: ='Raw Data'!M29 -> 98.2 | ... S29: ='Raw Data'!S29 -> 134.4 | T29: =IFERROR(S29/R29-1,"") -> 0.022053232 | U29: =IFERROR(S29/F29-1,"") -> 0.344
A30: ='Raw Data'!A30 -> ABS | B30: Polymers | C30: INR/kg | D30: as reported | E30: 26 | F30: ='Raw Data'!F30 -> 147.3 | G30: ='Raw Data'!G30 -> 146.8 | H30: ='Raw Data'!H30 -> 143.1 | I30: ='Raw Data'!I30 -> 137.6 | J30: ='Raw Data'!J30 -> 130.7 | K30: ='Raw Data'!K30 -> 124.1 | L30: ='Raw Data'!L30 -> 126.4 | M30: ='Raw Data'!M30 -> 130.6 | ... S30: ='Raw Data'!S30 -> 171.8 | T30: =IFERROR(S30/R30-1,"") -> -0.075349839 | U30: =IFERROR(S30/F30-1,"") -> 0.16632722
A31: ='Raw Data'!A31 -> Polycarbonate (PC) | B31: Polymers | C31: INR/kg | D31: as reported | E31: 27 | F31: ='Raw Data'!F31 -> 214.6 | G31: ='Raw Data'!G31 -> 218.3 | H31: ='Raw Data'!H31 -> 222.7 | I31: ='Raw Data'!I31 -> 221.6 | J31: ='Raw Data'!J31 -> 221.5 | K31: ='Raw Data'!K31 -> 209.6 | L31: ='Raw Data'!L31 -> 208.9 | M31: ='Raw Data'!M31 -> 194.4 | ... S31: ='Raw Data'!S31 -> 253 | T31: =IFERROR(S31/R31-1,"") -> -0.0097847358 | U31: =IFERROR(S31/F31-1,"") -> 0.17893756
A32: CHEMICALS
A33: ='Raw Data'!A33 -> Urea (Prilled), CFR | B33: Chemicals | C33: INR/kg | D33: x USD-INR / 1,000 | E33: 29 | F33: ='Raw Data'!F33*'Raw Data'!F$61/1000 -> 41.221934 | G33: ='Raw Data'!G33*'Raw Data'!G$61/1000 -> 46.80234 | H33: ='Raw Data'!H33*'Raw Data'!H$61/1000 -> 41.200515 | I33: ='Raw Data'!I33*'Raw Data'!I$61/1000 -> 39.639706 | J33: ='Raw Data'!J33*'Raw Data'!J$61/1000 -> 36.073816 | K33: ='Raw Data'!K33*'Raw Data'!K$61/1000 -> 37.96978 | L33: ='Raw Data'!L33*'Raw Data'!L$61/1000 -> 38.68523 | M33: ='Raw Data'!M33*'Raw Data'!M$61/1000 -> 38.884056 | ... S33: ='Raw Data'!S33*'Raw Data'!S$61/1000 -> 40.297778 | T33: =IFERROR(S33/R33-1,"") -> -0.064638191 | U33: =IFERROR(S33/F33-1,"") -> -0.022419048 | V33: Dollar-priced: INR move = commodity move + rupee move
A34: RUBBER & CARBON BLACK
A35: ='Raw Data'!A35 -> Natural Rubber (RSS 4) | B35: Rubber & Carbon Black | C35: INR/kg | D35: as reported | E35: 31 | F35: ='Raw Data'!F35 -> 207.26 | G35: ='Raw Data'!G35 -> 196.34 | H35: ='Raw Data'!H35 -> 188.41 | I35: ='Raw Data'!I35 -> 187.33 | J35: ='Raw Data'!J35 -> 186.05 | K35: ='Raw Data'!K35 -> 183.74 | L35: ='Raw Data'!L35 -> 191.68 | M35: ='Raw Data'!M35 -> 212.48 | ... S35: ='Raw Data'!S35 -> 278.76 | T35: =IFERROR(S35/R35-1,"") -> 0.0094879409 | U35: =IFERROR(S35/F35-1,"") -> 0.34497732
A36: ='Raw Data'!A36 -> Synthetic Rubber - SBR 1502 | B36: Rubber & Carbon Black | C36: INR/kg | D36: as reported | E36: 32 | F36: ='Raw Data'!F36 -> 184.18 | G36: ='Raw Data'!G36 -> 174.33 | H36: ='Raw Data'!H36 -> 177.57 | I36: ='Raw Data'!I36 -> 177.44 | J36: ='Raw Data'!J36 -> 176.52 | K36: ='Raw Data'!K36 -> 161.7 | L36: ='Raw Data'!L36 -> 155.59 | M36: ='Raw Data'!M36 -> 150.2 | ... S36: ='Raw Data'!S36 -> 251.5 | T36: =IFERROR(S36/R36-1,"") -> 0.019787527 | U36: =IFERROR(S36/F36-1,"") -> 0.365512
A37: ='Raw Data'!A37 -> EPDM | B37: Rubber & Carbon Black | C37: INR/kg | D37: as reported | E37: 33 | F37: ='Raw Data'!F37 -> 220.45 | G37: ='Raw Data'!G37 -> 219.12 | H37: ='Raw Data'!H37 -> 216.76 | I37: ='Raw Data'!I37 -> 215.11 | J37: ='Raw Data'!J37 -> 212.16 | K37: ='Raw Data'!K37 -> 211.48 | L37: ='Raw Data'!L37 -> 207.7 | M37: ='Raw Data'!M37 -> 205.19 | ... S37: ='Raw Data'!S37 -> 292.85 | T37: =IFERROR(S37/R37-1,"") -> 0.016769669 | U37: =IFERROR(S37/F37-1,"") -> 0.32841914
A38: ='Raw Data'!A38 -> Carbon Black (N330) | B38: Rubber & Carbon Black | C38: INR/kg | D38: as reported | E38: 34 | F38: ='Raw Data'!F38 -> 113.05 | G38: ='Raw Data'!G38 -> 105.68 | H38: ='Raw Data'!H38 -> 102.9 | I38: ='Raw Data'!I38 -> 99.55 | J38: ='Raw Data'!J38 -> 96.16 | K38: ='Raw Data'!K38 -> 96.3 | L38: ='Raw Data'!L38 -> 93.5 | M38: ='Raw Data'!M38 -> 92.64 | ... S38: ='Raw Data'!S38 -> 155.42 | T38: =IFERROR(S38/R38-1,"") -> -0.0087378022 | U38: =IFERROR(S38/F38-1,"") -> 0.37478992
A39: ='Raw Data'!A39 -> Polybutadiene Rubber (1220) | B39: Rubber & Carbon Black | C39: INR/kg | D39: as reported | E39: 35 | F39: ='Raw Data'!F39 -> 172.29 | G39: ='Raw Data'!G39 -> 169.86 | H39: ='Raw Data'!H39 -> 175.69 | I39: ='Raw Data'!I39 -> 171.66 | J39: ='Raw Data'!J39 -> 169.56 | K39: ='Raw Data'!K39 -> 168.85 | L39: ='Raw Data'!L39 -> 153.55 | M39: ='Raw Data'!M39 -> 150.95 | ... S39: ='Raw Data'!S39 -> 270.61 | T39: =IFERROR(S39/R39-1,"") -> -0.007263656 | U39: =IFERROR(S39/F39-1,"") -> 0.57066574
A40: ADVANCED CHEMISTRIES (BATTERY)
A41: ='Raw Data'!A41 -> Lithium Carbonate (99.5% batt grade) | B41: Advanced Chemistries (Battery) | C41: INR/kg | D41: x USD-INR | E41: 37 | F41: ='Raw Data'!F41*'Raw Data'!F$61 -> 729.2311 | G41: ='Raw Data'!G41*'Raw Data'!G$61 -> 826.7532 | H41: ='Raw Data'!H41*'Raw Data'!H$61 -> 833.7882 | I41: ='Raw Data'!I41*'Raw Data'!I$61 -> 840.9555 | J41: ='Raw Data'!J41*'Raw Data'!J$61 -> 918.3434 | K41: ='Raw Data'!K41*'Raw Data'!K$61 -> 1043.0362 | L41: ='Raw Data'!L41*'Raw Data'!L$61 -> 1600.2768 | M41: ='Raw Data'!M41*'Raw Data'!M$61 -> 1681.2012 | ... S41: ='Raw Data'!S41*'Raw Data'!S$61 -> 1853.765 | T41: =IFERROR(S41/R41-1,"") -> -0.015460086 | U41: =IFERROR(S41/F41-1,"") -> 1.5420817 | V41: Dollar-priced: INR move = commodity move + rupee move
A42: ='Raw Data'!A42 -> Lithium Hydroxide (56.5% batt grade) | B42: Advanced Chemistries (Battery) | C42: INR/kg | D42: x USD-INR | E42: 38 | F42: ='Raw Data'!F42*'Raw Data'!F$61 -> 703.2181 | G42: ='Raw Data'!G42*'Raw Data'!G$61 -> 755.3598 | H42: ='Raw Data'!H42*'Raw Data'!H$61 -> 826.677 | I42: ='Raw Data'!I42*'Raw Data'!I$61 -> 848.0747 | J42: ='Raw Data'!J42*'Raw Data'!J$61 -> 913.8724 | K42: ='Raw Data'!K42*'Raw Data'!K$61 -> 977.7898 | L42: ='Raw Data'!L42*'Raw Data'!L$61 -> 1529.0316 | M42: ='Raw Data'!M42*'Raw Data'!M$61 -> 1608.1452 | ... S42: ='Raw Data'!S42*'Raw Data'!S$61 -> 1717.374 | T42: =IFERROR(S42/R42-1,"") -> -0.0098623218 | U42: =IFERROR(S42/F42-1,"") -> 1.4421641 | V42: Dollar-priced: INR move = commodity move + rupee move
...

Sheet Commodity Indices
A1: COMMODITY PRICE INDICES (BASE = 100)
A2: Each series rebased to the base month set on Assumptions, on the chosen currency basis. These feed every basket.
A5: Commodity | B5: Category | C5: Basis | D5: Base month | E5: Base = 100 | F5: Jul-25 | G5: Aug-25 | H5: Sept-25 | I5: Oct-25 | J5: Nov-25 | K5: Dec-25 | L5: Jan-26 | M5: Feb-26 | N5: Mar-26 | O5: Apr-26 | P5: May-26 | Q5: June-26 | R5: July-26 | S5: Aug-26 | T5: MoM % | U5: YoY % | V5: Notes
A6: FERROUS - FLAT, LONG & SPECIAL STEEL
A7: ='Raw Data'!A7 -> HR Steel (HRC 1.8mm, IS2062) | B7: Ferrous - Flat, Long & Special Steel | C7: =Assumptions!$C$5 -> INR | D7: =Assumptions!$C$6 -> Jul-25 | E7: 100 | F7: =IF(Assumptions!$C$5="INR",'INR Normalised'!F7,'Raw Data'!F7)/IF(Assumptions!$C$5="INR",INDEX('INR Normalised'!$F7:$S7,Assumptions!$C$7),INDEX('Raw Data'!$F7:$S7,Assumptions!$C$7))*100 -> 100 | G7: =IF(Assumptions!$C$5="INR",'INR Normalised'!G7,'Raw Data'!G7)/IF(Assumptions!$C$5="INR",INDEX('INR Normalised'!$F7:$S7,Assumptions!$C$7),INDEX('Raw Data'!$F7:$S7,Assumptions!$C$7))*100 -> 100.95682 | H7: =IF(Assumptions!$C$5="INR",'INR Normalised'!H7,'Raw Data'!H7)/IF(Assumptions!$C$5="INR",INDEX('INR Normalised'!$F7:$S7,Assumptions!$C$7),INDEX('Raw Data'!$F7:$S7,Assumptions!$C$7))*100 -> 99.730128 | I7: =IF(Assumptions!$C$5="INR",'INR Normalised'!I7,'Raw Data'!I7)/IF(Assumptions!$C$5="INR",INDEX('INR Normalised'!$F7:$S7,Assumptions!$C$7),INDEX('Raw Data'!$F7:$S7,Assumptions!$C$7))*100 -> 97.767419 | J7: =IF(Assumptions!$C$5="INR",'INR Normalised'!J7,'Raw Data'!J7)/IF(Assumptions!$C$5="INR",INDEX('INR Normalised'!$F7:$S7,Assumptions!$C$7),INDEX('Raw Data'!$F7:$S7,Assumptions!$C$7))*100 -> 94.578018 | K7: =IF(Assumptions!$C$5="INR",'INR Normalised'!K7,'Raw Data'!K7)/IF(Assumptions!$C$5="INR",INDEX('INR Normalised'!$F7:$S7,Assumptions!$C$7),INDEX('Raw Data'!$F7:$S7,Assumptions!$C$7))*100 -> 96.329735 | L7: =IF(Assumptions!$C$5="INR",'INR Normalised'!L7,'Raw Data'!L7)/IF(Assumptions!$C$5="INR",INDEX('INR Normalised'!$F7:$S7,Assumptions!$C$7),INDEX('Raw Data'!$F7:$S7,Assumptions!$C$7))*100 -> 105.22571 | M7: =IF(Assumptions!$C$5="INR",'INR Normalised'!M7,'Raw Data'!M7)/IF(Assumptions!$C$5="INR",INDEX('INR Normalised'!$F7:$S7,Assumptions!$C$7),INDEX('Raw Data'!$F7:$S7,Assumptions!$C$7))*100 -> 108.36605 | ... S7: =IF(Assumptions!$C$5="INR",'INR Normalised'!S7,'Raw Data'!S7)/IF(Assumptions!$C$5="INR",INDEX('INR Normalised'!$F7:$S7,Assumptions!$C$7),INDEX('Raw Data'!$F7:$S7,Assumptions!$C$7))*100 -> 120.79293 | T7: =IFERROR(S7/R7-1,"") -> 0.01074068 | U7: =IFERROR(S7/F7-1,"") -> 0.20792934
A8: ='Raw Data'!A8 -> CR Steel (CRC 0.90mm, IS513 GrO) | B8: Ferrous - Flat, Long & Special Steel | C8: =Assumptions!$C$5 -> INR | D8: =Assumptions!$C$6 -> Jul-25 | E8: 100 | F8: =IF(Assumptions!$C$5="INR",'INR Normalised'!F8,'Raw Data'!F8)/IF(Assumptions!$C$5="INR",INDEX('INR Normalised'!$F8:$S8,Assumptions!$C$7),INDEX('Raw Data'!$F8:$S8,Assumptions!$C$7))*100 -> 100 | G8: =IF(Assumptions!$C$5="INR",'INR Normalised'!G8,'Raw Data'!G8)/IF(Assumptions!$C$5="INR",INDEX('INR Normalised'!$F8:$S8,Assumptions!$C$7),INDEX('Raw Data'!$F8:$S8,Assumptions!$C$7))*100 -> 100.97431 | H8: =IF(Assumptions!$C$5="INR",'INR Normalised'!H8,'Raw Data'!H8)/IF(Assumptions!$C$5="INR",INDEX('INR Normalised'!$F8:$S8,Assumptions!$C$7),INDEX('Raw Data'!$F8:$S8,Assumptions!$C$7))*100 -> 100.08857 | I8: =IF(Assumptions!$C$5="INR",'INR Normalised'!I8,'Raw Data'!I8)/IF(Assumptions!$C$5="INR",INDEX('INR Normalised'!$F8:$S8,Assumptions!$C$7),INDEX('Raw Data'!$F8:$S8,Assumptions!$C$7))*100 -> 98.317095 | J8: =IF(Assumptions!$C$5="INR",'INR Normalised'!J8,'Raw Data'!J8)/IF(Assumptions!$C$5="INR",INDEX('INR Normalised'!$F8:$S8,Assumptions!$C$7),INDEX('Raw Data'!$F8:$S8,Assumptions!$C$7))*100 -> 97.320638 | K8: =IF(Assumptions!$C$5="INR",'INR Normalised'!K8,'Raw Data'!K8)/IF(Assumptions!$C$5="INR",INDEX('INR Normalised'!$F8:$S8,Assumptions!$C$7),INDEX('Raw Data'!$F8:$S8,Assumptions!$C$7))*100 -> 97.201063 | L8: =IF(Assumptions!$C$5="INR",'INR Normalised'!L8,'Raw Data'!L8)/IF(Assumptions!$C$5="INR",INDEX('INR Normalised'!$F8:$S8,Assumptions!$C$7),INDEX('Raw Data'!$F8:$S8,Assumptions!$C$7))*100 -> 102.48007 | M8: =IF(Assumptions!$C$5="INR",'INR Normalised'!M8,'Raw Data'!M8)/IF(Assumptions!$C$5="INR",INDEX('INR Normalised'!$F8:$S8,Assumptions!$C$7),INDEX('Raw Data'!$F8:$S8,Assumptions!$C$7))*100 -> 105.64659 | ... S8: =IF(Assumptions!$C$5="INR",'INR Normalised'!S8,'Raw Data'!S8)/IF(Assumptions!$C$5="INR",INDEX('INR Normalised'!$F8:$S8,Assumptions!$C$7),INDEX('Raw Data'!$F8:$S8,Assumptions!$C$7))*100 -> 116.25332 | T8: =IFERROR(S8/R8-1,"") -> 0.0072908672 | U8: =IFERROR(S8/F8-1,"") -> 0.16253322
A9: ='Raw Data'!A9 -> Alloy Steel - Forging (20MnCr5) | B9: Ferrous - Flat, Long & Special Steel | C9: =Assumptions!$C$5 -> INR | D9: =Assumptions!$C$6 -> Jul-25 | E9: 100 | F9: =IF(Assumptions!$C$5="INR",'INR Normalised'!F9,'Raw Data'!F9)/IF(Assumptions!$C$5="INR",INDEX('INR Normalised'!$F9:$S9,Assumptions!$C$7),INDEX('Raw Data'!$F9:$S9,Assumptions!$C$7))*100 -> 100 | G9: =IF(Assumptions!$C$5="INR",'INR Normalised'!G9,'Raw Data'!G9)/IF(Assumptions!$C$5="INR",INDEX('INR Normalised'!$F9:$S9,Assumptions!$C$7),INDEX('Raw Data'!$F9:$S9,Assumptions!$C$7))*100 -> 100 | H9: =IF(Assumptions!$C$5="INR",'INR Normalised'!H9,'Raw Data'!H9)/IF(Assumptions!$C$5="INR",INDEX('INR Normalised'!$F9:$S9,Assumptions!$C$7),INDEX('Raw Data'!$F9:$S9,Assumptions!$C$7))*100 -> 98.790323 | I9: =IF(Assumptions!$C$5="INR",'INR Normalised'!I9,'Raw Data'!I9)/IF(Assumptions!$C$5="INR",INDEX('INR Normalised'!$F9:$S9,Assumptions!$C$7),INDEX('Raw Data'!$F9:$S9,Assumptions!$C$7))*100 -> 98.387097 | J9: =IF(Assumptions!$C$5="INR",'INR Normalised'!J9,'Raw Data'!J9)/IF(Assumptions!$C$5="INR",INDEX('INR Normalised'!$F9:$S9,Assumptions!$C$7),INDEX('Raw Data'!$F9:$S9,Assumptions!$C$7))*100 -> 97.177419 | K9: =IF(Assumptions!$C$5="INR",'INR Normalised'!K9,'Raw Data'!K9)/IF(Assumptions!$C$5="INR",INDEX('INR Normalised'!$F9:$S9,Assumptions!$C$7),INDEX('Raw Data'!$F9:$S9,Assumptions!$C$7))*100 -> 96.774194 | L9: =IF(Assumptions!$C$5="INR",'INR Normalised'!L9,'Raw Data'!L9)/IF(Assumptions!$C$5="INR",INDEX('INR Normalised'!$F9:$S9,Assumptions!$C$7),INDEX('Raw Data'!$F9:$S9,Assumptions!$C$7))*100 -> 98.064516 | M9: =IF(Assumptions!$C$5="INR",'INR Normalised'!M9,'Raw Data'!M9)/IF(Assumptions!$C$5="INR",INDEX('INR Normalised'!$F9:$S9,Assumptions!$C$7),INDEX('Raw Data'!$F9:$S9,Assumptions!$C$7))*100 -> 100 | ... S9: =IF(Assumptions!$C$5="INR",'INR Normalised'!S9,'Raw Data'!S9)/IF(Assumptions!$C$5="INR",INDEX('INR Normalised'!$F9:$S9,Assumptions!$C$7),INDEX('Raw Data'!$F9:$S9,Assumptions!$C$7))*100 -> 100.20968 | T9: =IFERROR(S9/R9-1,"") -> -0.0032087277 | U9: =IFERROR(S9/F9-1,"") -> 0.0020967742
A10: ='Raw Data'!A10 -> Alloy Steel - Forging (EN-8) | B10: Ferrous - Flat, Long & Special Steel | C10: =Assumptions!$C$5 -> INR | D10: =Assumptions!$C$6 -> Jul-25 | E10: 100 | F10: =IF(Assumptions!$C$5="INR",'INR Normalised'!F10,'Raw Data'!F10)/IF(Assumptions!$C$5="INR",INDEX('INR Normalised'!$F10:$S10,Assumptions!$C$7),INDEX('Raw Data'!$F10:$S10,Assumptions!$C$7))*100 -> 100 | G10: =IF(Assumptions!$C$5="INR",'INR Normalised'!G10,'Raw Data'!G10)/IF(Assumptions!$C$5="INR",INDEX('INR Normalised'!$F10:$S10,Assumptions!$C$7),INDEX('Raw Data'!$F10:$S10,Assumptions!$C$7))*100 -> 100 | H10: =IF(Assumptions!$C$5="INR",'INR Normalised'!H10,'Raw Data'!H10)/IF(Assumptions!$C$5="INR",INDEX('INR Normalised'!$F10:$S10,Assumptions!$C$7),INDEX('Raw Data'!$F10:$S10,Assumptions!$C$7))*100 -> 98.770492 | I10: =IF(Assumptions!$C$5="INR",'INR Normalised'!I10,'Raw Data'!I10)/IF(Assumptions!$C$5="INR",INDEX('INR Normalised'!$F10:$S10,Assumptions!$C$7),INDEX('Raw Data'!$F10:$S10,Assumptions!$C$7))*100 -> 98.360656 | J10: =IF(Assumptions!$C$5="INR",'INR Normalised'!J10,'Raw Data'!J10)/IF(Assumptions!$C$5="INR",INDEX('INR Normalised'!$F10:$S10,Assumptions!$C$7),INDEX('Raw Data'!$F10:$S10,Assumptions!$C$7))*100 -> 97.131148 | K10: =IF(Assumptions!$C$5="INR",'INR Normalised'!K10,'Raw Data'!K10)/IF(Assumptions!$C$5="INR",INDEX('INR Normalised'!$F10:$S10,Assumptions!$C$7),INDEX('Raw Data'!$F10:$S10,Assumptions!$C$7))*100 -> 96.721311 | L10: =IF(Assumptions!$C$5="INR",'INR Normalised'!L10,'Raw Data'!L10)/IF(Assumptions!$C$5="INR",INDEX('INR Normalised'!$F10:$S10,Assumptions!$C$7),INDEX('Raw Data'!$F10:$S10,Assumptions!$C$7))*100 -> 98.032787 | M10: =IF(Assumptions!$C$5="INR",'INR Normalised'!M10,'Raw Data'!M10)/IF(Assumptions!$C$5="INR",INDEX('INR Normalised'!$F10:$S10,Assumptions!$C$7),INDEX('Raw Data'!$F10:$S10,Assumptions!$C$7))*100 -> 100 | ... S10: =IF(Assumptions!$C$5="INR",'INR Normalised'!S10,'Raw Data'!S10)/IF(Assumptions!$C$5="INR",INDEX('INR Normalised'!$F10:$S10,Assumptions!$C$7),INDEX('Raw Data'!$F10:$S10,Assumptions!$C$7))*100 -> 96.721311 | T10: =IFERROR(S10/R10-1,"") -> -0.0033783784 | U10: =IFERROR(S10/F10-1,"") -> -0.032786885
A11: ='Raw Data'!A11 -> Pig Iron (Foundry Grade B) | B11: Ferrous - Flat, Long & Special Steel | C11: =Assumptions!$C$5 -> INR | D11: =Assumptions!$C$6 -> Jul-25 | E11: 100 | F11: =IF(Assumptions!$C$5="INR",'INR Normalised'!F11,'Raw Data'!F11)/IF(Assumptions!$C$5="INR",INDEX('INR Normalised'!$F11:$S11,Assumptions!$C$7),INDEX('Raw Data'!$F11:$S11,Assumptions!$C$7))*100 -> 100 | G11: =IF(Assumptions!$C$5="INR",'INR Normalised'!G11,'Raw Data'!G11)/IF(Assumptions!$C$5="INR",INDEX('INR Normalised'!$F11:$S11,Assumptions!$C$7),INDEX('Raw Data'!$F11:$S11,Assumptions!$C$7))*100 -> 99.933555 | H11: =IF(Assumptions!$C$5="INR",'INR Normalised'!H11,'Raw Data'!H11)/IF(Assumptions!$C$5="INR",INDEX('INR Normalised'!$F11:$S11,Assumptions!$C$7),INDEX('Raw Data'!$F11:$S11,Assumptions!$C$7))*100 -> 104.31894 | I11: =IF(Assumptions!$C$5="INR",'INR Normalised'!I11,'Raw Data'!I11)/IF(Assumptions!$C$5="INR",INDEX('INR Normalised'!$F11:$S11,Assumptions!$C$7),INDEX('Raw Data'!$F11:$S11,Assumptions!$C$7))*100 -> 104.18605 | J11: =IF(Assumptions!$C$5="INR",'INR Normalised'!J11,'Raw Data'!J11)/IF(Assumptions!$C$5="INR",INDEX('INR Normalised'!$F11:$S11,Assumptions!$C$7),INDEX('Raw Data'!$F11:$S11,Assumptions!$C$7))*100 -> 103.65449 | K11: =IF(Assumptions!$C$5="INR",'INR Normalised'!K11,'Raw Data'!K11)/IF(Assumptions!$C$5="INR",INDEX('INR Normalised'!$F11:$S11,Assumptions!$C$7),INDEX('Raw Data'!$F11:$S11,Assumptions!$C$7))*100 -> 101.66113 | L11: =IF(Assumptions!$C$5="INR",'INR Normalised'!L11,'Raw Data'!L11)/IF(Assumptions!$C$5="INR",INDEX('INR Normalised'!$F11:$S11,Assumptions!$C$7),INDEX('Raw Data'!$F11:$S11,Assumptions!$C$7))*100 -> 110.56478 | M11: =IF(Assumptions!$C$5="INR",'INR Normalised'!M11,'Raw Data'!M11)/IF(Assumptions!$C$5="INR",INDEX('INR Normalised'!$F11:$S11,Assumptions!$C$7),INDEX('Raw Data'!$F11:$S11,Assumptions!$C$7))*100 -> 113.40066 | ... S11: =IF(Assumptions!$C$5="INR",'INR Normalised'!S11,'Raw Data'!S11)/IF(Assumptions!$C$5="INR",INDEX('INR Normalised'!$F11:$S11,Assumptions!$C$7),INDEX('Raw Data'!$F11:$S11,Assumptions!$C$7))*100 -> 129.56811 | T11: =IFERROR(S11/R11-1,"") -> 0.052915767 | U11: =IFERROR(S11/F11-1,"") -> 0.29568106
A12: ='Raw Data'!A12 -> Stainless Steel (G304 CR Coil) | B12: Ferrous - Flat, Long & Special Steel | C12: =Assumptions!$C$5 -> INR | D12: =Assumptions!$C$6 -> Jul-25 | E12: 100 | F12: =IF(Assumptions!$C$5="INR",'INR Normalised'!F12,'Raw Data'!F12)/IF(Assumptions!$C$5="INR",INDEX('INR Normalised'!$F12:$S12,Assumptions!$C$7),INDEX('Raw Data'!$F12:$S12,Assumptions!$C$7))*100 -> 100 | G12: =IF(Assumptions!$C$5="INR",'INR Normalised'!G12,'Raw Data'!G12)/IF(Assumptions!$C$5="INR",INDEX('INR Normalised'!$F12:$S12,Assumptions!$C$7),INDEX('Raw Data'!$F12:$S12,Assumptions!$C$7))*100 -> 101.90918 | H12: =IF(Assumptions!$C$5="INR",'INR Normalised'!H12,'Raw Data'!H12)/IF(Assumptions!$C$5="INR",INDEX('INR Normalised'!$F12:$S12,Assumptions!$C$7),INDEX('Raw Data'!$F12:$S12,Assumptions!$C$7))*100 -> 103.45717 | I12: =IF(Assumptions!$C$5="INR",'INR Normalised'!I12,'Raw Data'!I12)/IF(Assumptions!$C$5="INR",INDEX('INR Normalised'!$F12:$S12,Assumptions!$C$7),INDEX('Raw Data'!$F12:$S12,Assumptions!$C$7))*100 -> 103.19917 | J12: =IF(Assumptions!$C$5="INR",'INR Normalised'!J12,'Raw Data'!J12)/IF(Assumptions!$C$5="INR",INDEX('INR Normalised'!$F12:$S12,Assumptions!$C$7),INDEX('Raw Data'!$F12:$S12,Assumptions!$C$7))*100 -> 99.329205 | K12: =IF(Assumptions!$C$5="INR",'INR Normalised'!K12,'Raw Data'!K12)/IF(Assumptions!$C$5="INR",INDEX('INR Normalised'!$F12:$S12,Assumptions!$C$7),INDEX('Raw Data'!$F12:$S12,Assumptions!$C$7))*100 -> 98.039216 | L12: =IF(Assumptions!$C$5="INR",'INR Normalised'!L12,'Raw Data'!L12)/IF(Assumptions!$C$5="INR",INDEX('INR Normalised'!$F12:$S12,Assumptions!$C$7),INDEX('Raw Data'!$F12:$S12,Assumptions!$C$7))*100 -> 102.55418 | M12: =IF(Assumptions!$C$5="INR",'INR Normalised'!M12,'Raw Data'!M12)/IF(Assumptions!$C$5="INR",INDEX('INR Normalised'!$F12:$S12,Assumptions!$C$7),INDEX('Raw Data'!$F12:$S12,Assumptions!$C$7))*100 -> 105.00516 | ... S12: =IF(Assumptions!$C$5="INR",'INR Normalised'!S12,'Raw Data'!S12)/IF(Assumptions!$C$5="INR",INDEX('INR Normalised'!$F12:$S12,Assumptions!$C$7),INDEX('Raw Data'!$F12:$S12,Assumptions!$C$7))*100 -> 116.09907 | T12: =IFERROR(S12/R12-1,"") -> 0.018099548 | U12: =IFERROR(S12/F12-1,"") -> 0.16099071
A13: ='Raw Data'!A13 -> Stainless Steel (G304 HR Coil) | B13: Ferrous - Flat, Long & Special Steel | C13: =Assumptions!$C$5 -> INR | D13: =Assumptions!$C$6 -> Jul-25 | E13: 100 | F13: =IF(Assumptions!$C$5="INR",'INR Normalised'!F13,'Raw Data'!F13)/IF(Assumptions!$C$5="INR",INDEX('INR Normalised'!$F13:$S13,Assumptions!$C$7),INDEX('Raw Data'!$F13:$S13,Assumptions!$C$7))*100 -> 100 | G13: =IF(Assumptions!$C$5="INR",'INR Normalised'!G13,'Raw Data'!G13)/IF(Assumptions!$C$5="INR",INDEX('INR Normalised'!$F13:$S13,Assumptions!$C$7),INDEX('Raw Data'!$F13:$S13,Assumptions!$C$7))*100 -> 101.69837 | H13: =IF(Assumptions!$C$5="INR",'INR Normalised'!H13,'Raw Data'!H13)/IF(Assumptions!$C$5="INR",INDEX('INR Normalised'!$F13:$S13,Assumptions!$C$7),INDEX('Raw Data'!$F13:$S13,Assumptions!$C$7))*100 -> 103.53261 | I13: =IF(Assumptions!$C$5="INR",'INR Normalised'!I13,'Raw Data'!I13)/IF(Assumptions!$C$5="INR",INDEX('INR Normalised'!$F13:$S13,Assumptions!$C$7),INDEX('Raw Data'!$F13:$S13,Assumptions!$C$7))*100 -> 103.26087 | J13: =IF(Assumptions!$C$5="INR",'INR Normalised'!J13,'Raw Data'!J13)/IF(Assumptions!$C$5="INR",INDEX('INR Normalised'!$F13:$S13,Assumptions!$C$7),INDEX('Raw Data'!$F13:$S13,Assumptions!$C$7))*100 -> 99.184783 | K13: =IF(Assumptions!$C$5="INR",'INR Normalised'!K13,'Raw Data'!K13)/IF(Assumptions!$C$5="INR",INDEX('INR Normalised'!$F13:$S13,Assumptions!$C$7),INDEX('Raw Data'!$F13:$S13,Assumptions!$C$7))*100 -> 98.695652 | L13: =IF(Assumptions!$C$5="INR",'INR Normalised'!L13,'Raw Data'!L13)/IF(Assumptions!$C$5="INR",INDEX('INR Normalised'!$F13:$S13,Assumptions!$C$7),INDEX('Raw Data'!$F13:$S13,Assumptions!$C$7))*100 -> 103.53261 | M13: =IF(Assumptions!$C$5="INR",'INR Normalised'!M13,'Raw Data'!M13)/IF(Assumptions!$C$5="INR",INDEX('INR Normalised'!$F13:$S13,Assumptions!$C$7),INDEX('Raw Data'!$F13:$S13,Assumptions!$C$7))*100 -> 105.57065 | ... S13: =IF(Assumptions!$C$5="INR",'INR Normalised'!S13,'Raw Data'!S13)/IF(Assumptions!$C$5="INR",INDEX('INR Normalised'!$F13:$S13,Assumptions!$C$7),INDEX('Raw Data'!$F13:$S13,Assumptions!$C$7))*100 -> 118.88587 | T13: =IFERROR(S13/R13-1,"") -> 0.022196262 | U13: =IFERROR(S13/F13-1,"") -> 0.1888587
A14: ='Raw Data'!A14 -> Steel Scrap (RM end scrap) | B14: Ferrous - Flat, Long & Special Steel | C14: =Assumptions!$C$5 -> INR | D14: =Assumptions!$C$6 -> Jul-25 | E14: 100 | F14: =IF(Assumptions!$C$5="INR",'INR Normalised'!F14,'Raw Data'!F14)/IF(Assumptions!$C$5="INR",INDEX('INR Normalised'!$F14:$S14,Assumptions!$C$7),INDEX('Raw Data'!$F14:$S14,Assumptions!$C$7))*100 -> 100 | G14: =IF(Assumptions!$C$5="INR",'INR Normalised'!G14,'Raw Data'!G14)/IF(Assumptions!$C$5="INR",INDEX('INR Normalised'!$F14:$S14,Assumptions!$C$7),INDEX('Raw Data'!$F14:$S14,Assumptions!$C$7))*100 -> 100.53682 | H14: =IF(Assumptions!$C$5="INR",'INR Normalised'!H14,'Raw Data'!H14)/IF(Assumptions!$C$5="INR",INDEX('INR Normalised'!$F14:$S14,Assumptions!$C$7),INDEX('Raw Data'!$F14:$S14,Assumptions!$C$7))*100 -> 97.522368 | I14: =IF(Assumptions!$C$5="INR",'INR Normalised'!I14,'Raw Data'!I14)/IF(Assumptions!$C$5="INR",INDEX('INR Normalised'!$F14:$S14,Assumptions!$C$7),INDEX('Raw Data'!$F14:$S14,Assumptions!$C$7))*100 -> 95.581555 | J14: =IF(Assumptions!$C$5="INR",'INR Normalised'!J14,'Raw Data'!J14)/IF(Assumptions!$C$5="INR",INDEX('INR Normalised'!$F14:$S14,Assumptions!$C$7),INDEX('Raw Data'!$F14:$S14,Assumptions!$C$7))*100 -> 92.360633 | K14: =IF(Assumptions!$C$5="INR",'INR Normalised'!K14,'Raw Data'!K14)/IF(Assumptions!$C$5="INR",INDEX('INR Normalised'!$F14:$S14,Assumptions!$C$7),INDEX('Raw Data'!$F14:$S14,Assumptions!$C$7))*100 -> 92.429456 | L14: =IF(Assumptions!$C$5="INR",'INR Normalised'!L14,'Raw Data'!L14)/IF(Assumptions!$C$5="INR",INDEX('INR Normalised'!$F14:$S14,Assumptions!$C$7),INDEX('Raw Data'!$F14:$S14,Assumptions!$C$7))*100 -> 97.178252 | M14: =IF(Assumptions!$C$5="INR",'INR Normalised'!M14,'Raw Data'!M14)/IF(Assumptions!$C$5="INR",INDEX('INR Normalised'!$F14:$S14,Assumptions!$C$7),INDEX('Raw Data'!$F14:$S14,Assumptions!$C$7))*100 -> 102.31796 | ... S14: =IF(Assumptions!$C$5="INR",'INR Normalised'!S14,'Raw Data'!S14)/IF(Assumptions!$C$5="INR",INDEX('INR Normalised'!$F14:$S14,Assumptions!$C$7),INDEX('Raw Data'!$F14:$S14,Assumptions!$C$7))*100 -> 102.61528 | T14: =IFERROR(S14/R14-1,"") -> 0.013458401 | U14: =IFERROR(S14/F14-1,"") -> 0.026152787
A15: UPSTREAM STEEL INPUTS
A16: ='Raw Data'!A16 -> Coking Coal (Premium HCC, Australia) | B16: Upstream Steel Inputs | C16: =Assumptions!$C$5 -> INR | D16: =Assumptions!$C$6 -> Jul-25 | E16: 100 | F16: =IF(Assumptions!$C$5="INR",'INR Normalised'!F16,'Raw Data'!F16)/IF(Assumptions!$C$5="INR",INDEX('INR Normalised'!$F16:$S16,Assumptions!$C$7),INDEX('Raw Data'!$F16:$S16,Assumptions!$C$7))*100 -> 100 | G16: =IF(Assumptions!$C$5="INR",'INR Normalised'!G16,'Raw Data'!G16)/IF(Assumptions!$C$5="INR",INDEX('INR Normalised'!$F16:$S16,Assumptions!$C$7),INDEX('Raw Data'!$F16:$S16,Assumptions!$C$7))*100 -> 106.91597 | H16: =IF(Assumptions!$C$5="INR",'INR Normalised'!H16,'Raw Data'!H16)/IF(Assumptions!$C$5="INR",INDEX('INR Normalised'!$F16:$S16,Assumptions!$C$7),INDEX('Raw Data'!$F16:$S16,Assumptions!$C$7))*100 -> 107.82574 | I16: =IF(Assumptions!$C$5="INR",'INR Normalised'!I16,'Raw Data'!I16)/IF(Assumptions!$C$5="INR",INDEX('INR Normalised'!$F16:$S16,Assumptions!$C$7),INDEX('Raw Data'!$F16:$S16,Assumptions!$C$7))*100 -> 110.60584 | J16: =IF(Assumptions!$C$5="INR",'INR Normalised'!J16,'Raw Data'!J16)/IF(Assumptions!$C$5="INR",INDEX('INR Normalised'!$F16:$S16,Assumptions!$C$7),INDEX('Raw Data'!$F16:$S16,Assumptions!$C$7))*100 -> 114.34625 | K16: =IF(Assumptions!$C$5="INR",'INR Normalised'!K16,'Raw Data'!K16)/IF(Assumptions!$C$5="INR",INDEX('INR Normalised'!$F16:$S16,Assumptions!$C$7),INDEX('Raw Data'!$F16:$S16,Assumptions!$C$7))*100 -> 122.92025 | L16: =IF(Assumptions!$C$5="INR",'INR Normalised'!L16,'Raw Data'!L16)/IF(Assumptions!$C$5="INR",INDEX('INR Normalised'!$F16:$S16,Assumptions!$C$7),INDEX('Raw Data'!$F16:$S16,Assumptions!$C$7))*100 -> 135.35871 | M16: =IF(Assumptions!$C$5="INR",'INR Normalised'!M16,'Raw Data'!M16)/IF(Assumptions!$C$5="INR",INDEX('INR Normalised'!$F16:$S16,Assumptions!$C$7),INDEX('Raw Data'!$F16:$S16,Assumptions!$C$7))*100 -> 143.51429 | ... S16: =IF(Assumptions!$C$5="INR",'INR Normalised'!S16,'Raw Data'!S16)/IF(Assumptions!$C$5="INR",INDEX('INR Normalised'!$F16:$S16,Assumptions!$C$7),INDEX('Raw Data'!$F16:$S16,Assumptions!$C$7))*100 -> 145.20828 | T16: =IFERROR(S16/R16-1,"") -> 0.00073838516 | U16: =IFERROR(S16/F16-1,"") -> 0.45208285
A17: ='Raw Data'!A17 -> Iron Ore (Fe 62%, Australia) | B17: Upstream Steel Inputs | C17: =Assumptions!$C$5 -> INR | D17: =Assumptions!$C$6 -> Jul-25 | E17: 100 | F17: =IF(Assumptions!$C$5="INR",'INR Normalised'!F17,'Raw Data'!F17)/IF(Assumptions!$C$5="INR",INDEX('INR Normalised'!$F17:$S17,Assumptions!$C$7),INDEX('Raw Data'!$F17:$S17,Assumptions!$C$7))*100 -> 100 | G17: =IF(Assumptions!$C$5="INR",'INR Normalised'!G17,'Raw Data'!G17)/IF(Assumptions!$C$5="INR",INDEX('INR Normalised'!$F17:$S17,Assumptions!$C$7),INDEX('Raw Data'!$F17:$S17,Assumptions!$C$7))*100 -> 104.72945 | H17: =IF(Assumptions!$C$5="INR",'INR Normalised'!H17,'Raw Data'!H17)/IF(Assumptions!$C$5="INR",INDEX('INR Normalised'!$F17:$S17,Assumptions!$C$7),INDEX('Raw Data'!$F17:$S17,Assumptions!$C$7))*100 -> 108.7271 | I17: =IF(Assumptions!$C$5="INR",'INR Normalised'!I17,'Raw Data'!I17)/IF(Assumptions!$C$5="INR",INDEX('INR Normalised'!$F17:$S17,Assumptions!$C$7),INDEX('Raw Data'!$F17:$S17,Assumptions!$C$7))*100 -> 109.88608 | J17: =IF(Assumptions!$C$5="INR",'INR Normalised'!J17,'Raw Data'!J17)/IF(Assumptions!$C$5="INR",INDEX('INR Normalised'!$F17:$S17,Assumptions!$C$7),INDEX('Raw Data'!$F17:$S17,Assumptions!$C$7))*100 -> 108.33371 | K17: =IF(Assumptions!$C$5="INR",'INR Normalised'!K17,'Raw Data'!K17)/IF(Assumptions!$C$5="INR",INDEX('INR Normalised'!$F17:$S17,Assumptions!$C$7),INDEX('Raw Data'!$F17:$S17,Assumptions!$C$7))*100 -> 112.95448 | L17: =IF(Assumptions!$C$5="INR",'INR Normalised'!L17,'Raw Data'!L17)/IF(Assumptions!$C$5="INR",INDEX('INR Normalised'!$F17:$S17,Assumptions!$C$7),INDEX('Raw Data'!$F17:$S17,Assumptions!$C$7))*100 -> 112.7879 | M17: =IF(Assumptions!$C$5="INR",'INR Normalised'!M17,'Raw Data'!M17)/IF(Assumptions!$C$5="INR",INDEX('INR Normalised'!$F17:$S17,Assumptions!$C$7),INDEX('Raw Data'!$F17:$S17,Assumptions!$C$7))*100 -> 105.31657 | ... S17: =IF(Assumptions!$C$5="INR",'INR Normalised'!S17,'Raw Data'!S17)/IF(Assumptions!$C$5="INR",INDEX('INR Normalised'!$F17:$S17,Assumptions!$C$7),INDEX('Raw Data'!$F17:$S17,Assumptions!$C$7))*100 -> 107.41482 | T17: =IFERROR(S17/R17-1,"") -> -0.023559611 | U17: =IFERROR(S17/F17-1,"") -> 0.074148241
A18: NON-FERROUS METALS
A19: ='Raw Data'!A19 -> Virgin Aluminium | B19: Non-Ferrous Metals | C19: =Assumptions!$C$5 -> INR | D19: =Assumptions!$C$6 -> Jul-25 | E19: 100 | F19: =IF(Assumptions!$C$5="INR",'INR Normalised'!F19,'Raw Data'!F19)/IF(Assumptions!$C$5="INR",INDEX('INR Normalised'!$F19:$S19,Assumptions!$C$7),INDEX('Raw Data'!$F19:$S19,Assumptions!$C$7))*100 -> 100 | G19: =IF(Assumptions!$C$5="INR",'INR Normalised'!G19,'Raw Data'!G19)/IF(Assumptions!$C$5="INR",INDEX('INR Normalised'!$F19:$S19,Assumptions!$C$7),INDEX('Raw Data'!$F19:$S19,Assumptions!$C$7))*100 -> 101.25104 | H19: =IF(Assumptions!$C$5="INR",'INR Normalised'!H19,'Raw Data'!H19)/IF(Assumptions!$C$5="INR",INDEX('INR Normalised'!$F19:$S19,Assumptions!$C$7),INDEX('Raw Data'!$F19:$S19,Assumptions!$C$7))*100 -> 104.44695 | I19: =IF(Assumptions!$C$5="INR",'INR Normalised'!I19,'Raw Data'!I19)/IF(Assumptions!$C$5="INR",INDEX('INR Normalised'!$F19:$S19,Assumptions!$C$7),INDEX('Raw Data'!$F19:$S19,Assumptions!$C$7))*100 -> 109.80587 | J19: =IF(Assumptions!$C$5="INR",'INR Normalised'!J19,'Raw Data'!J19)/IF(Assumptions!$C$5="INR",INDEX('INR Normalised'!$F19:$S19,Assumptions!$C$7),INDEX('Raw Data'!$F19:$S19,Assumptions!$C$7))*100 -> 111.7858 | K19: =IF(Assumptions!$C$5="INR",'INR Normalised'!K19,'Raw Data'!K19)/IF(Assumptions!$C$5="INR",INDEX('INR Normalised'!$F19:$S19,Assumptions!$C$7),INDEX('Raw Data'!$F19:$S19,Assumptions!$C$7))*100 -> 115.39684 | L19: =IF(Assumptions!$C$5="INR",'INR Normalised'!L19,'Raw Data'!L19)/IF(Assumptions!$C$5="INR",INDEX('INR Normalised'!$F19:$S19,Assumptions!$C$7),INDEX('Raw Data'!$F19:$S19,Assumptions!$C$7))*100 -> 127.35248 | M19: =IF(Assumptions!$C$5="INR",'INR Normalised'!M19,'Raw Data'!M19)/IF(Assumptions!$C$5="INR",INDEX('INR Normalised'!$F19:$S19,Assumptions!$C$7),INDEX('Raw Data'!$F19:$S19,Assumptions!$C$7))*100 -> 123.96798 | ... S19: =IF(Assumptions!$C$5="INR",'INR Normalised'!S19,'Raw Data'!S19)/IF(Assumptions!$C$5="INR",INDEX('INR Normalised'!$F19:$S19,Assumptions!$C$7),INDEX('Raw Data'!$F19:$S19,Assumptions!$C$7))*100 -> 138.32618 | T19: =IFERROR(S19/R19-1,"") -> 0.02710329 | U19: =IFERROR(S19/F19-1,"") -> 0.38326181
