Workbook

Sheet README
A1: INDIA ELECTRIC TWO-WHEELER — MODEL LANDSCAPE DATABASE
A2: Built for Bernstein India Autos. All data as of 25 August 2026 unless a cell states otherwise.
A5: PURPOSE | B5: A continuously usable model-level database of every meaningful electric two-wheeler on sale in India, plus the credible pipeline. Scooters and motorcycles are held on separate sheets because they are structurally different markets.
A7: SHEET GUIDE
A8: Scooters_Current | B8: Variant-level master for every e-scooter on sale. 58 variants across 26 brands. Filter-ready.
A9: Motorcycles_Current | B9: Variant-level master for every e-motorcycle on sale. 29 variants across 14 brands.
A10: Pipeline | B10: 24 upcoming products with an explicit CONFIRMATION LEVEL on each. Read this column before modelling anything.
A11: Price_Band_Map | B11: Live COUNTIF map of how many products sit in each price band, scooters vs motorcycles. Shows crowded bands and white space.
A12: Company_Profiles | B12: Ownership, funding, financials, capacity, network, cell strategy and the identified moat for 18 players.
A13: Volumes_MarketShare | B13: Vahan registrations FY22-FY26 plus Jul-26, with live share and YoY formulas.
A14: Industry_Penetration | B14: Total e-2W volumes, total 2W volumes and EV penetration by year, with live formulas.
A15: Supply_Chain_Barriers | B15: Component-by-component assessment of what is outsourceable and what is not. This is the analytical core of the entry-barrier thesis.
A16: Regulatory_Subsidy | B16: PM E-DRIVE, GST 2.0, FAME-II clawback, AIS-156, PLI, rare-earth magnet scheme, state policies.
A17: BOM_Economics | B17: Cell and pack cost benchmarks with live INR conversion driven by one editable FX cell.
A18: Sources | B18: Master source list with as-of dates.
A20: CONFIRMATION / CONFIDENCE CODES
A21: HIGH | B21: Sourced from an OEM website, official press release, regulatory filing or Vahan. Use directly.
A22: MEDIUM | B22: Credible auto media or a specification aggregator, cross-checked where possible. Verify before publishing a number.
A23: LOW | B23: Single-source, aggregator-only, or a category where disclosure is poor. Treat as indicative only.
A25: PIPELINE CONFIRMATION LEVELS
A26: COMPANY-CONFIRMED | B26: Officially announced by the company with a product commitment.
A27: COMPANY-GUIDED WINDOW | B27: Company has stated a quarter or window but not a date.
A28: COMPANY-SIGNALLED | B28: Management commentary or investor material implies it; no formal launch commitment.
A29: MEDIA-REPORTED | B29: Credible media or a patent filing. Not a company commitment.
A30: SPECULATIVE | B30: Industry chatter or inference. Model zero volume.
A32: CRITICAL DATA CAVEATS — READ BEFORE USING
A33: 1. Prices are in flux | B33: The PM E-DRIVE e-2W demand incentive (Rs2,500/kWh, cap Rs5,000) LAPSED on 31 July 2026. Ex-showroom prices observed in August 2026 are not comparable to launch prices quoted before that date. Both are captured in separate columns.
A34: 2. Vahan is retail, not wholesale | B34: All volume data is Vahan retail registration. It differs from OEM dispatch. An MHI inquiry specifically probed discrepancies between Ola's reported sales and Vahan. Anchor to Vahan.
A35: 3. Low-speed EVs are invisible | B35: Vehicles under 250W and 25 km/h need no registration and do NOT appear in Vahan. All industry volume figures therefore understate the true market.
A36: 4. Range claims are certification figures | B36: IDC and ARAI numbers are test-cycle results. Real-world range is typically 60-75 per cent of claimed. A separate real-world estimate column is provided and is clearly marked as an estimate.
A37: 5. Private-company financials | B37: River, Matter, Raptee, Simple and Ultraviolette figures are media-reported and largely unaudited.
A38: 6. Aggregator price conflicts | B38: Where sources disagree materially (Suzuki e-Access, TVS iQube variant naming, Bajaj Chetak top speeds), the conflict is flagged in the Analyst notes column rather than silently resolved.
A40: HOW TO KEEP THIS CURRENT
A41: Monthly | B41: Update Volumes_MarketShare with the latest Vahan month. Share and YoY columns recalculate automatically.
A42: On launch | B42: Add a new row to the relevant Current sheet and delete the corresponding Pipeline row. Copy the calculated columns down.
A43: Quarterly | B43: Refresh Company_Profiles financials and BOM_Economics FX (cell C13 on that sheet, shown in blue).
A45: COLOUR CONVENTION | B45: Blue text = an editable input assumption. Yellow fill = a cell you should review and update. Everything else is either sourced data or a formula.

Sheet Scooters_Current
A1: ELECTRIC SCOOTERS — INDIA MODEL MASTER (VARIANT LEVEL)
A2: 58 variants, 26 brands. Prices ex-showroom Delhi. PM E-DRIVE e-2W incentive lapsed 31-Jul-2026 — compare 'price at launch' and 'price latest' with care. Data as of 25-Aug-2026.
A3: ID | B3: OEM / parent | C3: Brand | D3: Model | E3: Variant | F3: Status | G3: Launch (M-Y) | H3: Positioning tier | I3: Price at launch (Rs, ex-shwr) | J3: Price latest (Rs, ex-shwr Delhi) | K3: Price as-of | L3: BaaS / subscription price | M3: Battery (kWh) | N3: Battery type | O3: Chemistry | P3: Cell sourcing | Q3: Motor type / drive | R3: Peak power (kW) | S3: Torque (Nm) | T3: Top speed (km/h) | U3: 0-40 km/h (s) | V3: Claimed range (km) | W3: Range cycle | X3: Real-world range est. (km) | Y3: Charger (W) | Z3: Charge time 0-80% | AA3: Fast charge / network | AB3: Kerb weight (kg) | AC3: Length (mm) | AD3: Width (mm) | AE3: Height (mm) | AF3: Wheelbase (mm) | AG3: Ground clearance (mm) | AH3: Seat height (mm) | AI3: Boot space (litres) | AJ3: Wheels / tyres | AK3: Brakes (F/R) | AL3: ABS / CBS | AM3: Display | AN3: Connectivity | AO3: Ride modes | AP3: Reverse | AQ3: OTA updates | AR3: Other key features | AS3: IP rating | AT3: Vehicle warranty | AU3: Battery warranty | AV3: Platform | AW3: Manufacturing / localisation | AX3: Key differentiator | AY3: Rs per kWh (calc) | AZ3: km per kWh (calc) | BA3: Price band (calc) | BB3: Data confidence | BC3: Source 1 | BD3: Source 2 | BE3: Analyst notes
A4: S001 | B4: Ather Energy (listed: ATHERENERG) | C4: Ather | D4: Rizta | E4: S 2.9 kWh | F4: On sale | G4: Apr-2024 | H4: Mass / family | I4: 109999 | J4: 114999 | K4: Aug-2026 | L4: n/a | M4: 2.9 | N4: Fixed | O4: Li-ion NMC | P4: Imported cells (LG/Samsung SDI class) — pack assembled in-house | Q4: PMSM, belt drive | R4: 4.3 | S4: 22 | T4: 80 | U4: n/a | V4: 123 | W4: IDC | X4: 85 | Y4: 350 | Z4: ~4h30m (Duo charger) | AA4: Ather Grid fast charging (6,100+ points) | AB4: 119 | AC4: 1850 | AD4: 750 | AE4: 1140 | AF4: 1285 | AG4: 150 | AH4: 780 | AI4: 34 | AJ4: 12-inch alloy, tubeless | AK4: Disc front / Drum rear | AL4: CBS | AM4: 7-inch LCD DeepView | AN4: 4G LTE + Bluetooth; AtherStack 7.0 | AO4: 2 | AP4: Yes | AQ4: Yes | AR4: Auto-hold, reverse, Alexa skill, crash/fall alert, pillion backrest optional | AS4: IP67 (pack) / IP65 (dash) | AT4: 3 yr / 30,000 km | AU4: 3 yr std; 5 yr/60,000 km with Pro Pack (8 yr extended optional) | AV4: Rizta / 450 shared architecture | AW4: PLI-certified; high stated localisation | AX4: Family-scooter pivot from performance brand; largest boot + AtherStack software | AY4: =IF(AND(ISNUMBER($J4),ISNUMBER($M4)),$J4/$M4,"n/a") -> 39654.828 | AZ4: =IF(AND(ISNUMBER($V4),ISNUMBER($M4)),$V4/$M4,"n/a") -> 42.413793 | BA4: =IF(NOT(ISNUMBER($J4)),"n/a",IF($J4<70000,"1. <Rs70k",IF($J4<100000,"2. Rs70k-1L",IF($J4<150000,"3. Rs1-1.5L",IF($J4<200000,"4. Rs1.5-2L",IF($J4<300000,"5. Rs2-3L","6. >Rs3L")))))) -> 3. Rs1-1.5L | BB4: HIGH | BC4: atherenergy.com/rizta (Aug-2026) | BD4: 91wheels / ZigWheels specs (Aug-2026) | BE4: ~70% of Ather volume. 3 lakh+ Rizta cumulative units reported by FADA/press Apr-2026.
A5: S002 | B5: Ather Energy | C5: Ather | D5: Rizta | E5: Z 2.9 kWh | F5: On sale | G5: Apr-2024 | H5: Mass / family | I5: n/a | J5: 132000 | K5: Aug-2026 | L5: n/a | M5: 2.9 | N5: Fixed | O5: Li-ion NMC | P5: In-house pack | Q5: PMSM, belt drive | R5: 4.3 | S5: 22 | T5: 80 | U5: n/a | V5: 126 | W5: IDC | X5: 88 | Y5: 350 | Z5: ~4h30m | AA5: Ather Grid | AB5: 125 | AC5: 1850 | AD5: 750 | AE5: 1140 | AF5: 1285 | AG5: 150 | AH5: 780 | AI5: 34 | AJ5: 12-inch alloy, tubeless | AK5: Disc front / Drum rear | AL5: CBS | AM5: 7-inch TFT DeepView touchscreen | AN5: 4G LTE, navigation, voice alerts | AO5: 2 | AP5: Yes | AQ5: Yes | AR5: Magic Twist regen, pillion backrest, Alexa | AS5: IP67 / IP65 | AT5: 3 yr / 30,000 km | AU5: 3 yr std; 5 yr/60,000 km w/ Pro Pack | AV5: Rizta | AW5: PLI-certified | AX5: Touchscreen + connected feature ladder over S | AY5: =IF(AND(ISNUMBER($J5),ISNUMBER($M5)),$J5/$M5,"n/a") -> 45517.241 | AZ5: =IF(AND(ISNUMBER($V5),ISNUMBER($M5)),$V5/$M5,"n/a") -> 43.448276 | BA5: =IF(NOT(ISNUMBER($J5)),"n/a",IF($J5<70000,"1. <Rs70k",IF($J5<100000,"2. Rs70k-1L",IF($J5<150000,"3. Rs1-1.5L",IF($J5<200000,"4. Rs1.5-2L",IF($J5<300000,"5. Rs2-3L","6. >Rs3L")))))) -> 3. Rs1-1.5L | BB5: MEDIUM | BC5: Autocar India variant page (Apr-2026) | BD5: Ather spec sheet | BE5: Autocar lists on-road Delhi Rs1.48L for Z 2.9; ex-showroom estimated.
A6: S003 | B6: Ather Energy | C6: Ather | D6: Rizta | E6: S 3.7 kWh | F6: On sale | G6: 2025 | H6: Mass / family | I6: n/a | J6: 138000 | K6: Aug-2026 | L6: n/a | M6: 3.7 | N6: Fixed | O6: Li-ion NMC | P6: In-house pack | Q6: PMSM, belt drive | R6: 4.3 | S6: 22 | T6: 80 | U6: n/a | V6: 159 | W6: IDC | X6: 110 | Y6: 350 | Z6: ~5h15m | AA6: Ather Grid | AB6: 125 | AC6: 1850 | AD6: 750 | AE6: 1140 | AF6: 1285 | AG6: 150 | AH6: 780 | AI6: 34 | AJ6: 12-inch alloy | AK6: Disc front / Drum rear | AL6: CBS | AM6: 7-inch LCD DeepView | AN6: 4G LTE + Bluetooth | AO6: 2 | AP6: Yes | AQ6: Yes | AR6: Auto-hold, reverse | AS6: IP67 / IP65 | AT6: 3 yr / 30,000 km | AU6: 3 yr std; 5 yr/60,000 km w/ Pro Pack | AV6: Rizta | AW6: PLI-certified | AX6: Long-range family variant | AY6: =IF(AND(ISNUMBER($J6),ISNUMBER($M6)),$J6/$M6,"n/a") -> 37297.297 | AZ6: =IF(AND(ISNUMBER($V6),ISNUMBER($M6)),$V6/$M6,"n/a") -> 42.972973 | BA6: =IF(NOT(ISNUMBER($J6)),"n/a",IF($J6<70000,"1. <Rs70k",IF($J6<100000,"2. Rs70k-1L",IF($J6<150000,"3. Rs1-1.5L",IF($J6<200000,"4. Rs1.5-2L",IF($J6<300000,"5. Rs2-3L","6. >Rs3L")))))) -> 3. Rs1-1.5L | BB6: MEDIUM | BC6: Autocar India (Apr-2026) | BD6: ZigWheels (Aug-2026) | BE6: On-road Delhi Rs1.52L per Autocar.
A7: S004 | B7: Ather Energy | C7: Ather | D7: Rizta | E7: Z 3.7 kWh | F7: On sale | G7: 2025 | H7: Mass / family | I7: n/a | J7: 152000 | K7: Aug-2026 | L7: n/a | M7: 3.7 | N7: Fixed | O7: Li-ion NMC | P7: In-house pack | Q7: PMSM, belt drive | R7: 4.3 | S7: 22 | T7: 80 | U7: n/a | V7: 159 | W7: IDC | X7: 112 | Y7: 350 | Z7: ~5h15m | AA7: Ather Grid | AB7: 125 | AC7: 1850 | AD7: 750 | AE7: 1140 | AF7: 1285 | AG7: 150 | AH7: 780 | AI7: 34 | AJ7: 12-inch alloy | AK7: Disc front / Drum rear | AL7: CBS | AM7: 7-inch TFT touchscreen | AN7: 4G LTE, nav, voice | AO7: 2 | AP7: Yes | AQ7: Yes | AR7: Magic Twist, Alexa, crash alert; Stack Pro pack option | AS7: IP67 / IP65 | AT7: 3 yr / 30,000 km | AU7: 3 yr std; 5 yr/60,000 km w/ Pro Pack (8 yr optional) | AV7: Rizta | AW7: PLI-certified | AX7: Top family variant; Stack Pro software bundle | AY7: =IF(AND(ISNUMBER($J7),ISNUMBER($M7)),$J7/$M7,"n/a") -> 41081.081 | AZ7: =IF(AND(ISNUMBER($V7),ISNUMBER($M7)),$V7/$M7,"n/a") -> 42.972973 | BA7: =IF(NOT(ISNUMBER($J7)),"n/a",IF($J7<70000,"1. <Rs70k",IF($J7<100000,"2. Rs70k-1L",IF($J7<150000,"3. Rs1-1.5L",IF($J7<200000,"4. Rs1.5-2L",IF($J7<300000,"5. Rs2-3L","6. >Rs3L")))))) -> 4. Rs1.5-2L | BB7: MEDIUM | BC7: Autocar India (Apr-2026) | BD7: ZigWheels lists Z Stack Pro at Rs1.80-1.84L | BE7: Software subscription (Pro/Stack Pro) is a recurring-revenue lever — watch attach rate.
A8: S005 | B8: Ather Energy | C8: Ather | D8: 450S | E8: 2.9 kWh | F8: On sale | G8: 2023 | H8: Premium performance | I8: n/a | J8: 130311 | K8: Aug-2026 | L8: n/a | M8: 2.9 | N8: Fixed | O8: Li-ion NMC | P8: In-house pack | Q8: PMSM, belt drive | R8: 5.4 | S8: 22 | T8: 90 | U8: 3.3 | V8: 115 | W8: IDC | X8: 80 | Y8: 350 | Z8: ~5h30m | AA8: Ather Grid | AB8: 111 | AC8: n/a | AD8: n/a | AE8: n/a | AF8: 1278 | AG8: 165 | AH8: 780 | AI8: 22 | AJ8: 12-inch alloy | AK8: Disc front / Disc rear | AL8: CBS | AM8: 7-inch LCD | AN8: Bluetooth + 4G | AO8: 3 | AP8: Yes | AQ8: Yes | AR8: Regen, auto-hold | AS8: IP67 | AT8: 3 yr / 30,000 km | AU8: 3 yr std | AV8: 450 platform | AW8: PLI-certified | AX8: Entry into the 450 performance line | AY8: =IF(AND(ISNUMBER($J8),ISNUMBER($M8)),$J8/$M8,"n/a") -> 44934.828 | AZ8: =IF(AND(ISNUMBER($V8),ISNUMBER($M8)),$V8/$M8,"n/a") -> 39.655172 | BA8: =IF(NOT(ISNUMBER($J8)),"n/a",IF($J8<70000,"1. <Rs70k",IF($J8<100000,"2. Rs70k-1L",IF($J8<150000,"3. Rs1-1.5L",IF($J8<200000,"4. Rs1.5-2L",IF($J8<300000,"5. Rs2-3L","6. >Rs3L")))))) -> 3. Rs1-1.5L | BB8: MEDIUM | BC8: BikeWale price list (Aug-2026) | BD8: Ather spec sheet | BE8: n/a
A9: S006 | B9: Ather Energy | C9: Ather | D9: 450X | E9: 2.9 / 3.7 kWh | F9: On sale | G9: 2020 (gen updates to 2025) | H9: Premium performance | I9: n/a | J9: 153902 | K9: Aug-2026 | L9: n/a | M9: 3.7 | N9: Fixed | O9: Li-ion NMC | P9: In-house pack | Q9: PMSM, belt drive | R9: 6.4 | S9: 26 | T9: 90 | U9: 2.9 | V9: 161 | W9: IDC | X9: 115 | Y9: 350 | Z9: ~4h30m (fast charge to 80%) | AA9: Ather Grid DC fast charge | AB9: 111 | AC9: n/a | AD9: n/a | AE9: n/a | AF9: 1278 | AG9: 165 | AH9: 780 | AI9: 22 | AJ9: 12-inch alloy | AK9: Disc / Disc | AL9: CBS | AM9: 7-inch TFT touchscreen | AN9: 4G, nav, AtherStack | AO9: 4 | AP9: Yes | AQ9: Yes | AR9: Warp mode, traction control, Magic Twist, Alexa | AS9: IP67 | AT9: 3 yr / 30,000 km | AU9: 3 yr std; extended options | AV9: 450 platform | AW9: PLI-certified | AX9: Original premium-performance halo product; deepest software stack in segment | AY9: =IF(AND(ISNUMBER($J9),ISNUMBER($M9)),$J9/$M9,"n/a") -> 41595.135 | AZ9: =IF(AND(ISNUMBER($V9),ISNUMBER($M9)),$V9/$M9,"n/a") -> 43.513514 | BA9: =IF(NOT(ISNUMBER($J9)),"n/a",IF($J9<70000,"1. <Rs70k",IF($J9<100000,"2. Rs70k-1L",IF($J9<150000,"3. Rs1-1.5L",IF($J9<200000,"4. Rs1.5-2L",IF($J9<300000,"5. Rs2-3L","6. >Rs3L")))))) -> 4. Rs1.5-2L | BB9: MEDIUM | BC9: BikeWale (Aug-2026) | BD9: ZigWheels (Aug-2026) | BE9: Cited by ZigWheels as one of India's 3 most popular e-scooters.
A10: S007 | B10: Ather Energy | C10: Ather | D10: 450 Apex | E10: 3.7 kWh | F10: On sale | G10: Jan-2024 | H10: Halo performance | I10: 189000 | J10: 195000 | K10: Aug-2026 | L10: n/a | M10: 3.7 | N10: Fixed | O10: Li-ion NMC | P10: In-house pack | Q10: PMSM, belt drive | R10: 7 | S10: 26 | T10: 100 | U10: 2.7 | V10: 157 | W10: IDC | X10: 110 | Y10: 350 | Z10: ~4h30m | AA10: Ather Grid | AB10: 112 | AC10: n/a | AD10: n/a | AE10: n/a | AF10: 1278 | AG10: 165 | AH10: 780 | AI10: 22 | AJ10: 12-inch alloy | AK10: Disc / Disc | AL10: CBS | AM10: 7-inch TFT touchscreen | AN10: 4G, nav, full AtherStack | AO10: 4 | AP10: Yes | AQ10: Yes | AR10: Warp+ mode, magnesium parts, translucent bodywork | AS10: IP67 | AT10: 3 yr / 30,000 km | AU10: 3 yr std | AV10: 450 platform | AW10: PLI-certified | AX10: Halo / brand-building variant; limited volume | AY10: =IF(AND(ISNUMBER($J10),ISNUMBER($M10)),$J10/$M10,"n/a") -> 52702.703 | AZ10: =IF(AND(ISNUMBER($V10),ISNUMBER($M10)),$V10/$M10,"n/a") -> 42.432432 | BA10: =IF(NOT(ISNUMBER($J10)),"n/a",IF($J10<70000,"1. <Rs70k",IF($J10<100000,"2. Rs70k-1L",IF($J10<150000,"3. Rs1-1.5L",IF($J10<200000,"4. Rs1.5-2L",IF($J10<300000,"5. Rs2-3L","6. >Rs3L")))))) -> 4. Rs1.5-2L | BB10: MEDIUM | BC10: Ather press release (Jan-2024) | BD10: Autocar India | BE10: Low-volume halo; matters for brand pricing power, not for volume forecasting.
A11: S008 | B11: TVS Motor Company (listed: TVSMOTOR) | C11: TVS | D11: iQube | E11: 2.2 kWh | F11: On sale | G11: 2022 (variant) | H11: Entry mass | I11: 94999 | J11: 119236 | K11: Aug-2026 | L11: BaaS option from Mar-2026 | M11: 2.2 | N11: Fixed | O11: Li-ion | P11: Imported cells; pack assembled in-house | Q11: BLDC hub | R11: 4.4 | S11: 33 | T11: 75 | U11: 4.2 | V11: 94 | W11: IDC | X11: 70 | Y11: 950 | Z11: 2h45m-2h50m (0-80%) | AA11: No DC fast charge | AB11: 110 | AC11: 1805 | AD11: 645 | AE11: 1140 | AF11: 1301 | AG11: 157 | AH11: 770 | AI11: 30 | AJ11: 12-inch alloy | AK11: Drum / Drum | AL11: CBS | AM11: 5-inch TFT | AN11: Bluetooth, SmartXonnect, OTA, geofencing | AO11: 2 | AP11: Yes | AQ11: Yes | AR11: Regen braking, Q-Park reverse, 118 connected features (higher trims) | AS11: IP67 (AIS-156 certified) | AT11: 3 yr / 50,000 km | AU11: 3 yr (2 yr extended optional) | AV11: iQube platform | AW11: High localisation; PLI-linked | AX11: Cheapest route into India's largest 2W service network (TVS) | AY11: =IF(AND(ISNUMBER($J11),ISNUMBER($M11)),$J11/$M11,"n/a") -> 54198.182 | AZ11: =IF(AND(ISNUMBER($V11),ISNUMBER($M11)),$V11/$M11,"n/a") -> 42.727273 | BA11: =IF(NOT(ISNUMBER($J11)),"n/a",IF($J11<70000,"1. <Rs70k",IF($J11<100000,"2. Rs70k-1L",IF($J11<150000,"3. Rs1-1.5L",IF($J11<200000,"4. Rs1.5-2L",IF($J11<300000,"5. Rs2-3L","6. >Rs3L")))))) -> 3. Rs1-1.5L | BB11: MEDIUM | BC11: BikeWale price list (Aug-2026) | BD11: tvsmotor.com spec pages | BE11: TVS = FY26 e-2W market leader, 341,513 units. Sources differ on 2.2 vs 2.3 kWh nameplate.
A12: S009 | B12: TVS Motor Company | C12: TVS | D12: iQube | E12: 3.1 kWh | F12: On sale | G12: 2025 | H12: Mass | I12: n/a | J12: 138495 | K12: Aug-2026 | L12: n/a | M12: 3.1 | N12: Fixed | O12: Li-ion | P12: n/a | Q12: BLDC hub | R12: 4.4 | S12: 33 | T12: 82 | U12: n/a | V12: 123 | W12: IDC | X12: 90 | Y12: 950 | Z12: ~4h00m (0-80%) | AA12: No | AB12: 118 | AC12: 1805 | AD12: 645 | AE12: 1140 | AF12: 1301 | AG12: 157 | AH12: 770 | AI12: 32 | AJ12: 12-inch alloy | AK12: Disc / Drum | AL12: CBS | AM12: 5-inch TFT | AN12: SmartXonnect, OTA, Alexa skill | AO12: 2 | AP12: Yes | AQ12: Yes | AR12: Q-Park reverse, crash/fall/anti-theft alert | AS12: IP67 / AIS-156 | AT12: 3 yr / 50,000 km | AU12: 3 yr | AV12: iQube | AW12: High localisation | AX12: Volume sweet spot of the iQube ladder | AY12: =IF(AND(ISNUMBER($J12),ISNUMBER($M12)),$J12/$M12,"n/a") -> 44675.806 | AZ12: =IF(AND(ISNUMBER($V12),ISNUMBER($M12)),$V12/$M12,"n/a") -> 39.677419 | BA12: =IF(NOT(ISNUMBER($J12)),"n/a",IF($J12<70000,"1. <Rs70k",IF($J12<100000,"2. Rs70k-1L",IF($J12<150000,"3. Rs1-1.5L",IF($J12<200000,"4. Rs1.5-2L",IF($J12<300000,"5. Rs2-3L","6. >Rs3L")))))) -> 3. Rs1-1.5L | BB12: MEDIUM | BC12: BikeWale (Aug-2026) | BD12: 91wheels (Aug-2026) | BE12: n/a
A13: S010 | B13: TVS Motor Company | C13: TVS | D13: iQube | E13: 3.5 kWh | F13: On sale | G13: 2024 | H13: Mass | I13: n/a | J13: 145640 | K13: Aug-2026 | L13: n/a | M13: 3.5 | N13: Fixed | O13: Li-ion | P13: n/a | Q13: BLDC hub | R13: 4.4 | S13: 33 | T13: 78 | U13: n/a | V13: 145 | W13: IDC | X13: 105 | Y13: 950 | Z13: ~4h30m-4h40m (0-80%) | AA13: No | AB13: 118 | AC13: 1805 | AD13: 645 | AE13: 1140 | AF13: 1301 | AG13: 157 | AH13: 770 | AI13: 32 | AJ13: 12-inch alloy | AK13: Disc / Drum | AL13: CBS | AM13: 5-inch TFT | AN13: SmartXonnect, 118 connected features, Alexa | AO13: 2 | AP13: Yes | AQ13: Yes | AR13: Fits 2 helmets, USB port, crash/fall alert | AS13: IP67 / AIS-156 | AT13: 3 yr / 50,000 km | AU13: 3 yr | AV13: iQube | AW13: High localisation | AX13: Long-range mass variant | AY13: =IF(AND(ISNUMBER($J13),ISNUMBER($M13)),$J13/$M13,"n/a") -> 41611.429 | AZ13: =IF(AND(ISNUMBER($V13),ISNUMBER($M13)),$V13/$M13,"n/a") -> 41.428571 | BA13: =IF(NOT(ISNUMBER($J13)),"n/a",IF($J13<70000,"1. <Rs70k",IF($J13<100000,"2. Rs70k-1L",IF($J13<150000,"3. Rs1-1.5L",IF($J13<200000,"4. Rs1.5-2L",IF($J13<300000,"5. Rs2-3L","6. >Rs3L")))))) -> 3. Rs1-1.5L | BB13: HIGH | BC13: tvsmotor.com iQube 3.5 kWh page | BD13: Autocar India (Aug-2026) | BE13: Autocar reader Q&A flags no fast-charge support as a purchase objection.
A14: S011 | B14: TVS Motor Company | C14: TVS | D14: iQube | E14: MillionR Special Edition | F14: On sale | G14: 2025 | H14: Mass | I14: n/a | J14: 140138 | K14: Aug-2026 | L14: n/a | M14: 3.1 | N14: Fixed | O14: Li-ion | P14: n/a | Q14: BLDC hub | R14: 4.4 | S14: 33 | T14: 82 | U14: n/a | V14: 123 | W14: IDC | X14: 90 | Y14: 950 | Z14: ~4h | AA14: No | AB14: 118 | AC14: n/a | AD14: n/a | AE14: n/a | AF14: 1301 | AG14: 157 | AH14: 770 | AI14: 32 | AJ14: 12-inch alloy | AK14: Disc / Drum | AL14: CBS | AM14: 5-inch TFT | AN14: SmartXonnect | AO14: 2 | AP14: Yes | AQ14: Yes | AR14: Commemorative 1-million-EV edition trim | AS14: IP67 | AT14: 3 yr / 50,000 km | AU14: 3 yr | AV14: iQube | AW14: High localisation | AX14: Milestone edition — marketing-led differentiation | AY14: =IF(AND(ISNUMBER($J14),ISNUMBER($M14)),$J14/$M14,"n/a") -> 45205.806 | AZ14: =IF(AND(ISNUMBER($V14),ISNUMBER($M14)),$V14/$M14,"n/a") -> 39.677419 | BA14: =IF(NOT(ISNUMBER($J14)),"n/a",IF($J14<70000,"1. <Rs70k",IF($J14<100000,"2. Rs70k-1L",IF($J14<150000,"3. Rs1-1.5L",IF($J14<200000,"4. Rs1.5-2L",IF($J14<300000,"5. Rs2-3L","6. >Rs3L")))))) -> 3. Rs1-1.5L | BB14: MEDIUM | BC14: BikeWale price list (Aug-2026) | BD14: n/a | BE14: n/a
A15: S012 | B15: TVS Motor Company | C15: TVS | D15: iQube | E15: S 4.7 kWh | F15: On sale | G15: 2025 | H15: Upper-mass | I15: n/a | J15: 165353 | K15: Aug-2026 | L15: n/a | M15: 4.7 | N15: Fixed | O15: Li-ion | P15: n/a | Q15: BLDC hub | R15: 4.4 | S15: 33 | T15: 82 | U15: n/a | V15: n/a | W15: IDC | X15: n/a | Y15: 950 | Z15: ~3h00m (0-80%) | AA15: No | AB15: n/a | AC15: n/a | AD15: n/a | AE15: n/a | AF15: 1301 | AG15: 157 | AH15: 770 | AI15: 32 | AJ15: 12-inch alloy | AK15: Disc / Drum | AL15: CBS | AM15: 12.7 cm (5-inch) TFT | AN15: SmartXonnect, OTA | AO15: 3 | AP15: Yes | AQ15: Yes | AR15: Q-Park, regen | AS15: IP67 | AT15: 3 yr / 50,000 km | AU15: 3 yr | AV15: iQube | AW15: High localisation | AX15: Bridges mass iQube to flagship ST | AY15: =IF(AND(ISNUMBER($J15),ISNUMBER($M15)),$J15/$M15,"n/a") -> 35181.489 | AZ15: =IF(AND(ISNUMBER($V15),ISNUMBER($M15)),$V15/$M15,"n/a") -> n/a | BA15: =IF(NOT(ISNUMBER($J15)),"n/a",IF($J15<70000,"1. <Rs70k",IF($J15<100000,"2. Rs70k-1L",IF($J15<150000,"3. Rs1-1.5L",IF($J15<200000,"4. Rs1.5-2L",IF($J15<300000,"5. Rs2-3L","6. >Rs3L")))))) -> 4. Rs1.5-2L | BB15: MEDIUM | BC15: BikeWale (Aug-2026) | BD15: 91wheels (Aug-2026) | BE15: Claimed range not consistently disclosed across sources.
A16: S013 | B16: TVS Motor Company | C16: TVS | D16: iQube | E16: ST 5.3 kWh | F16: On sale | G16: 2024 | H16: Flagship | I16: n/a | J16: 175582 | K16: Aug-2026 | L16: n/a | M16: 5.3 | N16: Fixed | O16: Li-ion | P16: n/a | Q16: BLDC hub | R16: 4.4 | S16: 33 | T16: 82 | U16: 4.3 | V16: 175 | W16: IDC (older 212 km claim withdrawn) | X16: 130 | Y16: 950 | Z16: 4h18m (0-80%) | AA16: No DC fast charge | AB16: n/a | AC16: n/a | AD16: n/a | AE16: n/a | AF16: 1301 | AG16: 157 | AH16: 770 | AI16: 32 | AJ16: 12-inch alloy | AK16: Disc / Drum | AL16: CBS | AM16: 17.78 cm (7-inch) touchscreen | AN16: SmartXonnect, nav, Alexa, OTA | AO16: 3 | AP16: Yes | AQ16: Yes | AR16: Largest pack in TVS range; TPMS on some trims | AS16: IP67 / AIS-156 | AT16: 3 yr / 50,000 km | AU16: 3 yr | AV16: iQube | AW16: High localisation | AX16: TVS's long-range flagship; competes with Ather 450X / Ola S1 Pro | AY16: =IF(AND(ISNUMBER($J16),ISNUMBER($M16)),$J16/$M16,"n/a") -> 33128.679 | AZ16: =IF(AND(ISNUMBER($V16),ISNUMBER($M16)),$V16/$M16,"n/a") -> 33.018868 | BA16: =IF(NOT(ISNUMBER($J16)),"n/a",IF($J16<70000,"1. <Rs70k",IF($J16<100000,"2. Rs70k-1L",IF($J16<150000,"3. Rs1-1.5L",IF($J16<200000,"4. Rs1.5-2L",IF($J16<300000,"5. Rs2-3L","6. >Rs3L")))))) -> 4. Rs1.5-2L | BB16: MEDIUM | BC16: 91wheels (Aug-2026) | BD16: BikeWale (Aug-2026) | BE16: Range claim revised: 212 km (launch marketing) vs ~175 km IDC now cited. Treat 175 km as the working figure.
A17: S014 | B17: TVS Motor Company | C17: TVS | D17: Orbiter | E17: V1 / V2 | F17: On sale | G17: Mar-2026 | H17: Entry urban | I17: 99900 | J17: 102459 | K17: Aug-2026 | L17: From Rs49,999 on BaaS | M17: 3.1 | N17: Fixed | O17: Li-ion | P17: n/a | Q17: BLDC hub | R17: 2.5 | S17: n/a | T17: 68 | U17: n/a | V17: 158 | W17: IDC | X17: 110 | Y17: n/a | Z17: n/a | AA17: No | AB17: n/a | AC17: n/a | AD17: n/a | AE17: n/a | AF17: n/a | AG17: n/a | AH17: n/a | AI17: 33 | AJ17: 12-inch | AK17: Drum / Drum | AL17: CBS | AM17: LCD | AN17: Bluetooth, basic connectivity | AO17: 2 | AP17: Yes | AQ17: n/a | AR17: 33L storage; BaaS-led pricing to undercut ICE | AS17: IP67 | AT17: 3 yr | AU17: 3 yr | AV17: New entry platform | AW17: High localisation | AX17: TVS's sub-Rs1L volume weapon; BaaS pricing attacks the ICE price gap directly | AY17: =IF(AND(ISNUMBER($J17),ISNUMBER($M17)),$J17/$M17,"n/a") -> 33051.29 | AZ17: =IF(AND(ISNUMBER($V17),ISNUMBER($M17)),$V17/$M17,"n/a") -> 50.967742 | BA17: =IF(NOT(ISNUMBER($J17)),"n/a",IF($J17<70000,"1. <Rs70k",IF($J17<100000,"2. Rs70k-1L",IF($J17<150000,"3. Rs1-1.5L",IF($J17<200000,"4. Rs1.5-2L",IF($J17<300000,"5. Rs2-3L","6. >Rs3L")))))) -> 3. Rs1-1.5L | BB17: MEDIUM | BC17: BikeWale (Aug-2026) | BD17: ZigWheels Orbiter V1 vs V2 (Mar-2026) | BE17: Key competitive datapoint: first credible sub-Rs50k effective entry price from a top-4 OEM.
A18: S015 | B18: TVS Motor Company | C18: TVS | D18: X | E18: 4.4 kWh | F18: On sale | G18: 2023 | H18: Premium crossover | I18: 249000 | J18: n/a | K18: Aug-2026 | L18: n/a | M18: 4.4 | N18: Fixed | O18: Li-ion | P18: n/a | Q18: PMSM | R18: 11 | S18: n/a | T18: 105 | U18: 2.6 | V18: 140 | W18: IDC | X18: 100 | Y18: n/a | Z18: ~3h (0-80%) | AA18: Yes | AB18: n/a | AC18: n/a | AD18: n/a | AE18: n/a | AF18: n/a | AG18: n/a | AH18: n/a | AI18: n/a | AJ18: 14/12-inch | AK18: Disc / Disc | AL18: Dual-channel | AM18: 10.2-inch TFT touchscreen | AN18: 4G, nav, OTA | AO18: 4 | AP18: Yes | AQ18: Yes | AR18: Largest display in segment; premium crossover positioning | AS18: IP67 | AT18: 3 yr | AU18: 3 yr | AV18: TVS X platform | AW18: High localisation | AX18: TVS's differentiated premium niche play — low volume, high ASP | AY18: =IF(AND(ISNUMBER($J18),ISNUMBER($M18)),$J18/$M18,"n/a") -> n/a | AZ18: =IF(AND(ISNUMBER($V18),ISNUMBER($M18)),$V18/$M18,"n/a") -> 31.818182 | BA18: =IF(NOT(ISNUMBER($J18)),"n/a",IF($J18<70000,"1. <Rs70k",IF($J18<100000,"2. Rs70k-1L",IF($J18<150000,"3. Rs1-1.5L",IF($J18<200000,"4. Rs1.5-2L",IF($J18<300000,"5. Rs2-3L","6. >Rs3L")))))) -> n/a | BB18: MEDIUM | BC18: TVS press material / Autocar India | BD18: n/a | BE18: Niche-thesis exhibit: differentiated premium positioning has NOT scaled volumes.
A19: S016 | B19: Bajaj Auto (listed: BAJAJ-AUTO) | C19: Bajaj | D19: Chetak | E19: 2501 | F19: On sale | G19: Jan-2026 | H19: Entry | I19: 87100 | J19: 99000 | K19: Aug-2026 | L19: n/a | M19: 2.5 | N19: Fixed | O19: Li-ion | P19: n/a | Q19: PMSM | R19: n/a | S19: n/a | T19: 55 | U19: n/a | V19: 113 | W19: IDC | X19: 80 | Y19: 750 | Z19: n/a | AA19: No | AB19: n/a | AC19: n/a | AD19: n/a | AE19: n/a | AF19: n/a | AG19: n/a | AH19: n/a | AI19: n/a | AJ19: 12-inch | AK19: Drum / Drum | AL19: CBS | AM19: Negative LCD | AN19: Bluetooth (TecPac optional) | AO19: 2 | AP19: n/a | AQ19: n/a | AR19: All-metal body; IP67; TecPac add-on from Rs4,000 + data pack | AS19: IP67 | AT19: 3 yr | AU19: 5 yr / 70,000 km (35-series claim) | AV19: Chetak 25/30 series | AW19: High localisation | AX19: Cheapest entry into an all-metal, dealer-backed Chetak | AY19: =IF(AND(ISNUMBER($J19),ISNUMBER($M19)),$J19/$M19,"n/a") -> 39600 | AZ19: =IF(AND(ISNUMBER($V19),ISNUMBER($M19)),$V19/$M19,"n/a") -> 45.2 | BA19: =IF(NOT(ISNUMBER($J19)),"n/a",IF($J19<70000,"1. <Rs70k",IF($J19<100000,"2. Rs70k-1L",IF($J19<150000,"3. Rs1-1.5L",IF($J19<200000,"4. Rs1.5-2L",IF($J19<300000,"5. Rs2-3L","6. >Rs3L")))))) -> 2. Rs70k-1L | BB19: MEDIUM | BC19: carhp.in variant explainer (Sep-2025) | BD19: Bajaj Chetak.com | BE19: Price flagged MEDIUM: PM E-DRIVE incentive lapsed 31-Jul-2026, prices in flux.
A20: S017 | B20: Bajaj Auto | C20: Bajaj | D20: Chetak | E20: 3001 | F20: On sale | G20: 2025 | H20: Entry-mid | I20: 99900 | J20: 109000 | K20: Aug-2026 | L20: n/a | M20: 3 | N20: Fixed | O20: Li-ion | P20: n/a | Q20: PMSM | R20: 3.1 | S20: n/a | T20: 63 | U20: n/a | V20: 127 | W20: IDC | X20: 90 | Y20: 750 | Z20: 3h50m (0-80%) | AA20: No | AB20: n/a | AC20: n/a | AD20: n/a | AE20: n/a | AF20: n/a | AG20: n/a | AH20: n/a | AI20: 35 | AJ20: 12-inch | AK20: Drum / Drum | AL20: CBS | AM20: Negative LCD | AN20: Bluetooth phone connectivity | AO20: 2 | AP20: n/a | AQ20: n/a | AR20: All-metal body, best-in-class 35L boot | AS20: IP67 | AT20: 3 yr | AU20: 5 yr / 70,000 km | AV20: Chetak 30 series | AW20: High localisation | AX20: Metal-body durability pitch at the Rs1L price point | AY20: =IF(AND(ISNUMBER($J20),ISNUMBER($M20)),$J20/$M20,"n/a") -> 36333.333 | AZ20: =IF(AND(ISNUMBER($V20),ISNUMBER($M20)),$V20/$M20,"n/a") -> 42.333333 | BA20: =IF(NOT(ISNUMBER($J20)),"n/a",IF($J20<70000,"1. <Rs70k",IF($J20<100000,"2. Rs70k-1L",IF($J20<150000,"3. Rs1-1.5L",IF($J20<200000,"4. Rs1.5-2L",IF($J20<300000,"5. Rs2-3L","6. >Rs3L")))))) -> 3. Rs1-1.5L | BB20: HIGH | BC20: Autocar India variant explainer | BD20: chetak.com | BE20: n/a
A21: S018 | B21: Bajaj Auto | C21: Bajaj | D21: Chetak | E21: 3503 | F21: On sale | G21: 2025 | H21: Mass | I21: 102000 | J21: 109000 | K21: Aug-2026 | L21: n/a | M21: 3.5 | N21: Fixed | O21: Li-ion | P21: n/a | Q21: PMSM | R21: 4 | S21: n/a | T21: 63 | U21: n/a | V21: 151 | W21: IDC | X21: 105 | Y21: 900 | Z21: 3h25m (0-80%) | AA21: No | AB21: n/a | AC21: n/a | AD21: n/a | AE21: n/a | AF21: n/a | AG21: n/a | AH21: n/a | AI21: 35 | AJ21: 12-inch | AK21: Drum / Drum | AL21: CBS | AM21: Negative LCD | AN21: Bluetooth, handlebar music control, call/SMS alerts | AO21: 2 | AP21: n/a | AQ21: n/a | AR21: Hill-hold, all-metal body, 35L boot | AS21: IP67 | AT21: 3 yr | AU21: 5 yr / 70,000 km | AV21: Chetak 35 series | AW21: High localisation | AX21: Best range-per-rupee in the Chetak ladder | AY21: =IF(AND(ISNUMBER($J21),ISNUMBER($M21)),$J21/$M21,"n/a") -> 31142.857 | AZ21: =IF(AND(ISNUMBER($V21),ISNUMBER($M21)),$V21/$M21,"n/a") -> 43.142857 | BA21: =IF(NOT(ISNUMBER($J21)),"n/a",IF($J21<70000,"1. <Rs70k",IF($J21<100000,"2. Rs70k-1L",IF($J21<150000,"3. Rs1-1.5L",IF($J21<200000,"4. Rs1.5-2L",IF($J21<300000,"5. Rs2-3L","6. >Rs3L")))))) -> 3. Rs1-1.5L | BB21: HIGH | BC21: chetak.com/series-35/chetak-c3503 | BD21: Autocar India (Jul-2026) | BE21: Top speed cited variously as 63 and 70 km/h — Bajaj site says 70 km/h.
A22: S019 | B22: Bajaj Auto | C22: Bajaj | D22: Chetak | E22: 3502 | F22: On sale | G22: 2025 | H22: Mass | I22: n/a | J22: 130306 | K22: Aug-2026 | L22: n/a | M22: 3.5 | N22: Fixed | O22: Li-ion | P22: n/a | Q22: PMSM | R22: 4 | S22: n/a | T22: 73 | U22: n/a | V22: 153 | W22: IDC | X22: 107 | Y22: 900 | Z22: 3h25m (0-80%) | AA22: No | AB22: n/a | AC22: n/a | AD22: n/a | AE22: n/a | AF22: n/a | AG22: n/a | AH22: n/a | AI22: 35 | AJ22: 12-inch | AK22: Disc / Drum | AL22: CBS | AM22: TFT with app connectivity | AN22: Bluetooth + TecPac (overspeed alert, guide-me-home, immobiliser, music) | AO22: 3 | AP22: n/a | AQ22: n/a | AR22: Front disc; TFT dash | AS22: IP67 | AT22: 3 yr | AU22: 5 yr / 70,000 km | AV22: Chetak 35 series | AW22: High localisation | AX22: Feature step-up variant | AY22: =IF(AND(ISNUMBER($J22),ISNUMBER($M22)),$J22/$M22,"n/a") -> 37230.286 | AZ22: =IF(AND(ISNUMBER($V22),ISNUMBER($M22)),$V22/$M22,"n/a") -> 43.714286 | BA22: =IF(NOT(ISNUMBER($J22)),"n/a",IF($J22<70000,"1. <Rs70k",IF($J22<100000,"2. Rs70k-1L",IF($J22<150000,"3. Rs1-1.5L",IF($J22<200000,"4. Rs1.5-2L",IF($J22<300000,"5. Rs2-3L","6. >Rs3L")))))) -> 3. Rs1-1.5L | BB22: HIGH | BC22: chetak.com/series-35/chetak-c3502 | BD22: Autocar India | BE22: Chetak.com quotes 80 km/h top speed for 3502 vs Autocar's 73 km/h — verify.
A23: S020 | B23: Bajaj Auto | C23: Bajaj | D23: Chetak | E23: 3501 | F23: On sale | G23: 2025 | H23: Upper-mass flagship | I23: 122500 | J23: 134000 | K23: Aug-2026 | L23: n/a | M23: 3.5 | N23: Fixed | O23: Li-ion | P23: n/a | Q23: PMSM | R23: 4 | S23: n/a | T23: 73 | U23: n/a | V23: 153 | W23: IDC | X23: 107 | Y23: 950 | Z23: 3h00m (0-80%) | AA23: No | AB23: n/a | AC23: n/a | AD23: n/a | AE23: n/a | AF23: n/a | AG23: n/a | AH23: n/a | AI23: 35 | AJ23: 12-inch | AK23: Disc / Drum | AL23: CBS | AM23: TFT touchscreen | AN23: Bluetooth, TecPac, sequential indicators | AO23: 3 | AP23: n/a | AQ23: n/a | AR23: Keyless ignition, sequential indicators, fastest-charging Chetak | AS23: IP67 | AT23: 3 yr | AU23: 5 yr / 70,000 km | AV23: Chetak 35 series | AW23: High localisation | AX23: Chetak flagship; all-metal body remains the brand's structural differentiator | AY23: =IF(AND(ISNUMBER($J23),ISNUMBER($M23)),$J23/$M23,"n/a") -> 38285.714 | AZ23: =IF(AND(ISNUMBER($V23),ISNUMBER($M23)),$V23/$M23,"n/a") -> 43.714286 | BA23: =IF(NOT(ISNUMBER($J23)),"n/a",IF($J23<70000,"1. <Rs70k",IF($J23<100000,"2. Rs70k-1L",IF($J23<150000,"3. Rs1-1.5L",IF($J23<200000,"4. Rs1.5-2L",IF($J23<300000,"5. Rs2-3L","6. >Rs3L")))))) -> 3. Rs1-1.5L | BB23: HIGH | BC23: Autocar India variant explainer | BD23: chetak.com | BE23: Bajaj FY26: 289,349 units, #2 in India.
A24: S021 | B24: Ola Electric (listed: OLAELEC) | C24: Ola Electric | D24: S1 X | E24: 2 kWh Gen 3 | F24: On sale | G24: 2025 | H24: Entry | I24: 79999 | J24: 84999 | K24: Aug-2026 | L24: n/a | M24: 2 | N24: Fixed | O24: Li-ion (4680 cylindrical on select trims) | P24: Ola in-house 4680 Bharat Cell (Krishnagiri) + imported | Q24: Mid-drive IPM | R24: n/a | S24: n/a | T24: n/a | U24: n/a | V24: n/a | W24: IDC | X24: n/a | Y24: n/a | Z24: n/a | AA24: Ola Hypercharger network | AB24: n/a | AC24: n/a | AD24: n/a | AE24: n/a | AF24: n/a | AG24: n/a | AH24: n/a | AI24: 34 | AJ24: 12-inch | AK24: Drum / Drum | AL24: CBS | AM24: LCD | AN24: MoveOS, Bluetooth | AO24: 3 | AP24: Yes | AQ24: Yes | AR24: MoveOS OTA platform | AS24: IP67 | AT24: 3 yr | AU24: 3 yr | AV24: Gen 3 | AW24: In-house cell + motor (ferrite, rare-earth-free on newer trims) | AX24: Lowest sticker price among the top-5 OEMs | AY24: =IF(AND(ISNUMBER($J24),ISNUMBER($M24)),$J24/$M24,"n/a") -> 42499.5 | AZ24: =IF(AND(ISNUMBER($V24),ISNUMBER($M24)),$V24/$M24,"n/a") -> n/a | BA24: =IF(NOT(ISNUMBER($J24)),"n/a",IF($J24<70000,"1. <Rs70k",IF($J24<100000,"2. Rs70k-1L",IF($J24<150000,"3. Rs1-1.5L",IF($J24<200000,"4. Rs1.5-2L",IF($J24<300000,"5. Rs2-3L","6. >Rs3L")))))) -> 2. Rs70k-1L | BB24: MEDIUM | BC24: Ola Electric price list / BikeDekho (Aug-2026) | BD24: n/a | BE24: Ola FY26 volumes fell 52% to 164,295. Treat all Ola pricing as promotional and volatile.
A25: S022 | B25: Ola Electric | C25: Ola Electric | D25: S1 X | E25: 3 kWh Gen 3 | F25: On sale | G25: 2025 | H25: Entry-mid | I25: n/a | J25: 99999 | K25: Aug-2026 | L25: n/a | M25: 3 | N25: Fixed | O25: Li-ion | P25: n/a | Q25: Mid-drive IPM | R25: n/a | S25: n/a | T25: n/a | U25: n/a | V25: n/a | W25: IDC | X25: n/a | Y25: n/a | Z25: n/a | AA25: Ola Hypercharger | AB25: n/a | AC25: n/a | AD25: n/a | AE25: n/a | AF25: n/a | AG25: n/a | AH25: n/a | AI25: 34 | AJ25: 12-inch | AK25: Drum / Drum | AL25: CBS | AM25: LCD | AN25: MoveOS | AO25: 3 | AP25: Yes | AQ25: Yes | AR25: n/a | AS25: IP67 | AT25: 3 yr | AU25: 3 yr | AV25: Gen 3 | AW25: n/a | AX25: Volume entry variant | AY25: =IF(AND(ISNUMBER($J25),ISNUMBER($M25)),$J25/$M25,"n/a") -> 33333 | AZ25: =IF(AND(ISNUMBER($V25),ISNUMBER($M25)),$V25/$M25,"n/a") -> n/a | BA25: =IF(NOT(ISNUMBER($J25)),"n/a",IF($J25<70000,"1. <Rs70k",IF($J25<100000,"2. Rs70k-1L",IF($J25<150000,"3. Rs1-1.5L",IF($J25<200000,"4. Rs1.5-2L",IF($J25<300000,"5. Rs2-3L","6. >Rs3L")))))) -> 2. Rs70k-1L | BB25: LOW | BC25: BikeDekho / aggregator listings (Aug-2026) | BD25: n/a | BE25: Spec disclosure inconsistent across sources.
A26: S023 | B26: Ola Electric | C26: Ola Electric | D26: S1 X | E26: 4 kWh Gen 3 | F26: On sale | G26: 2025 | H26: Mid | I26: n/a | J26: 114000 | K26: Aug-2026 | L26: n/a | M26: 4 | N26: Fixed | O26: Li-ion | P26: n/a | Q26: Mid-drive IPM | R26: n/a | S26: n/a | T26: n/a | U26: n/a | V26: 242 | W26: IDC | X26: 150 | Y26: n/a | Z26: n/a | AA26: Ola Hypercharger | AB26: n/a | AC26: n/a | AD26: n/a | AE26: n/a | AF26: n/a | AG26: n/a | AH26: n/a | AI26: 34 | AJ26: 12-inch | AK26: Disc / Drum | AL26: CBS | AM26: LCD | AN26: MoveOS | AO26: 3 | AP26: Yes | AQ26: Yes | AR26: n/a | AS26: IP67 | AT26: 3 yr | AU26: 3 yr | AV26: Gen 3 | AW26: n/a | AX26: Longest range at the sub-Rs1.2L price point on claimed figures | AY26: =IF(AND(ISNUMBER($J26),ISNUMBER($M26)),$J26/$M26,"n/a") -> 28500 | AZ26: =IF(AND(ISNUMBER($V26),ISNUMBER($M26)),$V26/$M26,"n/a") -> 60.5 | BA26: =IF(NOT(ISNUMBER($J26)),"n/a",IF($J26<70000,"1. <Rs70k",IF($J26<100000,"2. Rs70k-1L",IF($J26<150000,"3. Rs1-1.5L",IF($J26<200000,"4. Rs1.5-2L",IF($J26<300000,"5. Rs2-3L","6. >Rs3L")))))) -> 3. Rs1-1.5L | BB26: LOW | BC26: Aggregator listings (Aug-2026) | BD26: n/a | BE26: 242 km IDC claim is an outlier; real-world expected c.55-60% of claim.
A27: S024 | B27: Ola Electric | C27: Ola Electric | D27: S1 Pro | E27: 3 kWh Gen 3 | F27: On sale | G27: Jan-2025 | H27: Premium | I27: 115000 | J27: 125000 | K27: Aug-2026 | L27: n/a | M27: 3 | N27: Fixed | O27: Li-ion | P27: n/a | Q27: Mid-drive IPM | R27: 5.5 | S27: n/a | T27: 117 | U27: 4.3 | V27: 176 | W27: IDC | X27: 105 | Y27: n/a | Z27: 7h15m (0-80%, std charger) | AA27: Ola Hypercharger | AB27: 109 | AC27: 1900 | AD27: 850 | AE27: 1288 | AF27: 1359 | AG27: 160 | AH27: 791 | AI27: 34 | AJ27: 12-inch (90/90-12) | AK27: Disc / Disc | AL27: CBS | AM27: 7-inch TFT touchscreen | AN27: MoveOS, 4G, nav, OTA | AO27: 3 | AP27: Yes | AQ27: Yes | AR27: Cruise control, traction control, reverse, hill hold | AS27: IP67 | AT27: 3 yr | AU27: 3 yr | AV27: Gen 3 | AW27: In-house motor and (on some trims) 4680 cell | AX27: Highest claimed top speed among mass e-scooters | AY27: =IF(AND(ISNUMBER($J27),ISNUMBER($M27)),$J27/$M27,"n/a") -> 41666.667 | AZ27: =IF(AND(ISNUMBER($V27),ISNUMBER($M27)),$V27/$M27,"n/a") -> 58.666667 | BA27: =IF(NOT(ISNUMBER($J27)),"n/a",IF($J27<70000,"1. <Rs70k",IF($J27<100000,"2. Rs70k-1L",IF($J27<150000,"3. Rs1-1.5L",IF($J27<200000,"4. Rs1.5-2L",IF($J27<300000,"5. Rs2-3L","6. >Rs3L")))))) -> 3. Rs1-1.5L | BB27: MEDIUM | BC27: BikeDekho (Aug-2026) | BD27: ZigWheels (updated 31-Jul-2026) | BE27: Charging time (7h15m) is the weakest in the premium set — a real competitive liability.
A28: S025 | B28: Ola Electric | C28: Ola Electric | D28: S1 Pro | E28: 4 kWh Gen 3 | F28: On sale | G28: Jan-2025 | H28: Premium | I28: 135000 | J28: 144999 | K28: Aug-2026 | L28: n/a | M28: 4 | N28: Fixed | O28: Li-ion | P28: n/a | Q28: Mid-drive IPM | R28: 11 | S28: n/a | T28: 125 | U28: n/a | V28: 242 | W28: IDC | X28: 145 | Y28: n/a | Z28: ~6h30m | AA28: Ola Hypercharger | AB28: 109 | AC28: 1900 | AD28: 850 | AE28: 1288 | AF28: 1359 | AG28: 160 | AH28: 791 | AI28: 34 | AJ28: 12-inch | AK28: Disc / Disc | AL28: Dual ABS on some trims | AM28: 7-inch TFT touchscreen | AN28: MoveOS, 4G, nav, OTA | AO28: 4 | AP28: Yes | AQ28: Yes | AR28: Cruise control, traction control, hill hold | AS28: IP67 | AT28: 3 yr | AU28: 3 yr | AV28: Gen 3 | AW28: n/a | AX28: Spec-sheet leader on power and claimed range | AY28: =IF(AND(ISNUMBER($J28),ISNUMBER($M28)),$J28/$M28,"n/a") -> 36249.75 | AZ28: =IF(AND(ISNUMBER($V28),ISNUMBER($M28)),$V28/$M28,"n/a") -> 60.5 | BA28: =IF(NOT(ISNUMBER($J28)),"n/a",IF($J28<70000,"1. <Rs70k",IF($J28<100000,"2. Rs70k-1L",IF($J28<150000,"3. Rs1-1.5L",IF($J28<200000,"4. Rs1.5-2L",IF($J28<300000,"5. Rs2-3L","6. >Rs3L")))))) -> 3. Rs1-1.5L | BB28: MEDIUM | BC28: BikeWale (Apr-2026) | BD28: BikeDekho (Aug-2026) | BE28: n/a
A29: S026 | B29: Ola Electric | C29: Ola Electric | D29: S1 Pro+ | E29: 4 kWh | F29: On sale | G29: 2025 | H29: Premium+ | I29: n/a | J29: 160005 | K29: Aug-2026 | L29: n/a | M29: 4 | N29: Fixed | O29: Li-ion | P29: n/a | Q29: Mid-drive IPM | R29: 13 | S29: n/a | T29: 141 | U29: n/a | V29: n/a | W29: IDC | X29: n/a | Y29: n/a | Z29: n/a | AA29: Ola Hypercharger | AB29: n/a | AC29: 1900 | AD29: 850 | AE29: 1288 | AF29: 1359 | AG29: 160 | AH29: 791 | AI29: 34 | AJ29: 12-inch | AK29: Disc / Disc | AL29: Dual-channel | AM29: 7-inch TFT | AN29: MoveOS 5 | AO29: 4 | AP29: Yes | AQ29: Yes | AR29: Brake-by-wire on select trims | AS29: IP67 | AT29: 3 yr | AU29: 3 yr | AV29: Gen 3 | AW29: n/a | AX29: Performance flagship scooter | AY29: =IF(AND(ISNUMBER($J29),ISNUMBER($M29)),$J29/$M29,"n/a") -> 40001.25 | AZ29: =IF(AND(ISNUMBER($V29),ISNUMBER($M29)),$V29/$M29,"n/a") -> n/a | BA29: =IF(NOT(ISNUMBER($J29)),"n/a",IF($J29<70000,"1. <Rs70k",IF($J29<100000,"2. Rs70k-1L",IF($J29<150000,"3. Rs1-1.5L",IF($J29<200000,"4. Rs1.5-2L",IF($J29<300000,"5. Rs2-3L","6. >Rs3L")))))) -> 4. Rs1.5-2L | BB29: MEDIUM | BC29: BikeWale (Apr-2026) | BD29: n/a | BE29: n/a
A30: S027 | B30: Ola Electric | C30: Ola Electric | D30: S1 Pro+ | E30: 5.2 kWh | F30: On sale | G30: 2025 (repriced Sankalp 2025) | H30: Premium+ flagship | I30: n/a | J30: 170000 | K30: Aug-2026 | L30: n/a | M30: 5.2 | N30: Fixed | O30: Li-ion 4680 cylindrical | P30: Ola in-house 4680 Bharat Cell (mass deliveries from Nov-2025) | Q30: Mid-drive IPM (ferrite, rare-earth-free) | R30: 13 | S30: n/a | T30: 141 | U30: n/a | V30: 320 | W30: IDC | X30: 180 | Y30: n/a | Z30: n/a | AA30: Ola Hypercharger | AB30: n/a | AC30: 1900 | AD30: 850 | AE30: 1288 | AF30: 1359 | AG30: 160 | AH30: 791 | AI30: 34 | AJ30: 12-inch | AK30: Disc / Disc | AL30: Dual-channel | AM30: 7-inch TFT | AN30: MoveOS 5, 4G, nav | AO30: 4 | AP30: Yes | AQ30: Yes | AR30: 4680 Bharat Cell; ferrite motor hedges rare-earth risk | AS30: IP67 | AT30: 3 yr | AU30: 3 yr | AV30: Gen 3 | AW30: Deepest vertical integration in Indian e-2W (cells + motor in-house) | AX30: The clearest test of whether cell vertical integration creates a moat | AY30: =IF(AND(ISNUMBER($J30),ISNUMBER($M30)),$J30/$M30,"n/a") -> 32692.308 | AZ30: =IF(AND(ISNUMBER($V30),ISNUMBER($M30)),$V30/$M30,"n/a") -> 61.538462 | BA30: =IF(NOT(ISNUMBER($J30)),"n/a",IF($J30<70000,"1. <Rs70k",IF($J30<100000,"2. Rs70k-1L",IF($J30<150000,"3. Rs1-1.5L",IF($J30<200000,"4. Rs1.5-2L",IF($J30<300000,"5. Rs2-3L","6. >Rs3L")))))) -> 4. Rs1.5-2L | BB30: MEDIUM | BC30: Ola Sankalp 2025 announcements | BD30: thebikejunction / BikeWale (Aug-2026) | BE30: THESIS-CRITICAL: Ola integrated deepest and lost the most share. Vertical integration did not protect it.
A31: S028 | B31: Hero MotoCorp (listed: HEROMOTOCO) | C31: Vida | D31: VX2 | E31: Go 2.2 kWh | F31: On sale | G31: Jul-2025 | H31: Entry | I31: 99490 | J31: 109583 | K31: Aug-2026 | L31: From Rs59,490 (BaaS) | M31: 2.2 | N31: Removable (1 pack) | O31: Li-ion | P31: n/a | Q31: PMSM | R31: 6 | S31: n/a | T31: 70 | U31: 4.2 | V31: 93 | W31: IDC | X31: 68 | Y31: 580 | Z31: 3h07m (0-80%); 1h41m with 1,000W RQ charger | AA31: 5,900+ public fast-charging points (Vida network) | AB31: 106 | AC31: n/a | AD31: n/a | AE31: n/a | AF31: n/a | AG31: n/a | AH31: 777 | AI31: 33.2 | AJ31: 12-inch | AK31: Drum / Drum | AL31: CBS | AM31: LCD | AN31: Bluetooth, keyless | AO31: 2 | AP31: n/a | AQ31: n/a | AR31: Removable IP67 batteries — key differentiator for apartment dwellers | AS31: IP67 | AT31: 3 yr | AU31: 3 yr | AV31: VX2 platform | AW31: High localisation | AX31: Removable-battery convenience + Hero's ~6,000-touchpoint ICE network | AY31: =IF(AND(ISNUMBER($J31),ISNUMBER($M31)),$J31/$M31,"n/a") -> 49810.455 | AZ31: =IF(AND(ISNUMBER($V31),ISNUMBER($M31)),$V31/$M31,"n/a") -> 42.272727 | BA31: =IF(NOT(ISNUMBER($J31)),"n/a",IF($J31<70000,"1. <Rs70k",IF($J31<100000,"2. Rs70k-1L",IF($J31<150000,"3. Rs1-1.5L",IF($J31<200000,"4. Rs1.5-2L",IF($J31<300000,"5. Rs2-3L","6. >Rs3L")))))) -> 3. Rs1-1.5L | BB31: HIGH | BC31: vidaworld.com/compare.html | BD31: Autocar India variant explainer (Jul-2026) | BE31: Vida FY26 grew 196% to 144,330 — fastest scaler among incumbents.
A32: S029 | B32: Hero MotoCorp | C32: Vida | D32: VX2 | E32: Go 2.2 RQ | F32: On sale | G32: 2025 | H32: Entry | I32: n/a | J32: n/a | K32: Aug-2026 | L32: n/a | M32: 2.2 | N32: Removable | O32: Li-ion | P32: n/a | Q32: PMSM | R32: 6 | S32: n/a | T32: 70 | U32: 4.2 | V32: 93 | W32: IDC | X32: 68 | Y32: 1000 | Z32: 1h41m (0-80%) | AA32: Yes | AB32: 106 | AC32: n/a | AD32: n/a | AE32: n/a | AF32: n/a | AG32: n/a | AH32: 777 | AI32: 33.2 | AJ32: 12-inch | AK32: Drum / Drum | AL32: CBS | AM32: LCD | AN32: Bluetooth | AO32: 2 | AP32: n/a | AQ32: n/a | AR32: Mechanically identical to Go 2.2; bundled 1,000W fast charger | AS32: IP67 | AT32: 3 yr | AU32: 3 yr | AV32: VX2 | AW32: High localisation | AX32: Charger-bundle SKU — a low-cost way to sell 'fast charging' | AY32: =IF(AND(ISNUMBER($J32),ISNUMBER($M32)),$J32/$M32,"n/a") -> n/a | AZ32: =IF(AND(ISNUMBER($V32),ISNUMBER($M32)),$V32/$M32,"n/a") -> 42.272727 | BA32: =IF(NOT(ISNUMBER($J32)),"n/a",IF($J32<70000,"1. <Rs70k",IF($J32<100000,"2. Rs70k-1L",IF($J32<150000,"3. Rs1-1.5L",IF($J32<200000,"4. Rs1.5-2L",IF($J32<300000,"5. Rs2-3L","6. >Rs3L")))))) -> n/a | BB32: HIGH | BC32: Autocar India variant explainer (Jul-2026) | BD32: n/a | BE32: n/a
A33: S030 | B33: Hero MotoCorp | C33: Vida | D33: VX2 | E33: Go 3.1 kWh | F33: On sale | G33: 2026 | H33: Entry-mid | I33: n/a | J33: n/a | K33: Aug-2026 | L33: n/a | M33: 3.1 | N33: Removable | O33: Li-ion | P33: n/a | Q33: PMSM | R33: 6 | S33: n/a | T33: 70 | U33: 4.5 | V33: 127 | W33: IDC | X33: 92 | Y33: n/a | Z33: n/a | AA33: Yes | AB33: n/a | AC33: n/a | AD33: n/a | AE33: n/a | AF33: n/a | AG33: n/a | AH33: 777 | AI33: 33.2 | AJ33: 12-inch | AK33: Drum / Drum | AL33: CBS | AM33: LCD | AN33: Bluetooth | AO33: 2 | AP33: n/a | AQ33: n/a | AR33: Removable packs | AS33: IP67 | AT33: 3 yr | AU33: 3 yr | AV33: VX2 | AW33: High localisation | AX33: Range step-up in the Go family | AY33: =IF(AND(ISNUMBER($J33),ISNUMBER($M33)),$J33/$M33,"n/a") -> n/a | AZ33: =IF(AND(ISNUMBER($V33),ISNUMBER($M33)),$V33/$M33,"n/a") -> 40.967742 | BA33: =IF(NOT(ISNUMBER($J33)),"n/a",IF($J33<70000,"1. <Rs70k",IF($J33<100000,"2. Rs70k-1L",IF($J33<150000,"3. Rs1-1.5L",IF($J33<200000,"4. Rs1.5-2L",IF($J33<300000,"5. Rs2-3L","6. >Rs3L")))))) -> n/a | BB33: HIGH | BC33: vidaworld.com/compare.html (Aug-2026) | BD33: n/a | BE33: Vida site quotes 127 and 128 km on different pages.
A34: S031 | B34: Hero MotoCorp | C34: Vida | D34: VX2 | E34: Go FB 3.1 kWh (fixed battery) | F34: On sale | G34: Aug-2026 | H34: Entry-mid | I34: 113000 | J34: 113000 | K34: Aug-2026 | L34: n/a | M34: 3.1 | N34: Fixed | O34: Li-ion | P34: n/a | Q34: PMSM | R34: 6 | S34: n/a | T34: 70 | U34: n/a | V34: 128 | W34: IDC | X34: 93 | Y34: 1000 | Z34: 65 min (0-80%) | AA34: Yes | AB34: n/a | AC34: n/a | AD34: n/a | AE34: n/a | AF34: n/a | AG34: n/a | AH34: 777 | AI34: 33.2 | AJ34: 12-inch | AK34: Drum / Drum | AL34: CBS | AM34: LCD | AN34: Bluetooth | AO34: 2 | AP34: n/a | AQ34: n/a | AR34: First Vida with a NON-removable pack — a deliberate cost-down move | AS34: IP67 | AT34: 3 yr | AU34: 3 yr | AV34: VX2 | AW34: High localisation | AX34: Signals Hero trading its removable-battery USP for price competitiveness | AY34: =IF(AND(ISNUMBER($J34),ISNUMBER($M34)),$J34/$M34,"n/a") -> 36451.613 | AZ34: =IF(AND(ISNUMBER($V34),ISNUMBER($M34)),$V34/$M34,"n/a") -> 41.290323 | BA34: =IF(NOT(ISNUMBER($J34)),"n/a",IF($J34<70000,"1. <Rs70k",IF($J34<100000,"2. Rs70k-1L",IF($J34<150000,"3. Rs1-1.5L",IF($J34<200000,"4. Rs1.5-2L",IF($J34<300000,"5. Rs2-3L","6. >Rs3L")))))) -> 3. Rs1-1.5L | BB34: HIGH | BC34: BikeDekho news (01-Aug-2026) | BD34: BikeWale (Jul-2026) | BE34: Strategically notable: incumbents are now competing on price, not features.
A35: S032 | B35: Hero MotoCorp | C35: Vida | D35: VX2 | E35: Go 3.4 kWh | F35: On sale | G35: 2026 | H35: Mid | I35: n/a | J35: n/a | K35: Aug-2026 | L35: n/a | M35: 3.4 | N35: Removable (2 packs) | O35: Li-ion | P35: n/a | Q35: PMSM | R35: 6 | S35: n/a | T35: 70 | U35: 4.2 | V35: 146 | W35: IDC | X35: 105 | Y35: n/a | Z35: 62 min (0-80%) on public fast charge | AA35: Yes | AB35: n/a | AC35: n/a | AD35: n/a | AE35: n/a | AF35: n/a | AG35: n/a | AH35: 777 | AI35: 33.2 | AJ35: 12-inch | AK35: Drum / Drum | AL35: CBS | AM35: LCD | AN35: Bluetooth | AO35: 2 | AP35: n/a | AQ35: n/a | AR35: Two removable 1.7 kWh packs | AS35: IP67 | AT35: 3 yr | AU35: 3 yr | AV35: VX2 | AW35: High localisation | AX35: n/a | AY35: =IF(AND(ISNUMBER($J35),ISNUMBER($M35)),$J35/$M35,"n/a") -> n/a | AZ35: =IF(AND(ISNUMBER($V35),ISNUMBER($M35)),$V35/$M35,"n/a") -> 42.941176 | BA35: =IF(NOT(ISNUMBER($J35)),"n/a",IF($J35<70000,"1. <Rs70k",IF($J35<100000,"2. Rs70k-1L",IF($J35<150000,"3. Rs1-1.5L",IF($J35<200000,"4. Rs1.5-2L",IF($J35<300000,"5. Rs2-3L","6. >Rs3L")))))) -> n/a | BB35: HIGH | BC35: vidaworld.com/compare.html | BD35: n/a | BE35: n/a
A36: S033 | B36: Hero MotoCorp | C36: Vida | D36: VX2 | E36: Plus 3.4 kWh | F36: On sale | G36: Jul-2025 | H36: Mid | I36: 110000 | J36: 120000 | K36: Aug-2026 | L36: BaaS available | M36: 3.4 | N36: Removable (2 packs) | O36: Li-ion | P36: n/a | Q36: PMSM | R36: 6 | S36: n/a | T36: 80 | U36: 3.1 | V36: 146 | W36: IDC | X36: 105 | Y36: 1000 | Z36: 62 min (0-80%) | AA36: Yes — 5,900+ points | AB36: n/a | AC36: n/a | AD36: n/a | AE36: n/a | AF36: n/a | AG36: n/a | AH36: 777 | AI36: 33.2 | AJ36: 12-inch | AK36: Disc / Drum | AL36: CBS | AM36: TFT | AN36: Bluetooth, 3 ride modes, keyless | AO36: 3 | AP36: n/a | AQ36: n/a | AR36: TFT dash, disc brake, 3 modes | AS36: IP67 | AT36: 3 yr | AU36: 3 yr | AV36: VX2 | AW36: High localisation | AX36: Volume workhorse of the Vida line | AY36: =IF(AND(ISNUMBER($J36),ISNUMBER($M36)),$J36/$M36,"n/a") -> 35294.118 | AZ36: =IF(AND(ISNUMBER($V36),ISNUMBER($M36)),$V36/$M36,"n/a") -> 42.941176 | BA36: =IF(NOT(ISNUMBER($J36)),"n/a",IF($J36<70000,"1. <Rs70k",IF($J36<100000,"2. Rs70k-1L",IF($J36<150000,"3. Rs1-1.5L",IF($J36<200000,"4. Rs1.5-2L",IF($J36<300000,"5. Rs2-3L","6. >Rs3L")))))) -> 3. Rs1-1.5L | BB36: HIGH | BC36: vidaworld.com | BD36: Autocar India (Jul-2026) | BE36: Autocar reader feedback flags AUX/app glitches and switchgear quality — a service-cost watch item.
A37: S034 | B37: Hero MotoCorp | C37: Vida | D37: VX2 | E37: Plus 4.4 kWh | F37: On sale | G37: Jul-2026 | H37: Upper-mass flagship | I37: 143990 | J37: 150990 | K37: Aug-2026 | L37: n/a | M37: 4.4 | N37: Removable (2 x 2.2 kWh) | O37: Li-ion | P37: n/a | Q37: PMSM | R37: 6 | S37: n/a | T37: 90 | U37: 3.1 | V37: 187 | W37: IDC | X37: 140 | Y37: 1000 | Z37: 65 min (0-80%) | AA37: Yes | AB37: n/a | AC37: n/a | AD37: n/a | AE37: n/a | AF37: n/a | AG37: n/a | AH37: 777 | AI37: 33.2 | AJ37: 12-inch | AK37: Disc / Drum | AL37: CBS | AM37: TFT | AN37: Bluetooth, nav, 3 modes | AO37: 3 | AP37: n/a | AQ37: n/a | AR37: Largest removable-battery pack in India; ~140 km real-world Eco per brochure | AS37: IP67 | AT37: 3 yr | AU37: 3 yr | AV37: VX2 | AW37: High localisation | AX37: Longest-range removable-battery scooter — a genuine functional niche | AY37: =IF(AND(ISNUMBER($J37),ISNUMBER($M37)),$J37/$M37,"n/a") -> 34315.909 | AZ37: =IF(AND(ISNUMBER($V37),ISNUMBER($M37)),$V37/$M37,"n/a") -> 42.5 | BA37: =IF(NOT(ISNUMBER($J37)),"n/a",IF($J37<70000,"1. <Rs70k",IF($J37<100000,"2. Rs70k-1L",IF($J37<150000,"3. Rs1-1.5L",IF($J37<200000,"4. Rs1.5-2L",IF($J37<300000,"5. Rs2-3L","6. >Rs3L")))))) -> 4. Rs1.5-2L | BB37: HIGH | BC37: Autopunditz (11-Jul-2026) | BD37: vidaworld.com/vx2-plus-electric-scooter.html | BE37: Rs1,43,990 was the 'effective' launch price inclusive of incentives; incentives lapsed 31-Jul-2026.
A38: S035 | B38: Hero MotoCorp | C38: Vida | D38: V2 | E38: Plus / Pro | F38: On sale (being phased down) | G38: 2024 | H38: Mid-premium | I38: n/a | J38: 120000 | K38: Aug-2026 | L38: n/a | M38: 3.94 | N38: Removable | O38: Li-ion | P38: n/a | Q38: PMSM | R38: 6 | S38: n/a | T38: 80 | U38: n/a | V38: 165 | W38: IDC | X38: 115 | Y38: n/a | Z38: n/a | AA38: Yes | AB38: n/a | AC38: n/a | AD38: n/a | AE38: n/a | AF38: n/a | AG38: n/a | AH38: n/a | AI38: n/a | AJ38: 12-inch | AK38: Disc / Drum | AL38: CBS | AM38: 7-inch TFT | AN38: 4G, nav, OTA | AO38: 3 | AP38: Yes | AQ38: Yes | AR38: Older-generation Vida flagship | AS38: IP67 | AT38: 3 yr | AU38: 3 yr | AV38: V2 platform | AW38: High localisation | AX38: n/a | AY38: =IF(AND(ISNUMBER($J38),ISNUMBER($M38)),$J38/$M38,"n/a") -> 30456.853 | AZ38: =IF(AND(ISNUMBER($V38),ISNUMBER($M38)),$V38/$M38,"n/a") -> 41.878173 | BA38: =IF(NOT(ISNUMBER($J38)),"n/a",IF($J38<70000,"1. <Rs70k",IF($J38<100000,"2. Rs70k-1L",IF($J38<150000,"3. Rs1-1.5L",IF($J38<200000,"4. Rs1.5-2L",IF($J38<300000,"5. Rs2-3L","6. >Rs3L")))))) -> 3. Rs1-1.5L | BB38: LOW | BC38: Aggregator listings (Aug-2026) | BD38: n/a | BE38: Superseded by VX2 range; verify current availability.
A39: S036 | B39: Honda Motor (HMSI) | C39: Honda | D39: Activa e: | E39: Standard | F39: On sale | G39: Feb-2025 | H39: Mass (swap-only) | I39: 117000 | J39: 118147 | K39: Aug-2026 | L39: Swap subscription via Honda e:Swap | M39: 3 | N39: Swappable (2 x 1.5 kWh Honda Mobile Power Pack e:) | O39: Li-ion | P39: Honda Power Pack Energy India | Q39: PMSM | R39: 6 | S39: 22 | T39: 80 | U39: 7.3 | V39: 102 | W39: IDC | X39: 75 | Y39: n/a | Z39: Swap only — no home charging | AA39: Honda e:Swap stations (Bengaluru, Delhi, Mumbai) | AB39: 118 | AC39: 1830 | AD39: 700 | AE39: 1141 | AF39: 1310 | AG39: 171 | AH39: 765 | AI39: n/a | AJ39: 12-inch | AK39: Disc / Drum | AL39: CBS | AM39: 5-inch LCD | AN39: Bluetooth | AO39: 3 | AP39: n/a | AQ39: n/a | AR39: Battery-swap-only architecture; based on Honda CUV e: global platform | AS39: n/a | AT39: 3 yr | AU39: Covered under swap subscription | AV39: Honda global e: platform | AW39: Assembled in India | AX39: Only major OEM committed to a pure swap model for personal scooters | AY39: =IF(AND(ISNUMBER($J39),ISNUMBER($M39)),$J39/$M39,"n/a") -> 39382.333 | AZ39: =IF(AND(ISNUMBER($V39),ISNUMBER($M39)),$V39/$M39,"n/a") -> 34 | BA39: =IF(NOT(ISNUMBER($J39)),"n/a",IF($J39<70000,"1. <Rs70k",IF($J39<100000,"2. Rs70k-1L",IF($J39<150000,"3. Rs1-1.5L",IF($J39<200000,"4. Rs1.5-2L",IF($J39<300000,"5. Rs2-3L","6. >Rs3L")))))) -> 3. Rs1-1.5L | BB39: HIGH | BC39: Autocar India Activa e: page (Aug-2026) | BD39: BikeDekho (Aug-2026) | BE39: Swap-only limits geography: launched only in Mumbai, Delhi, Bengaluru phase 1. Key constraint on Honda's share.
A40: S037 | B40: Honda Motor (HMSI) | C40: Honda | D40: Activa e: | E40: RoadSync Duo | F40: On sale | G40: Feb-2025 | H40: Mass (swap-only) | I40: 151000 | J40: 152747 | K40: Aug-2026 | L40: Swap subscription | M40: 3 | N40: Swappable (2 x 1.5 kWh) | O40: Li-ion | P40: Honda Power Pack Energy India | Q40: PMSM | R40: 6 | S40: 22 | T40: 80 | U40: 7.3 | V40: 102 | W40: IDC | X40: 75 | Y40: n/a | Z40: Swap only | AA40: Honda e:Swap | AB40: 118 | AC40: 1830 | AD40: 700 | AE40: 1141 | AF40: 1310 | AG40: 171 | AH40: 765 | AI40: n/a | AJ40: 12-inch | AK40: Disc / Drum | AL40: CBS | AM40: 7-inch TFT | AN40: Honda RoadSync Duo app, nav, call/SMS | AO40: 3 | AP40: n/a | AQ40: n/a | AR40: Large TFT with turn-by-turn navigation | AS40: n/a | AT40: 3 yr | AU40: Under subscription | AV40: Honda global e: platform | AW40: Assembled in India | AX40: Honda's premium connected trim | AY40: =IF(AND(ISNUMBER($J40),ISNUMBER($M40)),$J40/$M40,"n/a") -> 50915.667 | AZ40: =IF(AND(ISNUMBER($V40),ISNUMBER($M40)),$V40/$M40,"n/a") -> 34 | BA40: =IF(NOT(ISNUMBER($J40)),"n/a",IF($J40<70000,"1. <Rs70k",IF($J40<100000,"2. Rs70k-1L",IF($J40<150000,"3. Rs1-1.5L",IF($J40<200000,"4. Rs1.5-2L",IF($J40<300000,"5. Rs2-3L","6. >Rs3L")))))) -> 4. Rs1.5-2L | BB40: HIGH | BC40: Autocar India (Aug-2026) | BD40: BikeDekho (Aug-2026) | BE40: n/a
...

Sheet Motorcycles_Current
A1: ELECTRIC MOTORCYCLES — INDIA MODEL MASTER (VARIANT LEVEL)
A2: 29 variants, 14 brands. E-motorcycles are under 5 per cent of e-2W volume — this is a niche market, not a mass one. Data as of 25-Aug-2026.
A3: ID | B3: OEM / parent | C3: Brand | D3: Model | E3: Variant | F3: Status | G3: Launch (M-Y) | H3: Positioning tier | I3: Price at launch (Rs, ex-shwr) | J3: Price latest (Rs, ex-shwr Delhi) | K3: Price as-of | L3: BaaS / subscription price | M3: Battery (kWh) | N3: Battery type | O3: Chemistry | P3: Cell sourcing | Q3: Motor type / drive | R3: Peak power (kW) | S3: Torque (Nm) | T3: Top speed (km/h) | U3: 0-40 km/h (s) | V3: Claimed range (km) | W3: Range cycle | X3: Real-world range est. (km) | Y3: Charger (W) | Z3: Charge time 0-80% | AA3: Fast charge / network | AB3: Kerb weight (kg) | AC3: Length (mm) | AD3: Width (mm) | AE3: Height (mm) | AF3: Wheelbase (mm) | AG3: Ground clearance (mm) | AH3: Seat height (mm) | AI3: Transmission | AJ3: Wheels / tyres | AK3: Brakes (F/R) | AL3: ABS / CBS | AM3: Display | AN3: Connectivity | AO3: Ride modes | AP3: Reverse | AQ3: OTA updates | AR3: Other key features | AS3: IP rating | AT3: Vehicle warranty | AU3: Battery warranty | AV3: Platform | AW3: Manufacturing / localisation | AX3: Key differentiator | AY3: Rs per kWh (calc) | AZ3: km per kWh (calc) | BA3: Price band (calc) | BB3: Data confidence | BC3: Source 1 | BD3: Source 2 | BE3: Analyst notes
A4: M001 | B4: Ultraviolette Automotive (private) | C4: Ultraviolette | D4: F77 Mach 2 / SuperStreet | E4: Original 7.1 kWh | F4: On sale | G4: 2024 (Mach 2 update) | H4: Performance flagship | I4: 299000 | J4: 309000 | K4: Aug-2026 | L4: n/a | M4: 7.1 | N4: Fixed | O4: Li-ion NMC cylindrical | P4: In-house SRB-10 pack; imported cells | Q4: PMSM, chain drive | R4: 27 | S4: 100 | T4: 155 | U4: 2.9 | V4: 211 | W4: IDC | X4: 150 | Y4: n/a | Z4: ~1h30m (fast); ~5h (std) | AA4: UV Supernova DC fast-charging network | AB4: 207 | AC4: n/a | AD4: n/a | AE4: n/a | AF4: 1380 | AG4: n/a | AH4: 800 | AI4: Manual (single speed) | AJ4: 17-inch alloy | AK4: Disc / Disc | AL4: Dual-channel ABS | AM4: TFT with 4G | AN4: 4G, nav, OTA, telemetry | AO4: 4 | AP4: Yes | AQ4: Yes | AR4: 10 levels regen, 4-level traction control, ballistic ride modes, aviation-derived drivetrain | AS4: IP67 | AT4: 3 yr | AU4: 5 yr / 100,000 km | AV4: F77 platform | AW4: Bengaluru; exports to Central Europe | AX4: India's most credible performance-EV brand; genuine premium price realisation | AY4: =IF(AND(ISNUMBER($J4),ISNUMBER($M4)),$J4/$M4,"n/a") -> 43521.127 | AZ4: =IF(AND(ISNUMBER($V4),ISNUMBER($M4)),$V4/$M4,"n/a") -> 29.71831 | BA4: =IF(NOT(ISNUMBER($J4)),"n/a",IF($J4<70000,"1. <Rs70k",IF($J4<100000,"2. Rs70k-1L",IF($J4<150000,"3. Rs1-1.5L",IF($J4<200000,"4. Rs1.5-2L",IF($J4<300000,"5. Rs2-3L","6. >Rs3L")))))) -> 6. >Rs3L | BB4: HIGH | BC4: ultraviolette.com/f77 (Aug-2026) | BD4: BikeDekho / ZigWheels (Aug-2026) | BE4: NICHE EXHIBIT #1: sustains a Rs3L+ ASP. Raised USD45m Series E (Zoho, Lingotto) Dec-2025.
A5: M002 | B5: Ultraviolette | C5: Ultraviolette | D5: F77 Mach 2 / SuperStreet | E5: Recon 10.3 kWh | F5: On sale | G5: 2024 | H5: Performance flagship | I5: n/a | J5: 424000 | K5: Aug-2026 | L5: n/a | M5: 10.3 | N5: Fixed | O5: Li-ion NMC cylindrical | P5: In-house SRB-10 pack | Q5: PMSM, chain drive | R5: 30 | S5: 100 | T5: 155 | U5: 2.8 | V5: 323 | W5: IDC (WMTC 231 km) | X5: 210 | Y5: n/a | Z5: ~1h30m (fast) | AA5: UV Supernova network | AB5: 207 | AC5: n/a | AD5: n/a | AE5: n/a | AF5: 1380 | AG5: n/a | AH5: 800 | AI5: Manual (single speed) | AJ5: 17-inch alloy | AK5: Disc / Disc | AL5: Dual-channel ABS | AM5: TFT | AN5: 4G, nav, OTA | AO5: 4 | AP5: Yes | AQ5: Yes | AR5: Largest battery in any Indian e-motorcycle; 800,000 km battery-warranty marketing claim | AS5: IP67 | AT5: 3 yr | AU5: 5 yr / 100,000 km | AV5: F77 platform | AW5: Bengaluru | AX5: Longest-range electric motorcycle sold in India | AY5: =IF(AND(ISNUMBER($J5),ISNUMBER($M5)),$J5/$M5,"n/a") -> 41165.049 | AZ5: =IF(AND(ISNUMBER($V5),ISNUMBER($M5)),$V5/$M5,"n/a") -> 31.359223 | BA5: =IF(NOT(ISNUMBER($J5)),"n/a",IF($J5<70000,"1. <Rs70k",IF($J5<100000,"2. Rs70k-1L",IF($J5<150000,"3. Rs1-1.5L",IF($J5<200000,"4. Rs1.5-2L",IF($J5<300000,"5. Rs2-3L","6. >Rs3L")))))) -> 6. >Rs3L | BB5: HIGH | BC5: ultraviolette.com | BD5: BikeDekho (Aug-2026) | BE5: WMTC 231 km is the credible number; 323 km is IDC. Use WMTC for range comparisons vs global peers.
