Workbook

Sheet Read Me
A1: India Auto OEMs — Manufacturing Capacity Database, FY10–FY26
A2: 12 OEMs | Company-level and plant-level capacity history, event logs, platforms and forward pipeline | Compiled 14-Oct-2026
A4: WHAT THIS IS
A5: Purpose | B5: One-stop reference for installed capacity, plant footprint, capacity events, platforms and announced additions across 12 Indian OEMs, built for capacity forecasting and utilisation analysis.
A6: Coverage | B6: Maruti Suzuki, Hyundai Motor India, M&M (SUV), Tata Motors PV, Tata Motors CV, Ashok Leyland, Bajaj Auto, TVS Motor, Royal Enfield (Eicher), Hero MotoCorp, Ola Electric, Ather Energy.
A7: Sheet map | B7: Summary (cross-company comparison, outlook tiers, charts) -> one sheet per OEM (sections A–H) -> Gap Register (what is missing and where to find it) -> Source Log (every ID cited) -> Chart Data (links feeding charts).
A9: OEM SHEET LAYOUT
A10: A. Snapshot | B10: Latest disclosed capacity, FY26 volume and utilisation, outlook base, company target and a one-line bottom line.
A11: B. History FY10–FY26 | B11: Row 19 is the capacity series used everywhere else. Rows 21–24 hold actual production and sales. Rows 25–28 are formulas. Row 30 cites source IDs per year; row 31 annotates each year.
A12: C. Plant matrix | B12: Plant-level capacity (and production where disclosed) by fiscal year. Only disclosed points are entered — gaps are deliberate.
A13: D–G | B13: Plant register, chronological capacity event log, platform/model/plant allocation, and forward pipeline split into certainty tiers.
A14: H. Analyst notes | B14: Interpretation, data caveats and what to check next.
A16: CONVENTIONS
A17: Fiscal year | B17: FY = year ending 31 March (FY26 = Apr-2025 to Mar-2026).
A18: Placement | B18: Capacity sits in the FY whose year-end it represents. A statement made in Apr–Jul with no intervening event is placed at the prior year-end (e.g., May-2016 HMIL 680k -> FY16). Post-FY26 events (FY27 YTD) appear in the event log and pipeline, not in row 19.
A19: Units | B19: Vehicles per annum unless stated. M&M discloses units/month — annualised x12 by formula. Ola cell capacity is in GWh and never summed with vehicles.
A20: Capacity definitions | B20: Companies use 'installed capacity', 'production ability', 'operational capacity' or 'design capacity' inconsistently. The basis code (row 20) and the snapshot definition record which one is used.
A21: Utilisation | B21: Three formula variants: production ÷ FY-end capacity (company convention), production ÷ average of opening and closing capacity (better in commissioning years), and sales ÷ FY-end capacity (fallback where production is undisclosed).
A22: Outlook tiers | B22: Tier 1 = commissioned after FY26 or under execution. Tier 2 = announced with site/timeline. Memo = targets, GWh items, shared or unquantified items — excluded from sums. 'Gap to target' = company target − (base + Tier 1 + Tier 2).
A24: COLOUR CODES
A25: Blue text | B25: Hard-coded input taken from a cited source.
A26: Black text | B26: Formula.
A27: Green text | B27: Link to another sheet.
A28: Orange fill | B28: Verify: lower-tier source, lower bound, or inferred date — use with care.
A29: Light blue fill | B29: Bracketed carry: identical disclosures before and after with no change announced in between (basis code marked *).
A31: SOURCE TIERS
A32: A | B32: Statutory/exchange filing, annual report, offer document (DRHP/RHP), SEC 20-F.
A33: B | B33: Company press release or company-published material.
A34: C | B34: Reputable media reporting company statements.
A35: D | B35: Secondary aggregator or encyclopaedic source — flagged for verification.
A37: WHY THERE ARE GAPS
A38: Disclosure regime | B38: Under the old Schedule VI (to FY11), Indian companies disclosed licensed and installed capacity in the notes to accounts. Revised Schedule VI (from FY12) dropped this, so capacity disclosure became voluntary — the main reason company totals thin out from FY12 for Tata, Ashok Leyland, Hero and TVS.
A39: No estimation | B39: Missing years are left blank. No interpolation, no analyst estimates in historical rows. The Gap Register lists each missing series and the document most likely to fill it.
A40: Volumes | B40: Production is used where disclosed; otherwise sales/dispatches; for EV pure-plays, retail registrations (labelled). Pre-FY12 Tata volumes are global 'Tata & other brand' figures and not like-for-like.

Sheet Summary
A1: Summary — Manufacturing capacity across 12 Indian OEMs
A2: All figures link to OEM sheets (green). Units: vehicles p.a. FY = year to 31-Mar. As of 14-Oct-2026.
A4: KEY TAKEAWAYS
A5: PV build cycle. | C5: ="Maruti, Hyundai, M&M and Tata PV exit FY26 with "&TEXT(C56/1000000,"0.0")&"m units of capacity; Tier 1 + Tier 2 projects take this to "&TEXT(H56/1000000,"0.0")&"m (+"&TEXT(H56/C56-1,"0%")&"), led by Maruti and M&M." -> Maruti, Hyundai, M&M and Tata PV exit FY26 with 5.1m units of capacity; Tier 1 + Tier 2 projects take this to 7.8m (+53%), led by Maruti and M&M.
A6: Utilisation splits the sector. | C6: ="FY26 utilisation is tight at Maruti ("&TEXT(L29,"0%")&"), TVS ("&TEXT(L36,"0%")&"), M&M ("&TEXT(L31,"0%")&") and Royal Enfield ("&TEXT(L37,"0%")&"); loose at Ola ("&TEXT(L39,"0%")&"), Ather ("&TEXT(L40,"0%")&"), Bajaj ("&TEXT(L35,"0%")&"), Tata PV ("&TEXT(L32,"0%")&") and Hyundai ("&TEXT(L30,"0%")&", diluted by Talegaon)." -> FY26 utilisation is tight at Maruti (98%), TVS (87%), M&M (85%) and Royal Enfield (85%); loose at Ola (16%), Ather (57%), Bajaj (71%), Tata PV (71%) and Hyundai (77%, diluted by Talegaon).
A7: Disclosure is the binding data constraint. | C7: ="Since Revised Schedule VI (FY12) capacity disclosure is voluntary: Tata CV, Ashok Leyland and Hero have no current company total in sources reviewed; see Gap Register for the documents that fill each series." -> Since Revised Schedule VI (FY12) capacity disclosure is voluntary: Tata CV, Ashok Leyland and Hero have no current company total in sources reviewed; see Gap Register for the documents that fill each series.
A8: 2W EV capacity: overbuilt at Ola, underbuilt elsewhere. | C8: ="Ola runs at "&TEXT(L39,"0%")&" of its 1.0m line while others add EV capacity: Bajaj Chetak 50k -> 60k/month, TVS EV to 50k/month, Hero Vida 25k -> 50k+/month, Ather +500k at AURIC (Q3FY27)." -> Ola runs at 16% of its 1.0m line while others add EV capacity: Bajaj Chetak 50k -> 60k/month, TVS EV to 50k/month, Hero Vida 25k -> 50k+/month, Ather +500k at AURIC (Q3FY27).
A9: Targets are mostly backed by named projects. | C9: ="Maruti's gap to 4.0m is "&TEXT(M44/1000000,"0.0")&"m; Tata PV's gap to 1.3m is "&TEXT(M47/1000,"0")&"k (debottlenecking not yet quantified); M&M's visible pipeline exceeds its 2x target by "&TEXT(-M46/1000,"0")&"k." -> Maruti's gap to 4.0m is 0.1m; Tata PV's gap to 1.3m is 100k (debottlenecking not yet quantified); M&M's visible pipeline exceeds its 2x target by 36k.
A11: 1. INSTALLED CAPACITY, FY-END, FY10–FY26 (units p.a.; blank = not disclosed in sources reviewed)
A12: Company | B12: Segment | C12: FY10 | D12: FY11 | E12: FY12 | F12: FY13 | G12: FY14 | H12: FY15 | I12: FY16 | J12: FY17 | K12: FY18 | L12: FY19 | M12: FY20 | N12: FY21 | O12: FY22 | P12: FY23 | Q12: FY24 | R12: FY25 | S12: FY26 | T12: Years disclosed (of 17) | U12: Capacity definition
A13: Maruti Suzuki | B13: PV | C13: =IF(ISNUMBER('Maruti Suzuki'!C19),'Maruti Suzuki'!C19,"") -> 1000000 | D13: =IF(ISNUMBER('Maruti Suzuki'!D19),'Maruti Suzuki'!D19,"") -> 1200000 | E13: =IF(ISNUMBER('Maruti Suzuki'!E19),'Maruti Suzuki'!E19,"") | F13: =IF(ISNUMBER('Maruti Suzuki'!F19),'Maruti Suzuki'!F19,"") | G13: =IF(ISNUMBER('Maruti Suzuki'!G19),'Maruti Suzuki'!G19,"") | H13: =IF(ISNUMBER('Maruti Suzuki'!H19),'Maruti Suzuki'!H19,"") -> 1500000 | I13: =IF(ISNUMBER('Maruti Suzuki'!I19),'Maruti Suzuki'!I19,"") -> 1500000 | J13: =IF(ISNUMBER('Maruti Suzuki'!J19),'Maruti Suzuki'!J19,"") -> 1750000 | ... S13: =IF(ISNUMBER('Maruti Suzuki'!S19),'Maruti Suzuki'!S19,"") -> 2400000 | T13: =COUNT(C13:S13) -> 14 | U13: ='Maruti Suzuki'!C7 -> Annual vehicle production capacity as stated by MSIL/Suzuki (two-shift basis), all four sites
A14: Hyundai India | B14: PV | C14: =IF(ISNUMBER('Hyundai India'!C19),'Hyundai India'!C19,"") -> 600000 | D14: =IF(ISNUMBER('Hyundai India'!D19),'Hyundai India'!D19,"") | E14: =IF(ISNUMBER('Hyundai India'!E19),'Hyundai India'!E19,"") | F14: =IF(ISNUMBER('Hyundai India'!F19),'Hyundai India'!F19,"") | G14: =IF(ISNUMBER('Hyundai India'!G19),'Hyundai India'!G19,"") | H14: =IF(ISNUMBER('Hyundai India'!H19),'Hyundai India'!H19,"") | I14: =IF(ISNUMBER('Hyundai India'!I19),'Hyundai India'!I19,"") -> 680000 | J14: =IF(ISNUMBER('Hyundai India'!J19),'Hyundai India'!J19,"") | ... S14: =IF(ISNUMBER('Hyundai India'!S19),'Hyundai India'!S19,"") -> 994000 | T14: =COUNT(C14:S14) -> 11 | U14: ='Hyundai India'!C7 -> Installed annual vehicle capacity per HMIL (DRHP/AR basis)
A15: M&M | B15: PV | C15: =IF(ISNUMBER('M&M'!C19),'M&M'!C19,"") | D15: =IF(ISNUMBER('M&M'!D19),'M&M'!D19,"") | E15: =IF(ISNUMBER('M&M'!E19),'M&M'!E19,"") | F15: =IF(ISNUMBER('M&M'!F19),'M&M'!F19,"") | G15: =IF(ISNUMBER('M&M'!G19),'M&M'!G19,"") | H15: =IF(ISNUMBER('M&M'!H19),'M&M'!H19,"") | I15: =IF(ISNUMBER('M&M'!I19),'M&M'!I19,"") | J15: =IF(ISNUMBER('M&M'!J19),'M&M'!J19,"") | ... S15: =IF(ISNUMBER('M&M'!S19),'M&M'!S19,"") -> 774000 | T15: =COUNT(C15:S15) -> 6 | U15: ='M&M'!C7 -> Operational SUV capacity, units/month x 12 (ICE 56.5k + BEV 8k at FY26 exit)
A16: Tata PV | B16: PV | C16: =IF(ISNUMBER('Tata PV'!C19),'Tata PV'!C19,"") | D16: =IF(ISNUMBER('Tata PV'!D19),'Tata PV'!D19,"") | E16: =IF(ISNUMBER('Tata PV'!E19),'Tata PV'!E19,"") | F16: =IF(ISNUMBER('Tata PV'!F19),'Tata PV'!F19,"") | G16: =IF(ISNUMBER('Tata PV'!G19),'Tata PV'!G19,"") | H16: =IF(ISNUMBER('Tata PV'!H19),'Tata PV'!H19,"") | I16: =IF(ISNUMBER('Tata PV'!I19),'Tata PV'!I19,"") | J16: =IF(ISNUMBER('Tata PV'!J19),'Tata PV'!J19,"") | ... S16: =IF(ISNUMBER('Tata PV'!S19),'Tata PV'!S19,"") -> 900000 | T16: =COUNT(C16:S16) -> 2 | U16: ='Tata PV'!C7 -> Installed PV capacity per management commentary (c.0.9m); Investor Day 2024 cited '1mn+' incl. expandable Sanand-2
A17: Tata CV | B17: CV | C17: =IF(ISNUMBER('Tata CV'!C19),'Tata CV'!C19,"") | D17: =IF(ISNUMBER('Tata CV'!D19),'Tata CV'!D19,"") | E17: =IF(ISNUMBER('Tata CV'!E19),'Tata CV'!E19,"") | F17: =IF(ISNUMBER('Tata CV'!F19),'Tata CV'!F19,"") | G17: =IF(ISNUMBER('Tata CV'!G19),'Tata CV'!G19,"") | H17: =IF(ISNUMBER('Tata CV'!H19),'Tata CV'!H19,"") | I17: =IF(ISNUMBER('Tata CV'!I19),'Tata CV'!I19,"") | J17: =IF(ISNUMBER('Tata CV'!J19),'Tata CV'!J19,"") | ... S17: =IF(ISNUMBER('Tata CV'!S19),'Tata CV'!S19,"") | T17: =COUNT(C17:S17) -> 0 | U17: ='Tata CV'!C7 -> No consolidated CV installed capacity found in sources reviewed
A18: Ashok Leyland | B18: CV | C18: =IF(ISNUMBER('Ashok Leyland'!C19),'Ashok Leyland'!C19,"") | D18: =IF(ISNUMBER('Ashok Leyland'!D19),'Ashok Leyland'!D19,"") -> 150000 | E18: =IF(ISNUMBER('Ashok Leyland'!E19),'Ashok Leyland'!E19,"") | F18: =IF(ISNUMBER('Ashok Leyland'!F19),'Ashok Leyland'!F19,"") | G18: =IF(ISNUMBER('Ashok Leyland'!G19),'Ashok Leyland'!G19,"") | H18: =IF(ISNUMBER('Ashok Leyland'!H19),'Ashok Leyland'!H19,"") | I18: =IF(ISNUMBER('Ashok Leyland'!I19),'Ashok Leyland'!I19,"") | J18: =IF(ISNUMBER('Ashok Leyland'!J19),'Ashok Leyland'!J19,"") | ... S18: =IF(ISNUMBER('Ashok Leyland'!S19),'Ashok Leyland'!S19,"") | T18: =COUNT(C18:S18) -> 1 | U18: ='Ashok Leyland'!C7 -> Installed capacity across seven plants (2010); no later company total found
A19: Bajaj Auto | B19: 2W/3W | C19: =IF(ISNUMBER('Bajaj Auto'!C19),'Bajaj Auto'!C19,"") | D19: =IF(ISNUMBER('Bajaj Auto'!D19),'Bajaj Auto'!D19,"") -> 5040000 | E19: =IF(ISNUMBER('Bajaj Auto'!E19),'Bajaj Auto'!E19,"") -> 5040000 | F19: =IF(ISNUMBER('Bajaj Auto'!F19),'Bajaj Auto'!F19,"") | G19: =IF(ISNUMBER('Bajaj Auto'!G19),'Bajaj Auto'!G19,"") | H19: =IF(ISNUMBER('Bajaj Auto'!H19),'Bajaj Auto'!H19,"") -> 6060000 | I19: =IF(ISNUMBER('Bajaj Auto'!I19),'Bajaj Auto'!I19,"") | J19: =IF(ISNUMBER('Bajaj Auto'!J19),'Bajaj Auto'!J19,"") | ... S19: =IF(ISNUMBER('Bajaj Auto'!S19),'Bajaj Auto'!S19,"") -> 7200000 | T19: =COUNT(C19:S19) -> 6 | U19: ='Bajaj Auto'!C7 -> Installed capacity, 2W + 3W (company statements)
A20: TVS Motor | B20: 2W/3W | C20: =IF(ISNUMBER('TVS Motor'!C19),'TVS Motor'!C19,"") | D20: =IF(ISNUMBER('TVS Motor'!D19),'TVS Motor'!D19,"") | E20: =IF(ISNUMBER('TVS Motor'!E19),'TVS Motor'!E19,"") | F20: =IF(ISNUMBER('TVS Motor'!F19),'TVS Motor'!F19,"") | G20: =IF(ISNUMBER('TVS Motor'!G19),'TVS Motor'!G19,"") | H20: =IF(ISNUMBER('TVS Motor'!H19),'TVS Motor'!H19,"") | I20: =IF(ISNUMBER('TVS Motor'!I19),'TVS Motor'!I19,"") | J20: =IF(ISNUMBER('TVS Motor'!J19),'TVS Motor'!J19,"") | ... S20: =IF(ISNUMBER('TVS Motor'!S19),'TVS Motor'!S19,"") -> 6800000 | T20: =COUNT(C20:S20) -> 2 | U20: ='TVS Motor'!C7 -> Total annual capacity per management (May-2026); earlier website figures split 2W/3W
A21: Royal Enfield | B21: 2W | C21: =IF(ISNUMBER('Royal Enfield'!C19),'Royal Enfield'!C19,"") | D21: =IF(ISNUMBER('Royal Enfield'!D19),'Royal Enfield'!D19,"") | E21: =IF(ISNUMBER('Royal Enfield'!E19),'Royal Enfield'!E19,"") | F21: =IF(ISNUMBER('Royal Enfield'!F19),'Royal Enfield'!F19,"") | G21: =IF(ISNUMBER('Royal Enfield'!G19),'Royal Enfield'!G19,"") | H21: =IF(ISNUMBER('Royal Enfield'!H19),'Royal Enfield'!H19,"") | I21: =IF(ISNUMBER('Royal Enfield'!I19),'Royal Enfield'!I19,"") | J21: =IF(ISNUMBER('Royal Enfield'!J19),'Royal Enfield'!J19,"") | ... S21: =IF(ISNUMBER('Royal Enfield'!S19),'Royal Enfield'!S19,"") -> 1460000 | T21: =COUNT(C21:S21) -> 3 | U21: ='Royal Enfield'!C7 -> Annual motorcycle capacity per Eicher ('around 14.6 lakh')
A22: Hero MotoCorp | B22: 2W | C22: =IF(ISNUMBER('Hero MotoCorp'!C19),'Hero MotoCorp'!C19,"") | D22: =IF(ISNUMBER('Hero MotoCorp'!D19),'Hero MotoCorp'!D19,"") | E22: =IF(ISNUMBER('Hero MotoCorp'!E19),'Hero MotoCorp'!E19,"") | F22: =IF(ISNUMBER('Hero MotoCorp'!F19),'Hero MotoCorp'!F19,"") | G22: =IF(ISNUMBER('Hero MotoCorp'!G19),'Hero MotoCorp'!G19,"") | H22: =IF(ISNUMBER('Hero MotoCorp'!H19),'Hero MotoCorp'!H19,"") -> 7650000 | I22: =IF(ISNUMBER('Hero MotoCorp'!I19),'Hero MotoCorp'!I19,"") | J22: =IF(ISNUMBER('Hero MotoCorp'!J19),'Hero MotoCorp'!J19,"") | ... S22: =IF(ISNUMBER('Hero MotoCorp'!S19),'Hero MotoCorp'!S19,"") | T22: =COUNT(C22:S22) -> 2 | U22: ='Hero MotoCorp'!C7 -> Plant-wise design capacity (11.6m); operational 9.1m at Mar-2020 per secondary source
A23: Ola Electric | B23: 2W-EV | C23: =IF(ISNUMBER('Ola Electric'!C19),'Ola Electric'!C19,"") | D23: =IF(ISNUMBER('Ola Electric'!D19),'Ola Electric'!D19,"") | E23: =IF(ISNUMBER('Ola Electric'!E19),'Ola Electric'!E19,"") | F23: =IF(ISNUMBER('Ola Electric'!F19),'Ola Electric'!F19,"") | G23: =IF(ISNUMBER('Ola Electric'!G19),'Ola Electric'!G19,"") | H23: =IF(ISNUMBER('Ola Electric'!H19),'Ola Electric'!H19,"") | I23: =IF(ISNUMBER('Ola Electric'!I19),'Ola Electric'!I19,"") | J23: =IF(ISNUMBER('Ola Electric'!J19),'Ola Electric'!J19,"") | ... S23: =IF(ISNUMBER('Ola Electric'!S19),'Ola Electric'!S19,"") | T23: =COUNT(C23:S23) -> 2 | U23: ='Ola Electric'!C7 -> Futurefactory installed vehicle capacity (DRHP); cells tracked separately in GWh
A24: Ather Energy | B24: 2W-EV | C24: =IF(ISNUMBER('Ather Energy'!C19),'Ather Energy'!C19,"") | D24: =IF(ISNUMBER('Ather Energy'!D19),'Ather Energy'!D19,"") | E24: =IF(ISNUMBER('Ather Energy'!E19),'Ather Energy'!E19,"") | F24: =IF(ISNUMBER('Ather Energy'!F19),'Ather Energy'!F19,"") | G24: =IF(ISNUMBER('Ather Energy'!G19),'Ather Energy'!G19,"") | H24: =IF(ISNUMBER('Ather Energy'!H19),'Ather Energy'!H19,"") | I24: =IF(ISNUMBER('Ather Energy'!I19),'Ather Energy'!I19,"") | J24: =IF(ISNUMBER('Ather Energy'!J19),'Ather Energy'!J19,"") | ... S24: =IF(ISNUMBER('Ather Energy'!S19),'Ather Energy'!S19,"") -> 420000 | T24: =COUNT(C24:S24) -> 5 | U24: ='Ather Energy'!C7 -> Hosur vehicle assembly capacity (c.35k/month)
A25: Orange/blue flags on the OEM sheets (verify / bracketed carry) are not repeated here. M&M = SUV operational capacity (monthly x12); Ola = Futurefactory vehicles only.
A27: 2. LATEST SNAPSHOT, FY26 UTILISATION AND CAPACITY GROWTH
A28: Company | B28: Segment | C28: Latest disclosed capacity | D28: As of | F28: Vehicle assembly sites | I28: FY26 volume | J28: Volume basis | L28: FY26 utilisation | M28: First FY in series | N28: Capacity (first) | O28: Last FY in series | P28: Capacity (last) | Q28: CAGR first -> last | R28: Bottom line
A29: Maruti Suzuki | B29: PV | C29: ='Maruti Suzuki'!C5 -> 2900000 | D29: ='Maruti Suzuki'!C6 -> 30-Jul-2026 | F29: ='Maruti Suzuki'!C8 -> 4 — Gurugram, Manesar, Kharkhoda (Haryana); Hansalpur (Gujarat). 5th site (Khoraj, Gujarat) in land stage | I29: ='Maruti Suzuki'!C9 -> 2340000 | J29: ='Maruti Suzuki'!C10 -> Production (FY26, company: >23.4 lakh) | L29: ='Maruti Suzuki'!C11 -> 0.975 | M29: FY10 | N29: ='Maruti Suzuki'!C19 -> 1000000 | O29: FY26 | P29: ='Maruti Suzuki'!S19 -> 2400000 | Q29: =IFERROR((P29/N29)^(1/(VALUE(RIGHT(O29,2))-VALUE(RIGHT(M29,2))))-1,"") -> 0.056241441 | R29: ='Maruti Suzuki'!C15 -> Capacity, not demand, is the binding constraint. FY26 output of 2.34m runs at c.94% of average installed capacity with c.190k orders pending at year-end. Two 250k plants (Kharkhoda-2, Hansalpur-D) are already live in FY27, and announced sites (Kharkhoda to 1m, Khoraj 1m, net of the Gurugram exit) cover almost all of the 4m FY31 target.
A30: Hyundai India | B30: PV | C30: ='Hyundai India'!C5 -> 994000 | D30: ='Hyundai India'!C6 -> FY26 (Mar-2026) | F30: ='Hyundai India'!C8 -> 2 — Chennai (Plants 1 & 2), Talegaon/Pune | I30: ='Hyundai India'!C9 -> 769280 | J30: ='Hyundai India'!C10 -> Production (FY26 AR, plant-wise) | L30: ='Hyundai India'!C11 -> 0.77392354 | M30: FY10 | N30: ='Hyundai India'!C19 -> 600000 | O30: FY26 | P30: ='Hyundai India'!S19 -> 994000 | Q30: =IFERROR((P30/N30)^(1/(VALUE(RIGHT(O30,2))-VALUE(RIGHT(M30,2))))-1,"") -> 0.032053464 | R30: ='Hyundai India'!C15 -> Talegaon resets the denominator. Capacity rises 21% to 994k in FY26 while output grows <1%; utilisation on year-end capacity falls to c.77%. The FY27-FY28 debate is about filling Pune and Chennai Plant 1, not adding new capacity.
A31: M&M | B31: PV | C31: ='M&M'!C5 -> 774000 | D31: ='M&M'!C6 -> FY26 exit (64.5k/month) | F31: ='M&M'!C8 -> SUVs: Chakan, Nashik (+ Haridwar/Zaheerabad under MLMML); Nagpur from 2028 | I31: ='M&M'!C9 -> 660276 | J31: ='M&M'!C10 -> Domestic SUV sales (FY26) — exports excluded | L31: ='M&M'!C11 -> 0.85306977 | M31: FY20 | N31: ='M&M'!M19 -> 228000 | O31: FY26 | P31: ='M&M'!S19 -> 774000 | Q31: =IFERROR((P31/N31)^(1/(VALUE(RIGHT(O31,2))-VALUE(RIGHT(M31,2))))-1,"") -> 0.22593568 | R31: ='M&M'!C15 -> The fastest capacity ramp in Indian PVs — running behind its own plan. SUV capacity more than triples from 19k/month (FY20) to 64.5k (FY26) and is guided to 82k by H2FY27 and c.132k/month by FY31 with Nagpur. FY25 (59k vs 64k plan) and FY26 (64.5k vs 72k plan) both undershoot guidance — execution slippage is the watch item.
A32: Tata PV | B32: PV | C32: ='Tata PV'!C5 -> 900000 | D32: ='Tata PV'!C6 -> Jun/Jul-2026 (mgmt) | F32: ='Tata PV'!C8 -> 5+ — Pune (five plants), Ranjangaon (JV), Sanand I & II, Panapakkam | I32: ='Tata PV'!C9 -> 642000 | J32: ='Tata PV'!C10 -> Total PV sales FY26 (c.642k incl. exports) | L32: ='Tata PV'!C11 -> 0.71333333 | M32: FY22 | N32: ='Tata PV'!O19 -> 480000 | O32: FY26 | P32: ='Tata PV'!S19 -> 900000 | Q32: =IFERROR((P32/N32)^(1/(VALUE(RIGHT(O32,2))-VALUE(RIGHT(M32,2))))-1,"") -> 0.17017366 | R32: ='Tata PV'!C15 -> Ample in aggregate, tight by model. c.0.9m installed vs c.642k FY26 sales (c.71%) yet management cites demand of c.70k/month outrunning supply — the constraint sits in specific shops and lines, which the Sanand +300k brownfield and multi-product line flexibility target.
A33: Tata CV | B33: CV | C33: ='Tata CV'!C5 -> n.d. | D33: ='Tata CV'!C6 -> Not disclosed | F33: ='Tata CV'!C8 -> 5 — Jamshedpur, Pune, Lucknow, Pantnagar, Dharwad | I33: ='Tata CV'!C9 -> 428329 | J33: ='Tata CV'!C10 -> Total CV sales FY26 (domestic + exports) | L33: ='Tata CV'!C11 -> n.d. | M33: n.d. | O33: n.d. | R33: ='Tata CV'!C15 -> The story is footprint, not units. No consolidated CV capacity figure is published post-FY11. FY26 sales rise 14% to 428k with capex guided at only 2-4% of revenue — brownfield headroom is assumed adequate. The Iveco tender (settlement 30-Oct-2026) adds a European/LatAm footprint and takes combined volume to 540k+.
A34: Ashok Leyland | B34: CV | C34: ='Ashok Leyland'!C5 -> 150000 | D34: ='Ashok Leyland'!C6 -> Sep-2010 (latest found) | F34: ='Ashok Leyland'!C8 -> 8 vehicle sites in India incl. Vijayawada (2025) and Lucknow EV (2026) | I34: ='Ashok Leyland'!C9 -> 220437 | J34: ='Ashok Leyland'!C10 -> Total deliveries FY26 (incl. exports) | L34: ='Ashok Leyland'!C11 -> n.d. | M34: n.d. | O34: n.d. | R34: ='Ashok Leyland'!C15 -> Disclosure stops in 2010. New capacity since is bus- and EV-led (Vijayawada 4,800 p.a., Lucknow 2,500 -> 5,000 p.a.) while FY26 deliveries hit a record 220k. Truck capacity headroom must be confirmed with management before modelling the next upcycle.
A35: Bajaj Auto | B35: 2W/3W | C35: ='Bajaj Auto'!C5 -> 7200000 | D35: ='Bajaj Auto'!C6 -> Jul-2026 (c.600k/month) | F35: ='Bajaj Auto'!C8 -> 4 — Waluj, Chakan (2 plants), Pantnagar, Akurdi (Chetak) | I35: ='Bajaj Auto'!C9 -> 5117667 | J35: ='Bajaj Auto'!C10 -> Total sales FY26 (domestic + exports) | L35: ='Bajaj Auto'!C11 -> 0.71078708 | M35: FY11 | N35: ='Bajaj Auto'!D19 -> 5040000 | O35: FY26 | P35: ='Bajaj Auto'!S19 -> 7200000 | Q35: =IFERROR((P35/N35)^(1/(VALUE(RIGHT(O35,2))-VALUE(RIGHT(M35,2))))-1,"") -> 0.024063288 | R35: ='Bajaj Auto'!C15 -> Exports drive the capacity call. FY26 volume of 5.12m (44% exports) sits at c.71% of the c.7.2m installed base, yet management is adding c.20% — read this as a mix-specific constraint (Chetak, CV/3W, premium motorcycles), not blanket shortage.
A36: TVS Motor | B36: 2W/3W | C36: ='TVS Motor'!C5 -> 6800000 | D36: ='TVS Motor'!C6 -> May-2026 (mgmt) | F36: ='TVS Motor'!C8 -> 3 in India — Hosur, Mysuru, Nalagarh (+ Karawang, Indonesia) | I36: ='TVS Motor'!C9 -> 5889000 | J36: ='TVS Motor'!C10 -> Total sales FY26 (2W + 3W incl. exports) | L36: ='TVS Motor'!C11 -> 0.86602941 | M36: FY23 | N36: ='TVS Motor'!P19 -> 5190000 | O36: FY26 | P36: ='TVS Motor'!S19 -> 6800000 | Q36: =IFERROR((P36/N36)^(1/(VALUE(RIGHT(O36,2))-VALUE(RIGHT(M36,2))))-1,"") -> 0.094243188 | R36: ='TVS Motor'!C15 -> TVS is outgrowing its plants. FY26 sales rise 24% to 5.89m on c.6.8m capacity (c.87%); management adds 1.5m within 12 months and is evaluating a new site, with EV lines going to 50k/month.
A37: Royal Enfield | B37: 2W | C37: ='Royal Enfield'!C5 -> 1460000 | D37: ='Royal Enfield'!C6 -> Feb/May-2026 | F37: ='Royal Enfield'!C8 -> 4 — Thiruvottiyur, Oragadam, Vallam Vadagal, Cheyyar (all Tamil Nadu) | I37: ='Royal Enfield'!C9 -> 1238659 | J37: ='Royal Enfield'!C10 -> Total sales FY26 (domestic + exports) | L37: ='Royal Enfield'!C11 -> 0.84839658 | M37: FY18 | N37: ='Royal Enfield'!K19 -> 825000 | O37: FY26 | P37: ='Royal Enfield'!S19 -> 1460000 | Q37: =IFERROR((P37/N37)^(1/(VALUE(RIGHT(O37,2))-VALUE(RIGHT(M37,2))))-1,"") -> 0.073958163 | R37: ='Royal Enfield'!C15 -> Running hot, expanding cheaply. FY26 volume of 1.24m (+23%) on c.1.46m capacity (c.85%); the Rs958cr Cheyyar expansion to 2.0m by FY28 costs c.Rs18k per unit of added capacity.
A38: Hero MotoCorp | B38: 2W | C38: ='Hero MotoCorp'!C5 -> 11600000 | D38: ='Hero MotoCorp'!C6 -> Mar-2020 (design, incl. Chittoor at full ramp) | F38: ='Hero MotoCorp'!C8 -> 6 — Dharuhera, Gurugram, Haridwar, Neemrana, Halol, Chittoor | I38: ='Hero MotoCorp'!C9 -> 6468834 | J38: ='Hero MotoCorp'!C10 -> Total dispatches FY26 (domestic + exports) | L38: ='Hero MotoCorp'!C11 -> 0.5576581 | M38: FY15 | N38: ='Hero MotoCorp'!H19 -> 7650000 | O38: FY20 | P38: ='Hero MotoCorp'!M19 -> 9100000 | Q38: =IFERROR((P38/N38)^(1/(VALUE(RIGHT(O38,2))-VALUE(RIGHT(M38,2))))-1,"") -> 0.035323308 | R38: ='Hero MotoCorp'!C15 -> Largest installed base, weakest current disclosure. Plant design capacity of 11.6m (2020) vs 6.47m FY26 dispatches implies c.5m units of structural slack; incremental capex now goes to EV lines (Vida 25k -> 50k+/month), not ICE.
A39: Ola Electric | B39: 2W-EV | C39: ='Ola Electric'!C5 -> 1000000 | D39: ='Ola Electric'!C6 -> Oct-2023 (DRHP) | F39: ='Ola Electric'!C8 -> 1 vehicle site (Futurefactory) + cell Gigafactory | I39: ='Ola Electric'!C9 -> 164295 | J39: ='Ola Electric'!C10 -> Retail registrations FY26 (media; not company deliveries) | L39: ='Ola Electric'!C11 -> 0.164295 | M39: FY22 | N39: ='Ola Electric'!O19 -> 500000 | O39: FY24 | P39: ='Ola Electric'!Q19 -> 1000000 | Q39: =IFERROR((P39/N39)^(1/(VALUE(RIGHT(O39,2))-VALUE(RIGHT(M39,2))))-1,"") -> 0.41421356 | R39: ='Ola Electric'!C15 -> Massive overcapacity in vehicles; capital has moved to cells. 1.0m vehicle capacity vs 164k FY26 retail (c.16%) after a 52% volume decline; the gigafactory runs at c.2.5 GWh installed with 5-6 GWh targeted.
A40: Ather Energy | B40: 2W-EV | C40: ='Ather Energy'!C5 -> 420000 | D40: ='Ather Energy'!C6 -> Aug-2026 | F40: ='Ather Energy'!C8 -> 1 (Hosur, two units); AURIC Bidkin commissioning Q3FY27 | I40: ='Ather Energy'!C9 -> 239178 | J40: ='Ather Energy'!C10 -> Retail registrations FY26 (media) | L40: ='Ather Energy'!C11 -> 0.56947143 | M40: FY22 | N40: ='Ather Energy'!O19 -> 120000 | O40: FY26 | P40: ='Ather Energy'!S19 -> 420000 | Q40: =IFERROR((P40/N40)^(1/(VALUE(RIGHT(O40,2))-VALUE(RIGHT(M40,2))))-1,"") -> 0.3677824 | R40: ='Ather Energy'!C15 -> Capacity is about to more than double. Hosur's 420k (c.57% utilised on FY26 retail of 239k) plus AURIC phase 1 (500k) in Q3FY27 takes capacity to 920k; management already flags 13-15k lost sales a month and is weighing an earlier phase 2.
A42: 3. CAPACITY OUTLOOK BY CERTAINTY TIER (units p.a.) — is the company target backed by named projects?
A43: Company | B43: Segment | C43: Base capacity | D43: Base | F43: Tier 1 adds | G43: Tier 2 adds | H43: Visible capacity | I43: Visible ÷ base | J43: Company target | K43: Target timing | M43: Gap to target | N43: Read-across
A44: Maruti Suzuki | B44: PV | C44: ='Maruti Suzuki'!C12 -> 2400000 | D44: ='Maruti Suzuki'!F12 -> FY26 year-end (row 19) | F44: =SUMIFS('Maruti Suzuki'!$D$83:$D$88,'Maruti Suzuki'!$G$83:$G$88,"Tier 1") -> 500000 | G44: =SUMIFS('Maruti Suzuki'!$D$83:$D$88,'Maruti Suzuki'!$G$83:$G$88,"Tier 2") -> 1000000 | H44: =IF(ISNUMBER(C44),C44+F44+G44,"") -> 3900000 | I44: =IF(AND(ISNUMBER(H44),ISNUMBER(C44)),H44/C44,"") -> 1.625 | J44: ='Maruti Suzuki'!C13 -> 4000000 | K44: ='Maruti Suzuki'!C14 -> FY2030-31 | M44: =IF(AND(ISNUMBER(J44),ISNUMBER(H44)),J44-H44,"") -> 100000 | N44: Tier 1 already live; Tier 2 includes the Gurugram exit (-0.5m). Remaining gap to 4m is small.
...

Sheet Maruti Suzuki
A1: Maruti Suzuki India Ltd (MSIL) — incl. Hansalpur (ex-Suzuki Motor Gujarat)
A2: MARUTI IN | Segment: PV | Units: vehicles p.a. unless stated | FY = year to 31-Mar | As of 14-Oct-2026
A3: Scope: Group India car capacity: Gurugram + Manesar + Kharkhoda (MSIL) and Hansalpur (Suzuki Motor Gujarat, 100% Suzuki until it became an MSIL subsidiary in FY24; since merged into MSIL). Excludes Toyota-built models sold by MSIL.
A4: A. SNAPSHOT
A5: Latest disclosed installed capacity (units p.a.) | C5: 2900000 | F5: As of 30-Jul-2026 [MS21]
A6: As of | C6: 30-Jul-2026
A7: Capacity definition / scope | C7: Annual vehicle production capacity as stated by MSIL/Suzuki (two-shift basis), all four sites
A8: Vehicle assembly sites | C8: 4 — Gurugram, Manesar, Kharkhoda (Haryana); Hansalpur (Gujarat). 5th site (Khoraj, Gujarat) in land stage
A9: FY26 volume (units) | C9: =IF(ISNUMBER(S21),S21,"n.d.") -> 2340000 | F9: Production (FY26, company: >23.4 lakh)
A10: FY26 volume basis | C10: Production (FY26, company: >23.4 lakh)
A11: FY26 utilisation | C11: =IFERROR(C9/S19,"n.d.") -> 0.975 | F11: FY26 volume ÷ FY26 year-end capacity (row 19)
A12: Outlook base capacity (units p.a.) | C12: =S19 -> 2400000 | F12: FY26 year-end (row 19)
A13: Company capacity target (units p.a.) | C13: 4000000 | F13: [MS11; MS23]
A14: Target timing | C14: FY2030-31
A15: Bottom line | C15: Capacity, not demand, is the binding constraint. FY26 output of 2.34m runs at c.94% of average installed capacity with c.190k orders pending at year-end. Two 250k plants (Kharkhoda-2, Hansalpur-D) are already live in FY27, and announced sites (Kharkhoda to 1m, Khoraj 1m, net of the Gurugram exit) cover almost all of the 4m FY31 target.
A17: B. COMPANY-LEVEL CAPACITY AND OUTPUT HISTORY, FY10–FY26 (blue = sourced input; black = formula; orange = verify; light blue = bracketed carry)
A18: Metric | B18: Unit | C18: FY10 | D18: FY11 | E18: FY12 | F18: FY13 | G18: FY14 | H18: FY15 | I18: FY16 | J18: FY17 | K18: FY18 | L18: FY19 | M18: FY20 | N18: FY21 | O18: FY22 | P18: FY23 | Q18: FY24 | R18: FY25 | S18: FY26 | T18: Notes
A19: Installed capacity, FY-end (reported) | B19: units p.a. | C19: 1000000 | D19: 1200000 | H19: 1500000 | I19: 1500000 | J19: 1750000 | K19: 1750000 | L19: 2000000 | M19: 2000000 | N19: 2000000 | O19: 2250000 | P19: 2250000 | Q19: 2250000 | R19: 2600000 | S19: 2400000 | T19: Group capacity incl. Hansalpur from FY17. FY12-FY14 FY-end figures not found in sources reviewed (Plant B Oct-2011, Plant C 2013).
A20: Capacity basis code | B20: code | C20: R | D20: R | H20: R | I20: R | J20: S | K20: S | L20: R | M20: R | N20: R | O20: R | P20: R | Q20: R | R20: R | S20: R | T20: R = company-reported total; S = sum of company-disclosed plants; M = management statement via media; A = monthly x12; D = DRHP/RHP
A21: Production — actual | B21: units | H21: 1308128 | P21: 1922000 | Q21: 1984000 | R21: 2102000 | S21: 2340000 | T21: FY23-FY26 rounded to thousands as reported. FY10 production >1.0m (millionth car rolled out 23-Mar-2010) — not entered.
A22: Sales / dispatches — actual, total | B22: units | C22: 1018365 | M22: 1563297 | N22: 1457861 | R22: 2234266 | S22: 2422713 | T22: Total = domestic incl. OEM supplies + exports. FY10 from AR; FY20-21 from monthly release; FY25-26 from results release.
A23: of which domestic | B23: units | C23: 870790 | I23: 1305351 | J23: 1444541 | K23: 1653500 | L23: 1753700 | M23: 1436124 | N23: 1323396 | R23: 1901681 | S23: 1974939 | T23: FY16-FY21: PV+LCV excl. OEM supplies to Toyota (not like-for-like with FY25-26, which include OEM supplies of c.113k in FY26).
A24: of which exports | B24: units | C24: 147575 | M24: 102171 | N24: 96139 | R24: 332585 | S24: 447774
A25: Utilisation — production ÷ FY-end capacity | B25: % | C25: =IF(AND(ISNUMBER(C21),ISNUMBER(C19)),C21/C19,"") | D25: =IF(AND(ISNUMBER(D21),ISNUMBER(D19)),D21/D19,"") | E25: =IF(AND(ISNUMBER(E21),ISNUMBER(E19)),E21/E19,"") | F25: =IF(AND(ISNUMBER(F21),ISNUMBER(F19)),F21/F19,"") | G25: =IF(AND(ISNUMBER(G21),ISNUMBER(G19)),G21/G19,"") | H25: =IF(AND(ISNUMBER(H21),ISNUMBER(H19)),H21/H19,"") -> 0.87208533 | I25: =IF(AND(ISNUMBER(I21),ISNUMBER(I19)),I21/I19,"") | J25: =IF(AND(ISNUMBER(J21),ISNUMBER(J19)),J21/J19,"") | ... S25: =IF(AND(ISNUMBER(S21),ISNUMBER(S19)),S21/S19,"") -> 0.975 | T25: Formula. Company convention (e.g., HMIL DRHP). Depressed in commissioning years.
A26: Utilisation — production ÷ avg(opening, closing) capacity | B26: % | C26: =IF(AND(ISNUMBER(C21),ISNUMBER(C19)),C21/C19,"") | D26: =IF(AND(ISNUMBER(D21),ISNUMBER(D19)),D21/IF(ISNUMBER(C19),AVERAGE(C19,D19),D19),"") | E26: =IF(AND(ISNUMBER(E21),ISNUMBER(E19)),E21/IF(ISNUMBER(D19),AVERAGE(D19,E19),E19),"") | F26: =IF(AND(ISNUMBER(F21),ISNUMBER(F19)),F21/IF(ISNUMBER(E19),AVERAGE(E19,F19),F19),"") | G26: =IF(AND(ISNUMBER(G21),ISNUMBER(G19)),G21/IF(ISNUMBER(F19),AVERAGE(F19,G19),G19),"") | H26: =IF(AND(ISNUMBER(H21),ISNUMBER(H19)),H21/IF(ISNUMBER(G19),AVERAGE(G19,H19),H19),"") -> 0.87208533 | I26: =IF(AND(ISNUMBER(I21),ISNUMBER(I19)),I21/IF(ISNUMBER(H19),AVERAGE(H19,I19),I19),"") | J26: =IF(AND(ISNUMBER(J21),ISNUMBER(J19)),J21/IF(ISNUMBER(I19),AVERAGE(I19,J19),J19),"") | K26: =IF(AND(ISNUMBER(K21),ISNUMBER(K19)),K21/IF(ISNUMBER(J19),AVERAGE(J19,K19),K19),"") | ... S26: =IF(AND(ISNUMBER(S21),ISNUMBER(S19)),S21/IF(ISNUMBER(R19),AVERAGE(R19,S19),S19),"") -> 0.936 | T26: Formula. Uses closing capacity where opening not disclosed.
A27: Utilisation — sales ÷ FY-end capacity | B27: % | C27: =IF(ISNUMBER(C19),IF(ISNUMBER(C22),C22/C19,IF(ISNUMBER(C23),C23/C19,"")),"") -> 1.018365 | D27: =IF(ISNUMBER(D19),IF(ISNUMBER(D22),D22/D19,IF(ISNUMBER(D23),D23/D19,"")),"") | E27: =IF(ISNUMBER(E19),IF(ISNUMBER(E22),E22/E19,IF(ISNUMBER(E23),E23/E19,"")),"") | F27: =IF(ISNUMBER(F19),IF(ISNUMBER(F22),F22/F19,IF(ISNUMBER(F23),F23/F19,"")),"") | G27: =IF(ISNUMBER(G19),IF(ISNUMBER(G22),G22/G19,IF(ISNUMBER(G23),G23/G19,"")),"") | H27: =IF(ISNUMBER(H19),IF(ISNUMBER(H22),H22/H19,IF(ISNUMBER(H23),H23/H19,"")),"") | I27: =IF(ISNUMBER(I19),IF(ISNUMBER(I22),I22/I19,IF(ISNUMBER(I23),I23/I19,"")),"") -> 0.870234 | J27: =IF(ISNUMBER(J19),IF(ISNUMBER(J22),J22/J19,IF(ISNUMBER(J23),J23/J19,"")),"") -> 0.825452 | ... S27: =IF(ISNUMBER(S19),IF(ISNUMBER(S22),S22/S19,IF(ISNUMBER(S23),S23/S19,"")),"") -> 1.0094638 | T27: Formula. Uses total sales, else domestic (understates where exports excluded).
A28: Capacity change vs prior FY | B28: units p.a. | D28: =IF(AND(ISNUMBER(D19),ISNUMBER(C19)),D19-C19,"") -> 200000 | E28: =IF(AND(ISNUMBER(E19),ISNUMBER(D19)),E19-D19,"") | F28: =IF(AND(ISNUMBER(F19),ISNUMBER(E19)),F19-E19,"") | G28: =IF(AND(ISNUMBER(G19),ISNUMBER(F19)),G19-F19,"") | H28: =IF(AND(ISNUMBER(H19),ISNUMBER(G19)),H19-G19,"") | I28: =IF(AND(ISNUMBER(I19),ISNUMBER(H19)),I19-H19,"") -> 0 | J28: =IF(AND(ISNUMBER(J19),ISNUMBER(I19)),J19-I19,"") -> 250000 | K28: =IF(AND(ISNUMBER(K19),ISNUMBER(J19)),K19-J19,"") -> 0 | ... S28: =IF(AND(ISNUMBER(S19),ISNUMBER(R19)),S19-R19,"") -> -200000 | T28: Formula; blank where either year undisclosed.
A29: Utilisation — company-reported | B29: % | T29: MSIL does not publish a utilisation %; FY26 release states sales were capacity-limited.
A30: Source IDs (see Source Log) | C30: MS01; MS02; MS04 | D30: MS03; MS05 | E30: MS30 | F30: MS03 | G30: MS13 | H30: MS06; MS07 | I30: MS07; MS08 | J30: MS06; MS07; MS10 | K30: MS10; MS29 | L30: MS09; MS10 | M30: MS10; MS22 | N30: MS10; MS22 | O30: MS10 | P30: MS12; MS19 | Q30: HY10; MS15; MS19 | R30: MS13; MS14; MS15; MS17; MS19 | S30: MS16; MS17; MS18; MS20
A31: Year notes | C31: Gurugram 0.70m (3 plants) + Manesar 0.30m | D31: 0.85m + 0.35m via productivity, no new plant | E31: Manesar Plant B (+0.25m) SOP Oct-2011 | F31: Plan: 1.75m by FY13-end incl. Plant C | G31: Manesar Plant C commissioned (2013) | H31: Implied by Suzuki: Gujarat +0.25m takes India to 1.75m | I31: Gurugram 0.7m + Manesar 0.8m; effective c.1.45m | J31: SMG Plant A SOP 1-Feb-2017 | K31: MSIL 1.5-1.55m (sources differ) + SMG 0.25m | L31: SMG Plant B + powertrain (Jan-2019) | M31: No change until Plant C | N31: No change until Plant C | O31: SMG Plant C SOP Apr-2021 | P31: 1.5m Haryana + 0.75m Gujarat | Q31: Unchanged; +0.1m Manesar line falls in FY25 | R31: +0.1m Manesar (Apr-24); Kharkhoda P1 (Feb-25) | S31: Gurugram restated 0.7m -> 0.5m
A33: C. PLANT-LEVEL CAPACITY AND OUTPUT BY FISCAL YEAR (disclosed points only; no interpolation)
A34: Plant / line | B34: Unit | C34: FY10 | D34: FY11 | E34: FY12 | F34: FY13 | G34: FY14 | H34: FY15 | I34: FY16 | J34: FY17 | K34: FY18 | L34: FY19 | M34: FY20 | N34: FY21 | O34: FY22 | P34: FY23 | Q34: FY24 | R34: FY25 | S34: FY26 | T34: Notes [sources]
A35: Gurugram (Haryana) | B35: units p.a. | C35: 700000 | D35: 850000 | I35: 700000 | R35: 700000 | S35: 500000 | T35: 3 assembly plants; Plant 1 (c.0.16m) phase-out from 2009; restated to 0.5m by May-2026 [MS02; MS03; MS07; MS23; MS20]
A36: Manesar (Haryana) | B36: units p.a. | C36: 300000 | D36: 350000 | I36: 800000 | R36: 900000 | S36: 900000 | T36: Plant A 2007, Plant B Oct-2011, Plant C 2013, +0.1m line Apr-2024 [MS02; MS03; MS07; MS13; MS20]
A37: Memo: Gurugram + Manesar combined (company-stated) | B37: units p.a. | L37: 1500000 | N37: 1500000 | P37: 1500000 | T37: 'Production ability' of MSIL's Haryana plants [MS09; MS10; MS12]
A38: Hansalpur (Gujarat) — ex-SMG | B38: units p.a. | J38: 250000 | K38: 250000 | L38: 500000 | M38: 500000 | N38: 500000 | O38: 750000 | P38: 750000 | Q38: 750000 | R38: 750000 | S38: 750000 | T38: Sum of plants at 250k each: A Feb-2017, B Jan-2019, C Apr-2021 (D Jul-2026 = FY27) [MS10; MS11; MS21]
A39: Kharkhoda (Haryana) | B39: units p.a. | R39: 250000 | S39: 250000 | T39: Plant 1 SOP 25-Feb-2025; Plant 2 SOP 18-May-2026 (FY27) [MS14; MS20]
A40: Hansalpur powertrain — engines | B40: engines p.a. | O40: 500000 | T40: SOP Jan-2019 with Plant B; 500k transmissions also [MS10]
A42: D. PLANT REGISTER
A43: Plant / site | B43: Location | D43: Entity / ownership | F43: SOP / commissioned | G43: Vehicle category | I43: Key models (latest disclosed) | M43: Platforms | O43: Initial capacity (units p.a.) | P43: Latest capacity (units p.a.) | Q43: As of | R43: Status | S43: Notes | V43: Sources [confidence]
...

Sheet Hyundai India
A1: Hyundai Motor India Ltd (HMIL)
A2: HYUNDAI IN | Segment: PV | Units: vehicles p.a. unless stated | FY = year to 31-Mar | As of 14-Oct-2026
A3: Scope: Chennai (Sriperumbudur: Plant 1 and Plant 2 — separate assembly lines) and Talegaon (Pune, ex-GM India) from Oct-2025. Excludes Kia India (Anantapur), a sister HMG company.
A4: A. SNAPSHOT
A5: Latest disclosed installed capacity (units p.a.) | C5: 994000 | F5: As of FY26 (Mar-2026) [HY11; HY15]
A6: As of | C6: FY26 (Mar-2026)
A7: Capacity definition / scope | C7: Installed annual vehicle capacity per HMIL (DRHP/AR basis)
A8: Vehicle assembly sites | C8: 2 — Chennai (Plants 1 & 2), Talegaon/Pune
A9: FY26 volume (units) | C9: =IF(ISNUMBER(S21),S21,"n.d.") -> 769280 | F9: Production (FY26 AR, plant-wise)
A10: FY26 volume basis | C10: Production (FY26 AR, plant-wise)
A11: FY26 utilisation | C11: =IFERROR(C9/S19,"n.d.") -> 0.77392354 | F11: FY26 volume ÷ FY26 year-end capacity (row 19)
A12: Outlook base capacity (units p.a.) | C12: =S19 -> 994000 | F12: FY26 year-end (row 19)
A13: Company capacity target (units p.a.) | C13: 1074000 | F13: [HY10; HY12]
A14: Target timing | C14: Talegaon at 250k (c.2028)
A15: Bottom line | C15: Talegaon resets the denominator. Capacity rises 21% to 994k in FY26 while output grows <1%; utilisation on year-end capacity falls to c.77%. The FY27-FY28 debate is about filling Pune and Chennai Plant 1, not adding new capacity.
A17: B. COMPANY-LEVEL CAPACITY AND OUTPUT HISTORY, FY10–FY26 (blue = sourced input; black = formula; orange = verify; light blue = bracketed carry)
A18: Metric | B18: Unit | C18: FY10 | D18: FY11 | E18: FY12 | F18: FY13 | G18: FY14 | H18: FY15 | I18: FY16 | J18: FY17 | K18: FY18 | L18: FY19 | M18: FY20 | N18: FY21 | O18: FY22 | P18: FY23 | Q18: FY24 | R18: FY25 | S18: FY26 | T18: Notes
A19: Installed capacity, FY-end (reported) | B19: units p.a. | C19: 600000 | I19: 680000 | K19: 700000 | L19: 750000 | M19: 750000 | N19: 750000 | O19: 758000 | P19: 770000 | Q19: 824000 | R19: 824000 | S19: 994000 | T19: FY11-FY15 and FY17 not found. FY20-FY21 bracketed (7.5 lakh until H1-2023 per Aug-2023 statement; DRHP shows 758k for FY22 — rounding).
A20: Capacity basis code | B20: code | C20: M | I20: M | K20: M | L20: M | M20: M* | N20: M* | O20: D | P20: D | Q20: D | R20: R | S20: R | T20: R = company-reported total; S = sum of company-disclosed plants; M = management statement via media; A = monthly x12; D = DRHP/RHP
A21: Production — actual | B21: units | O21: 606100 | P21: 727300 | Q21: 787500 | R21: 762900 | S21: 769280 | T21: FY22-FY26 from FY26 AR Board's Report (plant-wise in section C). CY2016 665k and CY2017 678k (calendar) noted in HY18.
A22: Sales / dispatches — actual, total | B22: units | O22: 610760 | P22: 720565 | Q22: 777876 | R22: 762052 | S22: 775031 | T22: Domestic + exports per FY26 AR.
A23: of which domestic | B23: units | O23: 481500 | P23: 567546 | Q23: 614721 | R23: 598666 | S23: 584906
A24: of which exports | B24: units | O24: 129260 | P24: 153019 | Q24: 163155 | R24: 163386 | S24: 190125
A25: Utilisation — production ÷ FY-end capacity | B25: % | C25: =IF(AND(ISNUMBER(C21),ISNUMBER(C19)),C21/C19,"") | D25: =IF(AND(ISNUMBER(D21),ISNUMBER(D19)),D21/D19,"") | E25: =IF(AND(ISNUMBER(E21),ISNUMBER(E19)),E21/E19,"") | F25: =IF(AND(ISNUMBER(F21),ISNUMBER(F19)),F21/F19,"") | G25: =IF(AND(ISNUMBER(G21),ISNUMBER(G19)),G21/G19,"") | H25: =IF(AND(ISNUMBER(H21),ISNUMBER(H19)),H21/H19,"") | I25: =IF(AND(ISNUMBER(I21),ISNUMBER(I19)),I21/I19,"") | J25: =IF(AND(ISNUMBER(J21),ISNUMBER(J19)),J21/J19,"") | ... S25: =IF(AND(ISNUMBER(S21),ISNUMBER(S19)),S21/S19,"") -> 0.77392354 | T25: Formula. Company convention (e.g., HMIL DRHP). Depressed in commissioning years.
A26: Utilisation — production ÷ avg(opening, closing) capacity | B26: % | C26: =IF(AND(ISNUMBER(C21),ISNUMBER(C19)),C21/C19,"") | D26: =IF(AND(ISNUMBER(D21),ISNUMBER(D19)),D21/IF(ISNUMBER(C19),AVERAGE(C19,D19),D19),"") | E26: =IF(AND(ISNUMBER(E21),ISNUMBER(E19)),E21/IF(ISNUMBER(D19),AVERAGE(D19,E19),E19),"") | F26: =IF(AND(ISNUMBER(F21),ISNUMBER(F19)),F21/IF(ISNUMBER(E19),AVERAGE(E19,F19),F19),"") | G26: =IF(AND(ISNUMBER(G21),ISNUMBER(G19)),G21/IF(ISNUMBER(F19),AVERAGE(F19,G19),G19),"") | H26: =IF(AND(ISNUMBER(H21),ISNUMBER(H19)),H21/IF(ISNUMBER(G19),AVERAGE(G19,H19),H19),"") | I26: =IF(AND(ISNUMBER(I21),ISNUMBER(I19)),I21/IF(ISNUMBER(H19),AVERAGE(H19,I19),I19),"") | J26: =IF(AND(ISNUMBER(J21),ISNUMBER(J19)),J21/IF(ISNUMBER(I19),AVERAGE(I19,J19),J19),"") | K26: =IF(AND(ISNUMBER(K21),ISNUMBER(K19)),K21/IF(ISNUMBER(J19),AVERAGE(J19,K19),K19),"") | ... S26: =IF(AND(ISNUMBER(S21),ISNUMBER(S19)),S21/IF(ISNUMBER(R19),AVERAGE(R19,S19),S19),"") -> 0.84629263 | T26: Formula. Uses closing capacity where opening not disclosed.
A27: Utilisation — sales ÷ FY-end capacity | B27: % | C27: =IF(ISNUMBER(C19),IF(ISNUMBER(C22),C22/C19,IF(ISNUMBER(C23),C23/C19,"")),"") | D27: =IF(ISNUMBER(D19),IF(ISNUMBER(D22),D22/D19,IF(ISNUMBER(D23),D23/D19,"")),"") | E27: =IF(ISNUMBER(E19),IF(ISNUMBER(E22),E22/E19,IF(ISNUMBER(E23),E23/E19,"")),"") | F27: =IF(ISNUMBER(F19),IF(ISNUMBER(F22),F22/F19,IF(ISNUMBER(F23),F23/F19,"")),"") | G27: =IF(ISNUMBER(G19),IF(ISNUMBER(G22),G22/G19,IF(ISNUMBER(G23),G23/G19,"")),"") | H27: =IF(ISNUMBER(H19),IF(ISNUMBER(H22),H22/H19,IF(ISNUMBER(H23),H23/H19,"")),"") | I27: =IF(ISNUMBER(I19),IF(ISNUMBER(I22),I22/I19,IF(ISNUMBER(I23),I23/I19,"")),"") | J27: =IF(ISNUMBER(J19),IF(ISNUMBER(J22),J22/J19,IF(ISNUMBER(J23),J23/J19,"")),"") | ... S27: =IF(ISNUMBER(S19),IF(ISNUMBER(S22),S22/S19,IF(ISNUMBER(S23),S23/S19,"")),"") -> 0.77970926 | T27: Formula. Uses total sales, else domestic (understates where exports excluded).
A28: Capacity change vs prior FY | B28: units p.a. | D28: =IF(AND(ISNUMBER(D19),ISNUMBER(C19)),D19-C19,"") | E28: =IF(AND(ISNUMBER(E19),ISNUMBER(D19)),E19-D19,"") | F28: =IF(AND(ISNUMBER(F19),ISNUMBER(E19)),F19-E19,"") | G28: =IF(AND(ISNUMBER(G19),ISNUMBER(F19)),G19-F19,"") | H28: =IF(AND(ISNUMBER(H19),ISNUMBER(G19)),H19-G19,"") | I28: =IF(AND(ISNUMBER(I19),ISNUMBER(H19)),I19-H19,"") | J28: =IF(AND(ISNUMBER(J19),ISNUMBER(I19)),J19-I19,"") | K28: =IF(AND(ISNUMBER(K19),ISNUMBER(J19)),K19-J19,"") | ... S28: =IF(AND(ISNUMBER(S19),ISNUMBER(R19)),S19-R19,"") -> 170000 | T28: Formula; blank where either year undisclosed.
A29: Utilisation — company-reported | B29: % | O29: 0.7996 | P29: 0.9445 | T29: DRHP: Chennai utilisation on closing installed capacity (row 25 replicates this basis).
A30: Source IDs (see Source Log) | C30: HY04 | D30: HY04 | I30: HY05 | J30: HY05; HY18 | K30: HY06; HY18 | L30: HY07 | M30: HY09 | N30: HY09 | O30: HY08; HY11 | P30: HY08; HY11 | Q30: HY09; HY10; HY11 | R30: HY11 | S30: HY11; HY15
A31: Year notes | C31: Plant 2 (Feb-2008) doubled capacity to 0.6m | D31: c.12% debottleneck to c.670k planned | I31: Stated May-2016 as fully utilised | J31: Third plant (1m) evaluated; not executed | K31: Stated Mar/Jul-2018 | L31: +50k from Jan-2019 (value engineering) | M31: Bracketed: 7.5 lakh until H1-CY2023 | N31: Bracketed: 7.5 lakh until H1-CY2023 | O31: DRHP | P31: DRHP | Q31: 770k -> 824k (H1-CY2023) | R31: Talegaon engine shop SOP Jun-2025 (FY26) | S31: Talegaon vehicles from 1-Oct-2025 (+170k)
A33: C. PLANT-LEVEL CAPACITY AND OUTPUT BY FISCAL YEAR (disclosed points only; no interpolation)
A34: Plant / line | B34: Unit | C34: FY10 | D34: FY11 | E34: FY12 | F34: FY13 | G34: FY14 | H34: FY15 | I34: FY16 | J34: FY17 | K34: FY18 | L34: FY19 | M34: FY20 | N34: FY21 | O34: FY22 | P34: FY23 | Q34: FY24 | R34: FY25 | S34: FY26 | T34: Notes [sources]
A35: Chennai (Plants 1+2) capacity | B35: units p.a. | C35: 600000 | I35: 680000 | K35: 700000 | L35: 750000 | M35: 750000 | N35: 750000 | O35: 758000 | P35: 770000 | Q35: 824000 | R35: 824000 | S35: 824000 | T35: Plant 1 (1998, 300k reached 2006) + Plant 2 (Feb-2008, 300k) [HY01; HY02; HY08; HY11]
A36: Talegaon / Pune capacity | B36: units p.a. | S36: 170000 | T36: SOP 1-Oct-2025; to 250k by 2028 [HY11; HY12]
A37: Production — Chennai Plant 1 | B37: units | O37: 289308 | P37: 350342 | Q37: 408150 | R37: 408800 | S37: 352375 | T37: FY26 AR [HY11]
A38: Production — Chennai Plant 2 | B38: units | O38: 316792 | P38: 376958 | Q38: 379350 | R38: 354100 | S38: 352075 | T38: FY26 AR [HY11]
A39: Production — Pune (Talegaon) | B39: units | S39: 64830 | T39: Six months of operation [HY11]
A40: Check: plant production sum | B40: units | C40: =IF(COUNT(C37,C38,C39)=0,"",SUM(C37,C38,C39)) | D40: =IF(COUNT(D37,D38,D39)=0,"",SUM(D37,D38,D39)) | E40: =IF(COUNT(E37,E38,E39)=0,"",SUM(E37,E38,E39)) | F40: =IF(COUNT(F37,F38,F39)=0,"",SUM(F37,F38,F39)) | G40: =IF(COUNT(G37,G38,G39)=0,"",SUM(G37,G38,G39)) | H40: =IF(COUNT(H37,H38,H39)=0,"",SUM(H37,H38,H39)) | I40: =IF(COUNT(I37,I38,I39)=0,"",SUM(I37,I38,I39)) | J40: =IF(COUNT(J37,J38,J39)=0,"",SUM(J37,J38,J39)) | ... S40: =IF(COUNT(S37,S38,S39)=0,"",SUM(S37,S38,S39)) -> 769280 | T40: Formula; should equal row 21
A41: Talegaon engine capacity | B41: engines p.a. | S41: 150000 | T41: Engine shop SOP 16-Jun-2025 [HY12; HY13]
A43: D. PLANT REGISTER
...

Sheet M&M
A1: Mahindra & Mahindra Ltd — Automotive (SUV)
A2: MM IN | Segment: PV | Units: vehicles p.a. unless stated | FY = year to 31-Mar | As of 14-Oct-2026
A3: Scope: SUV operational capacity disclosed by M&M in units/month (ICE + BEV); annualised x12. Excludes LCV/3W (MLMML), trucks and tractors unless stated.
A4: A. SNAPSHOT
A5: Latest disclosed installed capacity (units p.a.) | C5: 774000 | F5: As of FY26 exit (64.5k/month) [MM08; MM11]
A6: As of | C6: FY26 exit (64.5k/month)
A7: Capacity definition / scope | C7: Operational SUV capacity, units/month x 12 (ICE 56.5k + BEV 8k at FY26 exit)
A8: Vehicle assembly sites | C8: SUVs: Chakan, Nashik (+ Haridwar/Zaheerabad under MLMML); Nagpur from 2028
A9: FY26 volume (units) | C9: =IF(ISNUMBER(S23),S23,"n.d.") -> 660276 | F9: Domestic SUV sales (FY26) — exports excluded
A10: FY26 volume basis | C10: Domestic SUV sales (FY26) — exports excluded
A11: FY26 utilisation | C11: =IFERROR(C9/S19,"n.d.") -> 0.85306977 | F11: FY26 volume ÷ FY26 year-end capacity (row 19)
A12: Outlook base capacity (units p.a.) | C12: =S19 -> 774000 | F12: FY26 year-end (row 19)
A13: Company capacity target (units p.a.) | C13: =2*S19 -> 1548000 | F13: [MM08; MM09]
A14: Target timing | C14: FY31 (2x FY26)
A15: Bottom line | C15: The fastest capacity ramp in Indian PVs — running behind its own plan. SUV capacity more than triples from 19k/month (FY20) to 64.5k (FY26) and is guided to 82k by H2FY27 and c.132k/month by FY31 with Nagpur. FY25 (59k vs 64k plan) and FY26 (64.5k vs 72k plan) both undershoot guidance — execution slippage is the watch item.
A17: B. COMPANY-LEVEL CAPACITY AND OUTPUT HISTORY, FY10–FY26 (blue = sourced input; black = formula; orange = verify; light blue = bracketed carry)
A18: Metric | B18: Unit | C18: FY10 | D18: FY11 | E18: FY12 | F18: FY13 | G18: FY14 | H18: FY15 | I18: FY16 | J18: FY17 | K18: FY18 | L18: FY19 | M18: FY20 | N18: FY21 | O18: FY22 | P18: FY23 | Q18: FY24 | R18: FY25 | S18: FY26 | T18: Notes
A19: Installed capacity, FY-end (reported) | B19: units p.a. | M19: =IF(ISNUMBER(M35),M35*12,"") -> 228000 | O19: =IF(ISNUMBER(O35),O35*12,"") -> 348000 | P19: =IF(ISNUMBER(P35),P35*12,"") -> 468000 | Q19: =IF(ISNUMBER(Q35),Q35*12,"") -> 588000 | R19: =IF(ISNUMBER(R35),R35*12,"") -> 708000 | S19: =IF(ISNUMBER(S35),S35*12,"") -> 774000 | T19: Formula: monthly operational capacity (section C) x 12. No consistent company series before FY20 in sources reviewed.
A20: Capacity basis code | B20: code | M20: A | O20: A | P20: A | Q20: A | R20: A | S20: A | T20: R = company-reported total; S = sum of company-disclosed plants; M = management statement via media; A = monthly x12; D = DRHP/RHP
A21: Production — actual | B21: units | T21: Not disclosed in sources reviewed.
A22: Sales / dispatches — actual, total | B22: units | T22: Total SUV incl. exports not captured.
A23: of which domestic | B23: units | R23: 551487 | S23: 660276 | T23: Domestic SUV volumes (record 660,276 in FY26).
A24: of which exports | B24: units
A25: Utilisation — production ÷ FY-end capacity | B25: % | C25: =IF(AND(ISNUMBER(C21),ISNUMBER(C19)),C21/C19,"") | D25: =IF(AND(ISNUMBER(D21),ISNUMBER(D19)),D21/D19,"") | E25: =IF(AND(ISNUMBER(E21),ISNUMBER(E19)),E21/E19,"") | F25: =IF(AND(ISNUMBER(F21),ISNUMBER(F19)),F21/F19,"") | G25: =IF(AND(ISNUMBER(G21),ISNUMBER(G19)),G21/G19,"") | H25: =IF(AND(ISNUMBER(H21),ISNUMBER(H19)),H21/H19,"") | I25: =IF(AND(ISNUMBER(I21),ISNUMBER(I19)),I21/I19,"") | J25: =IF(AND(ISNUMBER(J21),ISNUMBER(J19)),J21/J19,"") | ... S25: =IF(AND(ISNUMBER(S21),ISNUMBER(S19)),S21/S19,"") | T25: Formula. Company convention (e.g., HMIL DRHP). Depressed in commissioning years.
A26: Utilisation — production ÷ avg(opening, closing) capacity | B26: % | C26: =IF(AND(ISNUMBER(C21),ISNUMBER(C19)),C21/C19,"") | D26: =IF(AND(ISNUMBER(D21),ISNUMBER(D19)),D21/IF(ISNUMBER(C19),AVERAGE(C19,D19),D19),"") | E26: =IF(AND(ISNUMBER(E21),ISNUMBER(E19)),E21/IF(ISNUMBER(D19),AVERAGE(D19,E19),E19),"") | F26: =IF(AND(ISNUMBER(F21),ISNUMBER(F19)),F21/IF(ISNUMBER(E19),AVERAGE(E19,F19),F19),"") | G26: =IF(AND(ISNUMBER(G21),ISNUMBER(G19)),G21/IF(ISNUMBER(F19),AVERAGE(F19,G19),G19),"") | H26: =IF(AND(ISNUMBER(H21),ISNUMBER(H19)),H21/IF(ISNUMBER(G19),AVERAGE(G19,H19),H19),"") | I26: =IF(AND(ISNUMBER(I21),ISNUMBER(I19)),I21/IF(ISNUMBER(H19),AVERAGE(H19,I19),I19),"") | J26: =IF(AND(ISNUMBER(J21),ISNUMBER(J19)),J21/IF(ISNUMBER(I19),AVERAGE(I19,J19),J19),"") | K26: =IF(AND(ISNUMBER(K21),ISNUMBER(K19)),K21/IF(ISNUMBER(J19),AVERAGE(J19,K19),K19),"") | ... S26: =IF(AND(ISNUMBER(S21),ISNUMBER(S19)),S21/IF(ISNUMBER(R19),AVERAGE(R19,S19),S19),"") | T26: Formula. Uses closing capacity where opening not disclosed.
A27: Utilisation — sales ÷ FY-end capacity | B27: % | C27: =IF(ISNUMBER(C19),IF(ISNUMBER(C22),C22/C19,IF(ISNUMBER(C23),C23/C19,"")),"") | D27: =IF(ISNUMBER(D19),IF(ISNUMBER(D22),D22/D19,IF(ISNUMBER(D23),D23/D19,"")),"") | E27: =IF(ISNUMBER(E19),IF(ISNUMBER(E22),E22/E19,IF(ISNUMBER(E23),E23/E19,"")),"") | F27: =IF(ISNUMBER(F19),IF(ISNUMBER(F22),F22/F19,IF(ISNUMBER(F23),F23/F19,"")),"") | G27: =IF(ISNUMBER(G19),IF(ISNUMBER(G22),G22/G19,IF(ISNUMBER(G23),G23/G19,"")),"") | H27: =IF(ISNUMBER(H19),IF(ISNUMBER(H22),H22/H19,IF(ISNUMBER(H23),H23/H19,"")),"") | I27: =IF(ISNUMBER(I19),IF(ISNUMBER(I22),I22/I19,IF(ISNUMBER(I23),I23/I19,"")),"") | J27: =IF(ISNUMBER(J19),IF(ISNUMBER(J22),J22/J19,IF(ISNUMBER(J23),J23/J19,"")),"") | ... S27: =IF(ISNUMBER(S19),IF(ISNUMBER(S22),S22/S19,IF(ISNUMBER(S23),S23/S19,"")),"") -> 0.85306977 | T27: Formula. Uses total sales, else domestic (understates where exports excluded).
A28: Capacity change vs prior FY | B28: units p.a. | D28: =IF(AND(ISNUMBER(D19),ISNUMBER(C19)),D19-C19,"") | E28: =IF(AND(ISNUMBER(E19),ISNUMBER(D19)),E19-D19,"") | F28: =IF(AND(ISNUMBER(F19),ISNUMBER(E19)),F19-E19,"") | G28: =IF(AND(ISNUMBER(G19),ISNUMBER(F19)),G19-F19,"") | H28: =IF(AND(ISNUMBER(H19),ISNUMBER(G19)),H19-G19,"") | I28: =IF(AND(ISNUMBER(I19),ISNUMBER(H19)),I19-H19,"") | J28: =IF(AND(ISNUMBER(J19),ISNUMBER(I19)),J19-I19,"") | K28: =IF(AND(ISNUMBER(K19),ISNUMBER(J19)),K19-J19,"") | ... S28: =IF(AND(ISNUMBER(S19),ISNUMBER(R19)),S19-R19,"") -> 66000 | T28: Formula; blank where either year undisclosed.
A29: Utilisation — company-reported | B29: % | T29: Q4FY25: >90% SUV utilisation (MM07); Q3FY26: EV 93%, CV 86% (MM15) — not entered as point values.
A30: Source IDs (see Source Log) | C30: MM01 | M30: MM05 | O30: MM03; MM04 | P30: MM04; MM05 | Q30: MM05 | R30: MM08; MM13 | S30: MM08; MM11; MM12
A31: Year notes | C31: Chakan SOP 13-Mar-2010 (0.3m incl. 50k trucks) | M31: 19k/month | O31: 29k/month (stated Q2FY23) | P31: 39k/month | Q31: 49k/month | R31: 59k/month vs 64k plan | S31: 64.5k/month vs 72k plan; Nagpur announced
A33: C. PLANT-LEVEL CAPACITY AND OUTPUT BY FISCAL YEAR (disclosed points only; no interpolation)
A34: Plant / line | B34: Unit | C34: FY10 | D34: FY11 | E34: FY12 | F34: FY13 | G34: FY14 | H34: FY15 | I34: FY16 | J34: FY17 | K34: FY18 | L34: FY19 | M34: FY20 | N34: FY21 | O34: FY22 | P34: FY23 | Q34: FY24 | R34: FY25 | S34: FY26 | T34: Notes [sources]
A35: SUV operational capacity — total | B35: units/month | M35: 19000 | O35: 29000 | P35: 39000 | Q35: 49000 | R35: 59000 | S35: 64500 | T35: Drives row 19 (x12) [MM03; MM04; MM05; MM08]
A36: of which ICE | B36: units/month | R36: 54000 | S36: 56500 | T36: [MM07; MM08]
A37: of which BEV | B37: units/month | R37: 5000 | S37: 8000 | T37: INGLO + XUV400 [MM08]
A38: Memo: capacity guided a year earlier | B38: units/month | R38: 64000 | S38: 72000 | T38: Plan vs delivery [MM05]
A39: Chakan plant (all vehicles) | B39: units p.a. | C39: 300000 | M39: 320000 | T39: Incl. trucks; 2019 statement placed in FY20 [MM01; MM02]
A41: D. PLANT REGISTER
A42: Plant / site | B42: Location | D42: Entity / ownership | F42: SOP / commissioned | G42: Vehicle category | I42: Key models (latest disclosed) | M42: Platforms | O42: Initial capacity (units p.a.) | P42: Latest capacity (units p.a.) | Q42: As of | R42: Status | S42: Notes | V42: Sources [confidence]
A43: Chakan | B43: Pune, Maharashtra | D43: M&M (EVs via Mahindra Electric Automobile) | F43: 13-Mar-2010 | G43: SUV; trucks; BEV | I43: Scorpio-N, trucks 0.75-49t (2022); XUV700, Thar Roxx, INGLO BEVs (per media) | M43: Scorpio-N ladder; W601; INGLO; NU_IQ (FY28) | O43: 300000 | P43: 320000 | Q43: c.2019 | R43: Operating; +10k/month NU_IQ by FY28 | S43: 700 acres; engine shop 120k UV + 40k truck engines at SOP; capex c.Rs4,000cr planned (2007) | V43: [High/Med] MM01; MM02; MM14; MM16; MM09
...

Sheet Tata PV
A1: Tata Motors Passenger Vehicles Ltd (TMPV) — India PV/EV (ex-JLR plants abroad)
A2: TMPV IN | Segment: PV | Units: vehicles p.a. unless stated | FY = year to 31-Mar | As of 14-Oct-2026
A3: Scope: India PV/EV capacity: Pune (Pimpri/Chikhli), Ranjangaon (FIAPL JV with Stellantis), Sanand I, Sanand II (ex-Ford, TPEML), Panapakkam (with JLR, from Feb-2026). TMPV demerged from the CV business on 1-Oct-2025.
A4: A. SNAPSHOT
A5: Latest disclosed installed capacity (units p.a.) | C5: 900000 | F5: As of Jun/Jul-2026 (mgmt) [TP12; TP08]
A6: As of | C6: Jun/Jul-2026 (mgmt)
A7: Capacity definition / scope | C7: Installed PV capacity per management commentary (c.0.9m); Investor Day 2024 cited '1mn+' incl. expandable Sanand-2
A8: Vehicle assembly sites | C8: 5+ — Pune (five plants), Ranjangaon (JV), Sanand I & II, Panapakkam
A9: FY26 volume (units) | C9: =IF(ISNUMBER(S22),S22,"n.d.") -> 642000 | F9: Total PV sales FY26 (c.642k incl. exports)
A10: FY26 volume basis | C10: Total PV sales FY26 (c.642k incl. exports)
A11: FY26 utilisation | C11: =IFERROR(C9/S19,"n.d.") -> 0.71333333 | F11: FY26 volume ÷ FY26 year-end capacity (row 19)
A12: Outlook base capacity (units p.a.) | C12: =S19 -> 900000 | F12: FY26 year-end (row 19)
A13: Company capacity target (units p.a.) | C13: 1300000 | F13: [TP11; TP12]
A14: Target timing | C14: 2-3 years from Jun-2026 (c.FY29)
A15: Bottom line | C15: Ample in aggregate, tight by model. c.0.9m installed vs c.642k FY26 sales (c.71%) yet management cites demand of c.70k/month outrunning supply — the constraint sits in specific shops and lines, which the Sanand +300k brownfield and multi-product line flexibility target.
A17: B. COMPANY-LEVEL CAPACITY AND OUTPUT HISTORY, FY10–FY26 (blue = sourced input; black = formula; orange = verify; light blue = bracketed carry)
A18: Metric | B18: Unit | C18: FY10 | D18: FY11 | E18: FY12 | F18: FY13 | G18: FY14 | H18: FY15 | I18: FY16 | J18: FY17 | K18: FY18 | L18: FY19 | M18: FY20 | N18: FY21 | O18: FY22 | P18: FY23 | Q18: FY24 | R18: FY25 | S18: FY26 | T18: Notes
A19: Installed capacity, FY-end (reported) | B19: units p.a. | O19: 480000 | S19: 900000 | T19: Management-commentary only; no year-end series since FY11. FY24 '1mn+' (Investor Day) vs c.0.9m (Jun-2026) — definitional (expandable vs installed); not entered.
A20: Capacity basis code | B20: code | O20: M | S20: M | T20: R = company-reported total; S = sum of company-disclosed plants; M = management statement via media; A = monthly x12; D = DRHP/RHP
A21: Production — actual | B21: units | T21: Not disclosed in sources reviewed.
A22: Sales / dispatches — actual, total | B22: units | C22: =232006+35107 -> 267113 | D22: =269194+53544 -> 322738 | E22: =298991+56329 -> 355320 | S22: 642000 | T22: FY10-FY12: 'Tata & other brand' cars + UVs per 20-F (incl. Fiat cars distributed and exports) — not like-for-like. FY26 c.642k (rounded, media).
A23: of which domestic | B23: units | R23: 553585 | S23: 631387 | T23: Domestic PV (incl. EV).
A24: of which exports | B24: units
A25: Utilisation — production ÷ FY-end capacity | B25: % | C25: =IF(AND(ISNUMBER(C21),ISNUMBER(C19)),C21/C19,"") | D25: =IF(AND(ISNUMBER(D21),ISNUMBER(D19)),D21/D19,"") | E25: =IF(AND(ISNUMBER(E21),ISNUMBER(E19)),E21/E19,"") | F25: =IF(AND(ISNUMBER(F21),ISNUMBER(F19)),F21/F19,"") | G25: =IF(AND(ISNUMBER(G21),ISNUMBER(G19)),G21/G19,"") | H25: =IF(AND(ISNUMBER(H21),ISNUMBER(H19)),H21/H19,"") | I25: =IF(AND(ISNUMBER(I21),ISNUMBER(I19)),I21/I19,"") | J25: =IF(AND(ISNUMBER(J21),ISNUMBER(J19)),J21/J19,"") | ... S25: =IF(AND(ISNUMBER(S21),ISNUMBER(S19)),S21/S19,"") | T25: Formula. Company convention (e.g., HMIL DRHP). Depressed in commissioning years.
A26: Utilisation — production ÷ avg(opening, closing) capacity | B26: % | C26: =IF(AND(ISNUMBER(C21),ISNUMBER(C19)),C21/C19,"") | D26: =IF(AND(ISNUMBER(D21),ISNUMBER(D19)),D21/IF(ISNUMBER(C19),AVERAGE(C19,D19),D19),"") | E26: =IF(AND(ISNUMBER(E21),ISNUMBER(E19)),E21/IF(ISNUMBER(D19),AVERAGE(D19,E19),E19),"") | F26: =IF(AND(ISNUMBER(F21),ISNUMBER(F19)),F21/IF(ISNUMBER(E19),AVERAGE(E19,F19),F19),"") | G26: =IF(AND(ISNUMBER(G21),ISNUMBER(G19)),G21/IF(ISNUMBER(F19),AVERAGE(F19,G19),G19),"") | H26: =IF(AND(ISNUMBER(H21),ISNUMBER(H19)),H21/IF(ISNUMBER(G19),AVERAGE(G19,H19),H19),"") | I26: =IF(AND(ISNUMBER(I21),ISNUMBER(I19)),I21/IF(ISNUMBER(H19),AVERAGE(H19,I19),I19),"") | J26: =IF(AND(ISNUMBER(J21),ISNUMBER(J19)),J21/IF(ISNUMBER(I19),AVERAGE(I19,J19),J19),"") | K26: =IF(AND(ISNUMBER(K21),ISNUMBER(K19)),K21/IF(ISNUMBER(J19),AVERAGE(J19,K19),K19),"") | ... S26: =IF(AND(ISNUMBER(S21),ISNUMBER(S19)),S21/IF(ISNUMBER(R19),AVERAGE(R19,S19),S19),"") | T26: Formula. Uses closing capacity where opening not disclosed.
