Workbook

Sheet Read Me
A1: M&M (MM IN) — Growth Gems & SOTP Scenario Framework
A2: Bernstein India Autos | Client deliverable | 21 August 2026 | All values Rs mn unless stated
A5: PURPOSE | B5: Answers the client question: how should the Growth Gems be valued going forward, and how should that flow into M&M's overall SOTP? The workbook converts the existing single-point SOTP into a five-case scenario framework built on six explicit, independently flexible axes.
A7: THE SIX AXES | B7: 1. Core auto+farm — P/E multiple x FY28E earnings level 2. Listed subsidiaries — control premium, stake-level discount, re-rating 3. MEAL (EV subsidiary) — valuation METHODOLOGY, not just level 4. Growth Gems — book / private mark / monetisation mark / 5x-Challenge target 5. Holdco discount — 0% to 25% 6. Structure events — IPOs, InvIT, stake sales (drive movement across axes 3-5)
A9: THE CENTRAL ISSUE | B9: MEAL is c.22% of the current gross SOTP and is carried on a 'last funding round +20%/yr' mark of Rs 1,296,000mn. That methodology is contradicted by MEAL's own CCPS conversion on 1 May 2026 at a value of Rs 40,425cr (Rs 404,250mn) — roughly one third. MEAL is therefore modelled as the PRIMARY scenario axis, not a fixed block.
A11: TAB GUIDE | B11: Assumptions ....... every input and scenario lever. THE ONLY TAB TO EDIT. Current SOTP ...... the existing valuation, reproduced as-is, with issues flagged Growth Gems ....... gem-by-gem valuation ladder across all five scenarios MEAL Valuation .... the EV subsidiary methodology ladder Scenario SOTP ..... the summary five-case grid and target prices SOTP Detail ....... full SOTP in the original format, one table per scenario, with a logic column Sensitivity ....... core multiple vs MEAL value, and holdco discount flex
A13: COLOUR LEGEND | B13: BLUE text = hardcoded input or scenario lever — edit these BLACK text = formula calculated on the same sheet GREEN text = link pulled from another sheet YELLOW fill = key assumption worth challenging
A15: HEALTH WARNING | B15: Gem book values are an allocation of the Rs 199,487mn 'Other investments' line in the existing SOTP and are ESTIMATES, not disclosed segmentals. Private marks (LMM Rs 10,822cr Lightrock round, Jul-26; Susten OTPP-implied) are reported transaction values. Blue-sky targets are management's stated ambition, not our forecast.

Sheet Assumptions
A1: Assumptions & Scenario Levers
A2: Blue cells are inputs — this is the only tab that should be edited. Everything else recalculates.
A4: 1. GLOBAL INPUTS
A5: Input | B5: Value | C5: Unit | H5: Source / logic
A6: Shares outstanding | B6: 1203 | C6: mn | H6: Verified share count, Aug-26. NOTE: the existing SOTP implies c.1,243mn (3,284,241 / 2,642) — c.3% too high, which understates every per-share line.
A7: Current share price | B7: 3418 | C7: Rs | H7: Market price, 21-Aug-26. Used only for upside/downside.
A8: INR/USD | B8: 88 | C8: - | H8: Used to translate management's US$ Growth Gem valuation targets.
A9: FY28E core PAT (auto + farm, ex-S&A) | B9: 182458 | C9: Rs mn | H9: Derived from the existing SOTP: core value 3,284,241 / 18x = FY28E PAT. Anchors the core leg so the model reconciles to the current note.
A11: 2. LISTED SUBSIDIARIES — MARKET DATA (refresh to a single trading date before publishing)
A12: Entity | B12: Mcap (Rs mn) | C12: M&M stake % | H12: Source / logic
A13: MMFSL (MMFS IN) | B13: 553760 | C13: 0.52 | H13: Mcap c.Rs 55,376cr (Aug-26) — the existing SOTP carries Rs 49,553cr. Refresh upward.
A14: Tech Mahindra (TECHM IN) | B14: 1530000 | C14: 0.28 | H14: Mcap c.Rs 153,000cr — consistent with the existing SOTP. Non-core, minority-controlled.
A15: M&M Logistics (MAHLOG IN) | B15: 41310 | C15: 0.58 | H15: Per existing SOTP; rights issue completed FY26 — verify post-issue mcap and stake.
A16: Mahindra Lifespace (MAHLIFE IN) | B16: 79929 | C16: 0.51 | H16: Per existing SOTP; consistent with market (c.Rs 7,700-8,500cr).
A17: Mahindra Holidays (MHRL IN) | B17: 64000 | C17: 0.67 | H17: Mcap c.Rs 6,400cr (Aug-26) — the existing SOTP carries Rs 4,422cr. Refresh upward.
A19: 3. MEAL (EV SUBSIDIARY) — INPUTS
A20: Input | B20: Value | C20: Unit | H20: Source / logic
A21: M&M stake in MEAL (post CCPS conversion) | B21: 0.9245 | C21: % | H21: BSE filing 1-May-26: CCPS converted, M&M diluted from 99.99% to 92.45%. The existing SOTP labels the stake '78%' but computes 1,214,767/1,296,000 = 93.7% — the label is wrong and the maths is close to right.
A22: MEAL CCPS conversion value (1-May-26) | B22: 404250 | C22: Rs mn | H22: Rs 40,425cr per the BSE filing. Best read as a contractual conversion-mechanism value, not a fresh round — but it is the ONLY transaction-based datapoint on MEAL equity value, and it sits at c.1/3 of the carried mark.
A23: MEAL funding-round mark (Temasek Aug-23 +20%/yr) | B23: 1296000 | C23: Rs mn | H23: The existing SOTP methodology: Rs 80,580cr Temasek mark (Aug-23) compounded at 20% p.a. Never tested by a priced round.
A24: FY26 EV business revenue (actual) | B24: 141110 | C24: Rs mn | H24: Sum of FY26 quarterly EV-business revenue. Blends MEAL with e-SUV contract manufacturing and PLI — treat as approximate.
A25: FY28E EV business revenue | B25: 235000 | C25: Rs mn | H25: Bernstein estimate. Scaling from c.5-6k/month Born-Electric run-rate on 8k/month Chakan capacity.
A27: 4. SCENARIO LEVERS — the six axes
A28: Lever | B28: Stress | C28: Bear | D28: Base | E28: Bull | F28: Blue Sky | G28: Unit | H28: Logic — why the lever moves this way
A29: Core P/E multiple (x FY28E) | B29: 12 | C29: 14 | D29: 18 | E29: 20 | F29: 22 | G29: x | H29: Base 18x is the existing note. 14x = the trough M&M has traded at through a rural down-cycle; 22x = the peak paid for #1 SUV + #1 tractor share with 20% ROE. Highest single contributor to the spread.
A30: Core FY28E earnings vs consensus | B30: -0.15 | C30: -0.1 | D30: 0 | E30: 0.05 | F30: 0.1 | G30: % | H30: Bear cases assume CAFE-III compliance cost, rural cycle turn and SUV competitive intensity (Tata, Maruti e-Vitara/Victoris, Toyota, Kia) bite. Bull assumes GST 2.0 demand pull-through holds.
A31: Control premium on listed subs | B31: 0 | C31: 0 | D31: 0.2 | E31: 0.2 | F31: 0.2 | G31: % | H31: The existing SOTP applies 20% to the four controlled listed subs. Bear/stress strip it — a control premium is only real if control is monetisable, and M&M has shown no intent to sell these.
A32: Tech Mahindra stake discount | B32: 0.3 | C32: 0.15 | D32: 0 | E32: 0 | F32: 0 | G32: % | H32: TechM is non-core, only 28%-held, and structurally slower. The market habitually discounts it inside M&M. Zero discount only if a stake reduction is signalled.
A33: Listed sub re-rating / (de-rating) | B33: 0 | C33: 0 | D33: 0 | E33: 0.05 | F33: 0.15 | G33: % | H33: Bull/blue-sky assume the listed tail re-rates with the group as gem IPOs crystallise marks.
A34: MEAL EV/Sales on FY28E | B34: 0 | C34: 2 | D34: 3 | E34: 0 | F34: 0 | G34: x | H34: Market-based cross-check. Ola Electric trades c.4-5x forward EV/sales while loss-making; global EV pure-plays (Li Auto, XPeng, NIO) sit low-single-digit. 3x on a profitable, share-gaining #2 is the defensible base.
A35: MEAL IPO / listing premium | B35: 0 | C35: 0 | D35: 0 | E35: 0 | F35: 0.15 | G35: % | H35: Applied only in blue sky, where MEAL lists and the private mark is validated at a premium.
A36: Growth Gems — multiple of book (default) | B36: 0.8 | C36: 1 | D36: 1.5 | E36: 2 | F36: 0 | G36: x | H36: Applied to gems with no external mark. 1.0x book = the existing SOTP treatment (status quo). Stress writes down sub-scale gems; base credits the 18% ROE hurdle being met.
A37: Private-mark illiquidity discount | B37: 0 | C37: 0 | D37: 0.2 | E37: 0.1 | F37: 0 | G37: % | H37: Haircut on last-round private marks for illiquidity and stale-price risk. Falls as gems approach listing.
A38: '5x Challenge' delivery probability | B38: 0 | C38: 0 | D38: 0 | E38: 0 | F38: 0.6 | G38: % | H38: Probability applied to management's stated targets (US$2-3bn per scalable gem, US$1bn per emerging gem by FY30). Credited in blue sky only.
A39: Holdco discount | B39: 0.25 | C39: 0.2 | D39: 0.1 | E39: 0.05 | F39: 0 | G39: % | H39: Base 10% = the existing note. Indian pure holdcos trade at 50-80% NAV discounts; M&M is an operating company with a subsidiary tail, so 10% is the right order of magnitude but is generous. Narrows on each crystallised listing.
A41: Note: an example of how to use this tab — change D29 from 18x to 16x and every scenario table, the detail SOTP and the sensitivity grid update.

Sheet Current SOTP
A1: Existing Bernstein SOTP — reproduced as-is
A2: Exactly as supplied. Hardcoded reference only; the scenario model does not read from this tab.
A4: Entity | B4: % Stake | C4: Ticker | D4: Market cap (Rs mn) | E4: M&M share (Rs mn) | F4: Comments | G4: Per share (Rs) | H4: Issue flagged
A5: Standalone Ex S&A | B5: 1 | E5: 3284241 | F5: 18x FY28 | G5: 2642 | H5: Multiple is fair-to-slightly-full vs M&M's own history and vs Maruti / Tata / HMIL. Retained as the base-case anchor.
A6: Listed subsidiary
A7: MMFSL | B7: 0.52 | C7: MMFS IN | D7: 495525 | E7: 310635 | F7: with 20% control premium | G7: 250 | H7: Mcap stale — c.Rs 55,376cr as at Aug-26 vs Rs 49,553cr here. Understates the block.
A8: Tech Mahindra | B8: 0.28 | C8: TECHM IN | D8: 1530000 | E8: 431613 | G8: 347 | H8: Carried at full market with no discount. Non-core and only 28%-held — the market applies a discount here.
A9: M&M Logistics | B9: 0.58 | C9: MAHLOG | D9: 41310 | E9: 28796 | F9: with 20% control premium | G9: 23 | H9: Immaterial to the target. Refresh post rights issue.
A10: Mahindra Lifespace Devel | B10: 0.51 | C10: MAHLIFE | D10: 79929 | E10: 49185 | F10: with 20% control premium | G10: 40 | H10: Consistent with market.
A11: Mahindra Holidays & Resorts | B11: 0.67 | C11: MHRL IN | D11: 44220 | E11: 35648 | F11: with 20% control premium | G11: 29 | H11: Mcap stale — c.Rs 6,400cr as at Aug-26 vs Rs 4,422cr here.
A12: Mahindra EV subsidiary | B12: 0.78 | C12: Private valuation | D12: 1296000 | E12: 1214767 | F12: with 20% control premium | G12: 977 | H12: THE CENTRAL ISSUE. (i) Stake is 92.45% post the 1-May-26 CCPS conversion, not 78% — though the maths implies 93.7%, so the label is the error. (ii) No control premium is actually applied despite the comment. (iii) The 'funding round +20%/yr' mark of Rs 1,296,000mn is c.3x the Rs 404,250mn CCPS conversion value and c.2x a market EV/sales cross-check.
A13: Non listed subsidiaries / JV
A14: Other investment | E14: 199487 | F14: At 1x FY26 book value | G14: 160 | H14: Holds the entire unlisted Growth Gems portfolio at book. Ignores the LMM Lightrock mark (Rs 10,822cr, Jul-26), the Susten OTPP mark and the InvIT, and gives zero credit to the '5x Challenge'. This is the client's actual question.
A15: Total | G15: =SUM(G5:G14) -> 4468 | H15: Sums to Rs 4,469/sh as per the note.
A16: Target (rounded off) | B16: 10% holdco discount | G16: 4100 | H16: Rs 4,469 x 0.90 = Rs 4,022, rounded to Rs 4,100.
A18: Implied share count | E18: =E5/G5 -> 1243.0889 | F18: mn shares | H18: c.1,243mn vs the verified c.1,203mn. Correcting this alone lifts every per-share line by c.3%.

Sheet Growth Gems
A1: Growth Gems — valuation framework, gem by gem
A2: Four valuation regimes: book (status quo) -> private mark -> monetisation mark -> '5x Challenge' target
A4: Gem | B4: Category | C4: M&M stake | D4: Book / invested capital (Rs mn) | E4: Latest external mark (100%, Rs mn) | F4: 5x target (US$bn, 100%) | G4: Stress | H4: Bear | I4: Base | J4: Bull | K4: Blue Sky | L4: Valuation logic & source
A5: Mahindra Last Mile Mobility | B5: Scalable | C5: 0.7579 | D5: 35000 | E5: 108220 | F5: 2 | G5: =$D5*Assumptions!$B$36 -> 28000 | H5: =$D5*Assumptions!$C$36 -> 35000 | I5: =IF($E5>0,$E5*$C5,$D5*Assumptions!$D$36)*(1-Assumptions!$D$37) -> 65615.95 | J5: =MAX(IF($E5>0,$E5*$C5*1.5,0),$D5*Assumptions!$E$36)*(1-Assumptions!$E$37) -> 110726.92 | K5: =MAX($F5*Assumptions!$B$8*1000*$C5*Assumptions!$F$38,$J5) -> 110726.92 | L5: Lightrock-led Rs 322cr round, 30-Jul-26, at Rs 10,822cr — with IFC and the India-Japan Fund/NIIF. Prior IFC round (2023) at up to Rs 6,020cr, i.e. the mark has c.1.8x'd in three years. >100,000 cumulative e-3W sold in FY26, c.40% L5 share, 85% YoY Q1FY27 volume growth. IPO planned H2-2027 — the nearest crystallisation event and the single best leading indicator for the whole gems thesis.
A6: Mahindra Susten (renewables) | B6: Scalable | C6: 0.7 | D6: 40000 | E6: 100000 | F6: 2 | G6: =$D6*Assumptions!$B$36 -> 32000 | H6: =$D6*Assumptions!$C$36 -> 40000 | I6: =IF($E6>0,$E6*$C6,$D6*Assumptions!$D$36)*(1-Assumptions!$D$37) -> 56000 | J6: =MAX(IF($E6>0,$E6*$C6*1.5,0),$D6*Assumptions!$E$36)*(1-Assumptions!$E$37) -> 94500 | K6: =MAX($F6*Assumptions!$B$8*1000*$C6*Assumptions!$F$38,$J6) -> 94500 | L6: OTPP bought 30% in Sep-22 at US$300m, implying c.Rs 7,900cr equity value; Rs 1,800cr rights issue Aug-25 at Rs 60.40/sh. Scaling 1.5GW to 7GW. InvIT planned — an InvIT crystallises a yield-based mark and is the second unlock after LMM.
A7: Mahindra Trucks & Buses (incl. SML) | B7: Scalable | C7: 1 | D7: 45000 | E7: 0 | F7: 2 | G7: =$D7*Assumptions!$B$36 -> 36000 | H7: =$D7*Assumptions!$C$36 -> 45000 | I7: =IF($E7>0,$E7*$C7,$D7*Assumptions!$D$36)*(1-Assumptions!$D$37) -> 54000 | J7: =MAX(IF($E7>0,$E7*$C7*1.5,0),$D7*Assumptions!$E$36)*(1-Assumptions!$E$37) -> 81000 | K7: =MAX($F7*Assumptions!$B$8*1000*$C7*Assumptions!$F$38,$J7) -> 105600 | L7: SML (Swaraj Mazda) acquisition completed. Targeting top-3 ILCV and a Rs 15,000cr business by FY31. No external mark, so valued off book until profitability is demonstrated — the gem most exposed to the 18% ROE hurdle.
A8: Mahindra Accelo | B8: Emerging | C8: 1 | D8: 15000 | E8: 0 | F8: 1 | G8: =$D8*Assumptions!$B$36 -> 12000 | H8: =$D8*Assumptions!$C$36 -> 15000 | I8: =IF($E8>0,$E8*$C8,$D8*Assumptions!$D$36)*(1-Assumptions!$D$37) -> 18000 | J8: =MAX(IF($E8>0,$E8*$C8*1.5,0),$D8*Assumptions!$E$36)*(1-Assumptions!$E$37) -> 27000 | K8: =MAX($F8*Assumptions!$B$8*1000*$C8*Assumptions!$F$38,$J8) -> 52800 | L8: Steel processing and vehicle recycling. Targeting the largest organised recycler position, c.25% share by FY28. Scrappage-policy optionality is real but unpriced.
A9: Mahindra Aerostructures | B9: Emerging | C9: 1 | D9: 12000 | E9: 0 | F9: 1 | G9: =$D9*Assumptions!$B$36 -> 9600 | H9: =$D9*Assumptions!$C$36 -> 12000 | I9: =IF($E9>0,$E9*$C9,$D9*Assumptions!$D$36)*(1-Assumptions!$D$37) -> 14400 | J9: =MAX(IF($E9>0,$E9*$C9*1.5,0),$D9*Assumptions!$E$36)*(1-Assumptions!$E$37) -> 21600 | K9: =MAX($F9*Assumptions!$B$8*1000*$C9*Assumptions!$F$38,$J9) -> 52800 | L9: Preferred aero component supplier. Long-cycle, order-book visible, but sub-scale. Global aerostructure peers trade on EV/sales, not book — a re-mark is credible once revenue scales.
A10: Classic Legends (Jawa/Yezdi/BSA) | B10: Emerging | C10: 0.6 | D10: 10000 | E10: 0 | F10: 1 | G10: =$D10*Assumptions!$B$36 -> 8000 | H10: =$D10*Assumptions!$C$36 -> 10000 | I10: =IF($E10>0,$E10*$C10,$D10*Assumptions!$D$36)*(1-Assumptions!$D$37) -> 12000 | J10: =MAX(IF($E10>0,$E10*$C10*1.5,0),$D10*Assumptions!$E$36)*(1-Assumptions!$E$37) -> 18000 | K10: =MAX($F10*Assumptions!$B$8*1000*$C10*Assumptions!$F$38,$J10) -> 31680 | L10: BSA Goldstar 650 award-winning; exports scaling. The clearest candidate for a strategic sale rather than an IPO — a global motorcycle brand portfolio has scarcity value.
A11: Car&Bike / Mahindra First Choice | B11: Emerging | C11: 1 | D11: 6000 | E11: 0 | F11: 1 | G11: =$D11*Assumptions!$B$36 -> 4800 | H11: =$D11*Assumptions!$C$36 -> 6000 | I11: =IF($E11>0,$E11*$C11,$D11*Assumptions!$D$36)*(1-Assumptions!$D$37) -> 7200 | J11: =MAX(IF($E11>0,$E11*$C11*1.5,0),$D11*Assumptions!$E$36)*(1-Assumptions!$E$37) -> 10800 | K11: =MAX($F11*Assumptions!$B$8*1000*$C11*Assumptions!$F$38,$J11) -> 52800 | L11: Content-to-commerce used-vehicle platform. Asset-light; would be valued on GMV/take-rate, not book, if listed. Note M&M has already exited First Choice Services — the discipline cuts both ways.
A12: Bristlecone | B12: Adjacent | C12: 0.75 | D12: 8000 | E12: 0 | F12: 0.75 | G12: =$D12*Assumptions!$B$36 -> 6400 | H12: =$D12*Assumptions!$C$36 -> 8000 | I12: =IF($E12>0,$E12*$C12,$D12*Assumptions!$D$36)*(1-Assumptions!$D$37) -> 9600 | J12: =MAX(IF($E12>0,$E12*$C12*1.5,0),$D12*Assumptions!$E$36)*(1-Assumptions!$E$37) -> 14400 | K12: =MAX($F12*Assumptions!$B$8*1000*$C12*Assumptions!$F$38,$J12) -> 29700 | L12: Supply-chain software and consulting. Comparable listed SaaS/consulting multiples are well above book, but growth has been unremarkable — modest credit only.
A13: Other JVs, agri and residual | B13: Residual | C13: 1 | D13: 28487 | E13: 0 | F13: 0 | G13: =$D13*Assumptions!$B$36 -> 22789.6 | H13: =$D13*Assumptions!$C$36 -> 28487 | I13: =IF($E13>0,$E13*$C13,$D13*Assumptions!$D$36)*(1-Assumptions!$D$37) -> 34184.4 | J13: =MAX(IF($E13>0,$E13*$C13*1.5,0),$D13*Assumptions!$E$36)*(1-Assumptions!$E$37) -> 51276.6 | K13: =MAX($F13*Assumptions!$B$8*1000*$C13*Assumptions!$F$38,$J13) -> 51276.6 | L13: Balancing figure to the Rs 199,487mn 'Other investments' line: Mahindra Agri/Krish-e, Teqo, HZPC, Summit, the Manulife 50:50 life-insurance JV (each partner up to US$400m) and other JVs. Held at book throughout — no credit taken, and a new loss-making bet here is what would widen the holdco discount.
A14: Total Growth Gems (Rs mn) | D14: =SUM(D5:D13) -> 199487 | G14: =SUM(G5:G13) -> 159589.6 | H14: =SUM(H5:H13) -> 199487 | I14: =SUM(I5:I13) -> 271000.35 | J14: =SUM(J5:J13) -> 429303.52 | K14: =SUM(K5:K13) -> 581883.52 | L14: Book total ties to the Rs 199,487mn 'Other investments' line in the existing SOTP.
A15: Per M&M share (Rs) | G15: =G14/Assumptions!$B$6 -> 132.65968 | H15: =H14/Assumptions!$B$6 -> 165.82461 | I15: =I14/Assumptions!$B$6 -> 225.27045 | J15: =J14/Assumptions!$B$6 -> 356.86078 | K15: =K14/Assumptions!$B$6 -> 483.6937 | L15: Existing SOTP carries this bucket at Rs 160/sh. The Bear column is the like-for-like comparison (1x book on the corrected share count).
A17: MANAGEMENT'S STATED AMBITION
A18: Anish Shah, Q4 FY25 (5 May 2025) and reaffirmed at the Nov-2025 Investor Day: scalable Growth Gems carry valuation targets of US$2-3bn each, emerging gems US$1bn, under a '5x Challenge' over FY25-30.
A19: Autocar Professional (Nov-2025 Investor Day): the gems' share of group market capitalisation grew sevenfold between March 2020 and November 2025, reaching Rs 56,000cr.
A20: Credibility anchor: under Anish Shah, M&M exited c.15 underperforming businesses (SsangYong/KG Mobility, Peugeot Motocycles, US farm restructuring, Sampo Rosenlew, First Choice Services), hit the 18% ROE target within c.18 months, and now runs a hard 18% ROE turn-around-or-exit hurdle. This is the reason to credit the gems in a bull case — but not the reason to credit them today at book-plus.

Sheet MEAL Valuation
A1: Mahindra Electric Automobile Ltd (MEAL) — the primary scenario axis
A2: c.22% of the existing gross SOTP rests on one untested private mark. Methodology, not level, is the variable.
A4: Scenario | B4: Method | C4: Equity value 100% (Rs mn) | D4: M&M stake | E4: M&M share (Rs mn) | F4: Per share (Rs) | H4: Logic & derivation
A5: Stress | B5: CCPS conversion mark | C5: =Assumptions!$B$22 -> 404250 | D5: =Assumptions!$B$21 -> 0.9245 | E5: =C5*D5 -> 373729.12 | F5: =E5/Assumptions!$B$6 -> 310.66428 | H5: Marks MEAL at the Rs 40,425cr value at which the CCPS actually converted on 1-May-26. This is the only transaction-based datapoint that exists. BII and Temasek received 12.11cr, 9.23cr and 13.84cr shares respectively, and total dilution of c.7.55% sits at or above the top of the originally disclosed ownership bands (BII 2.75-4.76%, Temasek 1.49-2.97%) — consistent with a LOWER conversion valuation maximising investor shares. If a fresh priced round lands anywhere near here, the existing SOTP loses c.Rs 670/share.
A6: Bear | B6: 2.0x FY28E EV revenue | C6: =Assumptions!$B$25*Assumptions!$C$34 -> 470000 | D6: =Assumptions!$B$21 -> 0.9245 | E6: =C6*D6 -> 434515 | F6: =E6/Assumptions!$B$6 -> 361.19285 | H6: Market cross-check at a multiple consistent with global EV pure-plays that have stopped growing (NIO c.1x, Li Auto and XPeng low-single-digit forward EV/sales). Assumes Born-Electric volumes plateau at the current c.5-6k/month and the FY30 target of 20-30% of SUV sales being EV slips again.
A7: Base | B7: 3.0x FY28E EV revenue | C7: =Assumptions!$B$25*Assumptions!$D$34 -> 705000 | D7: =Assumptions!$B$21 -> 0.9245 | E7: =C7*D7 -> 651772.5 | F7: =E7/Assumptions!$B$6 -> 541.78928 | H7: Our recommended base. FY26 EV revenue c.Rs 14,111cr with EBITDA c.Rs 1,314cr and PBIT +Rs 287cr — MEAL is profitable, unlike Ola Electric (Rs 487cr Q3FY26 net loss, 61% volume decline, Emkay TP cut c.60% in Feb-26). A 3x multiple on a profitable c.19% e-PV share #2 player, against Ola's c.4-5x while loss-making, is defensible and conservative. Roughly HALVES the existing MEAL contribution.
A8: Bull | B8: Funding round +20%/yr (status quo) | C8: =Assumptions!$B$23 -> 1296000 | D8: =Assumptions!$B$21 -> 0.9245 | E8: =C8*D8 -> 1198152 | F8: =E8/Assumptions!$B$6 -> 995.97007 | H8: The existing SOTP methodology retained — Rs 80,580cr Temasek mark (Aug-23) compounded at 20% p.a. This is a BULL case, not a base case: it requires the next priced round to validate a mark c.3x the CCPS conversion value. Read-across: Tata's TPEM was marked at c.US$9.1bn in the Jan-23 TPG Rise round on a much larger base (c.68-70% India EV PV share) — M&M is being carried at a similar absolute value on roughly a quarter of the share.
A9: Blue Sky | B9: Funding round mark + IPO premium | C9: =Assumptions!$B$23*(1+Assumptions!$F$35) -> 1490400 | D9: =Assumptions!$B$21 -> 0.9245 | E9: =C9*D9 -> 1377874.8 | F9: =E9/Assumptions!$B$6 -> 1145.3656 | H9: MEAL lists and prices above the last private mark. Requires sustained >6,000/month Born-Electric volumes, consistently EBIT-positive EV margins, and the 8k/month Chakan capacity being filled.
A11: Existing SOTP carries MEAL at | F11: 977 | H11: Rs 977/sh on a c.1,243mn implied share count. Our base of c.Rs 540 implies a c.Rs 435/share reduction — by far the highest-leverage single edit in the model.

Sheet Scenario SOTP
A1: M&M SOTP — five-case scenario grid
A2: Per share (Rs) unless stated. Every cell is a live formula off the Assumptions tab.
A4: Building block | B4: Stress | C4: Bear | D4: Base | E4: Bull | F4: Blue Sky | H4: Methodology — how this block is valued and why it moves
A5: Core auto + farm (ex-S&A) | B5: =Assumptions!$B$9*(1+Assumptions!$B$30)*Assumptions!$B$29/Assumptions!$B$6 -> 1547.0254 | C5: =Assumptions!$B$9*(1+Assumptions!$C$30)*Assumptions!$C$29/Assumptions!$B$6 -> 1911.0314 | D5: =Assumptions!$B$9*(1+Assumptions!$D$30)*Assumptions!$D$29/Assumptions!$B$6 -> 2730.0449 | E5: =Assumptions!$B$9*(1+Assumptions!$E$30)*Assumptions!$E$29/Assumptions!$B$6 -> 3185.0524 | F5: =Assumptions!$B$9*(1+Assumptions!$F$30)*Assumptions!$F$29/Assumptions!$B$6 -> 3670.3937 | H5: FY28E core PAT x (1 + earnings delta) x P/E, divided by shares. Anchored to the existing note's 18x. #1 SUV share (25.3% revenue share FY26), #1 tractor share (43.6%, highest-ever full year), 52.3% LCV <3.5T. FY26 consolidated PAT Rs 17,099cr (+35% ex one-offs), ROE 20.1%.
A6: Listed subsidiaries | B6: =(Assumptions!$B$13*Assumptions!$C$13*(1+Assumptions!$B$31)+Assumptions!$B$14*Assumptions!$C$14*(1-Assumptions!$B$32)+Assumptions!$B$15*Assumptions!$C$15*(1+Assumptions!$B$31)+Assumptions!$B$16*Assumptions!$C$16*(1+Assumptions!$B$31)+Assumptions!$B$17*Assumptions!$C$17*(1+Assumptions!$B$31))*(1+Assumptions!$B$33)/Assumptions!$B$6 -> 578.08711 | C6: =(Assumptions!$B$13*Assumptions!$C$13*(1+Assumptions!$C$31)+Assumptions!$B$14*Assumptions!$C$14*(1-Assumptions!$C$32)+Assumptions!$B$15*Assumptions!$C$15*(1+Assumptions!$C$31)+Assumptions!$B$16*Assumptions!$C$16*(1+Assumptions!$C$31)+Assumptions!$B$17*Assumptions!$C$17*(1+Assumptions!$C$31))*(1+Assumptions!$C$33)/Assumptions!$B$6 -> 631.50357 | D6: =(Assumptions!$B$13*Assumptions!$C$13*(1+Assumptions!$D$31)+Assumptions!$B$14*Assumptions!$C$14*(1-Assumptions!$D$32)+Assumptions!$B$15*Assumptions!$C$15*(1+Assumptions!$D$31)+Assumptions!$B$16*Assumptions!$C$16*(1+Assumptions!$D$31)+Assumptions!$B$17*Assumptions!$C$17*(1+Assumptions!$D$31))*(1+Assumptions!$D$33)/Assumptions!$B$6 -> 750.68208 | E6: =(Assumptions!$B$13*Assumptions!$C$13*(1+Assumptions!$E$31)+Assumptions!$B$14*Assumptions!$C$14*(1-Assumptions!$E$32)+Assumptions!$B$15*Assumptions!$C$15*(1+Assumptions!$E$31)+Assumptions!$B$16*Assumptions!$C$16*(1+Assumptions!$E$31)+Assumptions!$B$17*Assumptions!$C$17*(1+Assumptions!$E$31))*(1+Assumptions!$E$33)/Assumptions!$B$6 -> 788.21619 | F6: =(Assumptions!$B$13*Assumptions!$C$13*(1+Assumptions!$F$31)+Assumptions!$B$14*Assumptions!$C$14*(1-Assumptions!$F$32)+Assumptions!$B$15*Assumptions!$C$15*(1+Assumptions!$F$31)+Assumptions!$B$16*Assumptions!$C$16*(1+Assumptions!$F$31)+Assumptions!$B$17*Assumptions!$C$17*(1+Assumptions!$F$31))*(1+Assumptions!$F$33)/Assumptions!$B$6 -> 863.2844 | H6: Mark-to-market on each stake, then flexed for the control premium (four controlled subs), a Tech Mahindra stake discount, and a group re-rating. TechM alone is c.40-45% of this block, which is why the discount on it drives most of the spread.
A7: MEAL (EV subsidiary) | B7: ='MEAL Valuation'!$F$5 -> 310.66428 | C7: ='MEAL Valuation'!$F$6 -> 361.19285 | D7: ='MEAL Valuation'!$F$7 -> 541.78928 | E7: ='MEAL Valuation'!$F$8 -> 995.97007 | F7: ='MEAL Valuation'!$F$9 -> 1145.3656 | H7: Pulled from the MEAL Valuation tab. The methodology itself changes by scenario — CCPS conversion mark / market EV-sales / funding-round mark / funding-round + IPO premium. This is the widest block in the model: c.Rs 311 to c.Rs 1,145 per share.
A8: Growth Gems & other investments | B8: ='Growth Gems'!$G$15 -> 132.65968 | C8: ='Growth Gems'!$H$15 -> 165.82461 | D8: ='Growth Gems'!$I$15 -> 225.27045 | E8: ='Growth Gems'!$J$15 -> 356.86078 | F8: ='Growth Gems'!$K$15 -> 483.6937 | H8: Pulled from the Growth Gems tab. Regime shifts by scenario: 0.8x book (write-down) / 1.0x book (existing SOTP treatment) / latest private marks less illiquidity / monetisation marks / '5x Challenge' targets probability-weighted.
A9: Gross SOTP (Rs/share) | B9: =SUM(B5:B8) -> 2568.4365 | C9: =SUM(C5:C8) -> 3069.5524 | D9: =SUM(D5:D8) -> 4247.7867 | E9: =SUM(E5:E8) -> 5326.0994 | F9: =SUM(F5:F8) -> 6162.7374 | H9: Sum of the four blocks, before the holdco discount.
A10: Holdco discount | B10: =Assumptions!$B$39 -> 0.25 | C10: =Assumptions!$C$39 -> 0.2 | D10: =Assumptions!$D$39 -> 0.1 | E10: =Assumptions!$E$39 -> 0.05 | F10: =Assumptions!$F$39 -> 0 | H10: Indian pure holdcos (Bajaj Holdings, Maharashtra Scooters, Kalyani, JSW Holdings) trade at 50-80% NAV discounts; global conglomerates 5-20%. M&M is an operating company with a subsidiary tail, so 10% is the right order of magnitude — but it narrows only when marks are crystallised, not when they are asserted.
A11: TARGET PRICE (Rs/share) | B11: =B9*(1-B10) -> 1926.3274 | C11: =C9*(1-C10) -> 2455.642 | D11: =D9*(1-D10) -> 3823.008 | E11: =E9*(1-E10) -> 5059.7944 | F11: =F9*(1-F10) -> 6162.7374
A12: Current price (Rs) | B12: =Assumptions!$B$7 -> 3418 | C12: =Assumptions!$B$7 -> 3418 | D12: =Assumptions!$B$7 -> 3418 | E12: =Assumptions!$B$7 -> 3418 | F12: =Assumptions!$B$7 -> 3418
A13: Upside / (downside) | B13: =B11/B12-1 -> -0.4364168 | C13: =C11/C12-1 -> -0.28155589 | D13: =D11/D12-1 -> 0.11849269 | E13: =E11/E12-1 -> 0.48033775 | F13: =F11/F12-1 -> 0.80302439
A14: Implied P/E on FY28E core PAT (x) | B14: =B11*Assumptions!$B$6/Assumptions!$B$9 -> 12.700851 | C14: =C11*Assumptions!$B$6/Assumptions!$B$9 -> 16.19078 | D14: =D11*Assumptions!$B$6/Assumptions!$B$9 -> 25.206232 | E14: =E11*Assumptions!$B$6/Assumptions!$B$9 -> 33.360733 | F14: =F11*Assumptions!$B$6/Assumptions!$B$9 -> 40.632765 | H14: Sanity check: what the whole target implies on core earnings alone. A number far above the core multiple is the model telling you how much of the target is non-core — and therefore how much rests on marks rather than earnings.
A16: SCENARIO NARRATIVES — the one-line story behind each case
A17: Scenario | B17: Target (Rs) | C17: Upside | H17: The story
A18: Stress | B18: =B11 -> 1926.3274 | C18: =B13 -> -0.4364168 | H18: MEAL is re-marked to the CCPS conversion value in a priced round or a listing, the core de-rates through a rural down-cycle with CAFE-III costs landing, control premiums prove unmonetisable, TechM is discounted 30%, gems are written down below book, and the holdco discount widens to 25% as capital goes into new loss-making bets. This is the 'the marks were never real' case.
A19: Bear | B19: =C11 -> 2455.642 | C19: =C13 -> -0.28155589 | H19: No crisis, just no credit. MEAL is valued on where loss-making EV pure-plays actually trade, gems stay at 1x book exactly as the existing SOTP has them, no control premium is given, and the holdco discount sits at 20%. Note this case is only c.Rs 30/share below where the stock trades — the market is roughly here.
A20: Base | B20: =D11 -> 3823.008 | C20: =D13 -> 0.11849269 | H20: OUR RECOMMENDED CASE. Core holds 18x on consensus FY28E. MEAL is cross-checked to market at 3x FY28E EV revenue rather than compounded off a 2023 round. Gems are marked to their latest actual private rounds (LMM at the Jul-26 Lightrock mark, Susten OTPP-implied) less a 20% illiquidity haircut. Control premiums retained, holdco discount 10%.
A21: Bull | B21: =E11 -> 5059.7944 | C21: =E13 -> 0.48033775 | H21: The existing note's MEAL methodology is vindicated by a fresh priced round, LMM lists in H2-2027 above its last mark, the Susten InvIT prices, gems re-rate to 2x book, the listed tail re-rates 5% with the group and the holdco discount narrows to 5% as marks become market prices.
A22: Blue Sky | B22: =F11 -> 6162.7374 | C22: =F13 -> 0.80302439 | H22: MEAL lists at a premium to the private mark AND management delivers the '5x Challenge' — US$2-3bn per scalable gem, US$1bn per emerging gem — at 60% probability, with the holdco discount eliminated. This is the number to quote when a client asks what the ambition is worth if fully executed. It is not a forecast.
A24: Street context | H24: Consensus c.38 analysts, average TP c.Rs 4,318, range Rs 3,030-5,005. Nomura Rs 4,875 (16x FY28F EV/EBITDA), CLSA Rs 4,702, Jefferies Rs 4,500, Motilal Rs 4,521, HSBC Rs 4,250, Nuvama Rs 3,800 (25x core FY28 EPS + Rs 580/sh aggregate subsidiary value), Geojit Rs 3,508. Critically, NO accessible broker note discloses a standalone MEAL valuation line — the EV subsidiary is bundled everywhere. That is the analytical gap this framework exploits.

Sheet SOTP Detail
A1: Full SOTP in the original format — one table per scenario
A2: Same layout as the existing note, with an added logic column showing how each line is derived.
A4: SCENARIO 1 of 5 — STRESS
A5: Entity | B5: % Stake | C5: Ticker | D5: Market cap (Rs mn) | E5: M&M share (Rs mn) | F5: Comments | G5: Per share (Rs) | H5: Logic — how this number is arrived at
A6: Standalone Ex S&A | B6: 1 | E6: =Assumptions!$B$9*(1+Assumptions!$B$30)*Assumptions!$B$29 -> 1861071.6 | F6: =TEXT(Assumptions!$B$29,"0.0")&"x FY28E, earnings "&TEXT(Assumptions!$B$30,"+0%;-0%;0%")&" vs cons" -> 12.0x FY28E, earnings -15% vs cons | G6: =E6/Assumptions!$B$6 -> 1547.0254 | H6: FY28E core PAT of Rs 182,458mn (back-solved from the existing note: Rs 3,284,241mn / 18x), flexed for the scenario earnings delta, times the scenario P/E, divided by 1,203mn shares.
A7: Listed subsidiary
A8: MMFSL | B8: =Assumptions!$C$13 -> 0.52 | C8: MMFS IN | D8: =Assumptions!$B$13 -> 553760 | E8: =D8*B8*(1+Assumptions!$B$31)*(1+Assumptions!$B$33) -> 287955.2 | F8: ="control prem "&TEXT(Assumptions!$B$31,"0%") -> control prem 0% | G8: =E8/Assumptions!$B$6 -> 239.36426 | H8: Mcap x 52% x (1 + control premium). Control premium applied only where M&M has majority control AND monetisable optionality. Mcap refreshed to c.Rs 55,376cr (the existing note uses a stale Rs 49,553cr).
A9: Tech Mahindra | B9: =Assumptions!$C$14 -> 0.28 | C9: TECHM IN | D9: =Assumptions!$B$14 -> 1530000 | E9: =D9*B9*(1-Assumptions!$B$32)*(1+Assumptions!$B$33) -> 299880 | F9: ="stake disc "&TEXT(Assumptions!$B$32,"0%") -> stake disc 30% | G9: =E9/Assumptions!$B$6 -> 249.27681 | H9: Mcap x 28% x (1 - stake discount). No control premium — M&M does not control TechM outright. The stake discount reflects that TechM is non-core, slower-growing, and that the market has never given M&M full credit for it inside the SOTP.
A10: M&M Logistics | B10: =Assumptions!$C$15 -> 0.58 | C10: MAHLOG IN | D10: =Assumptions!$B$15 -> 41310 | E10: =D10*B10*(1+Assumptions!$B$31)*(1+Assumptions!$B$33) -> 23959.8 | F10: ="control prem "&TEXT(Assumptions!$B$31,"0%") -> control prem 0% | G10: =E10/Assumptions!$B$6 -> 19.916708 | H10: Mcap x 58% x (1 + control premium). Immaterial to the target; refresh post the FY26 rights issue.
A11: Mahindra Lifespace | B11: =Assumptions!$C$16 -> 0.51 | C11: MAHLIFE IN | D11: =Assumptions!$B$16 -> 79929 | E11: =D11*B11*(1+Assumptions!$B$31)*(1+Assumptions!$B$33) -> 40763.79 | F11: ="control prem "&TEXT(Assumptions!$B$31,"0%") -> control prem 0% | G11: =E11/Assumptions!$B$6 -> 33.885112 | H11: Mcap x 51% x (1 + control premium). A listed 'scalable gem' — already marked to market, so it does not double-count against the Growth Gems tab.
A12: Mahindra Holidays | B12: =Assumptions!$C$17 -> 0.67 | C12: MHRL IN | D12: =Assumptions!$B$17 -> 64000 | E12: =D12*B12*(1+Assumptions!$B$31)*(1+Assumptions!$B$33) -> 42880 | F12: ="control prem "&TEXT(Assumptions!$B$31,"0%") -> control prem 0% | G12: =E12/Assumptions!$B$6 -> 35.644223 | H12: Mcap x 67% x (1 + control premium). Mcap refreshed to c.Rs 6,400cr (the existing note uses a stale Rs 4,422cr). Also a listed scalable gem.
A13: Mahindra EV subsidiary (MEAL) | B13: =Assumptions!$B$21 -> 0.9245 | C13: Private valuation | D13: ='MEAL Valuation'!$C$5 -> 404250 | E13: ='MEAL Valuation'!$E$5 -> 373729.12 | F13: ='MEAL Valuation'!$B$5 -> CCPS conversion mark | G13: ='MEAL Valuation'!$F$5 -> 310.66428 | H13: Stake corrected to 92.45% (BSE filing, 1-May-26) from the '78%' label in the existing note. No control premium — MEAL is already >92% owned and consolidated, so a control premium on top of a whole-company valuation double-counts. Method for this scenario is shown in the Comments column; full derivation on the MEAL Valuation tab.
A14: Non listed subsidiaries / JV
A15: Growth Gems & other investments | E15: ='Growth Gems'!$G$14 -> 159589.6 | F15: 0.8x book | G15: ='Growth Gems'!$G$15 -> 132.65968 | H15: Write-down case: sub-scale gems fail the 18% ROE hurdle and are exited below carrying value.
A16: Total (gross) | G16: =SUM(G6:G15) -> 2568.4365 | H16: Sum of all blocks before the holdco discount.
A17: Target (rounded off) | B17: =Assumptions!$B$39 -> 0.25 | C17: holdco discount | G17: =ROUND(G16*(1-B17),-2) -> 1900 | H17: Gross SOTP less the holdco discount, rounded to the nearest Rs 100 as per house convention.
A18: Upside / (downside) vs current price | G18: =G17/Assumptions!$B$7-1 -> -0.44411937
A21: SCENARIO 2 of 5 — BEAR
A22: Entity | B22: % Stake | C22: Ticker | D22: Market cap (Rs mn) | E22: M&M share (Rs mn) | F22: Comments | G22: Per share (Rs) | H22: Logic — how this number is arrived at
A23: Standalone Ex S&A | B23: 1 | E23: =Assumptions!$B$9*(1+Assumptions!$C$30)*Assumptions!$C$29 -> 2298970.8 | F23: =TEXT(Assumptions!$C$29,"0.0")&"x FY28E, earnings "&TEXT(Assumptions!$C$30,"+0%;-0%;0%")&" vs cons" -> 14.0x FY28E, earnings -10% vs cons | G23: =E23/Assumptions!$B$6 -> 1911.0314 | H23: FY28E core PAT of Rs 182,458mn (back-solved from the existing note: Rs 3,284,241mn / 18x), flexed for the scenario earnings delta, times the scenario P/E, divided by 1,203mn shares.
A24: Listed subsidiary
A25: MMFSL | B25: =Assumptions!$C$13 -> 0.52 | C25: MMFS IN | D25: =Assumptions!$B$13 -> 553760 | E25: =D25*B25*(1+Assumptions!$C$31)*(1+Assumptions!$C$33) -> 287955.2 | F25: ="control prem "&TEXT(Assumptions!$C$31,"0%") -> control prem 0% | G25: =E25/Assumptions!$B$6 -> 239.36426 | H25: Mcap x 52% x (1 + control premium). Control premium applied only where M&M has majority control AND monetisable optionality. Mcap refreshed to c.Rs 55,376cr (the existing note uses a stale Rs 49,553cr).
A26: Tech Mahindra | B26: =Assumptions!$C$14 -> 0.28 | C26: TECHM IN | D26: =Assumptions!$B$14 -> 1530000 | E26: =D26*B26*(1-Assumptions!$C$32)*(1+Assumptions!$C$33) -> 364140 | F26: ="stake disc "&TEXT(Assumptions!$C$32,"0%") -> stake disc 15% | G26: =E26/Assumptions!$B$6 -> 302.69327 | H26: Mcap x 28% x (1 - stake discount). No control premium — M&M does not control TechM outright. The stake discount reflects that TechM is non-core, slower-growing, and that the market has never given M&M full credit for it inside the SOTP.
A27: M&M Logistics | B27: =Assumptions!$C$15 -> 0.58 | C27: MAHLOG IN | D27: =Assumptions!$B$15 -> 41310 | E27: =D27*B27*(1+Assumptions!$C$31)*(1+Assumptions!$C$33) -> 23959.8 | F27: ="control prem "&TEXT(Assumptions!$C$31,"0%") -> control prem 0% | G27: =E27/Assumptions!$B$6 -> 19.916708 | H27: Mcap x 58% x (1 + control premium). Immaterial to the target; refresh post the FY26 rights issue.
A28: Mahindra Lifespace | B28: =Assumptions!$C$16 -> 0.51 | C28: MAHLIFE IN | D28: =Assumptions!$B$16 -> 79929 | E28: =D28*B28*(1+Assumptions!$C$31)*(1+Assumptions!$C$33) -> 40763.79 | F28: ="control prem "&TEXT(Assumptions!$C$31,"0%") -> control prem 0% | G28: =E28/Assumptions!$B$6 -> 33.885112 | H28: Mcap x 51% x (1 + control premium). A listed 'scalable gem' — already marked to market, so it does not double-count against the Growth Gems tab.
A29: Mahindra Holidays | B29: =Assumptions!$C$17 -> 0.67 | C29: MHRL IN | D29: =Assumptions!$B$17 -> 64000 | E29: =D29*B29*(1+Assumptions!$C$31)*(1+Assumptions!$C$33) -> 42880 | F29: ="control prem "&TEXT(Assumptions!$C$31,"0%") -> control prem 0% | G29: =E29/Assumptions!$B$6 -> 35.644223 | H29: Mcap x 67% x (1 + control premium). Mcap refreshed to c.Rs 6,400cr (the existing note uses a stale Rs 4,422cr). Also a listed scalable gem.
A30: Mahindra EV subsidiary (MEAL) | B30: =Assumptions!$B$21 -> 0.9245 | C30: Private valuation | D30: ='MEAL Valuation'!$C$6 -> 470000 | E30: ='MEAL Valuation'!$E$6 -> 434515 | F30: ='MEAL Valuation'!$B$6 -> 2.0x FY28E EV revenue | G30: ='MEAL Valuation'!$F$6 -> 361.19285 | H30: Stake corrected to 92.45% (BSE filing, 1-May-26) from the '78%' label in the existing note. No control premium — MEAL is already >92% owned and consolidated, so a control premium on top of a whole-company valuation double-counts. Method for this scenario is shown in the Comments column; full derivation on the MEAL Valuation tab.
A31: Non listed subsidiaries / JV
A32: Growth Gems & other investments | E32: ='Growth Gems'!$H$14 -> 199487 | F32: 1x book (as existing) | G32: ='Growth Gems'!$H$15 -> 165.82461 | H32: Status quo — identical treatment to the existing SOTP's Rs 199,487mn at 1x FY26 book.
A33: Total (gross) | G33: =SUM(G23:G32) -> 3069.5524 | H33: Sum of all blocks before the holdco discount.
A34: Target (rounded off) | B34: =Assumptions!$C$39 -> 0.2 | C34: holdco discount | G34: =ROUND(G33*(1-B34),-2) -> 2500 | H34: Gross SOTP less the holdco discount, rounded to the nearest Rs 100 as per house convention.
A35: Upside / (downside) vs current price | G35: =G34/Assumptions!$B$7-1 -> -0.26857812
A38: SCENARIO 3 of 5 — BASE
A39: Entity | B39: % Stake | C39: Ticker | D39: Market cap (Rs mn) | E39: M&M share (Rs mn) | F39: Comments | G39: Per share (Rs) | H39: Logic — how this number is arrived at
A40: Standalone Ex S&A | B40: 1 | E40: =Assumptions!$B$9*(1+Assumptions!$D$30)*Assumptions!$D$29 -> 3284244 | F40: =TEXT(Assumptions!$D$29,"0.0")&"x FY28E, earnings "&TEXT(Assumptions!$D$30,"+0%;-0%;0%")&" vs cons" -> 18.0x FY28E, earnings 0% vs cons | G40: =E40/Assumptions!$B$6 -> 2730.0449 | H40: FY28E core PAT of Rs 182,458mn (back-solved from the existing note: Rs 3,284,241mn / 18x), flexed for the scenario earnings delta, times the scenario P/E, divided by 1,203mn shares.
A41: Listed subsidiary
A42: MMFSL | B42: =Assumptions!$C$13 -> 0.52 | C42: MMFS IN | D42: =Assumptions!$B$13 -> 553760 | E42: =D42*B42*(1+Assumptions!$D$31)*(1+Assumptions!$D$33) -> 345546.24 | F42: ="control prem "&TEXT(Assumptions!$D$31,"0%") -> control prem 20% | G42: =E42/Assumptions!$B$6 -> 287.23711 | H42: Mcap x 52% x (1 + control premium). Control premium applied only where M&M has majority control AND monetisable optionality. Mcap refreshed to c.Rs 55,376cr (the existing note uses a stale Rs 49,553cr).
A43: Tech Mahindra | B43: =Assumptions!$C$14 -> 0.28 | C43: TECHM IN | D43: =Assumptions!$B$14 -> 1530000 | E43: =D43*B43*(1-Assumptions!$D$32)*(1+Assumptions!$D$33) -> 428400 | F43: ="stake disc "&TEXT(Assumptions!$D$32,"0%") -> stake disc 0% | G43: =E43/Assumptions!$B$6 -> 356.10973 | H43: Mcap x 28% x (1 - stake discount). No control premium — M&M does not control TechM outright. The stake discount reflects that TechM is non-core, slower-growing, and that the market has never given M&M full credit for it inside the SOTP.
A44: M&M Logistics | B44: =Assumptions!$C$15 -> 0.58 | C44: MAHLOG IN | D44: =Assumptions!$B$15 -> 41310 | E44: =D44*B44*(1+Assumptions!$D$31)*(1+Assumptions!$D$33) -> 28751.76 | F44: ="control prem "&TEXT(Assumptions!$D$31,"0%") -> control prem 20% | G44: =E44/Assumptions!$B$6 -> 23.90005 | H44: Mcap x 58% x (1 + control premium). Immaterial to the target; refresh post the FY26 rights issue.
A45: Mahindra Lifespace | B45: =Assumptions!$C$16 -> 0.51 | C45: MAHLIFE IN | D45: =Assumptions!$B$16 -> 79929 | E45: =D45*B45*(1+Assumptions!$D$31)*(1+Assumptions!$D$33) -> 48916.548 | F45: ="control prem "&TEXT(Assumptions!$D$31,"0%") -> control prem 20% | G45: =E45/Assumptions!$B$6 -> 40.662135 | H45: Mcap x 51% x (1 + control premium). A listed 'scalable gem' — already marked to market, so it does not double-count against the Growth Gems tab.
...

Sheet Sensitivity
A1: Sensitivity — where the value actually comes from
A2: Base-case listed subs, gems and holdco discount held constant unless stated.
A4: Static blocks used in the grids (base case)
A5: Listed subsidiaries (Rs/share) | B5: ='Scenario SOTP'!$D$6 -> 750.68208
A6: Growth Gems (Rs/share) | B6: ='Scenario SOTP'!$D$8 -> 225.27045
A7: Holdco discount | B7: =Assumptions!$D$39 -> 0.1
A8: FY28E core PAT (Rs mn) | B8: =Assumptions!$B$9 -> 182458
A9: Shares (mn) | B9: =Assumptions!$B$6 -> 1203
A11: GRID 1 — Target price (Rs): core P/E multiple vs MEAL value per share
A12: MEAL (Rs/sh) \ Core P/E (x) | B12: 12 | C12: 14 | D12: 16 | E12: 18 | F12: 20 | G12: 22
A13: 300 | B13: =($B$8*B$12/$B$9 + $B$5 + $A13 + $B$6)*(1-$B$7) -> 2786.3842 | C13: =($B$8*C$12/$B$9 + $B$5 + $A13 + $B$6)*(1-$B$7) -> 3059.3887 | D13: =($B$8*D$12/$B$9 + $B$5 + $A13 + $B$6)*(1-$B$7) -> 3332.3932 | E13: =($B$8*E$12/$B$9 + $B$5 + $A13 + $B$6)*(1-$B$7) -> 3605.3977 | F13: =($B$8*F$12/$B$9 + $B$5 + $A13 + $B$6)*(1-$B$7) -> 3878.4022 | G13: =($B$8*G$12/$B$9 + $B$5 + $A13 + $B$6)*(1-$B$7) -> 4151.4067 | J13: Read across a row to see the core-multiple risk; read down a column to see the MEAL methodology risk. The vertical spread (c.Rs 750/share from MEAL alone) is wider than the horizontal spread across a 10-turn P/E range — that is the whole argument for treating MEAL as the primary axis rather than a fixed block.
A14: 450 | B14: =($B$8*B$12/$B$9 + $B$5 + $A14 + $B$6)*(1-$B$7) -> 2921.3842 | C14: =($B$8*C$12/$B$9 + $B$5 + $A14 + $B$6)*(1-$B$7) -> 3194.3887 | D14: =($B$8*D$12/$B$9 + $B$5 + $A14 + $B$6)*(1-$B$7) -> 3467.3932 | E14: =($B$8*E$12/$B$9 + $B$5 + $A14 + $B$6)*(1-$B$7) -> 3740.3977 | F14: =($B$8*F$12/$B$9 + $B$5 + $A14 + $B$6)*(1-$B$7) -> 4013.4022 | G14: =($B$8*G$12/$B$9 + $B$5 + $A14 + $B$6)*(1-$B$7) -> 4286.4067
A15: 550 | B15: =($B$8*B$12/$B$9 + $B$5 + $A15 + $B$6)*(1-$B$7) -> 3011.3842 | C15: =($B$8*C$12/$B$9 + $B$5 + $A15 + $B$6)*(1-$B$7) -> 3284.3887 | D15: =($B$8*D$12/$B$9 + $B$5 + $A15 + $B$6)*(1-$B$7) -> 3557.3932 | E15: =($B$8*E$12/$B$9 + $B$5 + $A15 + $B$6)*(1-$B$7) -> 3830.3977 | F15: =($B$8*F$12/$B$9 + $B$5 + $A15 + $B$6)*(1-$B$7) -> 4103.4022 | G15: =($B$8*G$12/$B$9 + $B$5 + $A15 + $B$6)*(1-$B$7) -> 4376.4067
A16: 700 | B16: =($B$8*B$12/$B$9 + $B$5 + $A16 + $B$6)*(1-$B$7) -> 3146.3842 | C16: =($B$8*C$12/$B$9 + $B$5 + $A16 + $B$6)*(1-$B$7) -> 3419.3887 | D16: =($B$8*D$12/$B$9 + $B$5 + $A16 + $B$6)*(1-$B$7) -> 3692.3932 | E16: =($B$8*E$12/$B$9 + $B$5 + $A16 + $B$6)*(1-$B$7) -> 3965.3977 | F16: =($B$8*F$12/$B$9 + $B$5 + $A16 + $B$6)*(1-$B$7) -> 4238.4022 | G16: =($B$8*G$12/$B$9 + $B$5 + $A16 + $B$6)*(1-$B$7) -> 4511.4067
A17: 850 | B17: =($B$8*B$12/$B$9 + $B$5 + $A17 + $B$6)*(1-$B$7) -> 3281.3842 | C17: =($B$8*C$12/$B$9 + $B$5 + $A17 + $B$6)*(1-$B$7) -> 3554.3887 | D17: =($B$8*D$12/$B$9 + $B$5 + $A17 + $B$6)*(1-$B$7) -> 3827.3932 | E17: =($B$8*E$12/$B$9 + $B$5 + $A17 + $B$6)*(1-$B$7) -> 4100.3977 | F17: =($B$8*F$12/$B$9 + $B$5 + $A17 + $B$6)*(1-$B$7) -> 4373.4022 | G17: =($B$8*G$12/$B$9 + $B$5 + $A17 + $B$6)*(1-$B$7) -> 4646.4067
A18: 1000 | B18: =($B$8*B$12/$B$9 + $B$5 + $A18 + $B$6)*(1-$B$7) -> 3416.3842 | C18: =($B$8*C$12/$B$9 + $B$5 + $A18 + $B$6)*(1-$B$7) -> 3689.3887 | D18: =($B$8*D$12/$B$9 + $B$5 + $A18 + $B$6)*(1-$B$7) -> 3962.3932 | E18: =($B$8*E$12/$B$9 + $B$5 + $A18 + $B$6)*(1-$B$7) -> 4235.3977 | F18: =($B$8*F$12/$B$9 + $B$5 + $A18 + $B$6)*(1-$B$7) -> 4508.4022 | G18: =($B$8*G$12/$B$9 + $B$5 + $A18 + $B$6)*(1-$B$7) -> 4781.4067
A19: 1150 | B19: =($B$8*B$12/$B$9 + $B$5 + $A19 + $B$6)*(1-$B$7) -> 3551.3842 | C19: =($B$8*C$12/$B$9 + $B$5 + $A19 + $B$6)*(1-$B$7) -> 3824.3887 | D19: =($B$8*D$12/$B$9 + $B$5 + $A19 + $B$6)*(1-$B$7) -> 4097.3932 | E19: =($B$8*E$12/$B$9 + $B$5 + $A19 + $B$6)*(1-$B$7) -> 4370.3977 | F19: =($B$8*F$12/$B$9 + $B$5 + $A19 + $B$6)*(1-$B$7) -> 4643.4022 | G19: =($B$8*G$12/$B$9 + $B$5 + $A19 + $B$6)*(1-$B$7) -> 4916.4067
A22: GRID 2 — Target price (Rs): holdco discount vs Growth Gems value per share
A23: Gems (Rs/sh) \ Holdco discount | B23: 0 | C23: 0.05 | D23: 0.1 | E23: 0.15 | F23: 0.2 | G23: 0.25
A24: 160 | B24: =('Scenario SOTP'!$D$5 + $B$5 + 'Scenario SOTP'!$D$7 + $A24)*(1-B$23) -> 4182.5162 | C24: =('Scenario SOTP'!$D$5 + $B$5 + 'Scenario SOTP'!$D$7 + $A24)*(1-C$23) -> 3973.3904 | D24: =('Scenario SOTP'!$D$5 + $B$5 + 'Scenario SOTP'!$D$7 + $A24)*(1-D$23) -> 3764.2646 | E24: =('Scenario SOTP'!$D$5 + $B$5 + 'Scenario SOTP'!$D$7 + $A24)*(1-E$23) -> 3555.1388 | F24: =('Scenario SOTP'!$D$5 + $B$5 + 'Scenario SOTP'!$D$7 + $A24)*(1-F$23) -> 3346.013 | G24: =('Scenario SOTP'!$D$5 + $B$5 + 'Scenario SOTP'!$D$7 + $A24)*(1-G$23) -> 3136.8872 | J24: Gems and the holdco discount are linked, not independent: every crystallised listing raises the gems value AND narrows the discount, so the realistic path runs diagonally from bottom-left to top-right. Rs 160/sh at a 20% discount is roughly where the market prices M&M today; Rs 300/sh at 5% is the LMM-IPO-plus-Susten-InvIT outcome.
A25: 200 | B25: =('Scenario SOTP'!$D$5 + $B$5 + 'Scenario SOTP'!$D$7 + $A25)*(1-B$23) -> 4222.5162 | C25: =('Scenario SOTP'!$D$5 + $B$5 + 'Scenario SOTP'!$D$7 + $A25)*(1-C$23) -> 4011.3904 | D25: =('Scenario SOTP'!$D$5 + $B$5 + 'Scenario SOTP'!$D$7 + $A25)*(1-D$23) -> 3800.2646 | E25: =('Scenario SOTP'!$D$5 + $B$5 + 'Scenario SOTP'!$D$7 + $A25)*(1-E$23) -> 3589.1388 | F25: =('Scenario SOTP'!$D$5 + $B$5 + 'Scenario SOTP'!$D$7 + $A25)*(1-F$23) -> 3378.013 | G25: =('Scenario SOTP'!$D$5 + $B$5 + 'Scenario SOTP'!$D$7 + $A25)*(1-G$23) -> 3166.8872
A26: 250 | B26: =('Scenario SOTP'!$D$5 + $B$5 + 'Scenario SOTP'!$D$7 + $A26)*(1-B$23) -> 4272.5162 | C26: =('Scenario SOTP'!$D$5 + $B$5 + 'Scenario SOTP'!$D$7 + $A26)*(1-C$23) -> 4058.8904 | D26: =('Scenario SOTP'!$D$5 + $B$5 + 'Scenario SOTP'!$D$7 + $A26)*(1-D$23) -> 3845.2646 | E26: =('Scenario SOTP'!$D$5 + $B$5 + 'Scenario SOTP'!$D$7 + $A26)*(1-E$23) -> 3631.6388 | F26: =('Scenario SOTP'!$D$5 + $B$5 + 'Scenario SOTP'!$D$7 + $A26)*(1-F$23) -> 3418.013 | G26: =('Scenario SOTP'!$D$5 + $B$5 + 'Scenario SOTP'!$D$7 + $A26)*(1-G$23) -> 3204.3872
A27: 300 | B27: =('Scenario SOTP'!$D$5 + $B$5 + 'Scenario SOTP'!$D$7 + $A27)*(1-B$23) -> 4322.5162 | C27: =('Scenario SOTP'!$D$5 + $B$5 + 'Scenario SOTP'!$D$7 + $A27)*(1-C$23) -> 4106.3904 | D27: =('Scenario SOTP'!$D$5 + $B$5 + 'Scenario SOTP'!$D$7 + $A27)*(1-D$23) -> 3890.2646 | E27: =('Scenario SOTP'!$D$5 + $B$5 + 'Scenario SOTP'!$D$7 + $A27)*(1-E$23) -> 3674.1388 | F27: =('Scenario SOTP'!$D$5 + $B$5 + 'Scenario SOTP'!$D$7 + $A27)*(1-F$23) -> 3458.013 | G27: =('Scenario SOTP'!$D$5 + $B$5 + 'Scenario SOTP'!$D$7 + $A27)*(1-G$23) -> 3241.8872
A28: 400 | B28: =('Scenario SOTP'!$D$5 + $B$5 + 'Scenario SOTP'!$D$7 + $A28)*(1-B$23) -> 4422.5162 | C28: =('Scenario SOTP'!$D$5 + $B$5 + 'Scenario SOTP'!$D$7 + $A28)*(1-C$23) -> 4201.3904 | D28: =('Scenario SOTP'!$D$5 + $B$5 + 'Scenario SOTP'!$D$7 + $A28)*(1-D$23) -> 3980.2646 | E28: =('Scenario SOTP'!$D$5 + $B$5 + 'Scenario SOTP'!$D$7 + $A28)*(1-E$23) -> 3759.1388 | F28: =('Scenario SOTP'!$D$5 + $B$5 + 'Scenario SOTP'!$D$7 + $A28)*(1-F$23) -> 3538.013 | G28: =('Scenario SOTP'!$D$5 + $B$5 + 'Scenario SOTP'!$D$7 + $A28)*(1-G$23) -> 3316.8872
A29: 500 | B29: =('Scenario SOTP'!$D$5 + $B$5 + 'Scenario SOTP'!$D$7 + $A29)*(1-B$23) -> 4522.5162 | C29: =('Scenario SOTP'!$D$5 + $B$5 + 'Scenario SOTP'!$D$7 + $A29)*(1-C$23) -> 4296.3904 | D29: =('Scenario SOTP'!$D$5 + $B$5 + 'Scenario SOTP'!$D$7 + $A29)*(1-D$23) -> 4070.2646 | E29: =('Scenario SOTP'!$D$5 + $B$5 + 'Scenario SOTP'!$D$7 + $A29)*(1-E$23) -> 3844.1388 | F29: =('Scenario SOTP'!$D$5 + $B$5 + 'Scenario SOTP'!$D$7 + $A29)*(1-F$23) -> 3618.013 | G29: =('Scenario SOTP'!$D$5 + $B$5 + 'Scenario SOTP'!$D$7 + $A29)*(1-G$23) -> 3391.8872
A32: CATALYST WATCHLIST — what moves you between scenarios
A33: Catalyst | B33: Timing | C33: Axis affected | J33: Why it matters / what to watch
A34: LMM IPO | B34: H2 2027 | C34: Gems + holdco discount | J34: Prices the largest unlisted gem against its Rs 10,822cr Jul-26 mark. A listing above the mark validates the whole private-mark approach and pulls the holdco discount toward 5%; a listing below it is the first real evidence the gem marks are optimistic.
A35: Fresh priced MEAL round or MEAL IPO | B35: Open | C35: MEAL — decisive | J35: THE definitive test. Anywhere near the funding-round mark justifies moving base toward Rs 4,300-4,500; anywhere near the Rs 40,425cr CCPS conversion value caps fair value nearer Rs 3,200-3,400.
A36: Susten InvIT | B36: Open | C36: Gems + holdco discount | J36: Crystallises a yield-based mark on the second-largest gem and creates a repeatable monetisation template.
A37: Born-Electric monthly volumes | B37: Monthly | C37: MEAL | J37: Sustained >6,000/month on the 8k/month Chakan capacity, with EV margins consistently EBIT-positive, is what earns the move from 3x to a premium EV/sales multiple. FY26 e-SUV EBITDA margin 9.1%, EBIT 2.0% — thin.
A38: Core SUV and tractor share / margins | B38: Quarterly | C38: Core multiple | J38: 25.3% SUV revenue share and 43.6% tractor share are the highest-ever. The 18x base assumes these hold. Watch Tata, Maruti (e-Vitara, Victoris), Toyota and Kia, plus CAFE-III compliance cost.
A39: New capital into loss-making bets | B39: Ongoing | C39: Holdco discount | J39: The Manulife 50:50 life-insurance JV (each partner up to US$400m) is the test case. The 18% ROE hurdle is the whole reason the market gives M&M credit — capital going somewhere it cannot clear that hurdle widens the discount.
